Workbook

Sheet Cost File
B1: $/lb (2023) | C1: $/lb (2025) | D1: $/lb (2026) | E1: $/lb (2026) V1 | F1: Facad Adder | G1: Plt
A2: CS CARBOGRIND NANO 370-018 25KG (55LB) | B2: =15.6/2.205 -> 7.0748299 | C2: 6.17 | D2: =12.5/2.205 -> 5.6689342 | E2: =12.5/2.205 -> 5.6689342 | G2: Buy/Resale | I2: Xieta | J2: recent from Albert
A3: CS CARBOGRIND XT 360-100 25KG (55LB) | B3: 2.04 | C3: 2.04 | D3: =3.85/2.205 -> 1.7460317 | E3: =3.85/2.205 -> 1.7460317 | G3: Buy/Resale | I3: Xieta
A4: CS CARBOGRIND XT 360-300 BB-2205 | B4: 0.76 | C4: 1.03 | D4: =1.62/2.205 -> 0.73469388 | E4: =1.62/2.205 -> 0.73469388 | G4: Buy/Resale | I4: Xieta
A5: CS CARBOGRIND XT 360-400 25KG (55LB) | B5: 0.76 | C5: 1.27 | D5: =1.57/2.205 -> 0.71201814 | E5: =1.57/2.205 -> 0.71201814 | G5: Buy/Resale | I5: Xieta
A6: CS CARBOGRIND ZIRPLUS 340-030 BB-2205 | B6: =1750/2205 -> 0.79365079 | C6: 1.25 | D6: =1750/2205 -> 0.79365079 | E6: =1750/2205 -> 0.79365079 | G6: Buy/Resale | I6: Dakot
A7: FUSION ACTIVATOR C - 9.476 LB/GAL | B7: 8.12 | D7: 8.12 | E7: 8.12 | G7: Buy/Resale | I7: Riteks
A8: EP30/50 (LD30) | D8: =0.2189 -> 0.2189 | E8: 0.233 | F8: =E8+'Operations Adder'!$I$5 -> 0.25997576 | G8: EUF
A9: ACCUCAST LB BULK BAG | B9: 0.23 | C9: =0.19+0.03 -> 0.22 | D9: =0.2282+0.02 -> 0.2482 | E9: =0.2407+0.02 -> 0.2607 | F9: =E9+'Operations Adder'!$I$5 -> 0.28767576 | G9: EUF
A10: ACCUCAST LD 10 BULK BAG | B10: 0.23 | C10: =0.19+0.03 -> 0.22 | D10: =0.2282+0.03 -> 0.2582 | E10: =0.2407+0.02 -> 0.2607 | F10: =E10+'Operations Adder'!$I$5 -> 0.28767576 | G10: EUF
A11: ACCUCAST LD 40 BULK BAG | B11: 0.16 | C11: =0.16+0.03 -> 0.19 | D11: =0.2224+0.02 -> 0.2424 | E11: =0.2795+0.02 -> 0.2995 | F11: =E11+'Operations Adder'!$I$5 -> 0.32647576 | G11: EUF
A12: ACCUCAST LD 45 50LB BAG | B12: 0.16 | C12: =0.16+0.03 -> 0.19 | D12: =0.2224+0.05 -> 0.2724 | E12: =0.2795+0.05 -> 0.3295 | F12: =E12+'Operations Adder'!$I$5 -> 0.35647576 | G12: EUF
A13: CARBOBEAD SCOUR 12/18 BULK BAG | B13: 0.28 | C13: =0.19+0.03 -> 0.22 | D13: =0.233+0.02 -> 0.253 | E13: =0.2842+0.02 -> 0.3042 | F13: =E13+'Operations Adder'!$I$5 -> 0.33117576 | G13: EUF
A14: CARBOBEAD SCOUR 16/20 BULK BAG | B14: 0.23 | C14: =0.19+0.03 -> 0.22 | D14: =0.2282+0.02 -> 0.2482 | E14: =0.2407+0.02 -> 0.2607 | F14: =E14+'Operations Adder'!$I$5 -> 0.28767576 | G14: EUF
A15: CARBOBEAD-LT 12/18 BULK BAG | B15: 0.28 | C15: =0.19+0.03 -> 0.22 | D15: =0.233+0.02 -> 0.253 | E15: =0.2842+0.02 -> 0.3042 | F15: =E15+'Operations Adder'!$I$5 -> 0.33117576 | G15: EUF
A16: CARBOBEAD-LT 16/20 50LB BAG | B16: 0.23 | C16: =0.19+0.03 -> 0.22 | D16: =0.2282+0.05 -> 0.2782 | E16: =0.2407+0.05 -> 0.2907 | F16: =E16+'Operations Adder'!$I$5 -> 0.31767576 | G16: EUF
A17: CARBOBEAD-LT 16/20 BULK BAG | B17: 0.23 | C17: =0.19+0.03 -> 0.22 | D17: =0.2282+0.02 -> 0.2482 | E17: =0.2407+0.02 -> 0.2607 | F17: =E17+'Operations Adder'!$I$5 -> 0.28767576 | G17: EUF
A18: CARBOBEAD-LT 20/40 BULK BAG | B18: 0.23 | C18: =0.19+0.03 -> 0.22 | D18: =0.2224+0.02 -> 0.2424 | E18: =0.2432+0.02 -> 0.2632 | F18: =E18+'Operations Adder'!$I$5 -> 0.29017576 | G18: EUF
A19: CARBOGRIND 260-006 25KG BAG (55LB) | B19: 0.23 | C19: =0.19+0.03 -> 0.22 | D19: =0.2224+0.05 -> 0.2724 | E19: =0.2432+0.05 -> 0.2932 | F19: =E19+'Operations Adder'!$I$5 -> 0.32017576 | G19: EUF
A20: CARBOGRIND 260-008 25KG BAG (55LB) | B20: 0.23 | C20: =0.19+0.03 -> 0.22 | D20: =0.2224+0.05 -> 0.2724 | E20: =0.2432+0.05 -> 0.2932 | F20: =E20+'Operations Adder'!$I$5 -> 0.32017576 | G20: EUF
A21: CARBOGRIND 260-008 BULK BAG | B21: 0.23 | C21: =0.19+0.03 -> 0.22 | D21: =0.2224+0.02 -> 0.2424 | E21: =0.2423+0.02 -> 0.2623 | F21: =E21+'Operations Adder'!$I$5 -> 0.28927576 | G21: EUF
A22: CARBOGRIND 260-010 25KG BAG (55LB) | B22: 0.23 | C22: =0.19+0.03 -> 0.22 | D22: =0.2282+0.05 -> 0.2782 | E22: =0.2007+0.05 -> 0.2507 | F22: =E22+'Operations Adder'!$I$5 -> 0.27767576 | G22: EUF
A23: CARBOGRIND 260-010 BULK BAG | B23: 0.23 | C23: =0.19+0.03 -> 0.22 | D23: =0.2282+0.02 -> 0.2482 | E23: =0.2077+0.02 -> 0.2277 | F23: =E23+'Operations Adder'!$I$5 -> 0.25467576 | G23: EUF
A24: CARBOGRIND 260-015 25KG BAG (55LB) | B24: 0.28 | C24: =0.19+0.03 -> 0.22 | D24: =0.233+0.05 -> 0.283 | E24: =0.2842+0.05 -> 0.3342 | F24: =E24+'Operations Adder'!$I$5 -> 0.36117576 | G24: EUF
A25: CARBOGRIND 260-015 BULK BAG | B25: 0.28 | C25: =0.19+0.03 -> 0.22 | D25: =0.233+0.02 -> 0.253 | E25: =0.2842+0.02 -> 0.3042 | F25: =E25+'Operations Adder'!$I$5 -> 0.33117576 | G25: EUF
A26: CARBOGRIND 260-020 25KG BAG (55LB) | B26: 0.3 | C26: =0.19+0.03 -> 0.22 | D26: =0.233+0.05 -> 0.283 | E26: =0.2432+0.05 -> 0.2932 | F26: =E26+'Operations Adder'!$I$5 -> 0.32017576 | G26: EUF
A27: CARBOGRIND 260-020 3.5 GALLON (40lb) | B27: 0.3 | C27: =0.19+0.03 -> 0.22 | D27: =0.233+0.05 -> 0.283 | E27: =0.2432+0.05 -> 0.2932 | F27: =E27+'Operations Adder'!$I$5 -> 0.32017576 | G27: EUF
A28: CARBOGRIND 260-020 BULK BAG | B28: 0.3 | C28: =0.19+0.03 -> 0.22 | D28: =0.233+0.02 -> 0.253 | E28: =0.2432+0.02 -> 0.2632 | F28: =E28+'Operations Adder'!$I$5 -> 0.29017576 | G28: EUF
A29: CARBOGRIND 260-030 25KG BAG (55LB) | B29: 0.3 | C29: =0.19+0.03 -> 0.22 | D29: =0.2445+0.05 -> 0.2945 | E29: =0.2432+0.05 -> 0.2932 | F29: =E29+'Operations Adder'!$I$5 -> 0.32017576 | G29: EUF
A30: CARBOGRIND 260-030 BULK BAG | B30: 0.3 | C30: =0.19+0.03 -> 0.22 | D30: =0.2445+0.02 -> 0.2645 | E30: =0.2432+0.02 -> 0.2632 | F30: =E30+'Operations Adder'!$I$5 -> 0.29017576 | G30: EUF
A31: CARBOGRIND 280-030 BULK BAG | B31: 0.54 | C31: =0.4225+0.03 -> 0.4525 | D31: =0.4681+0.05 -> 0.5181 | E31: =0.4556+0.02 -> 0.4756 | F31: =E31+'Operations Adder'!$I$5 -> 0.50257576 | G31: EUF
A32: CARBO LITE 12/18 | B32: 0.28 | C32: =0.19 -> 0.19 | D32: =0.233 -> 0.233 | E32: 0.2842 | F32: =E32+'Operations Adder'!$I$5 -> 0.31117576 | G32: EUF
A33: CARBO LITE 12/18 Bulk Bag | B33: 0.28 | C33: =0.19+0.03 -> 0.22 | D33: =0.233+0.05 -> 0.283 | E33: =0.2842+0.02 -> 0.3042 | F33: =E33+'Operations Adder'!$I$5 -> 0.33117576 | G33: EUF
A34: CARBONRT CL 16/30-FP | B34: 0.4 | C34: 0.4 | D34: =0.6162 -> 0.6162 | E34: =0.5372 -> 0.5372 | F34: =E34+'Operations Adder'!$I$5 -> 0.56417576 | G34: EUF
A35: CARBONRT CL 20/40 | B35: 0.45 | C35: 0.45 | D35: =0.5104 -> 0.5104 | E35: =0.5372 -> 0.5372 | F35: =E35+'Operations Adder'!$I$5 -> 0.56417576 | G35: EUF
A36: CARBONRT CP 30/50 Bulk Bag | B36: 0.45 | C36: 0.45 | D36: =0.5104 -> 0.5104 | E36: =0.5372+0.04+0.02 -> 0.5972 | F36: =E36+'Operations Adder'!$I$6 -> 0.62339979 | G36: MCI
A37: CARBONRT KRYPTOSPHERE LD 35 BULK BAG | B37: 0.65 | C37: 0.65 | D37: =0.7147+0.02 -> 0.7347 | E37: =0.7585+0.02 -> 0.7785 | F37: =E37+'Operations Adder'!$I$5 -> 0.80547576 | G37: EUF
A38: KRYPTOSPHERE HD (B) 25 | B38: 0.95 | C38: 1.08 | D38: =0.9406 -> 0.9406 | E38: =0.9341 -> 0.9341 | F38: =E38+'Operations Adder'!$I$5 -> 0.96107576 | G38: EUF
A39: KRYPTOSPHERE LD 25 BULK BAG | B39: 0.55 | C39: =0.46+0.03 -> 0.49 | D39: =0.4447+0.02 -> 0.4647 | E39: =0.4236+0.02 -> 0.4436 | F39: =E39+'Operations Adder'!$I$5 -> 0.47057576 | G39: EUF
A40: KRYPTOSPHERE XT 25 | B40: 0.57 | C40: =0.5 -> 0.5 | D40: =0.4447+0.005 -> 0.4497 | E40: =0.4236+0.005 -> 0.4286 | F40: =E40+'Operations Adder'!$I$5 -> 0.45557576 | G40: EUF
...

Sheet Operations Adder
E3: Volume | F3: Facad | G3: Facad General | H3: Distribution | I3: Total
C4: NIL | D4: 572475 | E4: 13700000 | F4: =$D4/$E$14 -> 0.0018185933 | G4: {=SUM($D$8:$D$12/$E$14)} -> 0.004803793 | H4: =$D$13/$E$15 -> 0.019280681 | I4: =SUM(F4:H4) -> 0.025903067
C5: EUF | D5: 910149 | E5: 43750000 | F5: =$D5/$E$14 -> 0.0028912894 | G5: {=SUM($D$8:$D$12/$E$14)} -> 0.004803793 | H5: =$D$13/$E$15 -> 0.019280681 | I5: =SUM(F5:H5) -> 0.026975763
C6: MCI | D6: 665881 | E6: 56200000 | F6: =$D6/$E$14 -> 0.0021153181 | G6: {=SUM($D$8:$D$12/$E$14)} -> 0.004803793 | H6: =$D$13/$E$15 -> 0.019280681 | I6: =SUM(F6:H6) -> 0.026199792
C7: TMB | D7: 734633 | E7: 201140000 | F7: =$D7/$E$14 -> 0.0023337241 | G7: {=SUM($D$8:$D$12/$E$14)} -> 0.004803793 | H7: =$D$13/$E$15 -> 0.019280681 | I7: =SUM(F7:H7) -> 0.026418198
C8: NI Plant 1 | D8: 14184
C9: QC (Global) | D9: 151129
C10: EHS (Global) | D10: 455159
C11: VP Ops | D11: 259133
C12: L&M | D12: 632581
C13: Distribution | D13: 5653825
D14: Total Prod Volume: | E14: 314790000 | G14: 7166011
D15: Total Sales Volume | E15: 293237829 | G15: 2883138
F16: Sum | G16: 10049149
