Workbook

Sheet NI RC 2025 Std
A1: New Iberia Resin Coating
A2: 2025 STANDARDS
B3: CARBOBond Lite | E3: CARBOBond Lite EU | H3: CARBOBond KSLD | K3: RPM LITE / NEUTRAPROP LWC | N3: CARBOBond HSP | Q3: CARBO AIR
B4: 24 Standard | C4: 23 Actual | D4: 22 Standard | E4: 24 Standard | F4: 23 Actual | G4: 22 Standard | H4: 24 Standard | I4: 23 Actual | J4: 22 Standard | K4: 24 Standard | L4: 23 Actual | M4: 22 Standard | N4: 24 Standard | O4: 23 Actual | P4: 22 Standard | Q4: 24 Standard | R4: 23 Actual | S4: =+D4 -> 22 Standard
C5: Jan | F5: Jan | I5: (Aug) | L5: (Jan) | O5: (Aug) | R5: (Jan-Aug)
A6: Materials - Substrate | B6: =E119 -> 0.21293144 | C6: 0.261 | D6: 0.1639529 | E6: =G119 -> 0.21706426 | F6: 0.259 | G6: 0.18884365 | H6: =+I119 -> 0.52154785 | I6: 0.4369 | J6: 0.41938749 | K6: =K119 -> 0.2149 | L6: 0.1827 | M6: 0.15362762 | N6: =+M100 -> 0 | O6: 0.431 | P6: 0.80389422 | Q6: =+O98 -> 0.30469739 | R6: 0.15968841 | S6: 0.19086145
A7: Materials - Substrate Under-Absorption | B7: =$C97*D97 -> 0 | D7: 0 | E7: =$C97*F97 -> 0 | G7: 0 | H7: =$C97*I97 -> 0 | J7: 0 | K7: =$C97*J97 -> 0 | M7: 0.094857323 | N7: =$C97*O97 -> 0 | P7: 0
A8: Materials - Resin & Chemicals | B8: =E120+E121 -> 0.050440017 | C8: 0.0667 | D8: 0.038078 | E8: =G120+G121 -> 0.064046066 | F8: 0.0652 | G8: 0.060015662 | H8: =+I120+I121 -> 0.076234045 | I8: =0.5149-I6 -> 0.078 | J8: 0.056384154 | K8: =K120+K121 -> 0.2181838 | L8: =0.2569-L6 -> 0.0742 | M8: 0.15903358 | N8: =+M120+M121 -> 0.087444565 | O8: =0.5164-O6 -> 0.0854 | P8: 0.056384154 | Q8: =+O120+O121 -> 0.10145692 | R8: 0.072759577 | S8: 0.087415456
A9: Electricity | B9: =E164 -> 0.0083887564 | C9: 0.0019 | D9: 0.0059095494 | E9: =G164 -> 0.010531407 | F9: 0.0019 | G9: 0.0092314722 | H9: =J164 -> 0.06212471 | I9: 0.0088 | J9: 0.043221874 | K9: =K164 -> 0.018513164 | L9: 0.0117 | M9: 0.010135435 | N9: =+M164 -> 0.0088229437 | O9: 0.0088 | P9: 0.006738662 | Q9: =+O164 -> 0.011271451 | R9: 0.006525594 | S9: 0.0089969295
A10: Gas | B10: =E165 -> 0.0017786261 | C10: 0.004 | D10: 0.0013242333 | E10: =G165 -> 0.001820037 | F10: 0.0041 | G10: 0.00153375 | H10: =J165 -> 0.00023681914 | I10: 0.0038 | J10: 0.00029427407 | K10: =K165 -> 0.0012487474 | L10: 0.0011 | M10: 0.0011247591 | N10: =+M165 -> 0.0038181212 | O10: 0.0038 | P10: 0.0013537383 | Q10: =+O165 -> 0.0033852574 | R10: 0.0011625955 | S10: 0.0038428259
A11: R&M Supplies and Service | B11: =$H$180 -> 0.016297262 | C11: 0.0016 | D11: 0.006 | E11: =$H$180 -> 0.016297262 | F11: 0.0016 | G11: 0.0031413613 | H11: =$H$180 -> 0.016297262 | I11: 0.0094 | J11: 0.0031413613 | K11: =$H$180 -> 0.016297262 | L11: 0.0076 | M11: 0.0086705202 | N11: =$H$180 -> 0.016297262 | O11: 0.0094 | P11: 0.0031413613 | Q11: =$H$180 -> 0.016297262 | R11: 0.016241103 | S11: 0.0031413613
A12: Manufacturing Supplies | B12: =$H$183 -> 0.001303781 | C12: 0 | D12: 0.002 | E12: =$H$183 -> 0.001303781 | F12: 0 | G12: 0.0002617801 | H12: =$H$183 -> 0.001303781 | I12: 0.0003 | J12: 0.0002617801 | K12: =$H$183 -> 0.001303781 | L12: 0.0002 | M12: 0.00043352601 | N12: =$H$183 -> 0.001303781 | O12: 0.0003 | P12: 0.0002617801 | Q12: =$H$183 -> 0.001303781 | R12: 0.00053366327 | S12: 0.0002617801
A13: Other variable | B13: =$H$186 -> 0.022816167 | C13: 0.005 | D13: 0.006 | E13: =$H$186 -> 0.022816167 | F13: 0.0052 | G13: 0.0039267016 | H13: =$H$186 -> 0.022816167 | I13: 0.0134 | J13: 0.0039267016 | K13: =$H$186 -> 0.022816167 | L13: 0.0035 | M13: 0.0057803468 | N13: =$H$186 -> 0.022816167 | O13: 0.0134 | P13: 0.0039267016 | Q13: =$H$186 -> 0.022816167 | R13: 0.0059964109 | S13: 0.0039267016
A14: Total Variable Costs | B14: =SUM(B6:B13) -> 0.31395605 | C14: =SUM(C6:C13) -> 0.3402 | D14: =SUM(D6:D13) -> 0.22326468 | E14: =SUM(E6:E13) -> 0.33387898 | F14: =SUM(F6:F13) -> 0.337 | G14: =SUM(G6:G13) -> 0.26695437 | H14: =SUM(H6:H13) -> 0.70056064 | I14: =SUM(I6:I13) -> 0.5506 | ... L14: =SUM(L6:L13) -> 0.281 | M14: 0.43366311 | N14: =SUM(N6:N13) -> 0.14050284 | O14: =SUM(O6:O13) -> 0.5521 | P14: =SUM(P6:P13) -> 0.87570062 | Q14: =SUM(Q6:Q13) -> 0.46122824 | R14: =SUM(R6:R13) -> 0.26290735 | S14: 0.33373539
A16: Production Labor | B16: =$D$217/$B$64/1000 -> 0.048558141 | C16: 0.0165 | D16: 0.035940795 | E16: =$D$217/$B$64/1000 -> 0.048558141 | F16: 0.0165 | G16: 0.016663174 | H16: =$D$217/$B$64/1000 -> 0.048558141 | I16: 0.0283 | J16: 0.016663174 | K16: =$D$217/$B$64/1000 -> 0.048558141 | L16: 0.0095 | M16: 0.011741675 | N16: =$D$217/$B$64/1000 -> 0.048558141 | O16: 0.0283 | P16: 0.016663174 | Q16: =$D$217/$B$64/1000 -> 0.048558141 | R16: 0.013727223 | S16: 0.016663174
A17: Repairs & Maintenance Labor | B17: =$G$217/$B$64/1000 -> 0.015673026 | C17: 0.007 | D17: 0.0113712 | E17: =$G$217/$B$64/1000 -> 0.015673026 | F17: 0.007 | G17: 0.0040701571 | H17: =$G$217/$B$64/1000 -> 0.015673026 | I17: 0.0072 | J17: 0.0040701571 | K17: =$G$217/$B$64/1000 -> 0.015673026 | L17: 0.005 | M17: 0.0041080925 | N17: =$G$217/$B$64/1000 -> 0.015673026 | O17: 0.0072 | P17: 0.0040701571 | Q17: =$G$217/$B$64/1000 -> 0.015673026 | R17: 0.0016693747 | S17: 0.0040701571
A18: Indirect Payroll Costs (Benefits) | B18: =$J$217/$B$64/1000 -> 0.020872242 | C18: 0.0114 | D18: 0.014188877 | E18: =$J$217/$B$64/1000 -> 0.020872242 | F18: 0.0114 | G18: 0.0073786377 | H18: =$J$217/$B$64/1000 -> 0.020872242 | I18: 0.0071 | J18: 0.0073786377 | K18: =$J$217/$B$64/1000 -> 0.020872242 | L18: 0.0111 | M18: 0.0072598437 | N18: =$J$217/$B$64/1000 -> 0.020872242 | O18: 0.0071 | P18: 0.0073786377 | Q18: =$J$217/$B$64/1000 -> 0.020872242 | R18: 0.0056633179 | S18: 0.0073786377
A19: Supervision | B19: =$E$243 -> 0.0054291551 | C19: 0.035 | D19: 0 | E19: =$E$243 -> 0.0054291551 | F19: 0.0035 | G19: 0.0040554974 | H19: =$E$243 -> 0.0054291551 | I19: 0.002 | J19: 0.0040554974 | K19: =$E$243 -> 0.0054291551 | L19: 0.0073 | M19: 0.002449852 | N19: =$E$243 -> 0.0054291551 | O19: 0.002 | P19: 0.0040554974 | Q19: =$E$243 -> 0.0054291551 | R19: 0.0023710733 | S19: 0.0040554974
A20: Depreciation | B20: =$E$244 -> 0.0073063885 | C20: 0.0053 | D20: 0.01039048 | E20: =$E$244 -> 0.0073063885 | F20: 0.0053 | G20: 0.0029340314 | H20: =$E$244 -> 0.0073063885 | I20: 0.0038 | J20: 0.0029340314 | K20: =$E$244 -> 0.0073063885 | L20: 0.0058 | M20: 0.06367052 | N20: =$E$244 -> 0.0073063885 | O20: 0.0038 | P20: 0.0029340314 | Q20: =$E$244 -> 0.0073063885 | R20: 0.064182394 | S20: 0.0029340314
A21: Insurance & Taxes | B21: =$E$245 -> 0.02589309 | C21: 0.0168 | D21: 0.03763008 | E21: =$E$245 -> 0.02589309 | F21: 0.0168 | G21: 0.014736126 | H21: =$E$245 -> 0.02589309 | I21: 0.0135 | J21: 0.014736126 | K21: =$E$245 -> 0.02589309 | L21: 0.0037 | M21: 0.014046243 | N21: =$E$245 -> 0.02589309 | O21: 0.0135 | P21: 0.014736126 | Q21: =$E$245 -> 0.02589309 | R21: 0.015675972 | S21: 0.014736126
A22: Total Fixed Costs | B22: =SUM(B16:B21) -> 0.12373204 | C22: =SUM(C16:C21) -> 0.092 | D22: =SUM(D16:D21) -> 0.10952143 | E22: =SUM(E16:E21) -> 0.12373204 | F22: =SUM(F16:F21) -> 0.0605 | G22: =SUM(G16:G21) -> 0.049837623 | H22: =SUM(H16:H21) -> 0.12373204 | I22: =SUM(I16:I21) -> 0.0619 | ... L22: =SUM(L16:L21) -> 0.0424 | M22: 0.10327623 | N22: =SUM(N16:N21) -> 0.12373204 | O22: =SUM(O16:O21) -> 0.0619 | P22: =SUM(P16:P21) -> 0.049837623 | Q22: =SUM(Q16:Q21) -> 0.12373204 | R22: =SUM(R16:R21) -> 0.10328935 | S22: 0.10327623
A24: Total Cost per Pound at Gross | B24: =B14+B22 -> 0.43768809 | C24: =C14+C22 -> 0.4322 | D24: =D14+D22 -> 0.33278611 | E24: =E14+E22 -> 0.45761102 | F24: =F14+F22 -> 0.3975 | G24: =G14+G22 -> 0.316792 | H24: =H14+H22 -> 0.82429268 | I24: =I14+I22 -> 0.6125 | ... S24: =S14+S22 -> 0.43701161
A25: Less: Substrate Plant Under-absorption | B25: =-B7 -> 0 | D25: 0 | E25: =-E7 -> 0 | G25: 0 | H25: =-H7 -> 0 | J25: 0 | K25: =-K7 -> 0 | M25: 0 | N25: =-N7 -> 0 | Q25: =-Q7 -> 0 | S25: 0
A26: Less: RC Under-absorption | B26: 0 | C26: -0.079184632 | D26: 0 | E26: 0 | F26: 0 | G26: 0 | H26: 0 | I26: 0 | J26: 0 | K26: 0 | L26: 0 | M26: 0 | N26: 0 | O26: 0 | P26: 0 | Q26: 0 | R26: =IF(R9+R10+R11+R12+R13+R22>0.0498,0.0498-R9-R10-R11-R12-R13-R22,0) -> -0.083948722 | S26: 0
A27: Net Cost per Pound Absorbed | B27: =SUM(B24:B26) -> 0.43768809 | C27: =SUM(C24:C26) -> 0.35301537 | D27: =SUM(D24:D26) -> 0.33278611 | E27: =SUM(E24:E26) -> 0.45761102 | F27: =SUM(F24:F26) -> 0.3975 | G27: =SUM(G24:G26) -> 0.316792 | H27: =SUM(H24:H26) -> 0.82429268 | I27: =SUM(I24:I26) -> 0.6125 | ... S27: =SUM(S24:S26) -> 0.43701161
A29: Total Production (000 lbs) | B29: =+B79*0.5 -> 5250 | C29: 15431 | D29: 3000 | E29: =+B79*0.5 -> 5250 | F29: 9412 | G29: 25500 | H29: =+B81 -> 3000 | I29: 198 | J29: 300 | K29: =+B82 -> 90 | L29: 160 | M29: 1000 | N29: =+B80 -> 0 | O29: 827 | P29: 5000 | Q29: =+B84 -> 0 | R29: 3647.15 | S29: 1300
B34: Fusion | E34: ScaleGuard II CL | H34: KSXT | K34: ScaleGuard II KSHD (H) | N34: FilterGuard | Q34: XX
B35: 24 Standard | C35: 21 Actual | D35: 22 Standard | E35: 24 Standard | F35: 23 Actual | G35: 22 Standard | H35: 23 Standard | I35: 22 Actual | J35: =+D4 -> 22 Standard | K35: =+B4 -> 24 Standard | L35: 19 Actual | M35: =+D4 -> 22 Standard | N35: =+B4 -> 24 Standard | O35: XX Actual | P35: XX Standard | Q35: =+B4 -> 24 Standard | R35: 19 Actual | S35: =+D4 -> 22 Standard
C36: (Jul) | F36: (May) | I36: (Jan-Aug) | L36: (Jan-Sept)
A37: Materials - Substrate | B37: =E152 -> 0.34423291 | C37: 0.3421 | D37: 0.21326582 | E37: =G152 -> 0.63341571 | F37: 0.5729 | G37: 0.51387049 | H37: =I152 -> 0.4684443 | I37: 0.3911 | J37: 0 | L37: 0 | M37: 1.8829093 | N37: =+M152 -> 0.28401991 | O37: 0 | P37: 0 | R37: 0 | S37: 0
A38: Materials - Substrate Under-Absorption | B38: =$C137*D137 -> 0 | D38: 0 | E38: =$C134*F134 -> 0 | G38: 0 | H38: =$C129*H129 -> 0 | J38: 0 | M38: 0.16177979 | N38: 0 | P38: 0 | S38: 0
A39: Materials - Resin & Chemicals | B39: =E153+E154 -> 0.067817592 | C39: =0.4041-C37 -> 0.062 | D39: 0.067925472 | E39: =G153+G154 -> 0.053814952 | F39: 0.0496 | G39: 0.04253052 | H39: =I153+I154 -> 0.0065721369 | I39: 0.0058396524 | J39: 0 | L39: 0 | M39: 0.042578635 | N39: =+M153+M154 -> 0.78698195 | O39: 0 | P39: 0 | R39: 0 | S39: 0
A40: Electricity | B40: =E171 -> 0.01207814 | C40: 0.01 | D40: 0.009641779 | E40: =G171 -> 0.01384973 | F40: 0.0167 | G40: 0.0058784926 | H40: =I171 -> 0.0096111165 | I40: 0.017771324 | J40: 0 | L40: 0 | M40: 0.010135435 | N40: =M171 -> 0.046127878 | O40: 0 | P40: 0 | R40: 0 | S40: 0
A41: Gas | B41: =E172 -> 0.001583098 | C41: 0.002 | D41: 0.0017836723 | E41: =G172 -> 0.0027058421 | F41: 0.0011 | G41: 0.0012263426 | H41: =I172 -> 0.0013457382 | I41: 0.0036105204 | J41: 0 | L41: 0 | M41: 0.0011247591 | N41: =M172 -> 0.0020507934 | O41: 0 | P41: 0 | R41: 0 | S41: 0
A42: R&M Supplies and Service | B42: =$H$180 -> 0.016297262 | C42: 0.0036 | D42: 0.0031413613 | E42: =$H$180 -> 0.016297262 | F42: 0.0036 | G42: 0.0031413613 | H42: =$H$180 -> 0.016297262 | I42: 0.0059485597 | J42: 0 | L42: 0 | M42: 0.0086705202 | N42: =$H$180 -> 0.016297262 | O42: 0 | P42: 0 | R42: 0 | S42: 0
A43: Manufacturing Supplies | B43: =$H$183 -> 0.001303781 | C43: 0.0002 | D43: 0.0002617801 | E43: =$H$183 -> 0.001303781 | F43: 0 | G43: 0.0002617801 | H43: =$H$183 -> 0.001303781 | I43: 0.0009914408 | J43: 0 | L43: 0 | M43: 0.00043352601 | N43: =$H$183 -> 0.001303781 | O43: 0 | P43: 0 | R43: 0 | S43: 0
A44: Other variable | B44: =$H$186 -> 0.022816167 | C44: 0.0125 | D44: 0.0039267016 | E44: =$H$186 -> 0.022816167 | F44: 0.012 | G44: 0.0039267016 | H44: =$H$186 -> 0.022816167 | I44: 0.0092202407 | J44: 0 | L44: 0 | M44: 0.0057803468 | N44: =$H$186 -> 0.022816167 | O44: 0 | P44: 0 | R44: 0 | S44: 0
A45: Total Variable Costs | B45: =SUM(B37:B44) -> 0.46612895 | C45: =SUM(C37:C44) -> 0.4324 | D45: =SUM(D37:D44) -> 0.29994659 | E45: =SUM(E37:E44) -> 0.74420344 | F45: =SUM(F37:F44) -> 0.6559 | G45: =SUM(G37:G44) -> 0.57083569 | H45: =SUM(H37:H44) -> 0.5263905 | I45: =SUM(I37:I44) -> 0.43448174 | J45: =SUM(J37:J44) -> 0 | L45: =SUM(L37:L44) -> 0 | M45: 2.1134123 | N45: =SUM(N37:N44) -> 1.1595977 | O45: =SUM(O37:O44) -> 0 | P45: =SUM(P37:P44) -> 0 | R45: =SUM(R37:R44) -> 0 | S45: =SUM(S37:S44) -> 0
A47: Production Labor | B47: =$D$217/$B$64/1000 -> 0.048558141 | C47: 0.0172 | D47: 0.016663174 | E47: =$D$217/$B$64/1000 -> 0.048558141 | F47: 0.0253 | G47: 0.016663174 | H47: =$D$217/$B$64/1000 -> 0.048558141 | I47: 0.026626711 | J47: 0 | L47: 0 | M47: 0.011741675 | N47: =$D$217/$B$64/1000 -> 0.048558141 | O47: 0 | P47: 0 | R47: 0 | S47: 0
A48: Repairs & Maintenance Labor | B48: =$G$217/$B$64/1000 -> 0.015673026 | C48: 0.0064 | D48: 0.0040701571 | E48: =$G$217/$B$64/1000 -> 0.015673026 | F48: 0.0101 | G48: 0.0040701571 | H48: =$G$217/$B$64/1000 -> 0.015673026 | I48: 0.0076324228 | J48: 0 | L48: 0 | M48: 0.0041080925 | N48: =$G$217/$B$64/1000 -> 0.015673026 | O48: 0 | P48: 0 | R48: 0 | S48: 0
...

Sheet NI RC 2024 Std
A1: New Iberia Resin Coating
A2: 2024 STANDARDS
B3: CARBOBond Lite | E3: CARBOBond Lite EU | H3: CARBOBond KSLD | K3: RPM LITE / NEUTRAPROP LWC | N3: CARBOBond HSP | Q3: CARBO AIR
B4: 24 Standard | C4: 23 Actual | D4: 22 Standard | E4: 24 Standard | F4: 23 Actual | G4: 22 Standard | H4: 24 Standard | I4: 23 Actual | J4: 22 Standard | K4: 24 Standard | L4: 23 Actual | M4: 22 Standard | N4: 24 Standard | O4: 23 Actual | P4: 22 Standard | Q4: 24 Standard | R4: 23 Actual | S4: =+D4 -> 22 Standard
C5: Jan | F5: Jan | I5: (Aug) | L5: (Jan) | O5: (Aug) | R5: (Jan-Aug)
A6: Materials - Substrate | B6: =E119 -> 0.21293144 | C6: 0.261 | D6: 0.1639529 | E6: =G119 -> 0.21706426 | F6: 0.259 | G6: 0.18884365 | H6: =+I119 -> 0.52154785 | I6: 0.4369 | J6: 0.41938749 | K6: =K119 -> 0.2149 | L6: 0.1827 | M6: 0.15362762 | N6: =+M100 -> 0 | O6: 0.431 | P6: 0.80389422 | Q6: =+O98 -> 0.30469739 | R6: 0.15968841 | S6: 0.19086145
A7: Materials - Substrate Under-Absorption | B7: =$C97*D97 -> 0 | D7: 0 | E7: =$C97*F97 -> 0 | G7: 0 | H7: =$C97*I97 -> 0 | J7: 0 | K7: =$C97*J97 -> 0 | M7: 0.094857323 | N7: =$C97*O97 -> 0 | P7: 0
A8: Materials - Resin & Chemicals | B8: =E120+E121 -> 0.050440017 | C8: 0.0667 | D8: 0.038078 | E8: =G120+G121 -> 0.064046066 | F8: 0.0652 | G8: 0.060015662 | H8: =+I120+I121 -> 0.076234045 | I8: =0.5149-I6 -> 0.078 | J8: 0.056384154 | K8: =K120+K121 -> 0.2181838 | L8: =0.2569-L6 -> 0.0742 | M8: 0.15903358 | N8: =+M120+M121 -> 0.087444565 | O8: =0.5164-O6 -> 0.0854 | P8: 0.056384154 | Q8: =+O120+O121 -> 0.10145692 | R8: 0.072759577 | S8: 0.087415456
A9: Electricity | B9: =E164 -> 0.0083887564 | C9: 0.0019 | D9: 0.0059095494 | E9: =G164 -> 0.010531407 | F9: 0.0019 | G9: 0.0092314722 | H9: =J164 -> 0.06212471 | I9: 0.0088 | J9: 0.043221874 | K9: =K164 -> 0.018513164 | L9: 0.0117 | M9: 0.010135435 | N9: =+M164 -> 0.0088229437 | O9: 0.0088 | P9: 0.006738662 | Q9: =+O164 -> 0.011271451 | R9: 0.006525594 | S9: 0.0089969295
A10: Gas | B10: =E165 -> 0.0017786261 | C10: 0.004 | D10: 0.0013242333 | E10: =G165 -> 0.001820037 | F10: 0.0041 | G10: 0.00153375 | H10: =J165 -> 0.00023681914 | I10: 0.0038 | J10: 0.00029427407 | K10: =K165 -> 0.0012487474 | L10: 0.0011 | M10: 0.0011247591 | N10: =+M165 -> 0.0038181212 | O10: 0.0038 | P10: 0.0013537383 | Q10: =+O165 -> 0.0033852574 | R10: 0.0011625955 | S10: 0.0038428259
A11: R&M Supplies and Service | B11: =$H$180 -> 0.01650165 | C11: 0.0016 | D11: 0.006 | E11: =$H$180 -> 0.01650165 | F11: 0.0016 | G11: 0.0031413613 | H11: =$H$180 -> 0.01650165 | I11: 0.0094 | J11: 0.0031413613 | K11: =$H$180 -> 0.01650165 | L11: 0.0076 | M11: 0.0086705202 | N11: =$H$180 -> 0.01650165 | O11: 0.0094 | P11: 0.0031413613 | Q11: =$H$180 -> 0.01650165 | R11: 0.016241103 | S11: 0.0031413613
A12: Manufacturing Supplies | B12: =$H$183 -> 0.001320132 | C12: 0 | D12: 0.002 | E12: =$H$183 -> 0.001320132 | F12: 0 | G12: 0.0002617801 | H12: =$H$183 -> 0.001320132 | I12: 0.0003 | J12: 0.0002617801 | K12: =$H$183 -> 0.001320132 | L12: 0.0002 | M12: 0.00043352601 | N12: =$H$183 -> 0.001320132 | O12: 0.0003 | P12: 0.0002617801 | Q12: =$H$183 -> 0.001320132 | R12: 0.00053366327 | S12: 0.0002617801
A13: Other variable | B13: =$H$186 -> 0.02310231 | C13: 0.005 | D13: 0.006 | E13: =$H$186 -> 0.02310231 | F13: 0.0052 | G13: 0.0039267016 | H13: =$H$186 -> 0.02310231 | I13: 0.0134 | J13: 0.0039267016 | K13: =$H$186 -> 0.02310231 | L13: 0.0035 | M13: 0.0057803468 | N13: =$H$186 -> 0.02310231 | O13: 0.0134 | P13: 0.0039267016 | Q13: =$H$186 -> 0.02310231 | R13: 0.0059964109 | S13: 0.0039267016
A14: Total Variable Costs | B14: =SUM(B6:B13) -> 0.31446293 | C14: =SUM(C6:C13) -> 0.3402 | D14: =SUM(D6:D13) -> 0.22326468 | E14: =SUM(E6:E13) -> 0.33438586 | F14: =SUM(F6:F13) -> 0.337 | G14: =SUM(G6:G13) -> 0.26695437 | H14: =SUM(H6:H13) -> 0.70106752 | I14: =SUM(I6:I13) -> 0.5506 | ... L14: =SUM(L6:L13) -> 0.281 | M14: 0.43366311 | N14: =SUM(N6:N13) -> 0.14100972 | O14: =SUM(O6:O13) -> 0.5521 | P14: =SUM(P6:P13) -> 0.87570062 | Q14: =SUM(Q6:Q13) -> 0.46173512 | R14: =SUM(R6:R13) -> 0.26290735 | S14: 0.33373539
A16: Production Labor | B16: =$D$217/$B$64/1000 -> 0.040795043 | C16: 0.0165 | D16: 0.035940795 | E16: =$D$217/$B$64/1000 -> 0.040795043 | F16: 0.0165 | G16: 0.016663174 | H16: =$D$217/$B$64/1000 -> 0.040795043 | I16: 0.0283 | J16: 0.016663174 | K16: =$D$217/$B$64/1000 -> 0.040795043 | L16: 0.0095 | M16: 0.011741675 | N16: =$D$217/$B$64/1000 -> 0.040795043 | O16: 0.0283 | P16: 0.016663174 | Q16: =$D$217/$B$64/1000 -> 0.040795043 | R16: 0.013727223 | S16: 0.016663174
A17: Repairs & Maintenance Labor | B17: =$G$217/$B$64/1000 -> 0.013212612 | C17: 0.007 | D17: 0.0113712 | E17: =$G$217/$B$64/1000 -> 0.013212612 | F17: 0.007 | G17: 0.0040701571 | H17: =$G$217/$B$64/1000 -> 0.013212612 | I17: 0.0072 | J17: 0.0040701571 | K17: =$G$217/$B$64/1000 -> 0.013212612 | L17: 0.005 | M17: 0.0041080925 | N17: =$G$217/$B$64/1000 -> 0.013212612 | O17: 0.0072 | P17: 0.0040701571 | Q17: =$G$217/$B$64/1000 -> 0.013212612 | R17: 0.0016693747 | S17: 0.0040701571
A18: Indirect Payroll Costs (Benefits) | B18: =$J$217/$B$64/1000 -> 0.017821096 | C18: 0.0114 | D18: 0.014188877 | E18: =$J$217/$B$64/1000 -> 0.017821096 | F18: 0.0114 | G18: 0.0073786377 | H18: =$J$217/$B$64/1000 -> 0.017821096 | I18: 0.0071 | J18: 0.0073786377 | K18: =$J$217/$B$64/1000 -> 0.017821096 | L18: 0.0111 | M18: 0.0072598437 | N18: =$J$217/$B$64/1000 -> 0.017821096 | O18: 0.0071 | P18: 0.0073786377 | Q18: =$J$217/$B$64/1000 -> 0.017821096 | R18: 0.0056633179 | S18: 0.0073786377
A19: Supervision | B19: =$E$243 -> 0.0054972436 | C19: 0.035 | D19: 0 | E19: =$E$243 -> 0.0054972436 | F19: 0.0035 | G19: 0.0040554974 | H19: =$E$243 -> 0.0054972436 | I19: 0.002 | J19: 0.0040554974 | K19: =$E$243 -> 0.0054972436 | L19: 0.0073 | M19: 0.002449852 | N19: =$E$243 -> 0.0054972436 | O19: 0.002 | P19: 0.0040554974 | Q19: =$E$243 -> 0.0054972436 | R19: 0.0023710733 | S19: 0.0040554974
A20: Depreciation | B20: =$E$244 -> 0.0073980198 | C20: 0.0053 | D20: 0.01039048 | E20: =$E$244 -> 0.0073980198 | F20: 0.0053 | G20: 0.0029340314 | H20: =$E$244 -> 0.0073980198 | I20: 0.0038 | J20: 0.0029340314 | K20: =$E$244 -> 0.0073980198 | L20: 0.0058 | M20: 0.06367052 | N20: =$E$244 -> 0.0073980198 | O20: 0.0038 | P20: 0.0029340314 | Q20: =$E$244 -> 0.0073980198 | R20: 0.064182394 | S20: 0.0029340314
A21: Insurance & Taxes | B21: =$E$245 -> 0.026217822 | C21: 0.0168 | D21: 0.03763008 | E21: =$E$245 -> 0.026217822 | F21: 0.0168 | G21: 0.014736126 | H21: =$E$245 -> 0.026217822 | I21: 0.0135 | J21: 0.014736126 | K21: =$E$245 -> 0.026217822 | L21: 0.0037 | M21: 0.014046243 | N21: =$E$245 -> 0.026217822 | O21: 0.0135 | P21: 0.014736126 | Q21: =$E$245 -> 0.026217822 | R21: 0.015675972 | S21: 0.014736126
A22: Total Fixed Costs | B22: =SUM(B16:B21) -> 0.11094184 | C22: =SUM(C16:C21) -> 0.092 | D22: =SUM(D16:D21) -> 0.10952143 | E22: =SUM(E16:E21) -> 0.11094184 | F22: =SUM(F16:F21) -> 0.0605 | G22: =SUM(G16:G21) -> 0.049837623 | H22: =SUM(H16:H21) -> 0.11094184 | I22: =SUM(I16:I21) -> 0.0619 | ... L22: =SUM(L16:L21) -> 0.0424 | M22: 0.10327623 | N22: =SUM(N16:N21) -> 0.11094184 | O22: =SUM(O16:O21) -> 0.0619 | P22: =SUM(P16:P21) -> 0.049837623 | Q22: =SUM(Q16:Q21) -> 0.11094184 | R22: =SUM(R16:R21) -> 0.10328935 | S22: 0.10327623
A24: Total Cost per Pound at Gross | B24: =B14+B22 -> 0.42540476 | C24: =C14+C22 -> 0.4322 | D24: =D14+D22 -> 0.33278611 | E24: =E14+E22 -> 0.44532769 | F24: =F14+F22 -> 0.3975 | G24: =G14+G22 -> 0.316792 | H24: =H14+H22 -> 0.81200936 | I24: =I14+I22 -> 0.6125 | ... S24: =S14+S22 -> 0.43701161
A25: Less: Substrate Plant Under-absorption | B25: =-B7 -> 0 | D25: 0 | E25: =-E7 -> 0 | G25: 0 | H25: =-H7 -> 0 | J25: 0 | K25: =-K7 -> 0 | M25: 0 | N25: =-N7 -> 0 | Q25: =-Q7 -> 0 | S25: 0
A26: Less: RC Under-absorption | B26: 0 | C26: -0.079184632 | D26: 0 | E26: 0 | F26: 0 | G26: 0 | H26: 0 | I26: 0 | J26: 0 | K26: 0 | L26: 0 | M26: 0 | N26: 0 | O26: 0 | P26: 0 | Q26: 0 | R26: =IF(R9+R10+R11+R12+R13+R22>0.0498,0.0498-R9-R10-R11-R12-R13-R22,0) -> -0.083948722 | S26: 0
A27: Net Cost per Pound Absorbed | B27: =SUM(B24:B26) -> 0.42540476 | C27: =SUM(C24:C26) -> 0.35301537 | D27: =SUM(D24:D26) -> 0.33278611 | E27: =SUM(E24:E26) -> 0.44532769 | F27: =SUM(F24:F26) -> 0.3975 | G27: =SUM(G24:G26) -> 0.316792 | H27: =SUM(H24:H26) -> 0.81200936 | I27: =SUM(I24:I26) -> 0.6125 | ... S27: =SUM(S24:S26) -> 0.43701161
A29: Total Production (000 lbs) | B29: =+B79*0.5 -> 4350 | C29: 15431 | D29: 3000 | E29: =+B79*0.5 -> 4350 | F29: 9412 | G29: 25500 | H29: =+B81 -> 0 | I29: 198 | J29: 300 | K29: =+B82 -> 0 | L29: 160 | M29: 1000 | N29: =+B80 -> 0 | O29: 827 | P29: 5000 | Q29: =+B84 -> 0 | R29: 3647.15 | S29: 1300
B34: Fusion | E34: ScaleGuard II CL | H34: KSXT | K34: ScaleGuard II KSHD (H) | N34: FilterGuard | Q34: XX
B35: 24 Standard | C35: 21 Actual | D35: 22 Standard | E35: 24 Standard | F35: 23 Actual | G35: 22 Standard | H35: 23 Standard | I35: 22 Actual | J35: =+D4 -> 22 Standard | K35: =+B4 -> 24 Standard | L35: 19 Actual | M35: =+D4 -> 22 Standard | N35: =+B4 -> 24 Standard | O35: XX Actual | P35: XX Standard | Q35: =+B4 -> 24 Standard | R35: 19 Actual | S35: =+D4 -> 22 Standard
C36: (Jul) | F36: (May) | I36: (Jan-Aug) | L36: (Jan-Sept)
A37: Materials - Substrate | B37: =E152 -> 0.34423291 | C37: 0.3421 | D37: 0.21326582 | E37: =G152 -> 0.63341571 | F37: 0.5729 | G37: 0.51387049 | H37: =I152 -> 0.4684443 | I37: 0.3911 | J37: 0 | L37: 0 | M37: 1.8829093 | N37: =+M152 -> 0.28401991 | O37: 0 | P37: 0 | R37: 0 | S37: 0
A38: Materials - Substrate Under-Absorption | B38: =$C137*D137 -> 0 | D38: 0 | E38: =$C134*F134 -> 0 | G38: 0 | H38: =$C129*H129 -> 0 | J38: 0 | M38: 0.16177979 | N38: 0 | P38: 0 | S38: 0
A39: Materials - Resin & Chemicals | B39: =E153+E154 -> 0.067817592 | C39: =0.4041-C37 -> 0.062 | D39: 0.067925472 | E39: =G153+G154 -> 0.053814952 | F39: 0.0496 | G39: 0.04253052 | H39: =I153+I154 -> 0.0065721369 | I39: 0.0058396524 | J39: 0 | L39: 0 | M39: 0.042578635 | N39: =+M153+M154 -> 0.78698195 | O39: 0 | P39: 0 | R39: 0 | S39: 0
A40: Electricity | B40: =E171 -> 0.01207814 | C40: 0.01 | D40: 0.009641779 | E40: =G171 -> 0.01384973 | F40: 0.0167 | G40: 0.0058784926 | H40: =I171 -> 0.0096111165 | I40: 0.017771324 | J40: 0 | L40: 0 | M40: 0.010135435 | N40: =M171 -> 0.046127878 | O40: 0 | P40: 0 | R40: 0 | S40: 0
A41: Gas | B41: =E172 -> 0.001583098 | C41: 0.002 | D41: 0.0017836723 | E41: =G172 -> 0.0027058421 | F41: 0.0011 | G41: 0.0012263426 | H41: =I172 -> 0.0013457382 | I41: 0.0036105204 | J41: 0 | L41: 0 | M41: 0.0011247591 | N41: =M172 -> 0.0020507934 | O41: 0 | P41: 0 | R41: 0 | S41: 0
A42: R&M Supplies and Service | B42: =$H$180 -> 0.01650165 | C42: 0.0036 | D42: 0.0031413613 | E42: =$H$180 -> 0.01650165 | F42: 0.0036 | G42: 0.0031413613 | H42: =$H$180 -> 0.01650165 | I42: 0.0059485597 | J42: 0 | L42: 0 | M42: 0.0086705202 | N42: =$H$180 -> 0.01650165 | O42: 0 | P42: 0 | R42: 0 | S42: 0
A43: Manufacturing Supplies | B43: =$H$183 -> 0.001320132 | C43: 0.0002 | D43: 0.0002617801 | E43: =$H$183 -> 0.001320132 | F43: 0 | G43: 0.0002617801 | H43: =$H$183 -> 0.001320132 | I43: 0.0009914408 | J43: 0 | L43: 0 | M43: 0.00043352601 | N43: =$H$183 -> 0.001320132 | O43: 0 | P43: 0 | R43: 0 | S43: 0
A44: Other variable | B44: =$H$186 -> 0.02310231 | C44: 0.0125 | D44: 0.0039267016 | E44: =$H$186 -> 0.02310231 | F44: 0.012 | G44: 0.0039267016 | H44: =$H$186 -> 0.02310231 | I44: 0.0092202407 | J44: 0 | L44: 0 | M44: 0.0057803468 | N44: =$H$186 -> 0.02310231 | O44: 0 | P44: 0 | R44: 0 | S44: 0
A45: Total Variable Costs | B45: =SUM(B37:B44) -> 0.46663583 | C45: =SUM(C37:C44) -> 0.4324 | D45: =SUM(D37:D44) -> 0.29994659 | E45: =SUM(E37:E44) -> 0.74471032 | F45: =SUM(F37:F44) -> 0.6559 | G45: =SUM(G37:G44) -> 0.57083569 | H45: =SUM(H37:H44) -> 0.52689739 | I45: =SUM(I37:I44) -> 0.43448174 | J45: =SUM(J37:J44) -> 0 | L45: =SUM(L37:L44) -> 0 | M45: 2.1134123 | N45: =SUM(N37:N44) -> 1.1601046 | O45: =SUM(O37:O44) -> 0 | P45: =SUM(P37:P44) -> 0 | R45: =SUM(R37:R44) -> 0 | S45: =SUM(S37:S44) -> 0
A47: Production Labor | B47: =$D$217/$B$64/1000 -> 0.040795043 | C47: 0.0172 | D47: 0.016663174 | E47: =$D$217/$B$64/1000 -> 0.040795043 | F47: 0.0253 | G47: 0.016663174 | H47: =$D$217/$B$64/1000 -> 0.040795043 | I47: 0.026626711 | J47: 0 | L47: 0 | M47: 0.011741675 | N47: =$D$217/$B$64/1000 -> 0.040795043 | O47: 0 | P47: 0 | R47: 0 | S47: 0
A48: Repairs & Maintenance Labor | B48: =$G$217/$B$64/1000 -> 0.013212612 | C48: 0.0064 | D48: 0.0040701571 | E48: =$G$217/$B$64/1000 -> 0.013212612 | F48: 0.0101 | G48: 0.0040701571 | H48: =$G$217/$B$64/1000 -> 0.013212612 | I48: 0.0076324228 | J48: 0 | L48: 0 | M48: 0.0041080925 | N48: =$G$217/$B$64/1000 -> 0.013212612 | O48: 0 | P48: 0 | R48: 0 | S48: 0
...

Sheet NI RC 2022 Std (BOD)
A1: New Iberia Resin Coating | AB1: Activity | AC1: 10001005 | AD1: 10001005 | AE1: Gross | AF1: Qty/1000 | AG1: 10001005 | AH1: Absorbed | AI1: 10001005 | AJ1: Abs Cost
A2: 2022 STANDARDS | AA2: Unit | AB2: Type | AC2: Total Cost | AD2: Total Qty | AE2: Unit Cost | AF2: Prod lbs | AG2: Absorption | AH2: Unit Cost | AI2: Underabs | AJ2: per 10000
B3: CARBOBond Lite | E3: CARBOBond Lite EU | H3: CARBOBond KSLD | K3: RPM LITE / NEUTRAPROP LWC | N3: CARBOBond KSHD | Q3: CARBO AIR
B4: 21 Standard | C4: 19 Actual | D4: 21 Standard | E4: 22 Standard | F4: 19 Actual | G4: =+D4 -> 21 Standard | H4: 22 Standard | I4: =+C4 -> 19 Actual | J4: =+D4 -> 21 Standard | K4: 21 Standard | L4: 18 Actual | M4: =+D4 -> 21 Standard | N4: 22 Standard | O4: 21 Actual | P4: =+D4 -> 21 Standard | Q4: 22 Standard | R4: 18 Actual | S4: =+D4 -> 21 Standard | V4: Composite | W4: Absorb | X4: Underabsorb
C5: (Jan-Sept) | F5: (Jan-Sept) | I5: =+C5 -> (Jan-Sept) | L5: (Jan-Nov) | R5: (Jan-Oct)
A6: Materials - Substrate | B6: =E120 -> 0.18382013 | C6: 0.16092998 | D6: 0.1639529 | E6: =G120 -> 0.18884365 | F6: 0.15896741 | G6: 0.13998074 | H6: =+I120 -> 0.41938749 | I6: 0.30191317 | J6: 0.28067655 | K6: =K120 -> 0.19651963 | L6: 0.18307969 | M6: 0.15362762 | N6: =+M101 -> 0.80389422 | O6: 0 | P6: 0 | Q6: =+O99 -> 0.19086145 | R6: 0.15968841 | S6: 0.14400712 | V6: =($B6*$B$29+$E6*$E$29+$H6*$H$29+$K6*$K$29+$N6*$N$29+$Q6*$Q$29+$B37*$B$60+$E37*$E$60+$H37*$H$60+$K37*$K$60+$N37*$N$60+$Q37*$Q$60)/$B$64 -> 0.2930518 | W6: =V6 -> 0.2930518
A7: Materials - Substrate Under-Absorption | B7: =$C98*D98 -> 0 | D7: 0 | E7: =$C98*F98 -> 0 | G7: 0.08643106 | H7: =$C98*I98 -> 0 | J7: 0.22562455 | K7: =$C98*J98 -> 0 | M7: 0.094857323 | N7: =$C98*O98 -> 0 | P7: 0 | S7: 0.08891715 | V7: 0 | W7: 0
A8: Materials - Resin & Chemicals | B8: =E121+E122 -> 0.04393998 | C8: 0.051903794 | D8: 0.038078 | E8: =G121+G122 -> 0.060015662 | F8: 0.053990671 | G8: 0.053042779 | H8: =+I121+I122 -> 0.056384154 | I8: 0.05384576 | J8: 0.0471079 | K8: =K121+K122 -> 0.070148364 | L8: 0.071924563 | M8: 0.15903358 | N8: =+M121+M122 -> 0.056384154 | O8: 0 | P8: 0 | Q8: =+O121+O122 -> 0.087415456 | R8: 0.072759577 | S8: 0.074666525 | V8: =($B8*$B$29+$E8*$E$29+$H8*$H$29+$K8*$K$29+$N8*$N$29+$Q8*$Q$29+$B39*$B$60+$E39*$E$60+$H39*$H$60+$K39*$K$60+$N39*$N$60+$Q39*$Q$60)/$B$64 -> 0.059937247 | W8: =V8 -> 0.059937247 | X8: =V8-W8 -> 0
A9: Electricity | B9: =E161 -> 0.010280976 | C9: 0.0077075348 | D9: 0.0059095494 | E9: =G161 -> 0.0092314722 | F9: 0.0064153677 | G9: 0.010135435 | H9: =J161 -> 0.043221874 | I9: 0.023850562 | J9: 0.010726 | K9: =K161 -> 0.010280976 | L9: 0.019218863 | M9: 0.010135435 | N9: =+M161 -> 0.006738662 | O9: 0 | P9: 0 | Q9: =+O161 -> 0.0089969295 | R9: 0.006525594 | S9: 0.010135435 | V9: =($B9*$B$29+$E9*$E$29+$H9*$H$29+$K9*$K$29+$N9*$N$29+$Q9*$Q$29+$B40*$B$60+$E40*$E$60+$H40*$H$60+$K40*$K$60+$N40*$N$60+$Q40*$Q$60)/$B$64 -> 0.0090509841 | W9: =V9 -> 0.0090509841 | X9: =V9-W9 -> 0 | AA9: kwh | AB9: ELE01 | AC9: =ROUND(((D161*B$29*1000)+(F161*E$29*1000)+(H161*H$29*1000)+(J161*K$29*1000)+(L161*N$29*1000)+(N161*Q$29*1000)+(D168*B$60*1000)+(F168*E$60*1000)+(H168*H$60*1000)+(J168*K$60*1000)+(L168*N$60*1000)+(N168*Q$60*1000))*$B161,0) -> 302219 | AD9: =ROUND((D161*B$29*1000)+(F161*E$29*1000)+(H161*H$29*1000)+(J161*K$29*1000)+(L161*N$29*1000)+(N161*Q$29*1000)+(D168*B$60*1000)+(F168*E$60*1000)+(H168*H$60*1000)+(J168*K$60*1000)+(L168*N$60*1000)+(N168*Q$60*1000),0) -> 1270548 | AE9: =AC9/AD9 -> 0.23786508 | AF9: =ROUND(AD9/$B$64,3) -> 36.721 | AG9: =ROUND(W9*$AC$29,0) -> 313164 | AH9: =AG9/AD9 -> 0.24647947 | AI9: =AC9-AG9 -> -10945 | AJ9: =AH9*10000 -> 2464.7947
A10: Gas | B10: =E162 -> 0.0017614437 | C10: 0.00096524487 | D10: 0.0013242333 | E10: =G162 -> 0.00153375 | F10: 0.00088623983 | G10: 0.0011247591 | H10: =J162 -> 0.00029427407 | I10: 0.0011573683 | J10: 0.00126 | K10: =K162 -> 0.0017614437 | L10: 0.0011031846 | M10: 0.0011247591 | N10: =+M162 -> 0.0013537383 | O10: 0 | P10: 0 | Q10: =+O162 -> 0.0038428259 | R10: 0.0011625955 | S10: 0.0011247591 | V10: =($B10*$B$29+$E10*$E$29+$H10*$H$29+$K10*$K$29+$N10*$N$29+$Q10*$Q$29+$B41*$B$60+$E41*$E$60+$H41*$H$60+$K41*$K$60+$N41*$N$60+$Q41*$Q$60)/$B$64 -> 0.001563011 | W10: =V10 -> 0.001563011 | X10: =V10-W10 -> 0 | AA10: mbtu | AB10: GAS01 | AC10: =ROUND(((D162*B$29*1000)+(F162*E$29*1000)+(H162*H$29*1000)+(J162*K$29*1000)+(L162*N$29*1000)+(N162*Q$29*1000)+(D169*B$60*1000)+(F169*E$60*1000)+(H169*H$60*1000)+(J169*K$60*1000)+(L169*N$60*1000)+(N169*Q$60*1000))*$B162,0) -> 54398 | AD10: =ROUND(((D162*B$29*1000)+(F162*E$29*1000)+(H162*H$29*1000)+(J162*K$29*1000)+(L162*N$29*1000)+(N162*Q$29*1000)+(D169*B$60*1000)+(F169*E$60*1000)+(H169*H$60*1000)+(J169*K$60*1000)+(L169*N$60*1000)+(N169*Q$60*1000))*1000,0) -> 9087958 | AE10: =AC10/AD10 -> 0.0059857231 | AF10: =ROUND(AD10/$B$64,3) -> 262.658 | AG10: =ROUND(W10*$AC$29,0) -> 54080 | AH10: =AG10/AD10 -> 0.0059507317 | AI10: =AC10-AG10 -> 318 | AJ10: =AH10*10000 -> 59.507317
A11: R&M Supplies and Service | B11: =$H$177 -> 0.0034682081 | C11: 0.0052601959 | D11: 0.006 | E11: =$H$177 -> 0.0034682081 | F11: 0.0051242876 | G11: 0.0086705202 | H11: =$H$177 -> 0.0034682081 | I11: 0.023215913 | J11: 0.0099121126 | K11: =$H$177 -> 0.0034682081 | L11: 0.026688594 | M11: 0.0086705202 | N11: =$H$177 -> 0.0034682081 | O11: 0 | P11: 0 | Q11: =$H$177 -> 0.0034682081 | R11: 0.016241103 | S11: 0.0086705202 | V11: =($B11*$B$29+$E11*$E$29+$H11*$H$29+$K11*$K$29+$N11*$N$29+$Q11*$Q$29+$B42*$B$60+$E42*$E$60+$H42*$H$60+$K42*$K$60+$N42*$N$60+$Q42*$Q$60)/$B$64 -> 0.0034682081 | W11: =V11 -> 0.0034682081 | X11: =V11-W11 -> 0 | AA11: lb | AB11: RMS01 | AC11: =ROUND(G177,0) -> 120000 | AD11: =$B$64*1000 -> 34600000 | AE11: =AC11/AD11 -> 0.0034682081 | AF11: =ROUND(AD11/$B$64,3) -> 1000 | AG11: =ROUND(W11*$AC$29,0) -> 120000 | AH11: =AG11/AD11 -> 0.0034682081 | AI11: =AC11-AG11 -> 0 | AJ11: =AH11*10000 -> 34.682081
A12: Manufacturing Supplies | B12: =$H$180 -> 0.00028901734 | C12: 0.00028145605 | D12: 0.002 | E12: =$H$180 -> 0.00028901734 | F12: 0.0001613237 | G12: 0.00043352601 | H12: =$H$180 -> 0.00028901734 | I12: 0.00076914757 | J12: 0.00049560563 | K12: =$H$180 -> 0.00028901734 | L12: 0.0013365915 | M12: 0.00043352601 | N12: =$H$180 -> 0.00028901734 | O12: 0 | P12: 0 | Q12: =$H$180 -> 0.00028901734 | R12: 0.00053366327 | S12: 0.00043352601 | V12: =($B12*$B$29+$E12*$E$29+$H12*$H$29+$K12*$K$29+$N12*$N$29+$Q12*$Q$29+$B43*$B$60+$E43*$E$60+$H43*$H$60+$K43*$K$60+$N43*$N$60+$Q43*$Q$60)/$B$64 -> 0.00028901734 | W12: =V12 -> 0.00028901734 | X12: =V12-W12 -> 0 | AA12: lb | AB12: MFG01 | AC12: =ROUND(G180,0) -> 10000 | AD12: =$B$64*1000 -> 34600000 | AE12: =AC12/AD12 -> 0.00028901734 | AF12: =ROUND(AD12/$B$64,3) -> 1000 | AG12: =ROUND(W12*$AC$29,0) -> 10000 | AH12: =AG12/AD12 -> 0.00028901734 | AI12: =AC12-AG12 -> 0 | AJ12: =AH12*10000 -> 2.8901734
A13: Other variable | B13: =$H$183 -> 0.0043352601 | C13: 0.005539271 | D13: 0.006 | E13: =$H$183 -> 0.0043352601 | F13: 0.0047523717 | G13: 0.0057803468 | H13: =$H$183 -> 0.0043352601 | I13: 0.017048253 | J13: 0.0066080751 | K13: =$H$183 -> 0.0043352601 | L13: 0.026821614 | M13: 0.0057803468 | N13: =$H$183 -> 0.0043352601 | O13: 0 | P13: 0 | Q13: =$H$183 -> 0.0043352601 | R13: 0.0059964109 | S13: 0.0057803468 | V13: =($B13*$B$29+$E13*$E$29+$H13*$H$29+$K13*$K$29+$N13*$N$29+$Q13*$Q$29+$B44*$B$60+$E44*$E$60+$H44*$H$60+$K44*$K$60+$N44*$N$60+$Q44*$Q$60)/$B$64 -> 0.0043352601 | W13: =V13 -> 0.0043352601 | X13: =V13-W13 -> 0 | AA13: lb | AB13: VAR01 | AC13: =ROUND(G183,0) -> 150000 | AD13: =$B$64*1000 -> 34600000 | AE13: =AC13/AD13 -> 0.0043352601 | AF13: =ROUND(AD13/$B$64,3) -> 1000 | AG13: =ROUND(W13*$AC$29,0) -> 150000 | AH13: =AG13/AD13 -> 0.0043352601 | AI13: =AC13-AG13 -> 0 | AJ13: =AH13*10000 -> 43.352601
A14: Total Variable Costs | B14: =SUM(B6:B13) -> 0.24789502 | C14: =SUM(C6:C13) -> 0.23258747 | D14: =SUM(D6:D13) -> 0.22326468 | E14: =SUM(E6:E13) -> 0.26771702 | F14: =SUM(F6:F13) -> 0.23029767 | G14: 0.30559917 | H14: =SUM(H6:H13) -> 0.52738028 | I14: =SUM(I6:I13) -> 0.42180018 | J14: =SUM(J6:J13) -> 0.5824108 | K14: =SUM(K6:K13) -> 0.2868029 | L14: =SUM(L6:L13) -> 0.3301731 | M14: 0.43366311 | N14: =SUM(N6:N13) -> 0.87646326 | O14: =SUM(O6:O13) -> 0 | P14: =SUM(P6:P13) -> 0 | Q14: =SUM(Q6:Q13) -> 0.29920915 | R14: =SUM(R6:R13) -> 0.26290735 | S14: 0.33373539 | V14: =SUM(V6:V13) -> 0.37169553 | W14: =SUM(W6:W13) -> 0.37169553 | X14: =SUM(X6:X13) -> 0 | AC14: =SUM(AC9:AC13) -> 636617 | AG14: =SUM(AG9:AG13) -> 647244 | AI14: =SUM(AI9:AI13) -> -10627
A16: Production Labor | B16: =$D$214/$B$64/1000 -> 0.018490042 | C16: 0.018200142 | D16: 0.035940795 | E16: =$D$214/$B$64/1000 -> 0.018490042 | F16: 0.020063713 | G16: 0.011741675 | H16: =$D$214/$B$64/1000 -> 0.018490042 | I16: 0.012521635 | J16: 0.014552451 | K16: =$D$214/$B$64/1000 -> 0.018490042 | L16: 0.032785827 | M16: 0.011741675 | N16: =$D$214/$B$64/1000 -> 0.018490042 | O16: 0 | P16: 0 | Q16: =$D$214/$B$64/1000 -> 0.018490042 | R16: 0.013727223 | S16: 0.011741675 | V16: =($B16*$B$29+$E16*$E$29+$H16*$H$29+$K16*$K$29+$N16*$N$29+$Q16*$Q$29+$B47*$B$60+$E47*$E$60+$H47*$H$60+$K47*$K$60+$N47*$N$60+$Q47*$Q$60)/$B$64 -> 0.018490042 | W16: =+W24-W14 -> 0.031093519 | X16: =V16-W16 -> -0.012603477 | AA16: hr | AB16: DLAB01 | AC16: =ROUND(D212,0) -> 670220 | AD16: =ROUND(B212,0) -> 22000 | AE16: =AC16/AD16 -> 30.464545 | AF16: =ROUND(AD16/$B$64,3) -> 0.636 | AG16: =ROUND(W16*$AC$29,0) -> 1075836 | AH16: =AG16/AD16 -> 48.901636 | AI16: =AC16-AG16 -> -405616 | AJ16: =AH16*10000 -> 489016.36
A17: Repairs & Maintenance Labor | B17: =$G$214/$B$64/1000 -> 0.0044936416 | C17: 0.0048304191 | D17: 0.0113712 | E17: =$G$214/$B$64/1000 -> 0.0044936416 | F17: 0.0044471791 | G17: 0.0041080925 | H17: =$G$214/$B$64/1000 -> 0.0044936416 | I17: 0.0044303098 | J17: 0.004696359 | K17: =$G$214/$B$64/1000 -> 0.0044936416 | L17: 0.0088578354 | M17: 0.0041080925 | N17: =$G$214/$B$64/1000 -> 0.0044936416 | O17: 0 | P17: 0 | Q17: =$G$214/$B$64/1000 -> 0.0044936416 | R17: 0.0016693747 | S17: 0.0041080925 | V17: =($B17*$B$29+$E17*$E$29+$H17*$H$29+$K17*$K$29+$N17*$N$29+$Q17*$Q$29+$B48*$B$60+$E48*$E$60+$H48*$H$60+$K48*$K$60+$N48*$N$60+$Q48*$Q$60)/$B$64 -> 0.0044936416 | W17: 0 | X17: =V17-W17 -> 0.0044936416 | AA17: hr | AB17: MLAB01 | AC17: =ROUND(G212,0) -> 155480 | AD17: =ROUND(E212,0) -> 4400 | AE17: =AC17/AD17 -> 35.336364 | AF17: =ROUND(AD17/$B$64,3) -> 0.127 | AG17: =ROUND(W17*$AC$29,0) -> 0 | AH17: =AG17/AD17 -> 0 | AI17: =AC17-AG17 -> 155480 | AJ17: =AH17*10000 -> 0
A18: Indirect Payroll Costs (Benefits) | B18: =$J$214/$B$64/1000 -> 0.0081804217 | C18: 0.0068508297 | D18: 0.014188877 | E18: =$J$214/$B$64/1000 -> 0.0081804217 | F18: 0.0059757405 | G18: 0.0072598437 | H18: =$J$214/$B$64/1000 -> 0.0081804217 | I18: 0.014238166 | J18: 0.008765191 | K18: =$J$214/$B$64/1000 -> 0.0081804217 | L18: 0.038686584 | M18: 0.0072598437 | N18: =$J$214/$B$64/1000 -> 0.0081804217 | O18: 0 | P18: 0 | Q18: =$J$214/$B$64/1000 -> 0.0081804217 | R18: 0.0056633179 | S18: 0.0072598437 | V18: =($B18*$B$29+$E18*$E$29+$H18*$H$29+$K18*$K$29+$N18*$N$29+$Q18*$Q$29+$B49*$B$60+$E49*$E$60+$H49*$H$60+$K49*$K$60+$N49*$N$60+$Q49*$Q$60)/$B$64 -> 0.0081804217 | W18: 0 | X18: =V18-W18 -> 0.0081804217 | AA18: hr | AB18: IPC01 | AC18: =ROUND(J212,0) -> 294186 | AD18: =ROUND(H212,0) -> 26400 | AE18: =AC18/AD18 -> 11.143409 | AF18: =ROUND(AD18/$B$64,3) -> 0.763 | AG18: =ROUND(W18*$AC$29,0) -> 0 | AH18: =AG18/AD18 -> 0 | AI18: =AC18-AG18 -> 294186 | AJ18: =AH18*10000 -> 0
A19: Supervision | B19: =$E$240 -> 0.0044774566 | C19: 0.0022776301 | D19: 0 | E19: =$E$240 -> 0.0044774566 | F19: 0.0019225049 | G19: 0.002449852 | H19: =$E$240 -> 0.0044774566 | I19: 0.0092721693 | J19: 0.0028006635 | K19: =$E$240 -> 0.0044774566 | L19: 0.01254166 | M19: 0.002449852 | N19: =$E$240 -> 0.0044774566 | O19: 0 | P19: 0 | Q19: =$E$240 -> 0.0044774566 | R19: 0.0023710733 | S19: 0.002449852 | V19: =($B19*$B$29+$E19*$E$29+$H19*$H$29+$K19*$K$29+$N19*$N$29+$Q19*$Q$29+$B50*$B$60+$E50*$E$60+$H50*$H$60+$K50*$K$60+$N50*$N$60+$Q50*$Q$60)/$B$64 -> 0.0044774566 | W19: 0 | X19: =V19-W19 -> 0.0044774566 | AA19: lb | AB19: SUP01 | AC19: =ROUND(C240,0) -> 154920 | AD19: =$B$64*1000 -> 34600000 | AE19: =AC19/AD19 -> 0.0044774566 | AF19: =ROUND(AD19/$B$64,3) -> 1000 | AG19: =ROUND(W19*$AC$29,0) -> 0 | AH19: =AG19/AD19 -> 0 | AI19: =AC19-AG19 -> 154920 | AJ19: =AH19*10000 -> 0
A20: Depreciation | B20: =$E$241 -> 0.0032393064 | C20: 0.061012872 | D20: 0.01039048 | E20: =$E$241 -> 0.0032393064 | F20: 0.051498884 | G20: 0.06367052 | H20: =$E$241 -> 0.0032393064 | I20: 0.24870656 | J20: 0.072787947 | K20: =$E$241 -> 0.0032393064 | L20: 0.34045176 | M20: 0.06367052 | N20: =$E$241 -> 0.0032393064 | O20: 0 | P20: 0 | Q20: =$E$241 -> 0.0032393064 | R20: 0.064182394 | S20: 0.06367052 | V20: =($B20*$B$29+$E20*$E$29+$H20*$H$29+$K20*$K$29+$N20*$N$29+$Q20*$Q$29+$B51*$B$60+$E51*$E$60+$H51*$H$60+$K51*$K$60+$N51*$N$60+$Q51*$Q$60)/$B$64 -> 0.0032393064 | W20: =W24-W14-W16-W17-W18-W19-W21 -> 0 | X20: =V20-W20 -> 0.0032393064 | AA20: lb | AB20: DEP01 | AC20: =ROUND(C241,0) -> 112080 | AD20: =($B$29+$E$29+$H$29+$K$29+$N$29+B60+E60+H60+K60+N60+$Q$29+Q60)*1000 -> 34600000 | AE20: =AC20/AD20 -> 0.0032393064 | AF20: =ROUND(AD20/($B$29+$E$29+$H$29+$K$29+$N$29+B60+E60+H60+K60+N60),3) -> 1029.762 | AG20: =ROUND(W20*$AC$29,0) -> 0 | AH20: =AG20/AD20 -> 0 | AI20: =AC20-AG20 -> 112080 | AJ20: =AH20*10000 -> 0
A21: Insurance & Taxes | B21: =$E$242 -> 0.016269364 | C21: 0.01547789 | D21: 0.03763008 | E21: =$E$242 -> 0.016269364 | F21: 0.012959419 | G21: 0.014046243 | H21: =$E$242 -> 0.016269364 | I21: 0.064467032 | J21: 0.018172206 | K21: =$E$242 -> 0.016269364 | L21: 0.083528141 | M21: 0.014046243 | N21: =$E$242 -> 0.016269364 | O21: 0 | P21: 0 | Q21: =$E$242 -> 0.016269364 | R21: 0.015675972 | S21: 0.014046243 | V21: =($B21*$B$29+$E21*$E$29+$H21*$H$29+$K21*$K$29+$N21*$N$29+$Q21*$Q$29+$B52*$B$60+$E52*$E$60+$H52*$H$60+$K52*$K$60+$N52*$N$60+$Q52*$Q$60)/$B$64 -> 0.016269364 | W21: =W24-W14-W16-W17-W18-W19 -> 0 | X21: =V21-W21 -> 0.016269364 | AA21: lb | AB21: INS01 | AC21: =ROUND(C242,0) -> 562920 | AD21: =$B$64*1000 -> 34600000 | AE21: =AC21/AD21 -> 0.016269364 | AF21: =ROUND(AD21/$B$64,3) -> 1000 | AG21: =ROUND(W21*$AC$29,0) -> 0 | AH21: =AG21/AD21 -> 0 | AI21: =AC21-AG21 -> 562920 | AJ21: =AH21*10000 -> 0
A22: Total Fixed Costs | B22: =SUM(B16:B21) -> 0.055150233 | C22: =SUM(C16:C21) -> 0.10864978 | D22: =SUM(D16:D21) -> 0.10952143 | E22: =SUM(E16:E21) -> 0.055150233 | F22: =SUM(F16:F21) -> 0.09686744 | G22: 0.10327623 | H22: =SUM(H16:H21) -> 0.055150233 | I22: =SUM(I16:I21) -> 0.35363588 | J22: =SUM(J16:J21) -> 0.12177482 | K22: =SUM(K16:K21) -> 0.055150233 | L22: =SUM(L16:L21) -> 0.51685181 | M22: 0.10327623 | N22: =SUM(N16:N21) -> 0.055150233 | O22: =SUM(O16:O21) -> 0 | P22: =SUM(P16:P21) -> 0 | Q22: =SUM(Q16:Q21) -> 0.055150233 | R22: =SUM(R16:R21) -> 0.10328935 | S22: 0.10327623 | V22: =SUM(V16:V21) -> 0.055150233 | W22: =SUM(W16:W21) -> 0.031093519 | X22: =SUM(X16:X21) -> 0.024056713 | AC22: =SUM(AC16:AC21) -> 1949806 | AG22: =SUM(AG16:AG21) -> 1075836 | AI22: =SUM(AI16:AI21) -> 873970
AA23: Activity Cost | AC23: =AC14+AC22 -> 2586423 | AG23: =AG14+AG22 -> 1723080 | AI23: =AI14+AI22 -> 863343
A24: Total Cost per Pound at Gross | B24: =B14+B22 -> 0.30304525 | C24: =C14+C22 -> 0.34123726 | D24: =D14+D22 -> 0.33278611 | E24: =E14+E22 -> 0.32286725 | F24: =F14+F22 -> 0.32716511 | G24: =G14+G22 -> 0.40887539 | H24: =H14+H22 -> 0.58253051 | I24: =I14+I22 -> 0.77543605 | ... S24: =S14+S22 -> 0.43701161 | V24: =V14+V22 -> 0.42684576 | W24: =0.0498+V6+V7+V8 -> 0.40278904 | X24: =X14+X22 -> 0.024056713 | AA24: $/lb excl matl | AC24: =ROUND(AC23/AC29,5) -> 0.07475 | AG24: =ROUND(AG23/AC29,5) -> 0.0498 | AI24: =ROUND(AI23/AC29,5) -> 0.02495
A25: Less: Substrate Plant Under-absorption | B25: =-B7 -> 0 | D25: 0 | E25: =-E7 -> 0 | G25: -0.02807392 | H25: =-H7 -> 0 | J25: -0.22562455 | K25: =-K7 -> 0 | M25: -0.02886962 | N25: =-N7 -> 0 | Q25: =-Q7 -> 0 | S25: -0.027061741 | V25: 0
A26: Less: RC Under-absorption | B26: =IF(B9+B10+B11+B12+B13+B22>0.0498,0.0498-B9-B10-B11-B12-B13-B22,0) -> -0.025485138 | C26: -0.079184632 | D26: -0.081 | E26: 0 | F26: =IF(F9+F10+F11+F12+F13+F22>0.0498,0.0498-F9-F10-F11-F12-F13-F22,0) -> -0.064407031 | G26: =IF(G9+G10+G11+G12+G13+G22>0.0498,0.0498-G9-G10-G11-G12-G13-G22,0) -> -0.079620814 | H26: 0 | I26: -0.36723743 | J26: =IF(J9+J10+J11+J12+J13+J22>0.0498,0.0498-J9-J10-J11-J12-J13-J22,0) -> -0.10097661 | K26: =IF(K9+K10+K11+K12+K13+K22>0.0498,0.0498-K9-K10-K11-K12-K13-K22,0) -> -0.025485138 | L26: =IF(L9+L10+L11+L12+L13+L22>0.0498,0.0498-L9-L10-L11-L12-L13-L22,0) -> -0.54222065 | M26: =IF(M9+M10+M11+M12+M13+M22>0.0498,0.0498-M9-M10-M11-M12-M13-M22,0) -> -0.079620814 | N26: 0 | O26: =IF(O9+O10+O11+O12+O13+O22>0.0498,0.0498-O9-O10-O11-O12-O13-O22,0) -> 0 | P26: =IF(P9+P10+P11+P12+P13+P22>0.0498,0.0498-P9-P10-P11-P12-P13-P22,0) -> 0 | Q26: 0 | R26: =IF(R9+R10+R11+R12+R13+R22>0.0498,0.0498-R9-R10-R11-R12-R13-R22,0) -> -0.083948722 | S26: =IF(S9+S10+S11+S12+S13+S22>0.0498,0.0498-S9-S10-S11-S12-S13-S22,0) -> -0.079620814 | V26: =($B26*$B$29+$E26*$E$29+$H26*$H$29+$K26*$K$29+$N26*$N$29+$Q26*$Q$29+$B57*$B$60+$E57*$E$60+$H57*$H$60+$K57*$K$60+$N57*$N$60+$Q57*$Q$60)/$B$64 -> 0
A27: Net Cost per Pound Absorbed | B27: =SUM(B24:B26) -> 0.27756011 | C27: =SUM(C24:C26) -> 0.26205262 | D27: =SUM(D24:D26) -> 0.25178611 | E27: =SUM(E24:E26) -> 0.32286725 | F27: =SUM(F24:F26) -> 0.26275808 | G27: =SUM(G24:G26) -> 0.30118066 | H27: =SUM(H24:H26) -> 0.58253051 | I27: =SUM(I24:I26) -> 0.40819862 | ... S27: =SUM(S24:S26) -> 0.33032906 | V27: =SUM(V24:V26) -> 0.42684576
AA28: $/lb incl matl | AC28: =ROUND((AC24+(B8*B29+E8*E29+H8*H29+K8*K29+N8*N29+Q8*Q29+B39*B60+E39*E60+H39*H60)/B64),5) -> 0.13469 | AG28: =ROUND(AG24+W8,5) -> 0.10974 | AI28: =ROUND(AI24+X8,5) -> 0.02495
A29: Total Production (000 lbs) | B29: 0 | C29: 15431 | D29: 3000 | E29: 25500 | F29: 9412 | G29: 10000 | H29: =+B81 -> 300 | I29: 74 | J29: 0 | K29: =+B82 -> 0 | L29: 254 | M29: 1000 | N29: =+B80 -> 5000 | O29: 0 | P29: 0 | Q29: =+B84 -> 1000 | R29: 3647.15 | S29: 1300 | V29: =B29+E29+H29+K29+N29+Q29+B60+E60+H60+K60+N60+Q60 -> 34600 | AA29: Prod lbs | AC29: =ROUND($B$64*1000,0) -> 34600000
B34: Fusion | E34: ScaleGuard II CL | H34: KSXT | K34: ScaleGuard II KSHD (H) | N34: XX | Q34: XX
B35: 22 Standard | C35: 19 Actual | D35: =+D4 -> 21 Standard | E35: 22 Standard | F35: 19 Actual | G35: =+D4 -> 21 Standard | H35: 22 Standard | I35: 19 Actual | J35: =+D4 -> 21 Standard | K35: =+B4 -> 21 Standard | L35: 19 Actual | M35: =+D4 -> 21 Standard | N35: =+B4 -> 21 Standard | O35: 19 Actual | P35: =+D4 -> 21 Standard | Q35: =+B4 -> 21 Standard | R35: 19 Actual | S35: =+D4 -> 21 Standard
C36: (Jan-Sept) | F36: (Jan-Sept) | I36: (Jan-Sept) | L36: (Jan-Sept)
A37: Materials - Substrate | B37: =E149 -> 0.21326582 | C37: 0.34054143 | D37: 0.22007722 | E37: =G149 -> 0.51387049 | F37: 0.4105 | G37: 0.41282107 | H37: =I149 -> 0.41122404 | I37: 0.26541432 | J37: 0.28800984 | L37: 0 | M37: 1.8829093 | O37: 0 | P37: 0 | R37: 0 | S37: 0
A38: Materials - Substrate Under-Absorption | B38: =$C135*D135 -> 0 | D38: 0 | E38: =$C133*F133 -> 0 | G38: 0.046029189 | H38: =$C130*H130 -> 0 | J38: 0.09332723 | M38: 0.16177979 | P38: 0 | S38: 0
A39: Materials - Resin & Chemicals | B39: =E150+E151 -> 0.067925472 | C39: 0.093737947 | D39: 0.0467607 | E39: =G150+G151 -> 0.04253052 | F39: 0.043894371 | G39: 0.04221848 | H39: =I150+I151 -> 0.0059336936 | I39: 0.04843802 | J39: 0.008758525 | L39: 0 | M39: 0.042578635 | O39: 0 | P39: 0 | R39: 0 | S39: 0
A40: Electricity | B40: =E168 -> 0.009641779 | C40: 0.026041382 | D40: 0.0059095494 | E40: =G168 -> 0.0058784926 | F40: 0.014645894 | G40: 0.0059095494 | H40: =I168 -> 0.0076716424 | I40: 0.010462455 | J40: 0.0059095494 | L40: 0 | M40: 0.010135435 | O40: 0 | P40: 0 | R40: 0 | S40: 0
A41: Gas | B41: =E169 -> 0.0017836723 | C41: 0.0016828037 | D41: 0.0013242333 | E41: =G169 -> 0.0012263426 | F41: 0.0055474856 | G41: 0.0013242333 | H41: =I169 -> 0.001527635 | I41: 0.00084305984 | J41: 0.0013242333 | L41: 0 | M41: 0.0011247591 | O41: 0 | P41: 0 | R41: 0 | S41: 0
A42: R&M Supplies and Service | B42: =$H$177 -> 0.0034682081 | C42: 0.019710326 | D42: 0.006 | E42: =$H$177 -> 0.0034682081 | F42: 0.012018642 | G42: 0.006 | H42: =$H$177 -> 0.0034682081 | I42: 0.0073389729 | J42: 0.006 | L42: 0 | M42: 0.0086705202 | O42: 0 | P42: 0 | R42: 0 | S42: 0
A43: Manufacturing Supplies | B43: =$H$180 -> 0.00028901734 | C43: 0.0024000594 | D43: 0.002 | E43: =$H$180 -> 0.00028901734 | F43: 0.0007808962 | G43: 0.002 | H43: =$H$180 -> 0.00028901734 | I43: 0.00063205421 | J43: 0.002 | L43: 0 | M43: 0.00043352601 | O43: 0 | P43: 0 | R43: 0 | S43: 0
A44: Other variable | B44: =$H$183 -> 0.0043352601 | C44: 0.026652312 | D44: 0.006 | E44: =$H$183 -> 0.0043352601 | F44: 0.026473851 | G44: 0.006 | H44: =$H$183 -> 0.0043352601 | I44: 0.0094086246 | J44: 0.006 | L44: 0 | M44: 0.0057803468 | O44: 0 | P44: 0 | R44: 0 | S44: 0
A45: Total Variable Costs | B45: =SUM(B37:B44) -> 0.30070923 | C45: =SUM(C37:C44) -> 0.51076626 | D45: =SUM(D37:D44) -> 0.2880717 | E45: =SUM(E37:E44) -> 0.57159833 | F45: =SUM(F37:F44) -> 0.51386114 | G45: =SUM(G37:G44) -> 0.52230252 | H45: =SUM(H37:H44) -> 0.4344495 | I45: =SUM(I37:I44) -> 0.34253751 | J45: =SUM(J37:J44) -> 0.41132937 | L45: =SUM(L37:L44) -> 0 | M45: 2.1134123 | O45: =SUM(O37:O44) -> 0 | P45: =SUM(P37:P44) -> 0 | R45: =SUM(R37:R44) -> 0 | S45: =SUM(S37:S44) -> 0
...

Sheet NI RC 2022 Std 
A1: New Iberia Resin Coating | AB1: Activity | AC1: 10001005 | AD1: 10001005 | AE1: Gross | AF1: Qty/1000 | AG1: 10001005 | AH1: Absorbed | AI1: 10001005 | AJ1: Abs Cost
A2: 2022 STANDARDS | AA2: Unit | AB2: Type | AC2: Total Cost | AD2: Total Qty | AE2: Unit Cost | AF2: Prod lbs | AG2: Absorption | AH2: Unit Cost | AI2: Underabs | AJ2: per 10000
B3: CARBOBond Lite | E3: CARBOBond Lite EU | H3: CARBOBond KSLD | K3: RPM LITE / NEUTRAPROP LWC | N3: XX | Q3: CARBO AIR
B4: 21 Standard | C4: 19 Actual | D4: 21 Standard | E4: 22 Standard | F4: 19 Actual | G4: =+D4 -> 21 Standard | H4: 21 Standard | I4: =+C4 -> 19 Actual | J4: =+D4 -> 21 Standard | K4: 21 Standard | L4: 18 Actual | M4: =+D4 -> 21 Standard | N4: 21 Standard | O4: 19 Actual | P4: =+D4 -> 21 Standard | Q4: 21 Standard | R4: 18 Actual | S4: =+D4 -> 21 Standard | V4: Composite | W4: Absorb | X4: Underabsorb
C5: (Jan-Sept) | F5: (Jan-Sept) | I5: =+C5 -> (Jan-Sept) | L5: (Jan-Nov) | R5: (Jan-Oct)
A6: Materials - Substrate | B6: =E121 -> 0.18382013 | C6: 0.16092998 | D6: 0.1639529 | E6: =G121 -> 0.18884365 | F6: 0.15896741 | G6: 0.13998074 | I6: 0.30191317 | J6: 0.28067655 | K6: =K121 -> 0.19651963 | L6: 0.18307969 | M6: 0.15362762 | O6: 0 | P6: 0 | R6: 0.15968841 | S6: 0.14400712 | V6: =($B6*$B$29+$E6*$E$29+$H6*$H$29+$K6*$K$29+$N6*$N$29+$Q6*$Q$29+$B37*$B$60+$E37*$E$60+$H37*$H$60+$K37*$K$60+$N37*$N$60+$Q37*$Q$60)/$B$64 -> 0.22071572 | W6: =V6 -> 0.22071572
A7: Materials - Substrate Under-Absorption | B7: =$C100*D100 -> 0 | D7: 0 | E7: =$C100*F100 -> 0 | G7: 0.08643106 | J7: 0.22562455 | K7: =$C100*J100 -> 0 | M7: 0.094857323 | P7: 0 | S7: 0.08891715 | V7: 0 | W7: 0
A8: Materials - Resin & Chemicals | B8: =E122+E123 -> 0.04393998 | C8: 0.051903794 | D8: 0.038078 | E8: =G122+G123 -> 0.060015662 | F8: 0.053990671 | G8: 0.053042779 | I8: 0.05384576 | J8: 0.0471079 | K8: =K122+K123 -> 0.070148364 | L8: 0.071924563 | M8: 0.15903358 | O8: 0 | P8: 0 | R8: 0.072759577 | S8: 0.074666525 | V8: =($B8*$B$29+$E8*$E$29+$H8*$H$29+$K8*$K$29+$N8*$N$29+$Q8*$Q$29+$B39*$B$60+$E39*$E$60+$H39*$H$60+$K39*$K$60+$N39*$N$60+$Q39*$Q$60)/$B$64 -> 0.059302804 | W8: =V8 -> 0.059302804 | X8: =V8-W8 -> 0
A9: Electricity | B9: =E163 -> 0.010280976 | C9: 0.0077075348 | D9: 0.0059095494 | E9: =G163 -> 0.008774935 | F9: 0.0064153677 | G9: 0.010135435 | I9: 0.023850562 | J9: 0.010726 | K9: =K163 -> 0.010280976 | L9: 0.019218863 | M9: 0.010135435 | O9: 0 | P9: 0 | R9: 0.006525594 | S9: 0.010135435 | V9: =($B9*$B$29+$E9*$E$29+$H9*$H$29+$K9*$K$29+$N9*$N$29+$Q9*$Q$29+$B40*$B$60+$E40*$E$60+$H40*$H$60+$K40*$K$60+$N40*$N$60+$Q40*$Q$60)/$B$64 -> 0.0086692394 | W9: =V9 -> 0.0086692394 | X9: =V9-W9 -> 0 | AA9: kwh | AB9: ELE01 | AC9: =ROUND(((D163*B$29*1000)+(F163*E$29*1000)+(H163*H$29*1000)+(J163*K$29*1000)+(L163*N$29*1000)+(N163*Q$29*1000)+(D170*B$60*1000)+(F170*E$60*1000)+(H170*H$60*1000)+(J170*K$60*1000)+(L170*N$60*1000)+(N170*Q$60*1000))*$B163,0) -> 241872 | AD9: =ROUND((D163*B$29*1000)+(F163*E$29*1000)+(H163*H$29*1000)+(J163*K$29*1000)+(L163*N$29*1000)+(N163*Q$29*1000)+(D170*B$60*1000)+(F170*E$60*1000)+(H170*H$60*1000)+(J170*K$60*1000)+(L170*N$60*1000)+(N170*Q$60*1000),0) -> 1016844 | AE9: =AC9/AD9 -> 0.2378654 | AF9: =ROUND(AD9/$B$64,3) -> 36.446 | AG9: =ROUND(W9*$AC$29,0) -> 241872 | AH9: =AG9/AD9 -> 0.2378654 | AI9: =AC9-AG9 -> 0 | AJ9: =AH9*10000 -> 2378.654
A10: Gas | B10: =E164 -> 1.6495208e-06 | C10: 0.00096524487 | D10: 0.0013242333 | E10: =G164 -> 0.0013349276 | F10: 0.00088623983 | G10: 0.0011247591 | I10: 0.0011573683 | J10: 0.00126 | K10: =K164 -> 1.6495208e-06 | L10: 0.0011031846 | M10: 0.0011247591 | O10: 0 | P10: 0 | R10: 0.0011625955 | S10: 0.0011247591 | V10: =($B10*$B$29+$E10*$E$29+$H10*$H$29+$K10*$K$29+$N10*$N$29+$Q10*$Q$29+$B41*$B$60+$E41*$E$60+$H41*$H$60+$K41*$K$60+$N41*$N$60+$Q41*$Q$60)/$B$64 -> 0.0013734225 | W10: =V10 -> 0.0013734225 | X10: =V10-W10 -> 0 | AA10: mbtu | AB10: GAS01 | AC10: =ROUND(((D164*B$29*1000)+(F164*E$29*1000)+(H164*H$29*1000)+(J164*K$29*1000)+(L164*N$29*1000)+(N164*Q$29*1000)+(D171*B$60*1000)+(F171*E$60*1000)+(H171*H$60*1000)+(J171*K$60*1000)+(L171*N$60*1000)+(N171*Q$60*1000))*$B164,0) -> 38318 | AD10: =ROUND(((D164*B$29*1000)+(F164*E$29*1000)+(H164*H$29*1000)+(J164*K$29*1000)+(L164*N$29*1000)+(N164*Q$29*1000)+(D171*B$60*1000)+(F171*E$60*1000)+(H171*H$60*1000)+(J171*K$60*1000)+(L171*N$60*1000)+(N171*Q$60*1000))*1000,0) -> 6836008027 | AE10: =AC10/AD10 -> 5.6053182e-06 | AF10: =ROUND(AD10/$B$64,3) -> 245018.21 | AG10: =ROUND(W10*$AC$29,0) -> 38318 | AH10: =AG10/AD10 -> 5.6053182e-06 | AI10: =AC10-AG10 -> 0 | AJ10: =AH10*10000 -> 0.056053182
A11: R&M Supplies and Service | B11: =$H$179 -> 0.0043010753 | C11: 0.0052601959 | D11: 0.006 | E11: =$H$179 -> 0.0043010753 | F11: 0.0051242876 | G11: 0.0086705202 | I11: 0.023215913 | J11: 0.0099121126 | K11: =$H$179 -> 0.0043010753 | L11: 0.026688594 | M11: 0.0086705202 | O11: 0 | P11: 0 | R11: 0.016241103 | S11: 0.0086705202 | V11: =($B11*$B$29+$E11*$E$29+$H11*$H$29+$K11*$K$29+$N11*$N$29+$Q11*$Q$29+$B42*$B$60+$E42*$E$60+$H42*$H$60+$K42*$K$60+$N42*$N$60+$Q42*$Q$60)/$B$64 -> 0.0043010753 | W11: =V11 -> 0.0043010753 | X11: =V11-W11 -> 0 | AA11: lb | AB11: RMS01 | AC11: =ROUND(G179,0) -> 120000 | AD11: =$B$64*1000 -> 27900000 | AE11: =AC11/AD11 -> 0.0043010753 | AF11: =ROUND(AD11/$B$64,3) -> 1000 | AG11: =ROUND(W11*$AC$29,0) -> 120000 | AH11: =AG11/AD11 -> 0.0043010753 | AI11: =AC11-AG11 -> 0 | AJ11: =AH11*10000 -> 43.010753
A12: Manufacturing Supplies | B12: =$H$182 -> 0.00035842294 | C12: 0.00028145605 | D12: 0.002 | E12: =$H$182 -> 0.00035842294 | F12: 0.0001613237 | G12: 0.00043352601 | I12: 0.00076914757 | J12: 0.00049560563 | K12: =$H$182 -> 0.00035842294 | L12: 0.0013365915 | M12: 0.00043352601 | O12: 0 | P12: 0 | R12: 0.00053366327 | S12: 0.00043352601 | V12: =($B12*$B$29+$E12*$E$29+$H12*$H$29+$K12*$K$29+$N12*$N$29+$Q12*$Q$29+$B43*$B$60+$E43*$E$60+$H43*$H$60+$K43*$K$60+$N43*$N$60+$Q43*$Q$60)/$B$64 -> 0.00035842294 | W12: =V12 -> 0.00035842294 | X12: =V12-W12 -> 0 | AA12: lb | AB12: MFG01 | AC12: =ROUND(G182,0) -> 10000 | AD12: =$B$64*1000 -> 27900000 | AE12: =AC12/AD12 -> 0.00035842294 | AF12: =ROUND(AD12/$B$64,3) -> 1000 | AG12: =ROUND(W12*$AC$29,0) -> 10000 | AH12: =AG12/AD12 -> 0.00035842294 | AI12: =AC12-AG12 -> 0 | AJ12: =AH12*10000 -> 3.5842294
A13: Other variable | B13: =$H$185 -> 0.0053763441 | C13: 0.005539271 | D13: 0.006 | E13: =$H$185 -> 0.0053763441 | F13: 0.0047523717 | G13: 0.0057803468 | I13: 0.017048253 | J13: 0.0066080751 | K13: =$H$185 -> 0.0053763441 | L13: 0.026821614 | M13: 0.0057803468 | O13: 0 | P13: 0 | R13: 0.0059964109 | S13: 0.0057803468 | V13: =($B13*$B$29+$E13*$E$29+$H13*$H$29+$K13*$K$29+$N13*$N$29+$Q13*$Q$29+$B44*$B$60+$E44*$E$60+$H44*$H$60+$K44*$K$60+$N44*$N$60+$Q44*$Q$60)/$B$64 -> 0.0053763441 | W13: =V13 -> 0.0053763441 | X13: =V13-W13 -> 0 | AA13: lb | AB13: VAR01 | AC13: =ROUND(G185,0) -> 150000 | AD13: =$B$64*1000 -> 27900000 | AE13: =AC13/AD13 -> 0.0053763441 | AF13: =ROUND(AD13/$B$64,3) -> 1000 | AG13: =ROUND(W13*$AC$29,0) -> 150000 | AH13: =AG13/AD13 -> 0.0053763441 | AI13: =AC13-AG13 -> 0 | AJ13: =AH13*10000 -> 53.763441
A14: Total Variable Costs | B14: =SUM(B6:B13) -> 0.24807858 | C14: =SUM(C6:C13) -> 0.23258747 | D14: =SUM(D6:D13) -> 0.22326468 | E14: =SUM(E6:E13) -> 0.26900501 | F14: =SUM(F6:F13) -> 0.23029767 | G14: 0.30559917 | I14: =SUM(I6:I13) -> 0.42180018 | J14: =SUM(J6:J13) -> 0.5824108 | K14: =SUM(K6:K13) -> 0.28698646 | L14: =SUM(L6:L13) -> 0.3301731 | M14: 0.43366311 | O14: =SUM(O6:O13) -> 0 | P14: =SUM(P6:P13) -> 0 | R14: =SUM(R6:R13) -> 0.26290735 | S14: 0.33373539 | V14: =SUM(V6:V13) -> 0.30009703 | W14: =SUM(W6:W13) -> 0.30009703 | X14: =SUM(X6:X13) -> 0 | AC14: =SUM(AC9:AC13) -> 560190 | AG14: =SUM(AG9:AG13) -> 560190 | AI14: =SUM(AI9:AI13) -> 0
A16: Production Labor | B16: =$D$216/$B$64/1000 -> 0.023140287 | C16: 0.018200142 | D16: 0.035940795 | E16: =$D$216/$B$64/1000 -> 0.023140287 | F16: 0.020063713 | G16: 0.011741675 | I16: 0.012521635 | J16: 0.014552451 | K16: =$D$216/$B$64/1000 -> 0.023140287 | L16: 0.032785827 | M16: 0.011741675 | O16: 0 | P16: 0 | R16: 0.013727223 | S16: 0.011741675 | V16: =($B16*$B$29+$E16*$E$29+$H16*$H$29+$K16*$K$29+$N16*$N$29+$Q16*$Q$29+$B47*$B$60+$E47*$E$60+$H47*$H$60+$K47*$K$60+$N47*$N$60+$Q47*$Q$60)/$B$64 -> 0.023140287 | W16: =+W24-W14 -> 0.029721496 | X16: =V16-W16 -> -0.0065812083 | AA16: hr | AB16: DLAB01 | AC16: =ROUND(D214,0) -> 670220 | AD16: =ROUND(B214,0) -> 22000 | AE16: =AC16/AD16 -> 30.464545 | AF16: =ROUND(AD16/$B$64,3) -> 0.789 | AG16: =ROUND(W16*$AC$29,0) -> 829230 | AH16: =AG16/AD16 -> 37.692273 | AI16: =AC16-AG16 -> -159010 | AJ16: =AH16*10000 -> 376922.73
A17: Repairs & Maintenance Labor | B17: =$G$216/$B$64/1000 -> 0.0055727599 | C17: 0.0048304191 | D17: 0.0113712 | E17: =$G$216/$B$64/1000 -> 0.0055727599 | F17: 0.0044471791 | G17: 0.0041080925 | I17: 0.0044303098 | J17: 0.004696359 | K17: =$G$216/$B$64/1000 -> 0.0055727599 | L17: 0.0088578354 | M17: 0.0041080925 | O17: 0 | P17: 0 | R17: 0.0016693747 | S17: 0.0041080925 | V17: =($B17*$B$29+$E17*$E$29+$H17*$H$29+$K17*$K$29+$N17*$N$29+$Q17*$Q$29+$B48*$B$60+$E48*$E$60+$H48*$H$60+$K48*$K$60+$N48*$N$60+$Q48*$Q$60)/$B$64 -> 0.0055727599 | W17: 0 | X17: =V17-W17 -> 0.0055727599 | AA17: hr | AB17: MLAB01 | AC17: =ROUND(G214,0) -> 155480 | AD17: =ROUND(E214,0) -> 4400 | AE17: =AC17/AD17 -> 35.336364 | AF17: =ROUND(AD17/$B$64,3) -> 0.158 | AG17: =ROUND(W17*$AC$29,0) -> 0 | AH17: =AG17/AD17 -> 0 | AI17: =AC17-AG17 -> 155480 | AJ17: =AH17*10000 -> 0
A18: Indirect Payroll Costs (Benefits) | B18: =$J$216/$B$64/1000 -> 0.010221704 | C18: 0.0068508297 | D18: 0.014188877 | E18: =$J$216/$B$64/1000 -> 0.010221704 | F18: 0.0059757405 | G18: 0.0072598437 | I18: 0.014238166 | J18: 0.008765191 | K18: =$J$216/$B$64/1000 -> 0.010221704 | L18: 0.038686584 | M18: 0.0072598437 | O18: 0 | P18: 0 | R18: 0.0056633179 | S18: 0.0072598437 | V18: =($B18*$B$29+$E18*$E$29+$H18*$H$29+$K18*$K$29+$N18*$N$29+$Q18*$Q$29+$B49*$B$60+$E49*$E$60+$H49*$H$60+$K49*$K$60+$N49*$N$60+$Q49*$Q$60)/$B$64 -> 0.010221704 | W18: 0 | X18: =V18-W18 -> 0.010221704 | AA18: hr | AB18: IPC01 | AC18: =ROUND(J214,0) -> 294186 | AD18: =ROUND(H214,0) -> 26400 | AE18: =AC18/AD18 -> 11.143409 | AF18: =ROUND(AD18/$B$64,3) -> 0.946 | AG18: =ROUND(W18*$AC$29,0) -> 0 | AH18: =AG18/AD18 -> 0 | AI18: =AC18-AG18 -> 294186 | AJ18: =AH18*10000 -> 0
A19: Supervision | B19: =$E$243 -> 0.0055526882 | C19: 0.0022776301 | D19: 0 | E19: =$E$243 -> 0.0055526882 | F19: 0.0019225049 | G19: 0.002449852 | I19: 0.0092721693 | J19: 0.0028006635 | K19: =$E$243 -> 0.0055526882 | L19: 0.01254166 | M19: 0.002449852 | O19: 0 | P19: 0 | R19: 0.0023710733 | S19: 0.002449852 | V19: =($B19*$B$29+$E19*$E$29+$H19*$H$29+$K19*$K$29+$N19*$N$29+$Q19*$Q$29+$B50*$B$60+$E50*$E$60+$H50*$H$60+$K50*$K$60+$N50*$N$60+$Q50*$Q$60)/$B$64 -> 0.0055526882 | W19: 0 | X19: =V19-W19 -> 0.0055526882 | AA19: lb | AB19: SUP01 | AC19: =ROUND(C243,0) -> 154920 | AD19: =$B$64*1000 -> 27900000 | AE19: =AC19/AD19 -> 0.0055526882 | AF19: =ROUND(AD19/$B$64,3) -> 1000 | AG19: =ROUND(W19*$AC$29,0) -> 0 | AH19: =AG19/AD19 -> 0 | AI19: =AC19-AG19 -> 154920 | AJ19: =AH19*10000 -> 0
A20: Depreciation | B20: =$E$244 -> 0.0040172043 | C20: 0.061012872 | D20: 0.01039048 | E20: =$E$244 -> 0.0040172043 | F20: 0.051498884 | G20: 0.06367052 | I20: 0.24870656 | J20: 0.072787947 | K20: =$E$244 -> 0.0040172043 | L20: 0.34045176 | M20: 0.06367052 | O20: 0 | P20: 0 | R20: 0.064182394 | S20: 0.06367052 | V20: =($B20*$B$29+$E20*$E$29+$H20*$H$29+$K20*$K$29+$N20*$N$29+$Q20*$Q$29+$B51*$B$60+$E51*$E$60+$H51*$H$60+$K51*$K$60+$N51*$N$60+$Q51*$Q$60)/$B$64 -> 0.0040172043 | W20: =W24-W14-W16-W17-W18-W19-W21 -> 0 | X20: =V20-W20 -> 0.0040172043 | AA20: lb | AB20: DEP01 | AC20: =ROUND(C244,0) -> 112080 | AD20: =($B$29+$E$29+$H$29+$K$29+$N$29+B60+E60+H60+K60+N60)*1000 -> 27900000 | AE20: =AC20/AD20 -> 0.0040172043 | AF20: =ROUND(AD20/($B$29+$E$29+$H$29+$K$29+$N$29+B60+E60+H60+K60+N60),3) -> 1000 | AG20: =ROUND(W20*$AC$29,0) -> 0 | AH20: =AG20/AD20 -> 0 | AI20: =AC20-AG20 -> 112080 | AJ20: =AH20*10000 -> 0
A21: Insurance & Taxes | B21: =$E$245 -> 0.020176344 | C21: 0.01547789 | D21: 0.03763008 | E21: =$E$245 -> 0.020176344 | F21: 0.012959419 | G21: 0.014046243 | I21: 0.064467032 | J21: 0.018172206 | K21: =$E$245 -> 0.020176344 | L21: 0.083528141 | M21: 0.014046243 | O21: 0 | P21: 0 | R21: 0.015675972 | S21: 0.014046243 | V21: =($B21*$B$29+$E21*$E$29+$H21*$H$29+$K21*$K$29+$N21*$N$29+$Q21*$Q$29+$B52*$B$60+$E52*$E$60+$H52*$H$60+$K52*$K$60+$N52*$N$60+$Q52*$Q$60)/$B$64 -> 0.020176344 | W21: =W24-W14-W16-W17-W18-W19 -> 0 | X21: =V21-W21 -> 0.020176344 | AA21: lb | AB21: INS01 | AC21: =ROUND(C245,0) -> 562920 | AD21: =$B$64*1000 -> 27900000 | AE21: =AC21/AD21 -> 0.020176344 | AF21: =ROUND(AD21/$B$64,3) -> 1000 | AG21: =ROUND(W21*$AC$29,0) -> 0 | AH21: =AG21/AD21 -> 0 | AI21: =AC21-AG21 -> 562920 | AJ21: =AH21*10000 -> 0
