Workbook

Sheet 2025 Summary
B1: McIntyre Summary
C3: HT | D3: CarboProp | E3: CarboHSP | F3: Bauxite Pellets | G3: ID | H3: Nanomite C | L3: HT | M3: CarboProp | N3: CarboHSP | O3: Bauxite Pellets | P3: ID | Q3: Nanomite C
B4: Nov | K4: Nov | L4: ='Nov23'!$B$22 -> 0 | M4: ='Nov23'!$B$45 -> 0 | N4: ='Nov23'!$E$45 -> 0 | P4: ='Nov23'!$H$22 -> 0 | Q4: ='Nov23'!$H$45 -> 0
B5: Dec | K5: Dec | L5: ='Dec23'!$B$22 -> 0 | M5: ='Dec23'!$B$45 -> 0 | N5: ='Dec23'!$E$45 -> 0 | P5: ='Dec23'!$H$22 -> 0 | Q5: ='Dec23'!$H$45 -> 0
B6: Jan | C6: 0 | D6: 0 | E6: 0 | G6: 0 | H6: 2000 | K6: Jan | L6: =Jan!$B$22 -> 0 | M6: =Jan!$B$45 -> 0 | N6: =Jan!$E$45 -> 0 | P6: =Jan!$H$22 -> 0 | Q6: =Jan!$H$45 -> 0.3459
B7: Feb | C7: 1750 | D7: 3500 | E7: 0 | F7: 6400 | G7: 2590 | H7: 0 | K7: Feb | L7: =Feb!$B$22 -> 0.28330977 | M7: =Feb!B45 -> 0.26666777 | N7: =Feb!$E$45 -> 0 | O7: =Feb!E22 -> 0.22642002 | P7: =Feb!$H$22 -> 0.26666777 | Q7: =Feb!$H$45 -> 0
B8: Mar | C8: 0 | D8: 3000 | E8: 0 | F8: 9600 | G8: 4440 | H8: 0 | K8: Mar | L8: =Mar!$B$22 -> 0 | M8: =Mar!B45 -> 0.25593102 | N8: =Mar!$E$45 -> 0 | O8: =Mar!E22 -> 0.21568327 | P8: =Mar!$H$22 -> 0.25593102 | Q8: =Mar!$H$45 -> 0
B9: Apr | C9: 0 | D9: 0 | E9: 0 | F9: 0 | G9: 0 | H9: 2000 | K9: Apr | L9: =Apr!$B$22 -> 0 | M9: =Apr!B45 -> 0 | N9: =Apr!$E$45 -> 0 | P9: =Apr!$H$22 -> 0 | Q9: =Apr!$H$45 -> 0.3459
B10: May | C10: 0 | D10: 0 | E10: 900 | F10: 6400 | G10: 4000 | H10: 0 | K10: May | L10: =May!$B$22 -> 0 | M10: =May!$B$45 -> 0 | N10: =May!$E$45 -> 0.30724 | O10: =May!E22 -> 0.24342019 | P10: =May!$H$22 -> 0.28366794 | Q10: =May!$H$45 -> 0
B11: Jun | C11: 0 | D11: 0 | E11: 0 | F11: 6400 | G11: 3700 | H11: 2000 | K11: Jun | L11: =Jun!$B$22 -> 0 | M11: =Jun!$B$45 -> 0 | N11: =Jun!$E$45 -> 0 | O11: =Jun!E22 -> 0.23797616 | P11: =Jun!$H$22 -> 0.27822391 | Q11: =Jun!$H$45 -> 0.16147997
B12: Jul | C12: 0 | D12: 0 | E12: 0 | G12: 0 | H12: 6000 | K12: Jul | L12: =Jul!$B$22 -> 0 | M12: =Jul!$B$45 -> 0 | N12: =Jul!$E$45 -> 0 | P12: =Jul!$H$22 -> 0 | Q12: =Jul!$H$45 -> 0.2396585
B13: Aug | C13: 0 | D13: 0 | E13: 0 | G13: 0 | H13: 6000 | K13: Aug | L13: =Aug!$B$22 -> 0 | M13: =Aug!$B$45 -> 0 | N13: =Aug!$E$45 -> 0 | P13: =Aug!$H$22 -> 0 | Q13: =Aug!$H$45 -> 0.2396585
B14: Sep | C14: 0 | D14: 0 | E14: 0 | G14: 2590 | H14: 4600 | K14: Sep | L14: =Sep!$B$22 -> 0 | M14: =Sep!$B$45 -> 0 | N14: =Sep!$E$45 -> 0 | P14: =Sep!$H$22 -> 0.33073626 | Q14: =Sep!$H$45 -> 0.21399233
B15: Oct | C15: 1500 | D15: 0 | E15: 0 | G15: 1850 | H15: 2000 | K15: Oct | L15: =Oct!$B$22 -> 0.39188537 | M15: =Oct!$B$45 -> 0 | N15: =Oct!$E$45 -> 0 | P15: =Oct!$H$22 -> 0.37524337 | Q15: =Oct!$H$45 -> 0.25849944
B16: Nov | C16: 0 | D16: 0 | E16: 0 | G16: 0 | K16: Nov | L16: =Nov!$B$22 -> 0 | M16: =Nov!$B$45 -> 0 | N16: =Nov!$E$45 -> 0 | P16: =Nov!$H$22 -> 0 | Q16: =Nov!$H$45 -> 0
B17: Dec | C17: 0 | D17: 0 | E17: 0 | G17: 0 | H17: 0 | K17: Dec | L17: =Dec!$B$22 -> 0 | M17: =Dec!$B$45 -> 0 | N17: =Dec!$E$45 -> 0 | P17: =Dec!$H$22 -> 0 | Q17: =Dec!$H$45 -> 0
B19: Total | C19: =SUM(C6:C17) -> 3250 | D19: =SUM(D4:D17) -> 6500 | E19: =SUM(E4:E17) -> 900 | F19: =SUM(F6:F17) -> 28800 | G19: =SUM(G6:G17) -> 19170 | H19: =SUM(H6:H17) -> 24600

Sheet Nov23
A1: McINTYRE STANDARD 2025 | S1: COST CENTER 10001003 | AE1: Gross | AF1: Std | AG1: Abs Limit | AH1: Absorb | AI1: 10001003 | AJ1: Absorbed | AK1: 10001003 | AX1: Abs Cost
S2: CG | T2: CP | U2: HSP | V2: CL | W2: Nanomite C | X2: NRT | Y2: To Production | Z2: Idle Plant | AA2: TOTAL | AB2: Activity / Material | AC2: UOM | AD2: Ttl Unit Qty | AE2: Unit Cost | AF2: Cost/lb | AG2: Cost/lb | AH2: Cost/lb | AI2: Absorption | AJ2: Unit Cost | AK2: Underabs | AL2: EP Unit Qty | AM2: CP Unit Qty | AN2: HSP Unit Qty | AO2: CL Unit Qty | AP2: Nano C Qty | AQ2: NRT Unit Qty | AR2: EP Units/1000lb | AS2: CP Units/1000lb | AT2: HSP Units/1000lb | AU2: CL Units/1000lb | AV2: Nano C Units/1000lb | AW2: NRT Units/1000lb | AX2: per 10000
B3: HT | E3: Bauxite Pellets | H3: ID
B4: 25 Standard | C4: 23 Actual | D4: 22 Standard | E4: =B4 -> 25 Standard | F4: 23 Actual | G4: =+D4 -> 22 Standard | H4: =B4 -> 25 Standard | I4: 23 Actual | J4: =+D4 -> 22 Standard
F5: (Jan-Aug)
A6: Materials | B6: =IF($B$24<>0,$D$80,0) -> 0 | D6: 0 | E6: =IF(E24<>0,$L$88,0) -> 0 | F6: 0.071053254 | G6: 0.02685 | H6: =IF($H$24<>0,$D$88,0) -> 0 | J6: 0
A7: Electricity | B7: =IF($B$24<>0,$D$151,0) -> 0 | D7: 0 | E7: =IF(E24<>0,$D$151,0) -> 0 | F7: 0.03392679 | G7: 0.018883379 | H7: =IF(H24<>0,$D$151,0) -> 0 | J7: 0 | S7: =$C145*$B$24*1000*$B145 -> 0 | T7: =$C151*$B$47*1000*$B151 -> 0 | U7: =$F151*$E$47*1000*$E151 -> 0 | V7: =$F145*$E$24*1000*$E145 -> #DIV/0! | W7: =$I151*$H$47*1000*$H151 -> 0 | X7: =$I145*$H$24*1000*$H145 -> 0 | Y7: =SUM(S7:X7) -> #DIV/0! | Z7: 0 | AA7: =SUM(Y7:Z7) -> #DIV/0! | AB7: ELE01 | AC7: kwh | AD7: =ROUND((B145*B$24*1000)+(B151*B$47*1000)+(E145*E$24*1000)+(E151*E$47*1000)+(H145*H$24*1000)+(H151*H$47*1000),0) -> #DIV/0! | AE7: =Y7/AD7 -> #DIV/0! | AF7: =Y7/$AF$24/1000 -> #DIV/0! | AG7: 0.014890786 | AH7: =IF($AF$21<$AG$21,AF7,IF($AF$12<$AG$12,AF7,IF(AND($AF$12>$AG$12,$AF$20<$AG$20),($AG$12+($AG$20-$AF$20))/$AF$12*AF7,AF7/$AF$12*$AG$12))) -> #DIV/0! | AI7: =AH7*$Y$24*1000 -> #DIV/0! | AJ7: =AI7/AD7 -> #DIV/0! | AK7: =Y7-AI7 -> #DIV/0! | AL7: =ROUND($B145*$B$24*1000,0) -> 0 | AM7: =ROUND($B151*$B$47*1000,0) -> 0 | AN7: =ROUND($E151*$E$47*1000,0) -> 0 | AO7: =ROUND($E145*$E$24*1000,0) -> #DIV/0! | AP7: =ROUND($H151*$H$47*1000,0) -> 0 | AQ7: =ROUND($H145*$H$24*1000,0) -> 0 | AR7: =IF($B$24<>0,ROUND(AL7/B$24,3),0) -> 0 | AS7: =ROUND(AM7/B$47,3) -> #DIV/0! | AT7: =IF(E$47<>0,ROUND(AN7/E$47,3),0) -> 0 | AU7: =IF(F$24<>0,ROUND(AO7/F$24,3),0) -> #DIV/0! | AV7: =IF(H$47<>0,ROUND(AP7/H$47,3),0) -> 0 | AW7: =IF(H$24<>0,ROUND(AQ7/H$24,3),0) -> 0 | AX7: =AJ7*10000 -> #DIV/0!
A8: Gas | B8: =IF($B$24<>0,$D$152,0) -> 0 | D8: 0 | E8: =IF(E24<>0,$D$152,0) -> 0 | F8: 0.14600441 | G8: 0.04184 | H8: =IF(H24<>0,$D$152,0) -> 0 | J8: 0 | S8: =$C146*$B$24*1000*$B146 -> 0 | T8: =$C152*$B$47*1000*$B152 -> 0 | U8: =$F152*$E$47*1000*$E152 -> 0 | V8: =$F146*$E$24*1000*$E146 -> 0 | W8: =$I152*$H$47*1000*$H152 -> 0 | X8: =$I146*$H$24*1000*$H146 -> 0 | Y8: =SUM(S8:X8) -> 0 | Z8: 0 | AA8: =SUM(Y8:Z8) -> 0 | AB8: GAS01 | AC8: mbtu | AD8: =ROUND((B146*B$24*1000*1000)+(B152*B$47*1000*1000)+(E146*E$24*1000*1000)+(E152*E$47*1000*1000)+(H146*H$24*1000*1000)+(H152*H$47*1000*1000),0) -> 0 | AE8: =Y8/AD8 -> #DIV/0! | AF8: =Y8/$AF$24/1000 -> #DIV/0! | AG8: 0.042004912 | AH8: =IF($AF$21<$AG$21,AF8,IF($AF$12<$AG$12,AF8,IF(AND($AF$12>$AG$12,$AF$20<$AG$20),($AG$12+($AG$20-$AF$20))/$AF$12*AF8,AF8/$AF$12*$AG$12))) -> #DIV/0! | AI8: =AH8*$Y$24*1000 -> #DIV/0! | AJ8: =AI8/AD8 -> #DIV/0! | AK8: =Y8-AI8 -> #DIV/0! | AL8: =ROUND($B146*$B$24*1000*1000,0) -> 0 | AM8: =ROUND($B152*$B$47*1000*1000,0) -> 0 | AN8: =ROUND($E152*$E$47*1000*1000,0) -> 0 | AO8: =ROUND($E146*$E$24*1000*1000,0) -> 0 | AP8: =ROUND($H152*$H$47*1000*1000,0) -> 0 | AQ8: =ROUND($H146*$H$24*1000*1000,0) -> 0 | AR8: =IF($B$24<>0,ROUND(AL8/B$24,3),0) -> 0 | AS8: =ROUND(AM8/B$47,3) -> #DIV/0! | AT8: =IF(E$47<>0,ROUND(AN8/E$47,3),0) -> 0 | AU8: =IF(E$24<>0,ROUND(AO8/E$24,3),0) -> 0 | AV8: =IF(H$47<>0,ROUND(AP8/H$47,3),0) -> 0 | AW8: =IF(H$24<>0,ROUND(AQ8/H$24,3),0) -> 0 | AX8: =AJ8*10000 -> #DIV/0!
A9: R&M Supplies and Service | B9: =IF($B$24<>0,$H$159,0) -> 0 | D9: 0 | E9: =IF(E24<>0,$H$159,0) -> 0 | F9: 0.043366417 | G9: 0.022368421 | H9: =IF(H24<>0,$H$159,0) -> 0 | J9: 0 | S9: =B9*B$24*1000 -> 0 | T9: =B32*B$47*1000 -> 0 | U9: =E32*E$47*1000 -> 0 | V9: =E9*E$24*1000 -> 0 | W9: =H32*H$47*1000 -> 0 | X9: =H9*H$24*1000 -> 0 | Y9: =SUM(S9:X9) -> 0 | Z9: 0 | AA9: =SUM(Y9:Z9) -> 0 | AB9: RMS01 | AC9: lb | AD9: =ROUND((S9/H$159)+(T9/H$159)+(U9/H$159)+(V9/H$159)+(W9/H$159)+(X9/H$159),0) -> #DIV/0! | AE9: =Y9/AD9 -> #DIV/0! | AF9: =Y9/$AF$24/1000 -> #DIV/0! | AG9: 0.019544347 | AH9: =IF($AF$21<$AG$21,AF9,IF($AF$12<$AG$12,AF9,IF(AND($AF$12>$AG$12,$AF$20<$AG$20),($AG$12+($AG$20-$AF$20))/$AF$12*AF9,AF9/$AF$12*$AG$12))) -> #DIV/0! | AI9: =AH9*$Y$24*1000 -> #DIV/0! | AJ9: =AI9/AD9 -> #DIV/0! | AK9: =Y9-AI9 -> #DIV/0! | AL9: =S9/$AE9 -> #DIV/0! | AM9: =T9/$AE9 -> #DIV/0! | AN9: =U9/$AE9 -> #DIV/0! | AO9: =V9/$AE9 -> #DIV/0! | AP9: =W9/$AE9 -> #DIV/0! | AQ9: =X9/$AE9 -> #DIV/0! | AR9: =IF($B$24<>0,ROUND(AL9/B$24,3),0) -> 0 | AS9: =ROUND(AM9/B$47,3) -> #DIV/0! | AT9: =IF(E$47<>0,ROUND(AN9/E$47,3),0) -> 0 | AU9: =IF(E$24<>0,ROUND(AO9/E$24,3),0) -> 0 | AV9: =IF(H$47<>0,ROUND(AP9/H$47,3),0) -> 0 | AW9: =IF(H$24<>0,ROUND(AQ9/H$24,3),0) -> 0 | AX9: =AJ9*10000 -> #DIV/0!
A10: Manufacturing Supplies | B10: =IF($B$24<>0,$H$163,0) -> 0 | D10: 0 | E10: =IF(E24<>0,$H$163,0) -> 0 | F10: 0.00073336258 | G10: 0.00065789474 | H10: =IF($H$24<>0,$H$163,0) -> 0 | J10: 0 | S10: =B10*B$24*1000 -> 0 | T10: =B33*B$47*1000 -> 0 | U10: =E33*E$47*1000 -> 0 | V10: =E10*E$24*1000 -> 0 | W10: =H33*H$47*1000 -> 0 | X10: =H10*H$24*1000 -> 0 | Y10: =SUM(S10:X10) -> 0 | Z10: 0 | AA10: =SUM(Y10:Z10) -> 0 | AB10: MFG01 | AC10: lb | AD10: =ROUND((S10/H$163)+(T10/H$163)+(U10/H$163)+(V10/H$163)+(W10/H$163)+(X10/H$163),0) -> #DIV/0! | AE10: =Y10/AD10 -> #DIV/0! | AF10: =Y10/$AF$24/1000 -> #DIV/0! | AG10: 0.0012510769 | AH10: =IF($AF$21<$AG$21,AF10,IF($AF$12<$AG$12,AF10,IF(AND($AF$12>$AG$12,$AF$20<$AG$20),($AG$12+($AG$20-$AF$20))/$AF$12*AF10,AF10/$AF$12*$AG$12))) -> #DIV/0! | AI10: =AH10*$Y$24*1000 -> #DIV/0! | AJ10: =AI10/AD10 -> #DIV/0! | AK10: =Y10-AI10 -> #DIV/0! | AL10: =S10/$AE10 -> #DIV/0! | AM10: =T10/$AE10 -> #DIV/0! | AN10: =U10/$AE10 -> #DIV/0! | AO10: =V10/$AE10 -> #DIV/0! | AP10: =W10/$AE10 -> #DIV/0! | AQ10: =X10/$AE10 -> #DIV/0! | AR10: =IF($B$24<>0,ROUND(AL10/B$24,3),0) -> 0 | AS10: =ROUND(AM10/B$47,3) -> #DIV/0! | AT10: =IF(E$47<>0,ROUND(AN10/E$47,3),0) -> 0 | AU10: =IF(E$24<>0,ROUND(AO10/E$24,3),0) -> 0 | AV10: =IF(H$47<>0,ROUND(AP10/H$47,3),0) -> 0 | AW10: =IF(H$24<>0,ROUND(AQ10/H$24,3),0) -> 0 | AX10: =AJ10*10000 -> #DIV/0!
A11: Other variable | B11: =IF($B$24<>0,$H$166,0) -> 0 | D11: 0 | E11: =IF(E24<>0,$H$166,0) -> 0 | F11: 0.010235236 | G11: 0.0046052632 | H11: =IF($H$24<>0,$H$166,0) -> 0 | J11: 0 | S11: =B11*B$24*1000 -> 0 | T11: =B34*B$47*1000 -> 0 | U11: =E34*E$47*1000 -> 0 | V11: =E11*E$24*1000 -> 0 | W11: =H34*H$47*1000 -> 0 | X11: =H11*H$24*1000 -> 0 | Y11: =SUM(S11:X11) -> 0 | Z11: 0 | AA11: =SUM(Y11:Z11) -> 0 | AB11: VAR01 | AC11: lb | AD11: =ROUND((S11/H$166)+(T11/H$166)+(U11/H$166)+(V11/H$166)+(W11/H$166)+(X11/H$166),0) -> #DIV/0! | AE11: =Y11/AD11 -> #DIV/0! | AF11: =Y11/$AF$24/1000 -> #DIV/0! | AG11: 0.0037333371 | AH11: =IF($AF$21<$AG$21,AF11,IF($AF$12<$AG$12,AF11,IF(AND($AF$12>$AG$12,$AF$20<$AG$20),($AG$12+($AG$20-$AF$20))/$AF$12*AF11,AF11/$AF$12*$AG$12))) -> #DIV/0! | AI11: =AH11*$Y$24*1000 -> #DIV/0! | AJ11: =AI11/AD11 -> #DIV/0! | AK11: =Y11-AI11 -> #DIV/0! | AL11: =S11/$AE11 -> #DIV/0! | AM11: =T11/$AE11 -> #DIV/0! | AN11: =U11/$AE11 -> #DIV/0! | AO11: =V11/$AE11 -> #DIV/0! | AP11: =W11/$AE11 -> #DIV/0! | AQ11: =X11/$AE11 -> #DIV/0! | AR11: =IF($B$24<>0,ROUND(AL11/B$24,3),0) -> 0 | AS11: =ROUND(AM11/B$47,3) -> #DIV/0! | AT11: =IF(E$47<>0,ROUND(AN11/E$47,3),0) -> 0 | AU11: =IF(E$24<>0,ROUND(AO11/E$24,3),0) -> 0 | AV11: =IF(H$47<>0,ROUND(AP11/H$47,3),0) -> 0 | AW11: =IF(H$24<>0,ROUND(AQ11/H$24,3),0) -> 0 | AX11: =AJ11*10000 -> #DIV/0!
A12: Total Variable Costs | B12: =SUM(B6:B11) -> 0 | D12: =SUM(D6:D11) -> 0 | E12: =SUM(E6:E11) -> 0 | F12: =SUM(F6:F11) -> 0.30531947 | G12: =SUM(G6:G11) -> 0.11520496 | H12: =SUM(H6:H11) -> 0 | J12: =SUM(J6:J11) -> 0 | S12: =SUM(S7:S11) -> 0 | T12: =SUM(T7:T11) -> 0 | U12: =SUM(U7:U11) -> 0 | V12: =SUM(V7:V11) -> #DIV/0! | W12: =SUM(W7:W11) -> 0 | X12: =SUM(X7:X11) -> 0 | Y12: =SUM(Y7:Y11) -> #DIV/0! | Z12: =SUM(Z7:Z11) -> 0 | AA12: =SUM(AA7:AA11) -> #DIV/0! | AF12: =SUM(AF7:AF11) -> #DIV/0! | AG12: =SUM(AG7:AG11) -> 0.081424459 | AH12: =SUM(AH7:AH11) -> #DIV/0! | AI12: =SUM(AI7:AI11) -> #DIV/0! | AK12: =SUM(AK7:AK11) -> #DIV/0!
A14: Production Labor | B14: =IF($B$24<>0,$F$112/$B$49/1000,0) -> 0 | D14: 0 | E14: =IF(E24<>0,$F$112/$B$49/1000,0) -> 0 | F14: 0.055685781 | G14: 0.02638428 | H14: =IF($H$24<>0,$F$112/$B$49/1000,0) -> 0 | J14: 0 | S14: =B14*B$24*1000 -> 0 | T14: =B37*B$47*1000 -> 0 | U14: =E37*E$47*1000 -> 0 | V14: =E14*E$24*1000 -> 0 | W14: =H37*H$47*1000 -> 0 | X14: =H14*H$24*1000 -> 0 | Y14: =SUM(S14:X14) -> 0 | Z14: =-$D$115 -> 0 | AA14: =SUM(Y14:Z14) -> 0 | AB14: DLAB01 | AC14: hr | AD14: =ROUND((S14/C$116)+(T14/C$116)+(U14/C$116)+(V14/C$116)+(W14/C$116)+(X14/C$116),0) -> #DIV/0! | AE14: =Y14/AD14 -> #DIV/0! | AF14: =Y14/$AF$24/1000 -> #DIV/0! | AG14: 0.011488554 | AH14: =IF($AF$21<$AG$21,AF14,IF($AF$20<$AG$20,AF14,IF(AND($AF$20>$AG$20,$AF$12<$AG$12),($AG$20+($AG$12-$AF$12))/$AF$20*AF14,AF14/$AF$20*$AG$20))) -> #DIV/0! | AI14: =AH14*$Y$24*1000 -> #DIV/0! | AJ14: =AI14/AD14 -> #DIV/0! | AK14: =Y14-AI14 -> #DIV/0! | AL14: =ROUND(S14/$C116,0) -> #DIV/0! | AM14: =ROUND(T14/$C116,0) -> #DIV/0! | AN14: =ROUND(U14/$C116,0) -> #DIV/0! | AO14: =ROUND(V14/$C116,0) -> #DIV/0! | AP14: =ROUND(W14/$C116,0) -> #DIV/0! | AQ14: =ROUND(X14/$C116,0) -> #DIV/0! | AR14: =IF($B$24<>0,ROUND(AL14/B$24,3),0) -> 0 | AS14: =ROUND(AM14/B$47,3) -> #DIV/0! | AT14: =IF(E$47<>0,ROUND(AN14/E$47,3),0) -> 0 | AU14: =IF(E$24<>0,ROUND(AO14/E$24,3),0) -> 0 | AV14: =IF(H$47<>0,ROUND(AP14/H$47,3),0) -> 0 | AW14: =IF(H$24<>0,ROUND(AQ14/H$24,3),0) -> 0 | AX14: =AJ14*10000 -> #DIV/0!
A15: Repairs & Maintenance Labor | B15: =IF($B$24<>0,$F$113/$B$49/1000,0) -> 0 | D15: 0 | E15: =IF(E24<>0,$F$113/$B$49/1000,0) -> 0 | F15: 0.019535758 | G15: 0.00902044 | H15: =IF($H$24<>0,$F$113/$B$49/1000,0) -> 0 | J15: 0 | S15: =B15*B$24*1000 -> 0 | T15: =B38*B$47*1000 -> 0 | U15: =E38*E$47*1000 -> 0 | V15: =E15*E$24*1000 -> 0 | W15: =H38*H$47*1000 -> 0 | X15: =H15*H$24*1000 -> 0 | Y15: =SUM(S15:X15) -> 0 | Z15: =-$H$115 -> 0 | AA15: =SUM(Y15:Z15) -> 0 | AB15: MLAB01 | AC15: hr | AD15: =ROUND((S15/G$116)+(T15/G$116)+(U15/G$116)+(V15/G$116)+(W15/G$116)+(X15/G$116),0) -> #DIV/0! | AE15: =Y15/AD15 -> #DIV/0! | AF15: =Y15/$AF$24/1000 -> #DIV/0! | AG15: 0.007650221 | AH15: =IF($AF$21<$AG$21,AF15,IF($AF$20<$AG$20,AF15,IF(AND($AF$20>$AG$20,$AF$12<$AG$12),($AG$20+($AG$12-$AF$12))/$AF$20*AF15,AF15/$AF$20*$AG$20))) -> #DIV/0! | AI15: =AH15*$Y$24*1000 -> #DIV/0! | AJ15: =AI15/AD15 -> #DIV/0! | AK15: =Y15-AI15 -> #DIV/0! | AL15: =ROUND(S15/$G$116,0) -> #DIV/0! | AM15: =ROUND(T15/$G$116,0) -> #DIV/0! | AN15: =ROUND(U15/$G$116,0) -> #DIV/0! | AO15: =ROUND(V15/$G$116,0)-1 -> #DIV/0! | AP15: =ROUND(W15/$G$116,0) -> #DIV/0! | AQ15: =ROUND(X15/$G$116,0) -> #DIV/0! | AR15: =IF($B$24<>0,ROUND(AL15/B$24,3),0) -> 0 | AS15: =ROUND(AM15/B$47,3) -> #DIV/0! | AT15: =IF(E$47<>0,ROUND(AN15/E$47,3),0) -> 0 | AU15: =IF(E$24<>0,ROUND(AO15/E$24,3),0) -> 0 | AV15: =IF(H$47<>0,ROUND(AP15/H$47,3),0) -> 0 | AW15: =IF(H$24<>0,ROUND(AQ15/H$24,3),0) -> 0 | AX15: =AJ15*10000 -> #DIV/0!
A16: Indirect Payroll Costs (Benefits) | B16: =IF(B24<>0,$F$115/$B$49/1000,0) -> 0 | D16: 0 | E16: =IF(E24<>0,$F$115/$B$49/1000,0) -> 0 | F16: 0.01706523 | G16: 0.013928937 | H16: =IF($H$24<>0,$F$115/$B$49/1000,0) -> 0 | J16: 0 | S16: =B16*B$24*1000 -> 0 | T16: =B39*B$47*1000 -> 0 | U16: =E39*E$47*1000 -> 0 | V16: =E16*E$24*1000 -> 0 | W16: =H39*H$47*1000 -> 0 | X16: =H16*H$24*1000 -> 0 | Y16: =SUM(S16:X16) -> 0 | Z16: =-$D$122 -> 0 | AA16: =SUM(Y16:Z16) -> 0 | AB16: IPC01 | AC16: hr | AD16: =ROUND((S16/C$123)+(T16/C$123)+(U16/C$123)+(V16/C$123)+(W16/C$123)+(X16/C$123),0) -> #DIV/0! | AE16: =Y16/AD16 -> #DIV/0! | AF16: =Y16/$AF$24/1000 -> #DIV/0! | AG16: 0.0088563301 | AH16: =IF($AF$21<$AG$21,AF16,IF($AF$20<$AG$20,AF16,IF(AND($AF$20>$AG$20,$AF$12<$AG$12),($AG$20+($AG$12-$AF$12))/$AF$20*AF16,AF16/$AF$20*$AG$20))) -> #DIV/0! | AI16: =AH16*$Y$24*1000 -> #DIV/0! | AJ16: =AI16/AD16 -> #DIV/0! | AK16: =Y16-AI16 -> #DIV/0! | AL16: =ROUND(S16/$C123,0) -> #DIV/0! | AM16: =ROUND(T16/$C123,0) -> #DIV/0! | AN16: =ROUND(U16/$C123,0) -> #DIV/0! | AO16: =ROUND(V16/$C123,0) -> #DIV/0! | AP16: =ROUND(W16/$C123,0) -> #DIV/0! | AQ16: =ROUND(X16/$C123,0) -> #DIV/0! | AR16: =IF($B$24<>0,ROUND(AL16/B$24,3),0) -> 0 | AS16: =ROUND(AM16/B$47,3) -> #DIV/0! | AT16: =IF(E$47<>0,ROUND(AN16/E$47,3),0) -> 0 | AU16: =IF(E$24<>0,ROUND(AO16/E$24,3),0) -> 0 | AV16: =IF(H$47<>0,ROUND(AP16/H$47,3),0) -> 0 | AW16: =IF(H$24<>0,ROUND(AQ16/H$24,3),0) -> 0 | AX16: =AJ16*10000 -> #DIV/0!
A17: Supervision | B17: =IF($B$24<>0,$F$114/$B$49/1000,0) -> 0 | D17: 0 | E17: =IF(E24<>0,$F$114/$B$49/1000,0) -> 0 | F17: 0.0045810516 | G17: 0.0015771316 | H17: =IF($H$24<>0,$F$114/$B$49/1000,0) -> 0 | J17: 0 | S17: =B17*B$24*1000 -> 0 | T17: =B40*B$47*1000 -> 0 | U17: =E40*E$47*1000 -> 0 | V17: =E17*E$24*1000 -> 0 | W17: =H40*H$47*1000 -> 0 | X17: =H17*H$24*1000 -> 0 | Y17: =SUM(S17:X17) -> 0 | Z17: =C176/($C$184+$C$185)*$C$185 -> 0 | AA17: =SUM(Y17:Z17) -> 0 | AB17: SUP01 | AC17: lb | AD17: =ROUND((S17/F$176)+(T17/F$176)+(U17/F$176)+(V17/F$176)+(W17/F$176)+(X17/F$176),0) -> #DIV/0! | AE17: =Y17/AD17 -> #DIV/0! | AF17: =Y17/$AF$24/1000 -> #DIV/0! | AG17: 0.0021273119 | AH17: =IF($AF$21<$AG$21,AF17,IF($AF$20<$AG$20,AF17,IF(AND($AF$20>$AG$20,$AF$12<$AG$12),($AG$20+($AG$12-$AF$12))/$AF$20*AF17,AF17/$AF$20*$AG$20))) -> #DIV/0! | AI17: =AH17*$Y$24*1000 -> #DIV/0! | AJ17: =AI17/AD17 -> #DIV/0! | AK17: =Y17-AI17 -> #DIV/0! | AL17: =S17/$AE17 -> #DIV/0! | AM17: =T17/$AE17 -> #DIV/0! | AN17: =U17/$AE17 -> #DIV/0! | AO17: =V17/$AE17 -> #DIV/0! | AP17: =W17/$AE17 -> #DIV/0! | AQ17: =X17/$AE17 -> #DIV/0! | AR17: =IF($B$24<>0,ROUND(AL17/B$24,3),0) -> 0 | AS17: =ROUND(AM17/B$47,3) -> #DIV/0! | AT17: =IF(E$47<>0,ROUND(AN17/E$47,3),0) -> 0 | AU17: =IF(E$24<>0,ROUND(AO17/E$24,3),0) -> 0 | AV17: =IF(H$47<>0,ROUND(AP17/H$47,3),0) -> 0 | AW17: =IF(H$24<>0,ROUND(AQ17/H$24,3),0) -> 0 | AX17: =AJ17*10000 -> #DIV/0!
A18: Depreciation | B18: =IF($B$24<>0,$B$178/$B$49/1000,0) -> 0 | D18: 0 | E18: =IF(E24<>0,$B$178/$B$49/1000,0) -> 0 | F18: 0.0038559807 | G18: 0.0016578947 | H18: =IF($H$24<>0,$B$178/$B$49/1000,0) -> 0 | J18: 0 | S18: =B18*B$24*1000 -> 0 | T18: =B41*B$47*1000 -> 0 | U18: =E41*E$47*1000 -> 0 | V18: =E18*E$24*1000 -> 0 | W18: =H41*H$47*1000 -> 0 | X18: =H18*H$24*1000 -> 0 | Y18: =SUM(S18:X18) -> 0 | Z18: =C178/($C$184+$C$185)*$C$185 -> 0 | AA18: =SUM(Y18:Z18) -> 0 | AB18: DEP01 | AC18: lb | AD18: =ROUND((S18/F$178)+(T18/F$178)+(U18/F$178)+(V18/F$178)+(W18/F$178)+(X18/F$178),0) -> #DIV/0! | AE18: =Y18/AD18 -> #DIV/0! | AF18: =Y18/$AF$24/1000 -> #DIV/0! | AG18: 0.032747211 | AH18: =IF($AF$21<$AG$21,AF18,IF($AF$20<$AG$20,AF18,IF(AND($AF$20>$AG$20,$AF$12<$AG$12),($AG$20+($AG$12-$AF$12))/$AF$20*AF18,AF18/$AF$20*$AG$20))) -> #DIV/0! | AI18: =AH18*$Y$24*1000 -> #DIV/0! | AJ18: =AI18/AD18 -> #DIV/0! | AK18: =Y18-AI18 -> #DIV/0! | AL18: =S18/$AE18 -> #DIV/0! | AM18: =T18/$AE18 -> #DIV/0! | AN18: =U18/$AE18 -> #DIV/0! | AO18: =V18/$AE18 -> #DIV/0! | AP18: =W18/$AE18 -> #DIV/0! | AQ18: =X18/$AE18 -> #DIV/0! | AR18: =IF($B$24<>0,ROUND(AL18/B$24,3),0) -> 0 | AS18: =ROUND(AM18/B$47,3) -> #DIV/0! | AT18: =IF(E$47<>0,ROUND(AN18/E$47,3),0) -> 0 | AU18: =IF(E$24<>0,ROUND(AO18/E$24,3),0) -> 0 | AV18: =IF(H$47<>0,ROUND(AP18/H$47,3),0) -> 0 | AW18: =IF(H$24<>0,ROUND(AQ18/H$24,3),0) -> 0 | AX18: =AJ18*10000 -> #DIV/0!
A19: Insurance & Taxes | B19: =IF($B$24<>0,$B$177/$B$49/1000,0) -> 0 | D19: 0 | E19: =IF(E24<>0,$B$177/E26/1000,0) -> 0 | F19: 0.010801566 | G19: 0.0058026316 | H19: =IF($H$24<>0,$B$177/$B$49/1000,0) -> 0 | J19: 0 | S19: =B19*B$24*1000 -> 0 | T19: =B42*B$47*1000 -> 0 | U19: =E42*E$47*1000 -> 0 | V19: =E19*E$24*1000 -> 0 | W19: =H42*H$47*1000 -> 0 | X19: =H19*H$24*1000 -> 0 | Y19: =SUM(S19:X19) -> 0 | Z19: =C177/($C$184+$C$185)*$C$185 -> 0 | AA19: =SUM(Y19:Z19) -> 0 | AB19: INS01 | AC19: lb | AD19: =ROUND((S19/F$177)+(T19/F$177)+(U19/F$177)+(V19/F$177)+(W19/F$177)+(X19/F$177),0) -> #DIV/0! | AE19: =Y19/AD19 -> #DIV/0! | AF19: =Y19/$AF$24/1000 -> #DIV/0! | AG19: 0.0073609622 | AH19: =IF($AF$21<$AG$21,AF19,IF($AF$20<$AG$20,AF19,IF(AND($AF$20>$AG$20,$AF$12<$AG$12),($AG$20+($AG$12-$AF$12))/$AF$20*AF19,AF19/$AF$20*$AG$20))) -> #DIV/0! | AI19: =AH19*$Y$24*1000 -> #DIV/0! | AJ19: =AI19/AD19 -> #DIV/0! | AK19: =Y19-AI19 -> #DIV/0! | AL19: =S19/$AE19 -> #DIV/0! | AM19: =T19/$AE19 -> #DIV/0! | AN19: =U19/$AE19 -> #DIV/0! | AO19: =V19/$AE19 -> #DIV/0! | AP19: =W19/$AE19 -> #DIV/0! | AQ19: =X19/$AE19 -> #DIV/0! | AR19: =IF($B$24<>0,ROUND(AL19/B$24,3),0) -> 0 | AS19: =ROUND(AM19/B$47,3) -> #DIV/0! | AT19: =IF(E$47<>0,ROUND(AN19/E$47,3),0) -> 0 | AU19: =IF(E$24<>0,ROUND(AO19/E$24,3),0) -> 0 | AV19: =IF(H$47<>0,ROUND(AP19/H$47,3),0) -> 0 | AW19: =IF(H$24<>0,ROUND(AQ19/H$24,3),0) -> 0 | AX19: =AJ19*10000 -> #DIV/0!
A20: Total Fixed Costs | B20: =SUM(B14:B19) -> 0 | C20: =SUM(C14:C19) -> 0 | D20: =SUM(D14:D19) -> 0 | E20: =SUM(E14:E19) -> 0 | F20: =SUM(F14:F19) -> 0.11152537 | G20: =SUM(G14:G19) -> 0.058371315 | H20: =SUM(H14:H19) -> 0 | I20: =SUM(I14:I19) -> 0 | J20: =SUM(J14:J19) -> 0 | S20: =SUM(S14:S19) -> 0 | T20: =SUM(T14:T19) -> 0 | U20: =SUM(U14:U19) -> 0 | V20: =SUM(V14:V19) -> 0 | W20: =SUM(W14:W19) -> 0 | X20: =SUM(X14:X19) -> 0 | Y20: =SUM(Y14:Y19) -> 0 | Z20: =SUM(Z14:Z19) -> 0 | AA20: =SUM(AA14:AA19) -> 0 | AF20: =SUM(AF14:AF19) -> #DIV/0! | AG20: =SUM(AG14:AG19) -> 0.07023059 | AH20: =SUM(AH14:AH19) -> #DIV/0! | AI20: =SUM(AI14:AI19) -> #DIV/0! | AK20: =SUM(AK14:AK19) -> #DIV/0!
A21: Excess Costs | C21: -0.0273 | F21: -0.050457361 | S21: =S12+S20 -> 0 | T21: =T12+T20 -> 0 | U21: =U12+U20 -> 0 | V21: =V12+V20 -> #DIV/0! | W21: =W12+W20 -> 0 | X21: =X12+X20 -> 0 | Y21: =Y12+Y20 -> #DIV/0! | Z21: =Z12+Z20 -> 0 | AA21: =AA12+AA20 -> #DIV/0! | AB21: CCtr Total | AF21: =AF12+AF20 -> #DIV/0! | AG21: =AG12+AG20 -> 0.15165505 | AH21: =AH12+AH20 -> #DIV/0! | AI21: =AI12+AI20 -> #DIV/0! | AK21: =AK12+AK20 -> #DIV/0!
A22: TOTAL COSTS PER POUND | B22: =B12+B20 -> 0 | C22: =+C20+C21+C12 -> -0.0273 | D22: =D12+D20 -> 0 | E22: =E12+E20 -> 0 | F22: =F12+F20+F21 -> 0.36638748 | G22: =G12+G20 -> 0.17357627 | H22: =H12+H20 -> 0 | I22: =I12+I20 -> 0 | J22: =J12+J20 -> 0 | S22: =IF(B24<>0,ROUND(S21/(B24*1000),5),0) -> 0 | T22: =IF(B47<>0,ROUND(T21/(B47*1000),5),0) -> 0 | U22: =IF(E47<>0,ROUND(U21/(E47*1000),5),0) -> 0 | V22: =IF(E24<>0,ROUND(V21/(E24*1000),5),0) -> 0 | W22: =IF(H47<>0,ROUND(W21/(H47*1000),5),0) -> 0 | X22: =IF(H24<>0,ROUND(X21/(H24*1000),5),0) -> 0 | Y22: =Y21/Y24/1000 -> #DIV/0! | Z22: 0 | AA22: =ROUND(AA21/(B49*1000),5) -> #DIV/0! | AB22: Excl Matl | AI22: =AI21/AI24/1000 -> #DIV/0! | AK22: =AK21/AK24/1000 -> #DIV/0!
S23: =ROUND(S22+B6,5) -> 0 | T23: =ROUND(T22+B29,5) -> 0 | U23: =ROUND(U22+E29,5) -> 0 | V23: =ROUND(V22+E6,5) -> 0 | W23: =ROUND(W22+H29,5) -> 0 | X23: =ROUND(X22+H6,5) -> 0 | Y23: =Y22+(($B$6*$B$24*1000+$B$29*$B$47*1000+$E$29*$E$47*1000+$H$6*$H$24*1000+$H$29*$H$47*1000+$E$6*$E$24*1000)/($B$49*1000)) -> #DIV/0! | Z23: 0 | AA23: =AA22+(($B$6*$B$24*1000+$B$29*$B$47*1000+$E$6*$E$24*1000+$E$29*$E$47*1000+$H$6*$H$24*1000+$H$29*$H$47*1000)/($B$49*1000)) -> #DIV/0! | AB23: Incl Matl
A24: PRODUCTION ( in 000 lbs ) | B24: =B54 -> 0 | C24: 6211 | D24: 0 | E24: =B57 -> 0 | F24: 3204 | G24: 51000 | H24: =B58 -> 0 | I24: 4207 | J24: 0 | S24: =B24 -> 0 | T24: =B47 -> 0 | U24: =E47 -> 0 | V24: =E24 -> 0 | W24: =H47 -> 0 | X24: =H24 -> 0 | Y24: =SUM(S24:X24) -> 0 | Z24: 0 | AA24: =SUM(Y24:Z24) -> 0 | AF24: =Y24 -> 0 | AI24: =Y24 -> 0 | AK24: =Y24 -> 0
B26: CP | E26: HSP | H26: Nanomite C | AS26: 0.936
B27: =B4 -> 25 Standard | C27: 23 Actual | D27: =+D4 -> 22 Standard | E27: =E4 -> 25 Standard | F27: =+C27 -> 23 Actual | G27: =+D27 -> 22 Standard | H27: =H4 -> 25 Standard | I27: 23 Actual | J27: =+J4 -> 22 Standard | AS27: 0.264
C28: (Jan-Aug) | F28: (Jan-Aug) | I28: (Jan-Aug) | AS28: 286
A29: Materials | B29: =IF($B$47<>0,$D$88,0) -> 0 | C29: 0.1396 | D29: 0.06037434 | E29: =IF(E47<>0,$D$88,0) -> 0 | F29: 0.0865 | G29: 0 | H29: =IF(H47<>0,$L$80,0) -> 0 | I29: 0.0792 | J29: 0.02 | AS29: 8000
A30: Electricity | B30: =IF(B47<>0,$D$151,0) -> 0 | C30: 0.0273 | D30: 0.018883379 | E30: =IF(E47<>0,$G$151,0) -> 0 | F30: 0.0294 | G30: 0 | H30: =IF(H47<>0,$J$151,0) -> 0 | I30: 0.0124 | J30: 0.0027366213 | AS30: 1.2
A31: Gas | B31: =IF(B47<>0,$D$152,0) -> 0 | C31: 0.0379 | D31: 0.04184 | E31: =IF(E47<>0,$G$152,0) -> 0 | F31: 0.0465 | G31: 0 | H31: =IF(H47<>0,$J$152,0) -> 0 | I31: 0 | J31: 0
A32: R&M Supplies and Service | B32: =IF(B47<>0,$H$159,0) -> 0 | C32: 0.0358 | D32: 0.022368421 | E32: =IF(E47<>0,$H$159,0) -> 0 | F32: 0.0304 | G32: 0 | H32: =IF(H47<>0,$H$159,0) -> 0 | I32: 0.0164 | J32: 0.022368421
A33: Manufacturing Supplies | B33: =IF(B47<>0,$H$163,0) -> 0 | C33: 0.0006 | D33: 0.00065789474 | E33: =IF(E47<>0,$H$163,0) -> 0 | F33: 0.002 | G33: 0 | H33: =IF(H47<>0,$H$163,0) -> 0 | I33: 0.0014 | J33: 0.00065789474
A34: Other variable | B34: =IF($B$47<>0,$H$166,0) -> 0 | C34: 0.0101 | D34: 0.0046052632 | E34: =IF(E47<>0,$H$166,0) -> 0 | F34: 0.0118 | G34: 0 | H34: =IF(H47<>0,$H$166,0) -> 0 | I34: 0.0108 | J34: 0.0046052632
A35: Total Variable Costs | B35: =SUM(B29:B34) -> 0 | C35: =SUM(C29:C34) -> 0.2513 | D35: =SUM(D29:D34) -> 0.1487293 | E35: =SUM(E29:E34) -> 0 | F35: =SUM(F29:F34) -> 0.2066 | G35: =SUM(G29:G34) -> 0 | H35: =SUM(H29:H34) -> 0 | I35: =SUM(I29:I34) -> 0.1202 | J35: =SUM(J29:J34) -> 0.0503682
A37: Production Labor | B37: =IF(B47<>0,$F$112/$B$49/1000,0) -> 0 | C37: 0.0445 | D37: 0.02638428 | E37: =IF(E47<>0,$F$112/$B$49/1000,0) -> 0 | F37: 0.0483 | G37: 0 | H37: =IF(H47<>0,$F$112/$B$49/1000,0) -> 0 | I37: 0.0451 | J37: 0.02638428
A38: Repairs & Maintenance Labor | B38: =IF(B47<>0,$F$113/$B$49/1000,0) -> 0 | C38: 0.015 | D38: 0.00902044 | E38: =IF(E47<>0,$F$113/$B$49/1000,0) -> 0 | F38: 0.0144 | G38: 0 | H38: =IF(H47<>0,$F$113/$B$49/1000,0) -> 0 | I38: 0.0156 | J38: 0.00902044
A39: Indirect Payroll Costs (Benefits) | B39: =IF(B47<>0,$F$115/$B$49/1000,0) -> 0 | C39: 0.0194 | D39: 0.013928937 | E39: =IF(E47<>0,$F$115/$B$49/1000,0) -> 0 | F39: 0.0196 | G39: 0 | H39: =IF(H47<>0,$F$115/$B$49/1000,0) -> 0 | I39: 0.0285 | J39: 0.013928937
A40: Supervision | B40: =IF($B$47<>0,$F$114/$B$49/1000,0) -> 0 | C40: 0.0018 | D40: 0.0015771316 | E40: =IF(E47<>0,$F$114/$B$49/1000,0) -> 0 | F40: 0.0014 | G40: 0 | H40: =IF(H47<>0,$F$114/$B$49/1000,0) -> 0 | I40: 0.0022 | J40: 0.0015771316
A41: Depreciation | B41: =IF(B47<>0,$B$178/$B$49/1000,0) -> 0 | C41: 0.0043 | D41: 0.0016578947 | E41: =IF(E47<>0,$B$178/$B$49/1000,0) -> 0 | F41: 0.0042 | G41: 0 | H41: =IF(H47<>0,$B$178/$B$49/1000,0) -> 0 | I41: 0.0067 | J41: 0.0016578947
A42: Insurance & Taxes | B42: =IF(B47<>0,$B$177/B49/1000,0) -> 0 | C42: 0.0093 | D42: 0.0058026316 | E42: =IF(E47<>0,$B$177/B49/1000,0) -> 0 | F42: 0.0098 | G42: 0 | H42: =IF(H47<>0,$B$177/$B$49/1000,0) -> 0 | I42: 0.014 | J42: 0.0058026316
A43: Total Fixed Costs | B43: =SUM(B37:B42) -> 0 | C43: =SUM(C37:C42) -> 0.0943 | D43: =SUM(D37:D42) -> 0.058371315 | E43: =SUM(E37:E42) -> 0 | F43: =SUM(F37:F42) -> 0.0977 | G43: =SUM(G37:G42) -> 0 | H43: =SUM(H37:H42) -> 0 | I43: =SUM(I37:I42) -> 0.1121 | J43: =SUM(J37:J42) -> 0.058371315
...

Sheet Dec23
A1: McINTYRE STANDARD 2025 | S1: COST CENTER 10001003 | AE1: Gross | AF1: Std | AG1: Abs Limit | AH1: Absorb | AI1: 10001003 | AJ1: Absorbed | AK1: 10001003 | AX1: Abs Cost
S2: CG | T2: CP | U2: HSP | V2: CL | W2: Nanomite C | X2: NRT | Y2: To Production | Z2: Idle Plant | AA2: TOTAL | AB2: Activity / Material | AC2: UOM | AD2: Ttl Unit Qty | AE2: Unit Cost | AF2: Cost/lb | AG2: Cost/lb | AH2: Cost/lb | AI2: Absorption | AJ2: Unit Cost | AK2: Underabs | AL2: EP Unit Qty | AM2: CP Unit Qty | AN2: HSP Unit Qty | AO2: CL Unit Qty | AP2: Nano C Qty | AQ2: NRT Unit Qty | AR2: EP Units/1000lb | AS2: CP Units/1000lb | AT2: HSP Units/1000lb | AU2: CL Units/1000lb | AV2: Nano C Units/1000lb | AW2: NRT Units/1000lb | AX2: per 10000
B3: HT | E3: Bauxite Pellets | H3: ID
B4: 25 Standard | C4: 23 Actual | D4: 22 Standard | E4: =B4 -> 25 Standard | F4: 23 Actual | G4: =+D4 -> 22 Standard | H4: =B4 -> 25 Standard | I4: 23 Actual | J4: =+D4 -> 22 Standard
F5: (Jan-Aug)
A6: Materials | B6: =IF($B$24<>0,$D$80,0) -> 0 | D6: 0 | E6: =IF(E24<>0,$L$88,0) -> 0 | F6: 0.071053254 | G6: 0.02685 | H6: =IF($H$24<>0,$D$88,0) -> 0 | J6: 0
A7: Electricity | B7: =IF($B$24<>0,$D$151,0) -> 0 | D7: 0 | E7: =IF(E24<>0,$D$151,0) -> 0 | F7: 0.03392679 | G7: 0.018883379 | H7: =IF(H24<>0,$D$151,0) -> 0 | J7: 0 | S7: =$C145*$B$24*1000*$B145 -> 0 | T7: =$C151*$B$47*1000*$B151 -> 0 | U7: =$F151*$E$47*1000*$E151 -> 0 | V7: =$F145*$E$24*1000*$E145 -> #DIV/0! | W7: =$I151*$H$47*1000*$H151 -> 0 | X7: =$I145*$H$24*1000*$H145 -> 0 | Y7: =SUM(S7:X7) -> #DIV/0! | Z7: 0 | AA7: =SUM(Y7:Z7) -> #DIV/0! | AB7: ELE01 | AC7: kwh | AD7: =ROUND((B145*B$24*1000)+(B151*B$47*1000)+(E145*E$24*1000)+(E151*E$47*1000)+(H145*H$24*1000)+(H151*H$47*1000),0) -> #DIV/0! | AE7: =Y7/AD7 -> #DIV/0! | AF7: =Y7/$AF$24/1000 -> #DIV/0! | AG7: 0.014890786 | AH7: =IF($AF$21<$AG$21,AF7,IF($AF$12<$AG$12,AF7,IF(AND($AF$12>$AG$12,$AF$20<$AG$20),($AG$12+($AG$20-$AF$20))/$AF$12*AF7,AF7/$AF$12*$AG$12))) -> #DIV/0! | AI7: =AH7*$Y$24*1000 -> #DIV/0! | AJ7: =AI7/AD7 -> #DIV/0! | AK7: =Y7-AI7 -> #DIV/0! | AL7: =ROUND($B145*$B$24*1000,0) -> 0 | AM7: =ROUND($B151*$B$47*1000,0) -> 0 | AN7: =ROUND($E151*$E$47*1000,0) -> 0 | AO7: =ROUND($E145*$E$24*1000,0) -> #DIV/0! | AP7: =ROUND($H151*$H$47*1000,0) -> 0 | AQ7: =ROUND($H145*$H$24*1000,0) -> 0 | AR7: =IF($B$24<>0,ROUND(AL7/B$24,3),0) -> 0 | AS7: =ROUND(AM7/B$47,3) -> #DIV/0! | AT7: =IF(E$47<>0,ROUND(AN7/E$47,3),0) -> 0 | AU7: =IF(F$24<>0,ROUND(AO7/F$24,3),0) -> #DIV/0! | AV7: =IF(H$47<>0,ROUND(AP7/H$47,3),0) -> 0 | AW7: =IF(H$24<>0,ROUND(AQ7/H$24,3),0) -> 0 | AX7: =AJ7*10000 -> #DIV/0!
A8: Gas | B8: =IF($B$24<>0,$D$152,0) -> 0 | D8: 0 | E8: =IF(E24<>0,$D$152,0) -> 0 | F8: 0.14600441 | G8: 0.04184 | H8: =IF(H24<>0,$D$152,0) -> 0 | J8: 0 | S8: =$C146*$B$24*1000*$B146 -> 0 | T8: =$C152*$B$47*1000*$B152 -> 0 | U8: =$F152*$E$47*1000*$E152 -> 0 | V8: =$F146*$E$24*1000*$E146 -> 0 | W8: =$I152*$H$47*1000*$H152 -> 0 | X8: =$I146*$H$24*1000*$H146 -> 0 | Y8: =SUM(S8:X8) -> 0 | Z8: 0 | AA8: =SUM(Y8:Z8) -> 0 | AB8: GAS01 | AC8: mbtu | AD8: =ROUND((B146*B$24*1000*1000)+(B152*B$47*1000*1000)+(E146*E$24*1000*1000)+(E152*E$47*1000*1000)+(H146*H$24*1000*1000)+(H152*H$47*1000*1000),0) -> 0 | AE8: =Y8/AD8 -> #DIV/0! | AF8: =Y8/$AF$24/1000 -> #DIV/0! | AG8: 0.042004912 | AH8: =IF($AF$21<$AG$21,AF8,IF($AF$12<$AG$12,AF8,IF(AND($AF$12>$AG$12,$AF$20<$AG$20),($AG$12+($AG$20-$AF$20))/$AF$12*AF8,AF8/$AF$12*$AG$12))) -> #DIV/0! | AI8: =AH8*$Y$24*1000 -> #DIV/0! | AJ8: =AI8/AD8 -> #DIV/0! | AK8: =Y8-AI8 -> #DIV/0! | AL8: =ROUND($B146*$B$24*1000*1000,0) -> 0 | AM8: =ROUND($B152*$B$47*1000*1000,0) -> 0 | AN8: =ROUND($E152*$E$47*1000*1000,0) -> 0 | AO8: =ROUND($E146*$E$24*1000*1000,0) -> 0 | AP8: =ROUND($H152*$H$47*1000*1000,0) -> 0 | AQ8: =ROUND($H146*$H$24*1000*1000,0) -> 0 | AR8: =IF($B$24<>0,ROUND(AL8/B$24,3),0) -> 0 | AS8: =ROUND(AM8/B$47,3) -> #DIV/0! | AT8: =IF(E$47<>0,ROUND(AN8/E$47,3),0) -> 0 | AU8: =IF(E$24<>0,ROUND(AO8/E$24,3),0) -> 0 | AV8: =IF(H$47<>0,ROUND(AP8/H$47,3),0) -> 0 | AW8: =IF(H$24<>0,ROUND(AQ8/H$24,3),0) -> 0 | AX8: =AJ8*10000 -> #DIV/0!
A9: R&M Supplies and Service | B9: =IF($B$24<>0,$H$159,0) -> 0 | D9: 0 | E9: =IF(E24<>0,$H$159,0) -> 0 | F9: 0.043366417 | G9: 0.022368421 | H9: =IF(H24<>0,$H$159,0) -> 0 | J9: 0 | S9: =B9*B$24*1000 -> 0 | T9: =B32*B$47*1000 -> 0 | U9: =E32*E$47*1000 -> 0 | V9: =E9*E$24*1000 -> 0 | W9: =H32*H$47*1000 -> 0 | X9: =H9*H$24*1000 -> 0 | Y9: =SUM(S9:X9) -> 0 | Z9: 0 | AA9: =SUM(Y9:Z9) -> 0 | AB9: RMS01 | AC9: lb | AD9: =ROUND((S9/H$159)+(T9/H$159)+(U9/H$159)+(V9/H$159)+(W9/H$159)+(X9/H$159),0) -> #DIV/0! | AE9: =Y9/AD9 -> #DIV/0! | AF9: =Y9/$AF$24/1000 -> #DIV/0! | AG9: 0.019544347 | AH9: =IF($AF$21<$AG$21,AF9,IF($AF$12<$AG$12,AF9,IF(AND($AF$12>$AG$12,$AF$20<$AG$20),($AG$12+($AG$20-$AF$20))/$AF$12*AF9,AF9/$AF$12*$AG$12))) -> #DIV/0! | AI9: =AH9*$Y$24*1000 -> #DIV/0! | AJ9: =AI9/AD9 -> #DIV/0! | AK9: =Y9-AI9 -> #DIV/0! | AL9: =S9/$AE9 -> #DIV/0! | AM9: =T9/$AE9 -> #DIV/0! | AN9: =U9/$AE9 -> #DIV/0! | AO9: =V9/$AE9 -> #DIV/0! | AP9: =W9/$AE9 -> #DIV/0! | AQ9: =X9/$AE9 -> #DIV/0! | AR9: =IF($B$24<>0,ROUND(AL9/B$24,3),0) -> 0 | AS9: =ROUND(AM9/B$47,3) -> #DIV/0! | AT9: =IF(E$47<>0,ROUND(AN9/E$47,3),0) -> 0 | AU9: =IF(E$24<>0,ROUND(AO9/E$24,3),0) -> 0 | AV9: =IF(H$47<>0,ROUND(AP9/H$47,3),0) -> 0 | AW9: =IF(H$24<>0,ROUND(AQ9/H$24,3),0) -> 0 | AX9: =AJ9*10000 -> #DIV/0!
A10: Manufacturing Supplies | B10: =IF($B$24<>0,$H$163,0) -> 0 | D10: 0 | E10: =IF(E24<>0,$H$163,0) -> 0 | F10: 0.00073336258 | G10: 0.00065789474 | H10: =IF($H$24<>0,$H$163,0) -> 0 | J10: 0 | S10: =B10*B$24*1000 -> 0 | T10: =B33*B$47*1000 -> 0 | U10: =E33*E$47*1000 -> 0 | V10: =E10*E$24*1000 -> 0 | W10: =H33*H$47*1000 -> 0 | X10: =H10*H$24*1000 -> 0 | Y10: =SUM(S10:X10) -> 0 | Z10: 0 | AA10: =SUM(Y10:Z10) -> 0 | AB10: MFG01 | AC10: lb | AD10: =ROUND((S10/H$163)+(T10/H$163)+(U10/H$163)+(V10/H$163)+(W10/H$163)+(X10/H$163),0) -> #DIV/0! | AE10: =Y10/AD10 -> #DIV/0! | AF10: =Y10/$AF$24/1000 -> #DIV/0! | AG10: 0.0012510769 | AH10: =IF($AF$21<$AG$21,AF10,IF($AF$12<$AG$12,AF10,IF(AND($AF$12>$AG$12,$AF$20<$AG$20),($AG$12+($AG$20-$AF$20))/$AF$12*AF10,AF10/$AF$12*$AG$12))) -> #DIV/0! | AI10: =AH10*$Y$24*1000 -> #DIV/0! | AJ10: =AI10/AD10 -> #DIV/0! | AK10: =Y10-AI10 -> #DIV/0! | AL10: =S10/$AE10 -> #DIV/0! | AM10: =T10/$AE10 -> #DIV/0! | AN10: =U10/$AE10 -> #DIV/0! | AO10: =V10/$AE10 -> #DIV/0! | AP10: =W10/$AE10 -> #DIV/0! | AQ10: =X10/$AE10 -> #DIV/0! | AR10: =IF($B$24<>0,ROUND(AL10/B$24,3),0) -> 0 | AS10: =ROUND(AM10/B$47,3) -> #DIV/0! | AT10: =IF(E$47<>0,ROUND(AN10/E$47,3),0) -> 0 | AU10: =IF(E$24<>0,ROUND(AO10/E$24,3),0) -> 0 | AV10: =IF(H$47<>0,ROUND(AP10/H$47,3),0) -> 0 | AW10: =IF(H$24<>0,ROUND(AQ10/H$24,3),0) -> 0 | AX10: =AJ10*10000 -> #DIV/0!
A11: Other variable | B11: =IF($B$24<>0,$H$166,0) -> 0 | D11: 0 | E11: =IF(E24<>0,$H$166,0) -> 0 | F11: 0.010235236 | G11: 0.0046052632 | H11: =IF($H$24<>0,$H$166,0) -> 0 | J11: 0 | S11: =B11*B$24*1000 -> 0 | T11: =B34*B$47*1000 -> 0 | U11: =E34*E$47*1000 -> 0 | V11: =E11*E$24*1000 -> 0 | W11: =H34*H$47*1000 -> 0 | X11: =H11*H$24*1000 -> 0 | Y11: =SUM(S11:X11) -> 0 | Z11: 0 | AA11: =SUM(Y11:Z11) -> 0 | AB11: VAR01 | AC11: lb | AD11: =ROUND((S11/H$166)+(T11/H$166)+(U11/H$166)+(V11/H$166)+(W11/H$166)+(X11/H$166),0) -> #DIV/0! | AE11: =Y11/AD11 -> #DIV/0! | AF11: =Y11/$AF$24/1000 -> #DIV/0! | AG11: 0.0037333371 | AH11: =IF($AF$21<$AG$21,AF11,IF($AF$12<$AG$12,AF11,IF(AND($AF$12>$AG$12,$AF$20<$AG$20),($AG$12+($AG$20-$AF$20))/$AF$12*AF11,AF11/$AF$12*$AG$12))) -> #DIV/0! | AI11: =AH11*$Y$24*1000 -> #DIV/0! | AJ11: =AI11/AD11 -> #DIV/0! | AK11: =Y11-AI11 -> #DIV/0! | AL11: =S11/$AE11 -> #DIV/0! | AM11: =T11/$AE11 -> #DIV/0! | AN11: =U11/$AE11 -> #DIV/0! | AO11: =V11/$AE11 -> #DIV/0! | AP11: =W11/$AE11 -> #DIV/0! | AQ11: =X11/$AE11 -> #DIV/0! | AR11: =IF($B$24<>0,ROUND(AL11/B$24,3),0) -> 0 | AS11: =ROUND(AM11/B$47,3) -> #DIV/0! | AT11: =IF(E$47<>0,ROUND(AN11/E$47,3),0) -> 0 | AU11: =IF(E$24<>0,ROUND(AO11/E$24,3),0) -> 0 | AV11: =IF(H$47<>0,ROUND(AP11/H$47,3),0) -> 0 | AW11: =IF(H$24<>0,ROUND(AQ11/H$24,3),0) -> 0 | AX11: =AJ11*10000 -> #DIV/0!
A12: Total Variable Costs | B12: =SUM(B6:B11) -> 0 | D12: =SUM(D6:D11) -> 0 | E12: =SUM(E6:E11) -> 0 | F12: =SUM(F6:F11) -> 0.30531947 | G12: =SUM(G6:G11) -> 0.11520496 | H12: =SUM(H6:H11) -> 0 | J12: =SUM(J6:J11) -> 0 | S12: =SUM(S7:S11) -> 0 | T12: =SUM(T7:T11) -> 0 | U12: =SUM(U7:U11) -> 0 | V12: =SUM(V7:V11) -> #DIV/0! | W12: =SUM(W7:W11) -> 0 | X12: =SUM(X7:X11) -> 0 | Y12: =SUM(Y7:Y11) -> #DIV/0! | Z12: =SUM(Z7:Z11) -> 0 | AA12: =SUM(AA7:AA11) -> #DIV/0! | AF12: =SUM(AF7:AF11) -> #DIV/0! | AG12: =SUM(AG7:AG11) -> 0.081424459 | AH12: =SUM(AH7:AH11) -> #DIV/0! | AI12: =SUM(AI7:AI11) -> #DIV/0! | AK12: =SUM(AK7:AK11) -> #DIV/0!
A14: Production Labor | B14: =IF($B$24<>0,$F$112/$B$49/1000,0) -> 0 | D14: 0 | E14: =IF(E24<>0,$F$112/$B$49/1000,0) -> 0 | F14: 0.055685781 | G14: 0.02638428 | H14: =IF($H$24<>0,$F$112/$B$49/1000,0) -> 0 | J14: 0 | S14: =B14*B$24*1000 -> 0 | T14: =B37*B$47*1000 -> 0 | U14: =E37*E$47*1000 -> 0 | V14: =E14*E$24*1000 -> 0 | W14: =H37*H$47*1000 -> 0 | X14: =H14*H$24*1000 -> 0 | Y14: =SUM(S14:X14) -> 0 | Z14: =-$D$115 -> 0 | AA14: =SUM(Y14:Z14) -> 0 | AB14: DLAB01 | AC14: hr | AD14: =ROUND((S14/C$116)+(T14/C$116)+(U14/C$116)+(V14/C$116)+(W14/C$116)+(X14/C$116),0) -> #DIV/0! | AE14: =Y14/AD14 -> #DIV/0! | AF14: =Y14/$AF$24/1000 -> #DIV/0! | AG14: 0.011488554 | AH14: =IF($AF$21<$AG$21,AF14,IF($AF$20<$AG$20,AF14,IF(AND($AF$20>$AG$20,$AF$12<$AG$12),($AG$20+($AG$12-$AF$12))/$AF$20*AF14,AF14/$AF$20*$AG$20))) -> #DIV/0! | AI14: =AH14*$Y$24*1000 -> #DIV/0! | AJ14: =AI14/AD14 -> #DIV/0! | AK14: =Y14-AI14 -> #DIV/0! | AL14: =ROUND(S14/$C116,0) -> #DIV/0! | AM14: =ROUND(T14/$C116,0) -> #DIV/0! | AN14: =ROUND(U14/$C116,0) -> #DIV/0! | AO14: =ROUND(V14/$C116,0) -> #DIV/0! | AP14: =ROUND(W14/$C116,0) -> #DIV/0! | AQ14: =ROUND(X14/$C116,0) -> #DIV/0! | AR14: =IF($B$24<>0,ROUND(AL14/B$24,3),0) -> 0 | AS14: =ROUND(AM14/B$47,3) -> #DIV/0! | AT14: =IF(E$47<>0,ROUND(AN14/E$47,3),0) -> 0 | AU14: =IF(E$24<>0,ROUND(AO14/E$24,3),0) -> 0 | AV14: =IF(H$47<>0,ROUND(AP14/H$47,3),0) -> 0 | AW14: =IF(H$24<>0,ROUND(AQ14/H$24,3),0) -> 0 | AX14: =AJ14*10000 -> #DIV/0!
A15: Repairs & Maintenance Labor | B15: =IF($B$24<>0,$F$113/$B$49/1000,0) -> 0 | D15: 0 | E15: =IF(E24<>0,$F$113/$B$49/1000,0) -> 0 | F15: 0.019535758 | G15: 0.00902044 | H15: =IF($H$24<>0,$F$113/$B$49/1000,0) -> 0 | J15: 0 | S15: =B15*B$24*1000 -> 0 | T15: =B38*B$47*1000 -> 0 | U15: =E38*E$47*1000 -> 0 | V15: =E15*E$24*1000 -> 0 | W15: =H38*H$47*1000 -> 0 | X15: =H15*H$24*1000 -> 0 | Y15: =SUM(S15:X15) -> 0 | Z15: =-$H$115 -> 0 | AA15: =SUM(Y15:Z15) -> 0 | AB15: MLAB01 | AC15: hr | AD15: =ROUND((S15/G$116)+(T15/G$116)+(U15/G$116)+(V15/G$116)+(W15/G$116)+(X15/G$116),0) -> #DIV/0! | AE15: =Y15/AD15 -> #DIV/0! | AF15: =Y15/$AF$24/1000 -> #DIV/0! | AG15: 0.007650221 | AH15: =IF($AF$21<$AG$21,AF15,IF($AF$20<$AG$20,AF15,IF(AND($AF$20>$AG$20,$AF$12<$AG$12),($AG$20+($AG$12-$AF$12))/$AF$20*AF15,AF15/$AF$20*$AG$20))) -> #DIV/0! | AI15: =AH15*$Y$24*1000 -> #DIV/0! | AJ15: =AI15/AD15 -> #DIV/0! | AK15: =Y15-AI15 -> #DIV/0! | AL15: =ROUND(S15/$G$116,0) -> #DIV/0! | AM15: =ROUND(T15/$G$116,0) -> #DIV/0! | AN15: =ROUND(U15/$G$116,0) -> #DIV/0! | AO15: =ROUND(V15/$G$116,0)-1 -> #DIV/0! | AP15: =ROUND(W15/$G$116,0) -> #DIV/0! | AQ15: =ROUND(X15/$G$116,0) -> #DIV/0! | AR15: =IF($B$24<>0,ROUND(AL15/B$24,3),0) -> 0 | AS15: =ROUND(AM15/B$47,3) -> #DIV/0! | AT15: =IF(E$47<>0,ROUND(AN15/E$47,3),0) -> 0 | AU15: =IF(E$24<>0,ROUND(AO15/E$24,3),0) -> 0 | AV15: =IF(H$47<>0,ROUND(AP15/H$47,3),0) -> 0 | AW15: =IF(H$24<>0,ROUND(AQ15/H$24,3),0) -> 0 | AX15: =AJ15*10000 -> #DIV/0!
A16: Indirect Payroll Costs (Benefits) | B16: =IF(B24<>0,$F$115/$B$49/1000,0) -> 0 | D16: 0 | E16: =IF(E24<>0,$F$115/$B$49/1000,0) -> 0 | F16: 0.01706523 | G16: 0.013928937 | H16: =IF($H$24<>0,$F$115/$B$49/1000,0) -> 0 | J16: 0 | S16: =B16*B$24*1000 -> 0 | T16: =B39*B$47*1000 -> 0 | U16: =E39*E$47*1000 -> 0 | V16: =E16*E$24*1000 -> 0 | W16: =H39*H$47*1000 -> 0 | X16: =H16*H$24*1000 -> 0 | Y16: =SUM(S16:X16) -> 0 | Z16: =-$D$122 -> 0 | AA16: =SUM(Y16:Z16) -> 0 | AB16: IPC01 | AC16: hr | AD16: =ROUND((S16/C$123)+(T16/C$123)+(U16/C$123)+(V16/C$123)+(W16/C$123)+(X16/C$123),0) -> #DIV/0! | AE16: =Y16/AD16 -> #DIV/0! | AF16: =Y16/$AF$24/1000 -> #DIV/0! | AG16: 0.0088563301 | AH16: =IF($AF$21<$AG$21,AF16,IF($AF$20<$AG$20,AF16,IF(AND($AF$20>$AG$20,$AF$12<$AG$12),($AG$20+($AG$12-$AF$12))/$AF$20*AF16,AF16/$AF$20*$AG$20))) -> #DIV/0! | AI16: =AH16*$Y$24*1000 -> #DIV/0! | AJ16: =AI16/AD16 -> #DIV/0! | AK16: =Y16-AI16 -> #DIV/0! | AL16: =ROUND(S16/$C123,0) -> #DIV/0! | AM16: =ROUND(T16/$C123,0) -> #DIV/0! | AN16: =ROUND(U16/$C123,0) -> #DIV/0! | AO16: =ROUND(V16/$C123,0) -> #DIV/0! | AP16: =ROUND(W16/$C123,0) -> #DIV/0! | AQ16: =ROUND(X16/$C123,0) -> #DIV/0! | AR16: =IF($B$24<>0,ROUND(AL16/B$24,3),0) -> 0 | AS16: =ROUND(AM16/B$47,3) -> #DIV/0! | AT16: =IF(E$47<>0,ROUND(AN16/E$47,3),0) -> 0 | AU16: =IF(E$24<>0,ROUND(AO16/E$24,3),0) -> 0 | AV16: =IF(H$47<>0,ROUND(AP16/H$47,3),0) -> 0 | AW16: =IF(H$24<>0,ROUND(AQ16/H$24,3),0) -> 0 | AX16: =AJ16*10000 -> #DIV/0!
A17: Supervision | B17: =IF($B$24<>0,$F$114/$B$49/1000,0) -> 0 | D17: 0 | E17: =IF(E24<>0,$F$114/$B$49/1000,0) -> 0 | F17: 0.0045810516 | G17: 0.0015771316 | H17: =IF($H$24<>0,$F$114/$B$49/1000,0) -> 0 | J17: 0 | S17: =B17*B$24*1000 -> 0 | T17: =B40*B$47*1000 -> 0 | U17: =E40*E$47*1000 -> 0 | V17: =E17*E$24*1000 -> 0 | W17: =H40*H$47*1000 -> 0 | X17: =H17*H$24*1000 -> 0 | Y17: =SUM(S17:X17) -> 0 | Z17: =C176/($C$184+$C$185)*$C$185 -> 0 | AA17: =SUM(Y17:Z17) -> 0 | AB17: SUP01 | AC17: lb | AD17: =ROUND((S17/F$176)+(T17/F$176)+(U17/F$176)+(V17/F$176)+(W17/F$176)+(X17/F$176),0) -> #DIV/0! | AE17: =Y17/AD17 -> #DIV/0! | AF17: =Y17/$AF$24/1000 -> #DIV/0! | AG17: 0.0021273119 | AH17: =IF($AF$21<$AG$21,AF17,IF($AF$20<$AG$20,AF17,IF(AND($AF$20>$AG$20,$AF$12<$AG$12),($AG$20+($AG$12-$AF$12))/$AF$20*AF17,AF17/$AF$20*$AG$20))) -> #DIV/0! | AI17: =AH17*$Y$24*1000 -> #DIV/0! | AJ17: =AI17/AD17 -> #DIV/0! | AK17: =Y17-AI17 -> #DIV/0! | AL17: =S17/$AE17 -> #DIV/0! | AM17: =T17/$AE17 -> #DIV/0! | AN17: =U17/$AE17 -> #DIV/0! | AO17: =V17/$AE17 -> #DIV/0! | AP17: =W17/$AE17 -> #DIV/0! | AQ17: =X17/$AE17 -> #DIV/0! | AR17: =IF($B$24<>0,ROUND(AL17/B$24,3),0) -> 0 | AS17: =ROUND(AM17/B$47,3) -> #DIV/0! | AT17: =IF(E$47<>0,ROUND(AN17/E$47,3),0) -> 0 | AU17: =IF(E$24<>0,ROUND(AO17/E$24,3),0) -> 0 | AV17: =IF(H$47<>0,ROUND(AP17/H$47,3),0) -> 0 | AW17: =IF(H$24<>0,ROUND(AQ17/H$24,3),0) -> 0 | AX17: =AJ17*10000 -> #DIV/0!
A18: Depreciation | B18: =IF($B$24<>0,$B$178/$B$49/1000,0) -> 0 | D18: 0 | E18: =IF(E24<>0,$B$178/$B$49/1000,0) -> 0 | F18: 0.0038559807 | G18: 0.0016578947 | H18: =IF($H$24<>0,$B$178/$B$49/1000,0) -> 0 | J18: 0 | S18: =B18*B$24*1000 -> 0 | T18: =B41*B$47*1000 -> 0 | U18: =E41*E$47*1000 -> 0 | V18: =E18*E$24*1000 -> 0 | W18: =H41*H$47*1000 -> 0 | X18: =H18*H$24*1000 -> 0 | Y18: =SUM(S18:X18) -> 0 | Z18: =C178/($C$184+$C$185)*$C$185 -> 0 | AA18: =SUM(Y18:Z18) -> 0 | AB18: DEP01 | AC18: lb | AD18: =ROUND((S18/F$178)+(T18/F$178)+(U18/F$178)+(V18/F$178)+(W18/F$178)+(X18/F$178),0) -> #DIV/0! | AE18: =Y18/AD18 -> #DIV/0! | AF18: =Y18/$AF$24/1000 -> #DIV/0! | AG18: 0.032747211 | AH18: =IF($AF$21<$AG$21,AF18,IF($AF$20<$AG$20,AF18,IF(AND($AF$20>$AG$20,$AF$12<$AG$12),($AG$20+($AG$12-$AF$12))/$AF$20*AF18,AF18/$AF$20*$AG$20))) -> #DIV/0! | AI18: =AH18*$Y$24*1000 -> #DIV/0! | AJ18: =AI18/AD18 -> #DIV/0! | AK18: =Y18-AI18 -> #DIV/0! | AL18: =S18/$AE18 -> #DIV/0! | AM18: =T18/$AE18 -> #DIV/0! | AN18: =U18/$AE18 -> #DIV/0! | AO18: =V18/$AE18 -> #DIV/0! | AP18: =W18/$AE18 -> #DIV/0! | AQ18: =X18/$AE18 -> #DIV/0! | AR18: =IF($B$24<>0,ROUND(AL18/B$24,3),0) -> 0 | AS18: =ROUND(AM18/B$47,3) -> #DIV/0! | AT18: =IF(E$47<>0,ROUND(AN18/E$47,3),0) -> 0 | AU18: =IF(E$24<>0,ROUND(AO18/E$24,3),0) -> 0 | AV18: =IF(H$47<>0,ROUND(AP18/H$47,3),0) -> 0 | AW18: =IF(H$24<>0,ROUND(AQ18/H$24,3),0) -> 0 | AX18: =AJ18*10000 -> #DIV/0!
A19: Insurance & Taxes | B19: =IF($B$24<>0,$B$177/$B$49/1000,0) -> 0 | D19: 0 | E19: =IF(E24<>0,$B$177/E26/1000,0) -> 0 | F19: 0.010801566 | G19: 0.0058026316 | H19: =IF($H$24<>0,$B$177/$B$49/1000,0) -> 0 | J19: 0 | S19: =B19*B$24*1000 -> 0 | T19: =B42*B$47*1000 -> 0 | U19: =E42*E$47*1000 -> 0 | V19: =E19*E$24*1000 -> 0 | W19: =H42*H$47*1000 -> 0 | X19: =H19*H$24*1000 -> 0 | Y19: =SUM(S19:X19) -> 0 | Z19: =C177/($C$184+$C$185)*$C$185 -> 0 | AA19: =SUM(Y19:Z19) -> 0 | AB19: INS01 | AC19: lb | AD19: =ROUND((S19/F$177)+(T19/F$177)+(U19/F$177)+(V19/F$177)+(W19/F$177)+(X19/F$177),0) -> #DIV/0! | AE19: =Y19/AD19 -> #DIV/0! | AF19: =Y19/$AF$24/1000 -> #DIV/0! | AG19: 0.0073609622 | AH19: =IF($AF$21<$AG$21,AF19,IF($AF$20<$AG$20,AF19,IF(AND($AF$20>$AG$20,$AF$12<$AG$12),($AG$20+($AG$12-$AF$12))/$AF$20*AF19,AF19/$AF$20*$AG$20))) -> #DIV/0! | AI19: =AH19*$Y$24*1000 -> #DIV/0! | AJ19: =AI19/AD19 -> #DIV/0! | AK19: =Y19-AI19 -> #DIV/0! | AL19: =S19/$AE19 -> #DIV/0! | AM19: =T19/$AE19 -> #DIV/0! | AN19: =U19/$AE19 -> #DIV/0! | AO19: =V19/$AE19 -> #DIV/0! | AP19: =W19/$AE19 -> #DIV/0! | AQ19: =X19/$AE19 -> #DIV/0! | AR19: =IF($B$24<>0,ROUND(AL19/B$24,3),0) -> 0 | AS19: =ROUND(AM19/B$47,3) -> #DIV/0! | AT19: =IF(E$47<>0,ROUND(AN19/E$47,3),0) -> 0 | AU19: =IF(E$24<>0,ROUND(AO19/E$24,3),0) -> 0 | AV19: =IF(H$47<>0,ROUND(AP19/H$47,3),0) -> 0 | AW19: =IF(H$24<>0,ROUND(AQ19/H$24,3),0) -> 0 | AX19: =AJ19*10000 -> #DIV/0!
A20: Total Fixed Costs | B20: =SUM(B14:B19) -> 0 | C20: =SUM(C14:C19) -> 0 | D20: =SUM(D14:D19) -> 0 | E20: =SUM(E14:E19) -> 0 | F20: =SUM(F14:F19) -> 0.11152537 | G20: =SUM(G14:G19) -> 0.058371315 | H20: =SUM(H14:H19) -> 0 | I20: =SUM(I14:I19) -> 0 | J20: =SUM(J14:J19) -> 0 | S20: =SUM(S14:S19) -> 0 | T20: =SUM(T14:T19) -> 0 | U20: =SUM(U14:U19) -> 0 | V20: =SUM(V14:V19) -> 0 | W20: =SUM(W14:W19) -> 0 | X20: =SUM(X14:X19) -> 0 | Y20: =SUM(Y14:Y19) -> 0 | Z20: =SUM(Z14:Z19) -> 0 | AA20: =SUM(AA14:AA19) -> 0 | AF20: =SUM(AF14:AF19) -> #DIV/0! | AG20: =SUM(AG14:AG19) -> 0.07023059 | AH20: =SUM(AH14:AH19) -> #DIV/0! | AI20: =SUM(AI14:AI19) -> #DIV/0! | AK20: =SUM(AK14:AK19) -> #DIV/0!
A21: Excess Costs | C21: -0.0273 | F21: -0.050457361 | S21: =S12+S20 -> 0 | T21: =T12+T20 -> 0 | U21: =U12+U20 -> 0 | V21: =V12+V20 -> #DIV/0! | W21: =W12+W20 -> 0 | X21: =X12+X20 -> 0 | Y21: =Y12+Y20 -> #DIV/0! | Z21: =Z12+Z20 -> 0 | AA21: =AA12+AA20 -> #DIV/0! | AB21: CCtr Total | AF21: =AF12+AF20 -> #DIV/0! | AG21: =AG12+AG20 -> 0.15165505 | AH21: =AH12+AH20 -> #DIV/0! | AI21: =AI12+AI20 -> #DIV/0! | AK21: =AK12+AK20 -> #DIV/0!
A22: TOTAL COSTS PER POUND | B22: =B12+B20 -> 0 | C22: =+C20+C21+C12 -> -0.0273 | D22: =D12+D20 -> 0 | E22: =E12+E20 -> 0 | F22: =F12+F20+F21 -> 0.36638748 | G22: =G12+G20 -> 0.17357627 | H22: =H12+H20 -> 0 | I22: =I12+I20 -> 0 | J22: =J12+J20 -> 0 | S22: =IF(B24<>0,ROUND(S21/(B24*1000),5),0) -> 0 | T22: =IF(B47<>0,ROUND(T21/(B47*1000),5),0) -> 0 | U22: =IF(E47<>0,ROUND(U21/(E47*1000),5),0) -> 0 | V22: =IF(E24<>0,ROUND(V21/(E24*1000),5),0) -> 0 | W22: =IF(H47<>0,ROUND(W21/(H47*1000),5),0) -> 0 | X22: =IF(H24<>0,ROUND(X21/(H24*1000),5),0) -> 0 | Y22: =Y21/Y24/1000 -> #DIV/0! | Z22: 0 | AA22: =ROUND(AA21/(B49*1000),5) -> #DIV/0! | AB22: Excl Matl | AI22: =AI21/AI24/1000 -> #DIV/0! | AK22: =AK21/AK24/1000 -> #DIV/0!
S23: =ROUND(S22+B6,5) -> 0 | T23: =ROUND(T22+B29,5) -> 0 | U23: =ROUND(U22+E29,5) -> 0 | V23: =ROUND(V22+E6,5) -> 0 | W23: =ROUND(W22+H29,5) -> 0 | X23: =ROUND(X22+H6,5) -> 0 | Y23: =Y22+(($B$6*$B$24*1000+$B$29*$B$47*1000+$E$29*$E$47*1000+$H$6*$H$24*1000+$H$29*$H$47*1000+$E$6*$E$24*1000)/($B$49*1000)) -> #DIV/0! | Z23: 0 | AA23: =AA22+(($B$6*$B$24*1000+$B$29*$B$47*1000+$E$6*$E$24*1000+$E$29*$E$47*1000+$H$6*$H$24*1000+$H$29*$H$47*1000)/($B$49*1000)) -> #DIV/0! | AB23: Incl Matl
A24: PRODUCTION ( in 000 lbs ) | B24: =B54 -> 0 | C24: 6211 | D24: 0 | E24: =B57 -> 0 | F24: 3204 | G24: 51000 | H24: =B58 -> 0 | I24: 4207 | J24: 0 | S24: =B24 -> 0 | T24: =B47 -> 0 | U24: =E47 -> 0 | V24: =E24 -> 0 | W24: =H47 -> 0 | X24: =H24 -> 0 | Y24: =SUM(S24:X24) -> 0 | Z24: 0 | AA24: =SUM(Y24:Z24) -> 0 | AF24: =Y24 -> 0 | AI24: =Y24 -> 0 | AK24: =Y24 -> 0
B26: CP | E26: HSP | H26: Nanomite C | AS26: 0.936
B27: =B4 -> 25 Standard | C27: 23 Actual | D27: =+D4 -> 22 Standard | E27: =E4 -> 25 Standard | F27: =+C27 -> 23 Actual | G27: =+D27 -> 22 Standard | H27: =H4 -> 25 Standard | I27: 23 Actual | J27: =+J4 -> 22 Standard | AS27: 0.264
C28: (Jan-Aug) | F28: (Jan-Aug) | I28: (Jan-Aug) | AS28: 286
A29: Materials | B29: =IF($B$47<>0,$D$88,0) -> 0 | C29: 0.1396 | D29: 0.06037434 | E29: =IF(E47<>0,$D$88,0) -> 0 | F29: 0.0865 | G29: 0 | H29: =IF(H47<>0,$L$80,0) -> 0 | I29: 0.0792 | J29: 0.02 | AS29: 8000
A30: Electricity | B30: =IF(B47<>0,$D$151,0) -> 0 | C30: 0.0273 | D30: 0.018883379 | E30: =IF(E47<>0,$G$151,0) -> 0 | F30: 0.0294 | G30: 0 | H30: =IF(H47<>0,$J$151,0) -> 0 | I30: 0.0124 | J30: 0.0027366213 | AS30: 1.2
A31: Gas | B31: =IF(B47<>0,$D$152,0) -> 0 | C31: 0.0379 | D31: 0.04184 | E31: =IF(E47<>0,$G$152,0) -> 0 | F31: 0.0465 | G31: 0 | H31: =IF(H47<>0,$J$152,0) -> 0 | I31: 0 | J31: 0
A32: R&M Supplies and Service | B32: =IF(B47<>0,$H$159,0) -> 0 | C32: 0.0358 | D32: 0.022368421 | E32: =IF(E47<>0,$H$159,0) -> 0 | F32: 0.0304 | G32: 0 | H32: =IF(H47<>0,$H$159,0) -> 0 | I32: 0.0164 | J32: 0.022368421
A33: Manufacturing Supplies | B33: =IF(B47<>0,$H$163,0) -> 0 | C33: 0.0006 | D33: 0.00065789474 | E33: =IF(E47<>0,$H$163,0) -> 0 | F33: 0.002 | G33: 0 | H33: =IF(H47<>0,$H$163,0) -> 0 | I33: 0.0014 | J33: 0.00065789474
A34: Other variable | B34: =IF($B$47<>0,$H$166,0) -> 0 | C34: 0.0101 | D34: 0.0046052632 | E34: =IF(E47<>0,$H$166,0) -> 0 | F34: 0.0118 | G34: 0 | H34: =IF(H47<>0,$H$166,0) -> 0 | I34: 0.0108 | J34: 0.0046052632
A35: Total Variable Costs | B35: =SUM(B29:B34) -> 0 | C35: =SUM(C29:C34) -> 0.2513 | D35: =SUM(D29:D34) -> 0.1487293 | E35: =SUM(E29:E34) -> 0 | F35: =SUM(F29:F34) -> 0.2066 | G35: =SUM(G29:G34) -> 0 | H35: =SUM(H29:H34) -> 0 | I35: =SUM(I29:I34) -> 0.1202 | J35: =SUM(J29:J34) -> 0.0503682
A37: Production Labor | B37: =IF(B47<>0,$F$112/$B$49/1000,0) -> 0 | C37: 0.0445 | D37: 0.02638428 | E37: =IF(E47<>0,$F$112/$B$49/1000,0) -> 0 | F37: 0.0483 | G37: 0 | H37: =IF(H47<>0,$F$112/$B$49/1000,0) -> 0 | I37: 0.0451 | J37: 0.02638428
A38: Repairs & Maintenance Labor | B38: =IF(B47<>0,$F$113/$B$49/1000,0) -> 0 | C38: 0.015 | D38: 0.00902044 | E38: =IF(E47<>0,$F$113/$B$49/1000,0) -> 0 | F38: 0.0144 | G38: 0 | H38: =IF(H47<>0,$F$113/$B$49/1000,0) -> 0 | I38: 0.0156 | J38: 0.00902044
A39: Indirect Payroll Costs (Benefits) | B39: =IF(B47<>0,$F$115/$B$49/1000,0) -> 0 | C39: 0.0194 | D39: 0.013928937 | E39: =IF(E47<>0,$F$115/$B$49/1000,0) -> 0 | F39: 0.0196 | G39: 0 | H39: =IF(H47<>0,$F$115/$B$49/1000,0) -> 0 | I39: 0.0285 | J39: 0.013928937
A40: Supervision | B40: =IF($B$47<>0,$F$114/$B$49/1000,0) -> 0 | C40: 0.0018 | D40: 0.0015771316 | E40: =IF(E47<>0,$F$114/$B$49/1000,0) -> 0 | F40: 0.0014 | G40: 0 | H40: =IF(H47<>0,$F$114/$B$49/1000,0) -> 0 | I40: 0.0022 | J40: 0.0015771316
A41: Depreciation | B41: =IF(B47<>0,$B$178/$B$49/1000,0) -> 0 | C41: 0.0043 | D41: 0.0016578947 | E41: =IF(E47<>0,$B$178/$B$49/1000,0) -> 0 | F41: 0.0042 | G41: 0 | H41: =IF(H47<>0,$B$178/$B$49/1000,0) -> 0 | I41: 0.0067 | J41: 0.0016578947
A42: Insurance & Taxes | B42: =IF(B47<>0,$B$177/B49/1000,0) -> 0 | C42: 0.0093 | D42: 0.0058026316 | E42: =IF(E47<>0,$B$177/B49/1000,0) -> 0 | F42: 0.0098 | G42: 0 | H42: =IF(H47<>0,$B$177/$B$49/1000,0) -> 0 | I42: 0.014 | J42: 0.0058026316
A43: Total Fixed Costs | B43: =SUM(B37:B42) -> 0 | C43: =SUM(C37:C42) -> 0.0943 | D43: =SUM(D37:D42) -> 0.058371315 | E43: =SUM(E37:E42) -> 0 | F43: =SUM(F37:F42) -> 0.0977 | G43: =SUM(G37:G42) -> 0 | H43: =SUM(H37:H42) -> 0 | I43: =SUM(I37:I42) -> 0.1121 | J43: =SUM(J37:J42) -> 0.058371315
...

Sheet Jan
A1: McINTYRE STANDARD 2025 | S1: COST CENTER 10001003 | AE1: Gross | AF1: Std | AG1: Abs Limit | AH1: Absorb | AI1: 10001003 | AJ1: Absorbed | AK1: 10001003 | AX1: Abs Cost
S2: CG | T2: CP | U2: HSP | V2: CL | W2: Nanomite C | X2: NRT | Y2: To Production | Z2: Idle Plant | AA2: TOTAL | AB2: Activity / Material | AC2: UOM | AD2: Ttl Unit Qty | AE2: Unit Cost | AF2: Cost/lb | AG2: Cost/lb | AH2: Cost/lb | AI2: Absorption | AJ2: Unit Cost | AK2: Underabs | AL2: EP Unit Qty | AM2: CP Unit Qty | AN2: HSP Unit Qty | AO2: CL Unit Qty | AP2: Nano C Qty | AQ2: NRT Unit Qty | AR2: EP Units/1000lb | AS2: CP Units/1000lb | AT2: HSP Units/1000lb | AU2: CL Units/1000lb | AV2: Nano C Units/1000lb | AW2: NRT Units/1000lb | AX2: per 10000
B3: HT | E3: Bauxite Pellets | H3: ID
B4: 25 Standard | C4: 23 Actual | D4: 22 Standard | E4: =B4 -> 25 Standard | F4: 23 Actual | G4: =+D4 -> 22 Standard | H4: =B4 -> 25 Standard | I4: 23 Actual | J4: =+D4 -> 22 Standard
F5: (Jan-Aug)
A6: Materials | B6: =IF($B$24<>0,$D$80,0) -> 0 | D6: 0 | E6: =IF(E24<>0,$L$88,0) -> 0 | F6: 0.071053254 | G6: 0.02685 | H6: =IF($H$24<>0,$D$88,0) -> 0 | J6: 0
A7: Electricity | B7: =IF($B$24<>0,$D$151,0) -> 0 | D7: 0 | E7: =IF(E24<>0,$D$151,0) -> 0 | F7: 0.03392679 | G7: 0.018883379 | H7: =IF(H24<>0,$D$151,0) -> 0 | J7: 0 | S7: =$C145*$B$24*1000*$B145 -> 0 | T7: =$C151*$B$47*1000*$B151 -> 0 | U7: =$F151*$E$47*1000*$E151 -> 0 | V7: =$F145*$E$24*1000*$E145 -> 0 | W7: =$I151*$H$47*1000*$H151 -> 9166.1355 | X7: =$I145*$H$24*1000*$H145 -> 0 | Y7: =SUM(S7:X7) -> 9166.1355 | Z7: 0 | AA7: =SUM(Y7:Z7) -> 9166.1355 | AB7: ELE01 | AC7: kwh | AD7: =ROUND((B145*B$24*1000)+(B151*B$47*1000)+(E145*E$24*1000)+(E151*E$47*1000)+(H145*H$24*1000)+(H151*H$47*1000),0) -> 125563 | AE7: =Y7/AD7 -> 0.073000291 | AF7: =Y7/$AF$24/1000 -> 0.0045830677 | AG7: 0.014890786 | AH7: =IF($AF$21<$AG$21,AF7,IF($AF$12<$AG$12,AF7,IF(AND($AF$12>$AG$12,$AF$20<$AG$20),($AG$12+($AG$20-$AF$20))/$AF$12*AF7,AF7/$AF$12*$AG$12))) -> 0.0019184927 | AI7: =AH7*$Y$24*1000 -> 3836.9853 | AJ7: =AI7/AD7 -> 0.030558248 | AK7: =Y7-AI7 -> 5329.1502 | AL7: =ROUND($B145*$B$24*1000,0) -> 0 | AM7: =ROUND($B151*$B$47*1000,0) -> 0 | AN7: =ROUND($E151*$E$47*1000,0) -> 0 | AO7: =ROUND($E145*$E$24*1000,0) -> 0 | AP7: =ROUND($H151*$H$47*1000,0) -> 125563 | AQ7: =ROUND($H145*$H$24*1000,0) -> 0 | AR7: =IF($B$24<>0,ROUND(AL7/B$24,3),0) -> 0 | AS7: =ROUND(AM7/B$47,3) -> #DIV/0! | AT7: =IF(E$47<>0,ROUND(AN7/E$47,3),0) -> 0 | AU7: =IF(F$24<>0,ROUND(AO7/F$24,3),0) -> 0 | AV7: =IF(H$47<>0,ROUND(AP7/H$47,3),0) -> 62.782 | AW7: =IF(H$24<>0,ROUND(AQ7/H$24,3),0) -> 0 | AX7: =AJ7*10000 -> 305.58248
A8: Gas | B8: =IF($B$24<>0,$D$152,0) -> 0 | D8: 0 | E8: =IF(E24<>0,$D$152,0) -> 0 | F8: 0.14600441 | G8: 0.04184 | H8: =IF(H24<>0,$D$152,0) -> 0 | J8: 0 | S8: =$C146*$B$24*1000*$B146 -> 0 | T8: =$C152*$B$47*1000*$B152 -> 0 | U8: =$F152*$E$47*1000*$E152 -> 0 | V8: =$F146*$E$24*1000*$E146 -> 0 | W8: =$I152*$H$47*1000*$H152 -> 0 | X8: =$I146*$H$24*1000*$H146 -> 0 | Y8: =SUM(S8:X8) -> 0 | Z8: 0 | AA8: =SUM(Y8:Z8) -> 0 | AB8: GAS01 | AC8: mbtu | AD8: =ROUND((B146*B$24*1000*1000)+(B152*B$47*1000*1000)+(E146*E$24*1000*1000)+(E152*E$47*1000*1000)+(H146*H$24*1000*1000)+(H152*H$47*1000*1000),0) -> 0 | AE8: =Y8/AD8 -> #DIV/0! | AF8: =Y8/$AF$24/1000 -> 0 | AG8: 0.042004912 | AH8: =IF($AF$21<$AG$21,AF8,IF($AF$12<$AG$12,AF8,IF(AND($AF$12>$AG$12,$AF$20<$AG$20),($AG$12+($AG$20-$AF$20))/$AF$12*AF8,AF8/$AF$12*$AG$12))) -> 0 | AI8: =AH8*$Y$24*1000 -> 0 | AJ8: =AI8/AD8 -> #DIV/0! | AK8: =Y8-AI8 -> 0 | AL8: =ROUND($B146*$B$24*1000*1000,0) -> 0 | AM8: =ROUND($B152*$B$47*1000*1000,0) -> 0 | AN8: =ROUND($E152*$E$47*1000*1000,0) -> 0 | AO8: =ROUND($E146*$E$24*1000*1000,0) -> 0 | AP8: =ROUND($H152*$H$47*1000*1000,0) -> 0 | AQ8: =ROUND($H146*$H$24*1000*1000,0) -> 0 | AR8: =IF($B$24<>0,ROUND(AL8/B$24,3),0) -> 0 | AS8: =ROUND(AM8/B$47,3) -> #DIV/0! | AT8: =IF(E$47<>0,ROUND(AN8/E$47,3),0) -> 0 | AU8: =IF(E$24<>0,ROUND(AO8/E$24,3),0) -> 0 | AV8: =IF(H$47<>0,ROUND(AP8/H$47,3),0) -> 0 | AW8: =IF(H$24<>0,ROUND(AQ8/H$24,3),0) -> 0 | AX8: =AJ8*10000 -> #DIV/0!
A9: R&M Supplies and Service | B9: =IF($B$24<>0,$H$159,0) -> 0 | D9: 0 | E9: =IF(E24<>0,$H$159,0) -> 0 | F9: 0.043366417 | G9: 0.022368421 | H9: =IF(H24<>0,$H$159,0) -> 0 | J9: 0 | S9: =B9*B$24*1000 -> 0 | T9: =B32*B$47*1000 -> 0 | U9: =E32*E$47*1000 -> 0 | V9: =E9*E$24*1000 -> 0 | W9: =H32*H$47*1000 -> 297000 | X9: =H9*H$24*1000 -> 0 | Y9: =SUM(S9:X9) -> 297000 | Z9: 0 | AA9: =SUM(Y9:Z9) -> 297000 | AB9: RMS01 | AC9: lb | AD9: =ROUND((S9/H$159)+(T9/H$159)+(U9/H$159)+(V9/H$159)+(W9/H$159)+(X9/H$159),0) -> 2000000 | AE9: =Y9/AD9 -> 0.1485 | AF9: =Y9/$AF$24/1000 -> 0.1485 | AG9: 0.019544347 | AH9: =IF($AF$21<$AG$21,AF9,IF($AF$12<$AG$12,AF9,IF(AND($AF$12>$AG$12,$AF$20<$AG$20),($AG$12+($AG$20-$AF$20))/$AF$12*AF9,AF9/$AF$12*$AG$12))) -> 0.062162764 | AI9: =AH9*$Y$24*1000 -> 124325.53 | AJ9: =AI9/AD9 -> 0.062162764 | AK9: =Y9-AI9 -> 172674.47 | AL9: =S9/$AE9 -> 0 | AM9: =T9/$AE9 -> 0 | AN9: =U9/$AE9 -> 0 | AO9: =V9/$AE9 -> 0 | AP9: =W9/$AE9 -> 2000000 | AQ9: =X9/$AE9 -> 0 | AR9: =IF($B$24<>0,ROUND(AL9/B$24,3),0) -> 0 | AS9: =ROUND(AM9/B$47,3) -> #DIV/0! | AT9: =IF(E$47<>0,ROUND(AN9/E$47,3),0) -> 0 | AU9: =IF(E$24<>0,ROUND(AO9/E$24,3),0) -> 0 | AV9: =IF(H$47<>0,ROUND(AP9/H$47,3),0) -> 1000 | AW9: =IF(H$24<>0,ROUND(AQ9/H$24,3),0) -> 0 | AX9: =AJ9*10000 -> 621.62764
A10: Manufacturing Supplies | B10: =IF($B$24<>0,$H$163,0) -> 0 | D10: 0 | E10: =IF(E24<>0,$H$163,0) -> 0 | F10: 0.00073336258 | G10: 0.00065789474 | H10: =IF($H$24<>0,$H$163,0) -> 0 | J10: 0 | S10: =B10*B$24*1000 -> 0 | T10: =B33*B$47*1000 -> 0 | U10: =E33*E$47*1000 -> 0 | V10: =E10*E$24*1000 -> 0 | W10: =H33*H$47*1000 -> 16862 | X10: =H10*H$24*1000 -> 0 | Y10: =SUM(S10:X10) -> 16862 | Z10: 0 | AA10: =SUM(Y10:Z10) -> 16862 | AB10: MFG01 | AC10: lb | AD10: =ROUND((S10/H$163)+(T10/H$163)+(U10/H$163)+(V10/H$163)+(W10/H$163)+(X10/H$163),0) -> 2000000 | AE10: =Y10/AD10 -> 0.008431 | AF10: =Y10/$AF$24/1000 -> 0.008431 | AG10: 0.0012510769 | AH10: =IF($AF$21<$AG$21,AF10,IF($AF$12<$AG$12,AF10,IF(AND($AF$12>$AG$12,$AF$20<$AG$20),($AG$12+($AG$20-$AF$20))/$AF$12*AF10,AF10/$AF$12*$AG$12))) -> 0.0035292543 | AI10: =AH10*$Y$24*1000 -> 7058.5086 | AJ10: =AI10/AD10 -> 0.0035292543 | AK10: =Y10-AI10 -> 9803.4914 | AL10: =S10/$AE10 -> 0 | AM10: =T10/$AE10 -> 0 | AN10: =U10/$AE10 -> 0 | AO10: =V10/$AE10 -> 0 | AP10: =W10/$AE10 -> 2000000 | AQ10: =X10/$AE10 -> 0 | AR10: =IF($B$24<>0,ROUND(AL10/B$24,3),0) -> 0 | AS10: =ROUND(AM10/B$47,3) -> #DIV/0! | AT10: =IF(E$47<>0,ROUND(AN10/E$47,3),0) -> 0 | AU10: =IF(E$24<>0,ROUND(AO10/E$24,3),0) -> 0 | AV10: =IF(H$47<>0,ROUND(AP10/H$47,3),0) -> 1000 | AW10: =IF(H$24<>0,ROUND(AQ10/H$24,3),0) -> 0 | AX10: =AJ10*10000 -> 35.292543
A11: Other variable | B11: =IF($B$24<>0,$H$166,0) -> 0 | D11: 0 | E11: =IF(E24<>0,$H$166,0) -> 0 | F11: 0.010235236 | G11: 0.0046052632 | H11: =IF($H$24<>0,$H$166,0) -> 0 | J11: 0 | S11: =B11*B$24*1000 -> 0 | T11: =B34*B$47*1000 -> 0 | U11: =E34*E$47*1000 -> 0 | V11: =E11*E$24*1000 -> 0 | W11: =H34*H$47*1000 -> 66000 | X11: =H11*H$24*1000 -> 0 | Y11: =SUM(S11:X11) -> 66000 | Z11: 0 | AA11: =SUM(Y11:Z11) -> 66000 | AB11: VAR01 | AC11: lb | AD11: =ROUND((S11/H$166)+(T11/H$166)+(U11/H$166)+(V11/H$166)+(W11/H$166)+(X11/H$166),0) -> 2000000 | AE11: =Y11/AD11 -> 0.033 | AF11: =Y11/$AF$24/1000 -> 0.033 | AG11: 0.0037333371 | AH11: =IF($AF$21<$AG$21,AF11,IF($AF$12<$AG$12,AF11,IF(AND($AF$12>$AG$12,$AF$20<$AG$20),($AG$12+($AG$20-$AF$20))/$AF$12*AF11,AF11/$AF$12*$AG$12))) -> 0.013813948 | AI11: =AH11*$Y$24*1000 -> 27627.895 | AJ11: =AI11/AD11 -> 0.013813948 | AK11: =Y11-AI11 -> 38372.105 | AL11: =S11/$AE11 -> 0 | AM11: =T11/$AE11 -> 0 | AN11: =U11/$AE11 -> 0 | AO11: =V11/$AE11 -> 0 | AP11: =W11/$AE11 -> 2000000 | AQ11: =X11/$AE11 -> 0 | AR11: =IF($B$24<>0,ROUND(AL11/B$24,3),0) -> 0 | AS11: =ROUND(AM11/B$47,3) -> #DIV/0! | AT11: =IF(E$47<>0,ROUND(AN11/E$47,3),0) -> 0 | AU11: =IF(E$24<>0,ROUND(AO11/E$24,3),0) -> 0 | AV11: =IF(H$47<>0,ROUND(AP11/H$47,3),0) -> 1000 | AW11: =IF(H$24<>0,ROUND(AQ11/H$24,3),0) -> 0 | AX11: =AJ11*10000 -> 138.13948
A12: Total Variable Costs | B12: =SUM(B6:B11) -> 0 | D12: =SUM(D6:D11) -> 0 | E12: =SUM(E6:E11) -> 0 | F12: =SUM(F6:F11) -> 0.30531947 | G12: =SUM(G6:G11) -> 0.11520496 | H12: =SUM(H6:H11) -> 0 | J12: =SUM(J6:J11) -> 0 | S12: =SUM(S7:S11) -> 0 | T12: =SUM(T7:T11) -> 0 | U12: =SUM(U7:U11) -> 0 | V12: =SUM(V7:V11) -> 0 | W12: =SUM(W7:W11) -> 389028.14 | X12: =SUM(X7:X11) -> 0 | Y12: =SUM(Y7:Y11) -> 389028.14 | Z12: =SUM(Z7:Z11) -> 0 | AA12: =SUM(AA7:AA11) -> 389028.14 | AF12: =SUM(AF7:AF11) -> 0.19451407 | AG12: =SUM(AG7:AG11) -> 0.081424459 | AH12: =SUM(AH7:AH11) -> 0.081424459 | AI12: =SUM(AI7:AI11) -> 162848.92 | AK12: =SUM(AK7:AK11) -> 226179.22
