Workbook

Sheet 2025 Summary
D4: Ceramics | E4: HA | G4: Ceramics | H4: HA
C5: Nov | D5: 0 | G5: =#REF! -> #REF! | H5: =#REF! -> #REF!
C6: Dec | G6: =#REF! -> #REF! | H6: =#REF! -> #REF!
C7: Jan | D7: 30000 | E7: 4900 | G7: =Jan!$B$22 -> 0.13768507 | H7: =Jan!$E$45 -> 0.23615711
C8: Feb | D8: 0 | E8: 4900 | G8: =Feb!$B$22 -> 0 | H8: =Feb!$E$45 -> 0.25135472
C9: Mar | D9: 0 | E9: 4900 | G9: =Mar!$B$22 -> 0 | H9: =Mar!$E$45 -> 0.25135472
C10: Apr | D10: 30000 | E10: 4900 | G10: =Apr!$B$22 -> 0.13768507 | H10: =Apr!$E$45 -> 0.24615711
C11: May | E11: 4900 | G11: =May!$B$22 -> 0 | H11: =May!$E$45 -> 0.25135472
C12: Jun | D12: 0 | E12: 4900 | G12: =Jun!$B$22 -> 0 | H12: =Jun!$E$45 -> 0.25135472
C13: Jul | D13: 0 | E13: 4900 | G13: =Jul!$B$22 -> 0 | H13: =Jul!$E$45 -> 0.25135472
C14: Aug | D14: 0 | E14: 4900 | G14: =Aug!$B$22 -> 0 | H14: =Aug!$E$45 -> 0.25135472
C15: Sep | D15: 0 | E15: 4900 | G15: =Sep!$B$22 -> 0 | H15: =Sep!$E$45 -> 0.25135472
C16: Oct | D16: 11000 | E16: 4900 | G16: =Oct!$B$22 -> 0.19735191 | H16: =Oct!$E$45 -> 0.24717157
C17: Nov | E17: 4900 | G17: =Nov!$B$22 -> 0 | H17: =Nov!$E$45 -> 0.25135472
C18: Dec | E18: 4900 | G18: =Dec!$B$22 -> 0 | H18: =Dec!$E$45 -> 0.25135472
C20: Total | D20: =SUM(D4:D18) -> 71000 | E20: =SUM(E5:E18) -> 58800

Sheet Jan
A1: TOOMSBORO STANDARD 2025
B3: CERAMICS | E3: CG 280 | H3: CG 300
B4: 25 Standard | C4: 23 Actual | D4: 20 Standard | E4: =$B$4 -> 25 Standard | F4: =+C4 -> 23 Actual | G4: =+D4 -> 20 Standard | H4: =+B4 -> 25 Standard | I4: =+C4 -> 23 Actual | J4: =+D4 -> 20 Standard
C5: (Jan-Sept) | F5: (Jan-Sept) | I5: (Jan-Sept)
A6: Materials | B6: =IF(B24<>0,$D$82,0) -> 0.065965818 | C6: 0.0585 | D6: 0.04156581 | E6: =+H82 -> 0 | F6: 0 | G6: 0 | H6: =+D96 -> 0 | I6: 0 | J6: 0
A7: Electricity | B7: =IF(B24<>0,$D$163,0) -> 0.0101288 | C7: 0.0105 | D7: 0.020277329 | E7: =G163 -> 0.0198372 | F7: 0 | G7: 0 | H7: =J163 -> 0.0198372 | I7: 0 | J7: 0
A8: Gas | B8: =IF(B24<>0,$D$164,0) -> 0.026 | C8: 0.0156 | D8: 0.014965 | E8: =G164 -> 0.0171 | F8: 0 | G8: 0 | H8: =J164 -> 0.0171 | I8: 0 | J8: 0
A9: R&M Supplies and Service | B9: =IF(B24<>0,$J$177,0) -> 0.011766667 | C9: 0.0192 | D9: 0.015915789 | E9: =$H$177 -> 0.03 | F9: 0 | G9: 0 | H9: =$H$177 -> 0.03 | I9: 0 | J9: 0
A10: Manufacturing Supplies | B10: =IF(B24<>0,$J$181,0) -> 0.0025 | C10: 0.0008 | D10: 0.0026315789 | E10: =$H$181 -> 0.0055102041 | F10: 0 | G10: 0 | H10: =$H$181 -> 0.0055102041 | I10: 0 | J10: 0
A11: Other variable | B11: =IF(B24<>0,$J$184,0) -> 0.0019 | C11: 0.0058 | D11: 0.0094736842 | E11: =$H$184 -> 0.01122449 | F11: 0 | G11: 0 | H11: =$H$184 -> 0.01122449 | I11: 0 | J11: 0
A12: Total Variable Costs | B12: =SUM(B6:B11) -> 0.11826128 | C12: =SUM(C6:C11) -> 0.1104 | D12: =SUM(D6:D11) -> 0.10482919 | E12: =SUM(E6:E11) -> 0.083671894 | F12: =SUM(F6:F11) -> 0 | G12: =SUM(G6:G11) -> 0 | H12: =SUM(H6:H11) -> 0.083671894 | I12: =SUM(I6:I11) -> 0 | J12: =SUM(J6:J11) -> 0
A14: Production Labor | B14: =IF($B$24<>0,$F$152/B24/1000,0) -> 0.008496223 | C14: 0.0246 | D14: 0.0073599375 | E14: =$D$124*$E$108/$B$49/1000 -> 0.00013061064 | F14: 0 | G14: 0 | H14: =$D$124*$E$108/$B$49/1000 -> 0.00013061064 | I14: 0 | J14: 0
A15: Repairs & Maintenance Labor | B15: =IF($B$24<>0,$F$153/$B$24/1000,0) -> 0.0035945559 | C15: 0.009 | D15: 0.0042419375 | E15: =$H$124*$E$108/$B$49/1000 -> 0 | F15: 0 | G15: 0 | H15: =$H$124*$E$108/$B$49/1000 -> 0 | I15: 0 | J15: 0
A16: Indirect Payroll Costs (Benefits) | B16: =IF($B$24<>0,$F$155/$B$24/1000,0) -> 0.0036987737 | C16: 0.0079 | D16: 0.0053897125 | E16: =$D$131*$E$108/$B$49/1000 -> 0 | F16: 0 | G16: 0 | H16: =$D$131*$E$108/$B$49/1000 -> 0 | I16: 0 | J16: 0
A17: Supervision | B17: =IF($B$24<>0,$F$154/$B$24/1000,0) -> 0.00023846667 | C17: 0 | D17: 0.0026778947 | E17: =$F$194 -> 0 | F17: 0 | G17: 0 | H17: =$F$194 -> 0 | I17: 0 | J17: 0
A18: Depreciation | B18: =IF($B$24<>0,$B$196/$B$49/1000,0) -> 0.00065364613 | C18: 0.0027 | D18: 0.1672 | E18: =$F$196 -> 0.0078437536 | F18: 0 | G18: 0 | H18: =$F$196 -> 0.0078437536 | I18: 0 | J18: 0
A19: Insurance & Taxes | B19: =IF($B$24<>0,$B$195/$B$49/1000,0) -> 0.0027421203 | C19: 0.012 | D19: 0.012884211 | E19: =$F$195 -> 0.032905444 | F19: 0 | G19: 0 | H19: =$F$195 -> 0.032905444 | I19: 0 | J19: 0
A20: Total Fixed Costs | B20: =SUM(B14:B19) -> 0.019423786 | C20: =SUM(C14:C19) -> 0.0562 | D20: =SUM(D14:D19) -> 0.19975369 | E20: =SUM(E14:E19) -> 0.040879808 | F20: =SUM(F14:F19) -> 0 | G20: =SUM(G14:G19) -> 0 | H20: =SUM(H14:H19) -> 0.040879808 | I20: =SUM(I14:I19) -> 0 | J20: =SUM(J14:J19) -> 0
A22: TOTAL COSTS PER POUND | B22: =B12+B20 -> 0.13768507 | C22: =C12+C20 -> 0.1666 | D22: =D12+D20 -> 0.30458288 | E22: =E12+E20 -> 0.1245517 | F22: =F12+F20 -> 0 | G22: =G12+G20 -> 0 | H22: =H12+H20 -> 0.1245517 | I22: =I12+I20 -> 0 | J22: =J12+J20 -> 0
A24: PRODUCTION ( in 000 lbs ) | B24: =+B54 -> 30000 | C24: 0 | D24: 80000 | E24: =+B55 -> 0 | F24: 0 | G24: 0 | H24: =+B56 -> 0 | I24: 0 | J24: 0
B26: XXX | E26: HA PELLETS
B27: =$B$4 -> 25 Standard | C27: =+C4 -> 23 Actual | D27: =+D4 -> 20 Standard | E27: 24 Standard | F27: 23 Actual | G27: 22 Standard | H27: =+B27 -> 25 Standard | I27: =+C27 -> 23 Actual | J27: =+D27 -> 20 Standard
C28: (Jan-Sept) | F28: (Jan-Aug)
A29: Materials | B29: =D82 -> 0.065965818 | C29: 0 | D29: 0 | E29: =IF(E47<>0,$L$96,0) -> 0.070852832 | F29: 0.078 | G29: 0.06025968 | H29: 0 | I29: 0 | J29: 0
A30: Electricity | B30: =D169 -> 0 | C30: 0 | D30: 0 | E30: =IF(E47<>0,$G$169,0)-0.01 -> 0.033918811 | F30: 0.0432 | G30: 0.026879418 | H30: 0 | I30: 0 | J30: 0
A31: Gas | B31: =D170 -> 0 | C31: 0 | D31: 0 | E31: =IF(E47<>0,$G$170,0) -> 0.026 | F31: 0.019 | G31: 0.028567 | H31: =J170 -> 0 | I31: 0 | J31: 0
A32: R&M Supplies and Service | B32: =IF($B$47<>0,$H$177,0) -> 0 | C32: 0 | D32: 0 | E32: =IF(E47<>0,$H$177,0) -> 0.03 | F32: 0.0298 | G32: 0.027777778 | H32: 0 | I32: 0 | J32: 0
A33: Manufacturing Supplies | B33: =IF($B$47<>0,$H$181,0) -> 0 | C33: 0 | D33: 0 | E33: =IF(E47<>0,$H$181,0) -> 0.0055102041 | F33: 0.0012 | G33: 0.0069444444 | H33: 0 | I33: 0 | J33: 0
A34: Other variable | B34: =IF($B$47<>0,$H$184,0) -> 0 | C34: 0 | D34: 0 | E34: =IF(E47<>0,$H$184,0) -> 0.01122449 | F34: 0.0139 | G34: 0.0125 | H34: 0 | I34: 0 | J34: 0
A35: Total Variable Costs | B35: =SUM(B29:B34) -> 0.065965818 | C35: =SUM(C29:C34) -> 0 | D35: =SUM(D29:D34) -> 0 | E35: =SUM(E29:E34) -> 0.17750634 | F35: =SUM(F29:F34) -> 0.1851 | G35: =SUM(G29:G34) -> 0.16292832 | H35: =SUM(H29:H34) -> 0 | I35: =SUM(I29:I34) -> 0 | J35: =SUM(J29:J34) -> 0
A37: Production Labor | B37: =$D$124*$E$108/$B$49/1000 -> 0.00013061064 | C37: 0 | D37: 0 | E37: =IF($E$47<>0,$F$127/$E$47/1000,0) -> 0.040001507 | F37: 0.0353 | G37: 0.02156921 | H37: 0 | I37: 0 | J37: 0
A38: Repairs & Maintenance Labor | B38: =$H$124*$E$108/$B$49/1000 -> 0 | C38: 0 | D38: 0 | E38: =IF($E$47<>0,$F$128/$E$47/1000,0) -> 0.0048061173 | F38: 0.0067 | G38: 0.0051700857 | H38: 0 | I38: 0 | J38: 0
A39: Indirect Payroll Costs (Benefits) | B39: =$D$131*$E$108/$B$49/1000 -> 0 | C39: 0 | D39: 0 | E39: =IF($E$47<>0,$F$130/$E$47/1000,0) -> 0.012994211 | F39: 0.0112 | G39: 0.0080162316 | H39: 0 | I39: 0 | J39: 0
A40: Supervision | B40: =IF($B$49<>0,$F$194,0) -> 0 | C40: 0 | D40: 0 | E40: =IF($E$47<>0,$F$129/$E$47/1000,0) -> 0 | F40: 0 | G40: 0.00047638889 | H40: 0 | I40: 0 | J40: 0
A41: Depreciation | B41: =IF($B$49<>0,$F$196,0) -> 0.0078437536 | C41: 0 | D41: 0 | E41: =IF($E$47<>0,$B$196/$B$49/1000/4,0) -> 0.00016341153 | F41: 0.0085 | G41: 0.0056777778 | H41: 0 | I41: 0 | J41: 0
A42: Insurance & Taxes | B42: =IF($B$49<>0,$F$195,0) -> 0.032905444 | C42: 0 | D42: 0 | E42: =IF($E$47<>0,$B$195/$B$49/1000/4,0) -> 0.00068553009 | F42: 0.0362 | G42: 0.025861111 | H42: 0 | I42: 0 | J42: 0
A43: Total Fixed Costs | B43: =SUM(B37:B42) -> 0.040879808 | C43: =SUM(C37:C42) -> 0 | D43: =SUM(D37:D42) -> 0 | E43: =SUM(E37:E42) -> 0.058650778 | F43: =SUM(F37:F42) -> 0.0979 | G43: =SUM(G37:G42) -> 0.066770805 | H43: =SUM(H37:H42) -> 0 | I43: =SUM(I37:I42) -> 0 | J43: =SUM(J37:J42) -> 0
A44: Excess Costs | F44: -0.0455
A45: TOTAL COSTS PER POUND | B45: =B35+B43 -> 0.10684563 | C45: =C35+C43 -> 0 | D45: 0.19962946 | E45: =E35+E43+E44 -> 0.23615711 | F45: =F35+F43+F44 -> 0.2375 | G45: =+G35+G43 -> 0.22969913 | H45: =H35+H43 -> 0 | I45: =I35+I43 -> 0 | J45: =J35+J43 -> 0
A47: PRODUCTION ( in 000 lbs ) | B47: =+B57 -> 0 | C47: 0 | D47: 0 | E47: =+B58 -> 4900 | F47: 15776 | G47: 36000 | H47: =+B59 -> 0 | I47: 0 | J47: 0
...

Sheet Feb
A1: TOOMSBORO STANDARD 2025
B3: CERAMICS | E3: CG 280 | H3: CG 300
B4: 25 Standard | C4: 23 Actual | D4: 20 Standard | E4: =$B$4 -> 25 Standard | F4: =+C4 -> 23 Actual | G4: =+D4 -> 20 Standard | H4: =+B4 -> 25 Standard | I4: =+C4 -> 23 Actual | J4: =+D4 -> 20 Standard
C5: (Jan-Sept) | F5: (Jan-Sept) | I5: (Jan-Sept)
A6: Materials | B6: =IF(B24<>0,$D$82,0) -> 0 | C6: 0.0585 | D6: 0.04156581 | E6: =+H82 -> 0 | F6: 0 | G6: 0 | H6: =+D96 -> 0 | I6: 0 | J6: 0
A7: Electricity | B7: =IF(B24<>0,$D$163,0) -> 0 | C7: 0.0105 | D7: 0.020277329 | E7: =G163 -> 0.0198372 | F7: 0 | G7: 0 | H7: =J163 -> 0.0198372 | I7: 0 | J7: 0
A8: Gas | B8: =IF(B24<>0,$D$164,0) -> 0 | C8: 0.0156 | D8: 0.014965 | E8: =G164 -> 0.0171 | F8: 0 | G8: 0 | H8: =J164 -> 0.0171 | I8: 0 | J8: 0
A9: R&M Supplies and Service | B9: =IF(B24<>0,$J$177,0) -> 0 | C9: 0.0192 | D9: 0.015915789 | E9: =$H$177 -> 0.03 | F9: 0 | G9: 0 | H9: =$H$177 -> 0.03 | I9: 0 | J9: 0
A10: Manufacturing Supplies | B10: =IF(B24<>0,$J$181,0) -> 0 | C10: 0.0008 | D10: 0.0026315789 | E10: =$H$181 -> 0.0055102041 | F10: 0 | G10: 0 | H10: =$H$181 -> 0.0055102041 | I10: 0 | J10: 0
A11: Other variable | B11: =IF(B24<>0,$J$184,0) -> 0 | C11: 0.0058 | D11: 0.0094736842 | E11: =$H$184 -> 0.01122449 | F11: 0 | G11: 0 | H11: =$H$184 -> 0.01122449 | I11: 0 | J11: 0
A12: Total Variable Costs | B12: =SUM(B6:B11) -> 0 | C12: =SUM(C6:C11) -> 0.1104 | D12: =SUM(D6:D11) -> 0.10482919 | E12: =SUM(E6:E11) -> 0.083671894 | F12: =SUM(F6:F11) -> 0 | G12: =SUM(G6:G11) -> 0 | H12: =SUM(H6:H11) -> 0.083671894 | I12: =SUM(I6:I11) -> 0 | J12: =SUM(J6:J11) -> 0
A14: Production Labor | B14: =IF($B$24<>0,$F$152/B24/1000,0) -> 0 | C14: 0.0246 | D14: 0.0073599375 | E14: =$D$124*$E$108/$B$49/1000 -> 0.00093026761 | F14: 0 | G14: 0 | H14: =$D$124*$E$108/$B$49/1000 -> 0.00093026761 | I14: 0 | J14: 0
A15: Repairs & Maintenance Labor | B15: =IF($B$24<>0,$F$153/$B$24/1000,0) -> 0 | C15: 0.009 | D15: 0.0042419375 | E15: =$H$124*$E$108/$B$49/1000 -> 0 | F15: 0 | G15: 0 | H15: =$H$124*$E$108/$B$49/1000 -> 0 | I15: 0 | J15: 0
A16: Indirect Payroll Costs (Benefits) | B16: =IF($B$24<>0,$F$155/$B$24/1000,0) -> 0 | C16: 0.0079 | D16: 0.0053897125 | E16: =$D$131*$E$108/$B$49/1000 -> 0 | F16: 0 | G16: 0 | H16: =$D$131*$E$108/$B$49/1000 -> 0 | I16: 0 | J16: 0
A17: Supervision | B17: =IF($B$24<>0,$F$154/$B$24/1000,0) -> 0 | C17: 0 | D17: 0.0026778947 | E17: =$F$194 -> 0 | F17: 0 | G17: 0 | H17: =$F$194 -> 0 | I17: 0 | J17: 0
A18: Depreciation | B18: =IF($B$24<>0,$B$196/$B$49/1000,0) -> 0 | C18: 0.0027 | D18: 0.1672 | E18: =$F$196 -> 0.055866735 | F18: 0 | G18: 0 | H18: =$F$196 -> 0.055866735 | I18: 0 | J18: 0
A19: Insurance & Taxes | B19: =IF($B$24<>0,$B$195/$B$49/1000,0) -> 0 | C19: 0.012 | D19: 0.012884211 | E19: =$F$195 -> 0.23436735 | F19: 0 | G19: 0 | H19: =$F$195 -> 0.23436735 | I19: 0 | J19: 0
A20: Total Fixed Costs | B20: =SUM(B14:B19) -> 0 | C20: =SUM(C14:C19) -> 0.0562 | D20: =SUM(D14:D19) -> 0.19975369 | E20: =SUM(E14:E19) -> 0.29116435 | F20: =SUM(F14:F19) -> 0 | G20: =SUM(G14:G19) -> 0 | H20: =SUM(H14:H19) -> 0.29116435 | I20: =SUM(I14:I19) -> 0 | J20: =SUM(J14:J19) -> 0
A22: TOTAL COSTS PER POUND | B22: =B12+B20 -> 0 | C22: =C12+C20 -> 0.1666 | D22: =D12+D20 -> 0.30458288 | E22: =E12+E20 -> 0.37483624 | F22: =F12+F20 -> 0 | G22: =G12+G20 -> 0 | H22: =H12+H20 -> 0.37483624 | I22: =I12+I20 -> 0 | J22: =J12+J20 -> 0
A24: PRODUCTION ( in 000 lbs ) | B24: =+B54 -> 0 | C24: 0 | D24: 80000 | E24: =+B55 -> 0 | F24: 0 | G24: 0 | H24: =+B56 -> 0 | I24: 0 | J24: 0
B26: XXX | E26: HA PELLETS
B27: =$B$4 -> 25 Standard | C27: =+C4 -> 23 Actual | D27: =+D4 -> 20 Standard | E27: 24 Standard | F27: 23 Actual | G27: 22 Standard | H27: =+B27 -> 25 Standard | I27: =+C27 -> 23 Actual | J27: =+D27 -> 20 Standard
C28: (Jan-Sept) | F28: (Jan-Aug)
A29: Materials | B29: =D82 -> 0.065965818 | C29: 0 | D29: 0 | E29: =IF(E47<>0,$L$96,0) -> 0.070852832 | F29: 0.078 | G29: 0.06025968 | H29: 0 | I29: 0 | J29: 0
A30: Electricity | B30: =D169 -> 0 | C30: 0 | D30: 0 | E30: =IF(E47<>0,$G$169,0) -> 0.043918811 | F30: 0.0432 | G30: 0.026879418 | H30: 0 | I30: 0 | J30: 0
A31: Gas | B31: =D170 -> 0 | C31: 0 | D31: 0 | E31: =IF(E47<>0,$G$170,0) -> 0.026 | F31: 0.019 | G31: 0.028567 | H31: =J170 -> 0 | I31: 0 | J31: 0
A32: R&M Supplies and Service | B32: =IF($B$47<>0,$H$177,0) -> 0 | C32: 0 | D32: 0 | E32: =IF(E47<>0,$H$177,0) -> 0.03 | F32: 0.0298 | G32: 0.027777778 | H32: 0 | I32: 0 | J32: 0
A33: Manufacturing Supplies | B33: =IF($B$47<>0,$H$181,0) -> 0 | C33: 0 | D33: 0 | E33: =IF(E47<>0,$H$181,0) -> 0.0055102041 | F33: 0.0012 | G33: 0.0069444444 | H33: 0 | I33: 0 | J33: 0
A34: Other variable | B34: =IF($B$47<>0,$H$184,0) -> 0 | C34: 0 | D34: 0 | E34: =IF(E47<>0,$H$184,0) -> 0.01122449 | F34: 0.0139 | G34: 0.0125 | H34: 0 | I34: 0 | J34: 0
A35: Total Variable Costs | B35: =SUM(B29:B34) -> 0.065965818 | C35: =SUM(C29:C34) -> 0 | D35: =SUM(D29:D34) -> 0 | E35: =SUM(E29:E34) -> 0.18750634 | F35: =SUM(F29:F34) -> 0.1851 | G35: =SUM(G29:G34) -> 0.16292832 | H35: =SUM(H29:H34) -> 0 | I35: =SUM(I29:I34) -> 0 | J35: =SUM(J29:J34) -> 0
A37: Production Labor | B37: =$D$124*$E$108/$B$49/1000 -> 0.00093026761 | C37: 0 | D37: 0 | E37: =IF($E$47<>0,$F$127/$E$47/1000,0) -> 0.040001507 | F37: 0.0353 | G37: 0.02156921 | H37: 0 | I37: 0 | J37: 0
A38: Repairs & Maintenance Labor | B38: =$H$124*$E$108/$B$49/1000 -> 0 | C38: 0 | D38: 0 | E38: =IF($E$47<>0,$F$128/$E$47/1000,0) -> 0.0048061173 | F38: 0.0067 | G38: 0.0051700857 | H38: 0 | I38: 0 | J38: 0
A39: Indirect Payroll Costs (Benefits) | B39: =$D$131*$E$108/$B$49/1000 -> 0 | C39: 0 | D39: 0 | E39: =IF($E$47<>0,$F$130/$E$47/1000,0) -> 0.012994211 | F39: 0.0112 | G39: 0.0080162316 | H39: 0 | I39: 0 | J39: 0
A40: Supervision | B40: =IF($B$49<>0,$F$194,0) -> 0 | C40: 0 | D40: 0 | E40: =IF($E$47<>0,$F$129/$E$47/1000,0) -> 0 | F40: 0 | G40: 0.00047638889 | H40: 0 | I40: 0 | J40: 0
A41: Depreciation | B41: =IF($B$49<>0,$F$196,0) -> 0.055866735 | C41: 0 | D41: 0 | E41: =IF($E$47<>0,$B$196/$B$49/1000/4,0) -> 0.0011638903 | F41: 0.0085 | G41: 0.0056777778 | H41: 0 | I41: 0 | J41: 0
A42: Insurance & Taxes | B42: =IF($B$49<>0,$F$195,0) -> 0.23436735 | C42: 0 | D42: 0 | E42: =IF($E$47<>0,$B$195/$B$49/1000/4,0) -> 0.0048826531 | F42: 0.0362 | G42: 0.025861111 | H42: 0 | I42: 0 | J42: 0
A43: Total Fixed Costs | B43: =SUM(B37:B42) -> 0.29116435 | C43: =SUM(C37:C42) -> 0 | D43: =SUM(D37:D42) -> 0 | E43: =SUM(E37:E42) -> 0.063848379 | F43: =SUM(F37:F42) -> 0.0979 | G43: =SUM(G37:G42) -> 0.066770805 | H43: =SUM(H37:H42) -> 0 | I43: =SUM(I37:I42) -> 0 | J43: =SUM(J37:J42) -> 0
A44: Excess Costs | F44: -0.0455
A45: TOTAL COSTS PER POUND | B45: =B35+B43 -> 0.35713017 | C45: =C35+C43 -> 0 | D45: 0.19962946 | E45: =E35+E43+E44 -> 0.25135472 | F45: =F35+F43+F44 -> 0.2375 | G45: =+G35+G43 -> 0.22969913 | H45: =H35+H43 -> 0 | I45: =I35+I43 -> 0 | J45: =J35+J43 -> 0
A47: PRODUCTION ( in 000 lbs ) | B47: =+B57 -> 0 | C47: 0 | D47: 0 | E47: =+B58 -> 4900 | F47: 15776 | G47: 36000 | H47: =+B59 -> 0 | I47: 0 | J47: 0
...

Sheet Mar
A1: TOOMSBORO STANDARD 2025
B3: CERAMICS | E3: CG 280 | H3: CG 300
B4: 25 Standard | C4: 23 Actual | D4: 20 Standard | E4: =$B$4 -> 25 Standard | F4: =+C4 -> 23 Actual | G4: =+D4 -> 20 Standard | H4: =+B4 -> 25 Standard | I4: =+C4 -> 23 Actual | J4: =+D4 -> 20 Standard
C5: (Jan-Sept) | F5: (Jan-Sept) | I5: (Jan-Sept)
A6: Materials | B6: =IF(B24<>0,$D$82,0) -> 0 | C6: 0.0585 | D6: 0.04156581 | E6: =+H82 -> 0 | F6: 0 | G6: 0 | H6: =+D96 -> 0 | I6: 0 | J6: 0
A7: Electricity | B7: =IF(B24<>0,$D$163,0) -> 0 | C7: 0.0105 | D7: 0.020277329 | E7: =G163 -> 0.0198372 | F7: 0 | G7: 0 | H7: =J163 -> 0.0198372 | I7: 0 | J7: 0
A8: Gas | B8: =IF(B24<>0,$D$164,0) -> 0 | C8: 0.0156 | D8: 0.014965 | E8: =G164 -> 0.0171 | F8: 0 | G8: 0 | H8: =J164 -> 0.0171 | I8: 0 | J8: 0
A9: R&M Supplies and Service | B9: =IF(B24<>0,$J$177,0) -> 0 | C9: 0.0192 | D9: 0.015915789 | E9: =$H$177 -> 0.03 | F9: 0 | G9: 0 | H9: =$H$177 -> 0.03 | I9: 0 | J9: 0
A10: Manufacturing Supplies | B10: =IF(B24<>0,$J$181,0) -> 0 | C10: 0.0008 | D10: 0.0026315789 | E10: =$H$181 -> 0.0055102041 | F10: 0 | G10: 0 | H10: =$H$181 -> 0.0055102041 | I10: 0 | J10: 0
A11: Other variable | B11: =IF(B24<>0,$J$184,0) -> 0 | C11: 0.0058 | D11: 0.0094736842 | E11: =$H$184 -> 0.01122449 | F11: 0 | G11: 0 | H11: =$H$184 -> 0.01122449 | I11: 0 | J11: 0
A12: Total Variable Costs | B12: =SUM(B6:B11) -> 0 | C12: =SUM(C6:C11) -> 0.1104 | D12: =SUM(D6:D11) -> 0.10482919 | E12: =SUM(E6:E11) -> 0.083671894 | F12: =SUM(F6:F11) -> 0 | G12: =SUM(G6:G11) -> 0 | H12: =SUM(H6:H11) -> 0.083671894 | I12: =SUM(I6:I11) -> 0 | J12: =SUM(J6:J11) -> 0
A14: Production Labor | B14: =IF($B$24<>0,$F$152/B24/1000,0) -> 0 | C14: 0.0246 | D14: 0.0073599375 | E14: =$D$124*$E$108/$B$49/1000 -> 0.00093026761 | F14: 0 | G14: 0 | H14: =$D$124*$E$108/$B$49/1000 -> 0.00093026761 | I14: 0 | J14: 0
A15: Repairs & Maintenance Labor | B15: =IF($B$24<>0,$F$153/$B$24/1000,0) -> 0 | C15: 0.009 | D15: 0.0042419375 | E15: =$H$124*$E$108/$B$49/1000 -> 0 | F15: 0 | G15: 0 | H15: =$H$124*$E$108/$B$49/1000 -> 0 | I15: 0 | J15: 0
A16: Indirect Payroll Costs (Benefits) | B16: =IF($B$24<>0,$F$155/$B$24/1000,0) -> 0 | C16: 0.0079 | D16: 0.0053897125 | E16: =$D$131*$E$108/$B$49/1000 -> 0 | F16: 0 | G16: 0 | H16: =$D$131*$E$108/$B$49/1000 -> 0 | I16: 0 | J16: 0
A17: Supervision | B17: =IF($B$24<>0,$F$154/$B$24/1000,0) -> 0 | C17: 0 | D17: 0.0026778947 | E17: =$F$194 -> 0 | F17: 0 | G17: 0 | H17: =$F$194 -> 0 | I17: 0 | J17: 0
A18: Depreciation | B18: =IF($B$24<>0,$B$196/$B$49/1000,0) -> 0 | C18: 0.0027 | D18: 0.1672 | E18: =$F$196 -> 0.055866735 | F18: 0 | G18: 0 | H18: =$F$196 -> 0.055866735 | I18: 0 | J18: 0
A19: Insurance & Taxes | B19: =IF($B$24<>0,$B$195/$B$49/1000,0) -> 0 | C19: 0.012 | D19: 0.012884211 | E19: =$F$195 -> 0.23436735 | F19: 0 | G19: 0 | H19: =$F$195 -> 0.23436735 | I19: 0 | J19: 0
A20: Total Fixed Costs | B20: =SUM(B14:B19) -> 0 | C20: =SUM(C14:C19) -> 0.0562 | D20: =SUM(D14:D19) -> 0.19975369 | E20: =SUM(E14:E19) -> 0.29116435 | F20: =SUM(F14:F19) -> 0 | G20: =SUM(G14:G19) -> 0 | H20: =SUM(H14:H19) -> 0.29116435 | I20: =SUM(I14:I19) -> 0 | J20: =SUM(J14:J19) -> 0
A22: TOTAL COSTS PER POUND | B22: =B12+B20 -> 0 | C22: =C12+C20 -> 0.1666 | D22: =D12+D20 -> 0.30458288 | E22: =E12+E20 -> 0.37483624 | F22: =F12+F20 -> 0 | G22: =G12+G20 -> 0 | H22: =H12+H20 -> 0.37483624 | I22: =I12+I20 -> 0 | J22: =J12+J20 -> 0
A24: PRODUCTION ( in 000 lbs ) | B24: =+B54 -> 0 | C24: 0 | D24: 80000 | E24: =+B55 -> 0 | F24: 0 | G24: 0 | H24: =+B56 -> 0 | I24: 0 | J24: 0
B26: XXX | E26: HA PELLETS
B27: =$B$4 -> 25 Standard | C27: =+C4 -> 23 Actual | D27: =+D4 -> 20 Standard | E27: 24 Standard | F27: 23 Actual | G27: 22 Standard | H27: =+B27 -> 25 Standard | I27: =+C27 -> 23 Actual | J27: =+D27 -> 20 Standard
C28: (Jan-Sept) | F28: (Jan-Aug)
A29: Materials | B29: =D82 -> 0.065965818 | C29: 0 | D29: 0 | E29: =IF(E47<>0,$L$96,0) -> 0.070852832 | F29: 0.078 | G29: 0.06025968 | H29: 0 | I29: 0 | J29: 0
A30: Electricity | B30: =D169 -> 0 | C30: 0 | D30: 0 | E30: =IF(E47<>0,$G$169,0) -> 0.043918811 | F30: 0.0432 | G30: 0.026879418 | H30: 0 | I30: 0 | J30: 0
A31: Gas | B31: =D170 -> 0 | C31: 0 | D31: 0 | E31: =IF(E47<>0,$G$170,0) -> 0.026 | F31: 0.019 | G31: 0.028567 | H31: =J170 -> 0 | I31: 0 | J31: 0
A32: R&M Supplies and Service | B32: =IF($B$47<>0,$H$177,0) -> 0 | C32: 0 | D32: 0 | E32: =IF(E47<>0,$H$177,0) -> 0.03 | F32: 0.0298 | G32: 0.027777778 | H32: 0 | I32: 0 | J32: 0
A33: Manufacturing Supplies | B33: =IF($B$47<>0,$H$181,0) -> 0 | C33: 0 | D33: 0 | E33: =IF(E47<>0,$H$181,0) -> 0.0055102041 | F33: 0.0012 | G33: 0.0069444444 | H33: 0 | I33: 0 | J33: 0
A34: Other variable | B34: =IF($B$47<>0,$H$184,0) -> 0 | C34: 0 | D34: 0 | E34: =IF(E47<>0,$H$184,0) -> 0.01122449 | F34: 0.0139 | G34: 0.0125 | H34: 0 | I34: 0 | J34: 0
A35: Total Variable Costs | B35: =SUM(B29:B34) -> 0.065965818 | C35: =SUM(C29:C34) -> 0 | D35: =SUM(D29:D34) -> 0 | E35: =SUM(E29:E34) -> 0.18750634 | F35: =SUM(F29:F34) -> 0.1851 | G35: =SUM(G29:G34) -> 0.16292832 | H35: =SUM(H29:H34) -> 0 | I35: =SUM(I29:I34) -> 0 | J35: =SUM(J29:J34) -> 0
A37: Production Labor | B37: =$D$124*$E$108/$B$49/1000 -> 0.00093026761 | C37: 0 | D37: 0 | E37: =IF($E$47<>0,$F$127/$E$47/1000,0) -> 0.040001507 | F37: 0.0353 | G37: 0.02156921 | H37: 0 | I37: 0 | J37: 0
A38: Repairs & Maintenance Labor | B38: =$H$124*$E$108/$B$49/1000 -> 0 | C38: 0 | D38: 0 | E38: =IF($E$47<>0,$F$128/$E$47/1000,0) -> 0.0048061173 | F38: 0.0067 | G38: 0.0051700857 | H38: 0 | I38: 0 | J38: 0
A39: Indirect Payroll Costs (Benefits) | B39: =$D$131*$E$108/$B$49/1000 -> 0 | C39: 0 | D39: 0 | E39: =IF($E$47<>0,$F$130/$E$47/1000,0) -> 0.012994211 | F39: 0.0112 | G39: 0.0080162316 | H39: 0 | I39: 0 | J39: 0
A40: Supervision | B40: =IF($B$49<>0,$F$194,0) -> 0 | C40: 0 | D40: 0 | E40: =IF($E$47<>0,$F$129/$E$47/1000,0) -> 0 | F40: 0 | G40: 0.00047638889 | H40: 0 | I40: 0 | J40: 0
A41: Depreciation | B41: =IF($B$49<>0,$F$196,0) -> 0.055866735 | C41: 0 | D41: 0 | E41: =IF($E$47<>0,$B$196/$B$49/1000/4,0) -> 0.0011638903 | F41: 0.0085 | G41: 0.0056777778 | H41: 0 | I41: 0 | J41: 0
A42: Insurance & Taxes | B42: =IF($B$49<>0,$F$195,0) -> 0.23436735 | C42: 0 | D42: 0 | E42: =IF($E$47<>0,$B$195/$B$49/1000/4,0) -> 0.0048826531 | F42: 0.0362 | G42: 0.025861111 | H42: 0 | I42: 0 | J42: 0
A43: Total Fixed Costs | B43: =SUM(B37:B42) -> 0.29116435 | C43: =SUM(C37:C42) -> 0 | D43: =SUM(D37:D42) -> 0 | E43: =SUM(E37:E42) -> 0.063848379 | F43: =SUM(F37:F42) -> 0.0979 | G43: =SUM(G37:G42) -> 0.066770805 | H43: =SUM(H37:H42) -> 0 | I43: =SUM(I37:I42) -> 0 | J43: =SUM(J37:J42) -> 0
A44: Excess Costs | F44: -0.0455
A45: TOTAL COSTS PER POUND | B45: =B35+B43 -> 0.35713017 | C45: =C35+C43 -> 0 | D45: 0.19962946 | E45: =E35+E43+E44 -> 0.25135472 | F45: =F35+F43+F44 -> 0.2375 | G45: =+G35+G43 -> 0.22969913 | H45: =H35+H43 -> 0 | I45: =I35+I43 -> 0 | J45: =J35+J43 -> 0 | L45: =E45-0.245 -> 0.0063547165 | M45: =E47*1000*L45 -> 31138.111
M46: =M45/12 -> 2594.8426
...

Sheet Apr
A1: TOOMSBORO STANDARD 2025
B3: CERAMICS | E3: CG 280 | H3: CG 300
B4: 25 Standard | C4: 23 Actual | D4: 20 Standard | E4: =$B$4 -> 25 Standard | F4: =+C4 -> 23 Actual | G4: =+D4 -> 20 Standard | H4: =+B4 -> 25 Standard | I4: =+C4 -> 23 Actual | J4: =+D4 -> 20 Standard
C5: (Jan-Sept) | F5: (Jan-Sept) | I5: (Jan-Sept)
A6: Materials | B6: =IF(B24<>0,$D$82,0) -> 0.065965818 | C6: 0.0585 | D6: 0.04156581 | E6: =+H82 -> 0 | F6: 0 | G6: 0 | H6: =+D96 -> 0 | I6: 0 | J6: 0
A7: Electricity | B7: =IF(B24<>0,$D$163,0) -> 0.0101288 | C7: 0.0105 | D7: 0.020277329 | E7: =G163 -> 0.0198372 | F7: 0 | G7: 0 | H7: =J163 -> 0.0198372 | I7: 0 | J7: 0
A8: Gas | B8: =IF(B24<>0,$D$164,0) -> 0.026 | C8: 0.0156 | D8: 0.014965 | E8: =G164 -> 0.0171 | F8: 0 | G8: 0 | H8: =J164 -> 0.0171 | I8: 0 | J8: 0
A9: R&M Supplies and Service | B9: =IF(B24<>0,$J$177,0) -> 0.011766667 | C9: 0.0192 | D9: 0.015915789 | E9: =$H$177 -> 0.03 | F9: 0 | G9: 0 | H9: =$H$177 -> 0.03 | I9: 0 | J9: 0
A10: Manufacturing Supplies | B10: =IF(B24<>0,$J$181,0) -> 0.0025 | C10: 0.0008 | D10: 0.0026315789 | E10: =$H$181 -> 0.0055102041 | F10: 0 | G10: 0 | H10: =$H$181 -> 0.0055102041 | I10: 0 | J10: 0
A11: Other variable | B11: =IF(B24<>0,$J$184,0) -> 0.0019 | C11: 0.0058 | D11: 0.0094736842 | E11: =$H$184 -> 0.01122449 | F11: 0 | G11: 0 | H11: =$H$184 -> 0.01122449 | I11: 0 | J11: 0
A12: Total Variable Costs | B12: =SUM(B6:B11) -> 0.11826128 | C12: =SUM(C6:C11) -> 0.1104 | D12: =SUM(D6:D11) -> 0.10482919 | E12: =SUM(E6:E11) -> 0.083671894 | F12: =SUM(F6:F11) -> 0 | G12: =SUM(G6:G11) -> 0 | H12: =SUM(H6:H11) -> 0.083671894 | I12: =SUM(I6:I11) -> 0 | J12: =SUM(J6:J11) -> 0
A14: Production Labor | B14: =IF($B$24<>0,$F$152/B24/1000,0) -> 0.008496223 | C14: 0.0246 | D14: 0.0073599375 | E14: =$D$124*$E$108/$B$49/1000 -> 0.00013061064 | F14: 0 | G14: 0 | H14: =$D$124*$E$108/$B$49/1000 -> 0.00013061064 | I14: 0 | J14: 0
A15: Repairs & Maintenance Labor | B15: =IF($B$24<>0,$F$153/$B$24/1000,0) -> 0.0035945559 | C15: 0.009 | D15: 0.0042419375 | E15: =$H$124*$E$108/$B$49/1000 -> 0 | F15: 0 | G15: 0 | H15: =$H$124*$E$108/$B$49/1000 -> 0 | I15: 0 | J15: 0
A16: Indirect Payroll Costs (Benefits) | B16: =IF($B$24<>0,$F$155/$B$24/1000,0) -> 0.0036987737 | C16: 0.0079 | D16: 0.0053897125 | E16: =$D$131*$E$108/$B$49/1000 -> 0 | F16: 0 | G16: 0 | H16: =$D$131*$E$108/$B$49/1000 -> 0 | I16: 0 | J16: 0
A17: Supervision | B17: =IF($B$24<>0,$F$154/$B$24/1000,0) -> 0.00023846667 | C17: 0 | D17: 0.0026778947 | E17: =$F$194 -> 0 | F17: 0 | G17: 0 | H17: =$F$194 -> 0 | I17: 0 | J17: 0
A18: Depreciation | B18: =IF($B$24<>0,$B$196/$B$49/1000,0) -> 0.00065364613 | C18: 0.0027 | D18: 0.1672 | E18: =$F$196 -> 0.0078437536 | F18: 0 | G18: 0 | H18: =$F$196 -> 0.0078437536 | I18: 0 | J18: 0
A19: Insurance & Taxes | B19: =IF($B$24<>0,$B$195/$B$49/1000,0) -> 0.0027421203 | C19: 0.012 | D19: 0.012884211 | E19: =$F$195 -> 0.032905444 | F19: 0 | G19: 0 | H19: =$F$195 -> 0.032905444 | I19: 0 | J19: 0
A20: Total Fixed Costs | B20: =SUM(B14:B19) -> 0.019423786 | C20: =SUM(C14:C19) -> 0.0562 | D20: =SUM(D14:D19) -> 0.19975369 | E20: =SUM(E14:E19) -> 0.040879808 | F20: =SUM(F14:F19) -> 0 | G20: =SUM(G14:G19) -> 0 | H20: =SUM(H14:H19) -> 0.040879808 | I20: =SUM(I14:I19) -> 0 | J20: =SUM(J14:J19) -> 0
A22: TOTAL COSTS PER POUND | B22: =B12+B20 -> 0.13768507 | C22: =C12+C20 -> 0.1666 | D22: =D12+D20 -> 0.30458288 | E22: =E12+E20 -> 0.1245517 | F22: =F12+F20 -> 0 | G22: =G12+G20 -> 0 | H22: =H12+H20 -> 0.1245517 | I22: =I12+I20 -> 0 | J22: =J12+J20 -> 0
A24: PRODUCTION ( in 000 lbs ) | B24: =+B54 -> 30000 | C24: 0 | D24: 80000 | E24: =+B55 -> 0 | F24: 0 | G24: 0 | H24: =+B56 -> 0 | I24: 0 | J24: 0
B26: XXX | E26: HA PELLETS
B27: =$B$4 -> 25 Standard | C27: =+C4 -> 23 Actual | D27: =+D4 -> 20 Standard | E27: 24 Standard | F27: 23 Actual | G27: 22 Standard | H27: =+B27 -> 25 Standard | I27: =+C27 -> 23 Actual | J27: =+D27 -> 20 Standard
C28: (Jan-Sept) | F28: (Jan-Aug)
A29: Materials | B29: =D82 -> 0.065965818 | C29: 0 | D29: 0 | E29: =IF(E47<>0,$L$96,0) -> 0.070852832 | F29: 0.078 | G29: 0.06025968 | H29: 0 | I29: 0 | J29: 0
A30: Electricity | B30: =D169 -> 0 | C30: 0 | D30: 0 | E30: =IF(E47<>0,$G$169,0) -> 0.043918811 | F30: 0.0432 | G30: 0.026879418 | H30: 0 | I30: 0 | J30: 0
A31: Gas | B31: =D170 -> 0 | C31: 0 | D31: 0 | E31: =IF(E47<>0,$G$170,0) -> 0.026 | F31: 0.019 | G31: 0.028567 | H31: =J170 -> 0 | I31: 0 | J31: 0
A32: R&M Supplies and Service | B32: =IF($B$47<>0,$H$177,0) -> 0 | C32: 0 | D32: 0 | E32: =IF(E47<>0,$H$177,0) -> 0.03 | F32: 0.0298 | G32: 0.027777778 | H32: 0 | I32: 0 | J32: 0
A33: Manufacturing Supplies | B33: =IF($B$47<>0,$H$181,0) -> 0 | C33: 0 | D33: 0 | E33: =IF(E47<>0,$H$181,0) -> 0.0055102041 | F33: 0.0012 | G33: 0.0069444444 | H33: 0 | I33: 0 | J33: 0
A34: Other variable | B34: =IF($B$47<>0,$H$184,0) -> 0 | C34: 0 | D34: 0 | E34: =IF(E47<>0,$H$184,0) -> 0.01122449 | F34: 0.0139 | G34: 0.0125 | H34: 0 | I34: 0 | J34: 0
A35: Total Variable Costs | B35: =SUM(B29:B34) -> 0.065965818 | C35: =SUM(C29:C34) -> 0 | D35: =SUM(D29:D34) -> 0 | E35: =SUM(E29:E34) -> 0.18750634 | F35: =SUM(F29:F34) -> 0.1851 | G35: =SUM(G29:G34) -> 0.16292832 | H35: =SUM(H29:H34) -> 0 | I35: =SUM(I29:I34) -> 0 | J35: =SUM(J29:J34) -> 0
A37: Production Labor | B37: =$D$124*$E$108/$B$49/1000 -> 0.00013061064 | C37: 0 | D37: 0 | E37: =IF($E$47<>0,$F$127/$E$47/1000,0) -> 0.040001507 | F37: 0.0353 | G37: 0.02156921 | H37: 0 | I37: 0 | J37: 0
A38: Repairs & Maintenance Labor | B38: =$H$124*$E$108/$B$49/1000 -> 0 | C38: 0 | D38: 0 | E38: =IF($E$47<>0,$F$128/$E$47/1000,0) -> 0.0048061173 | F38: 0.0067 | G38: 0.0051700857 | H38: 0 | I38: 0 | J38: 0
A39: Indirect Payroll Costs (Benefits) | B39: =$D$131*$E$108/$B$49/1000 -> 0 | C39: 0 | D39: 0 | E39: =IF($E$47<>0,$F$130/$E$47/1000,0) -> 0.012994211 | F39: 0.0112 | G39: 0.0080162316 | H39: 0 | I39: 0 | J39: 0
A40: Supervision | B40: =IF($B$49<>0,$F$194,0) -> 0 | C40: 0 | D40: 0 | E40: =IF($E$47<>0,$F$129/$E$47/1000,0) -> 0 | F40: 0 | G40: 0.00047638889 | H40: 0 | I40: 0 | J40: 0
A41: Depreciation | B41: =IF($B$49<>0,$F$196,0) -> 0.0078437536 | C41: 0 | D41: 0 | E41: =IF($E$47<>0,$B$196/$B$49/1000/4,0) -> 0.00016341153 | F41: 0.0085 | G41: 0.0056777778 | H41: 0 | I41: 0 | J41: 0
A42: Insurance & Taxes | B42: =IF($B$49<>0,$F$195,0) -> 0.032905444 | C42: 0 | D42: 0 | E42: =IF($E$47<>0,$B$195/$B$49/1000/4,0) -> 0.00068553009 | F42: 0.0362 | G42: 0.025861111 | H42: 0 | I42: 0 | J42: 0
A43: Total Fixed Costs | B43: =SUM(B37:B42) -> 0.040879808 | C43: =SUM(C37:C42) -> 0 | D43: =SUM(D37:D42) -> 0 | E43: =SUM(E37:E42) -> 0.058650778 | F43: =SUM(F37:F42) -> 0.0979 | G43: =SUM(G37:G42) -> 0.066770805 | H43: =SUM(H37:H42) -> 0 | I43: =SUM(I37:I42) -> 0 | J43: =SUM(J37:J42) -> 0
A44: Excess Costs | F44: -0.0455
A45: TOTAL COSTS PER POUND | B45: =B35+B43 -> 0.10684563 | C45: =C35+C43 -> 0 | D45: 0.19962946 | E45: =E35+E43+E44 -> 0.24615711 | F45: =F35+F43+F44 -> 0.2375 | G45: =+G35+G43 -> 0.22969913 | H45: =H35+H43 -> 0 | I45: =I35+I43 -> 0 | J45: =J35+J43 -> 0 | L45: =E45-0.245 -> 0.0011571148 | M45: =E47*1000*L45 -> 5669.8624
M46: =M45/12 -> 472.48853
...

Sheet May
A1: TOOMSBORO STANDARD 2025
B3: CERAMICS | E3: CG 280 | H3: CG 300
B4: 25 Standard | C4: 23 Actual | D4: 20 Standard | E4: =$B$4 -> 25 Standard | F4: =+C4 -> 23 Actual | G4: =+D4 -> 20 Standard | H4: =+B4 -> 25 Standard | I4: =+C4 -> 23 Actual | J4: =+D4 -> 20 Standard
C5: (Jan-Sept) | F5: (Jan-Sept) | I5: (Jan-Sept)
A6: Materials | B6: =IF(B24<>0,$D$82,0) -> 0 | C6: 0.0585 | D6: 0.04156581 | E6: =+H82 -> 0 | F6: 0 | G6: 0 | H6: =+D96 -> 0 | I6: 0 | J6: 0
A7: Electricity | B7: =IF(B24<>0,$D$163,0) -> 0 | C7: 0.0105 | D7: 0.020277329 | E7: =G163 -> 0.0198372 | F7: 0 | G7: 0 | H7: =J163 -> 0.0198372 | I7: 0 | J7: 0
A8: Gas | B8: =IF(B24<>0,$D$164,0) -> 0 | C8: 0.0156 | D8: 0.014965 | E8: =G164 -> 0.0171 | F8: 0 | G8: 0 | H8: =J164 -> 0.0171 | I8: 0 | J8: 0
A9: R&M Supplies and Service | B9: =IF(B24<>0,$J$177,0) -> 0 | C9: 0.0192 | D9: 0.015915789 | E9: =$H$177 -> 0.03 | F9: 0 | G9: 0 | H9: =$H$177 -> 0.03 | I9: 0 | J9: 0
A10: Manufacturing Supplies | B10: =IF(B24<>0,$J$181,0) -> 0 | C10: 0.0008 | D10: 0.0026315789 | E10: =$H$181 -> 0.0055102041 | F10: 0 | G10: 0 | H10: =$H$181 -> 0.0055102041 | I10: 0 | J10: 0
A11: Other variable | B11: =IF(B24<>0,$J$184,0) -> 0 | C11: 0.0058 | D11: 0.0094736842 | E11: =$H$184 -> 0.01122449 | F11: 0 | G11: 0 | H11: =$H$184 -> 0.01122449 | I11: 0 | J11: 0
A12: Total Variable Costs | B12: =SUM(B6:B11) -> 0 | C12: =SUM(C6:C11) -> 0.1104 | D12: =SUM(D6:D11) -> 0.10482919 | E12: =SUM(E6:E11) -> 0.083671894 | F12: =SUM(F6:F11) -> 0 | G12: =SUM(G6:G11) -> 0 | H12: =SUM(H6:H11) -> 0.083671894 | I12: =SUM(I6:I11) -> 0 | J12: =SUM(J6:J11) -> 0
A14: Production Labor | B14: =IF($B$24<>0,$F$152/B24/1000,0) -> 0 | C14: 0.0246 | D14: 0.0073599375 | E14: =$D$124*$E$108/$B$49/1000 -> 0.00093026761 | F14: 0 | G14: 0 | H14: =$D$124*$E$108/$B$49/1000 -> 0.00093026761 | I14: 0 | J14: 0
A15: Repairs & Maintenance Labor | B15: =IF($B$24<>0,$F$153/$B$24/1000,0) -> 0 | C15: 0.009 | D15: 0.0042419375 | E15: =$H$124*$E$108/$B$49/1000 -> 0 | F15: 0 | G15: 0 | H15: =$H$124*$E$108/$B$49/1000 -> 0 | I15: 0 | J15: 0
A16: Indirect Payroll Costs (Benefits) | B16: =IF($B$24<>0,$F$155/$B$24/1000,0) -> 0 | C16: 0.0079 | D16: 0.0053897125 | E16: =$D$131*$E$108/$B$49/1000 -> 0 | F16: 0 | G16: 0 | H16: =$D$131*$E$108/$B$49/1000 -> 0 | I16: 0 | J16: 0
A17: Supervision | B17: =IF($B$24<>0,$F$154/$B$24/1000,0) -> 0 | C17: 0 | D17: 0.0026778947 | E17: =$F$194 -> 0 | F17: 0 | G17: 0 | H17: =$F$194 -> 0 | I17: 0 | J17: 0
A18: Depreciation | B18: =IF($B$24<>0,$B$196/$B$49/1000,0) -> 0 | C18: 0.0027 | D18: 0.1672 | E18: =$F$196 -> 0.055866735 | F18: 0 | G18: 0 | H18: =$F$196 -> 0.055866735 | I18: 0 | J18: 0
A19: Insurance & Taxes | B19: =IF($B$24<>0,$B$195/$B$49/1000,0) -> 0 | C19: 0.012 | D19: 0.012884211 | E19: =$F$195 -> 0.23436735 | F19: 0 | G19: 0 | H19: =$F$195 -> 0.23436735 | I19: 0 | J19: 0
A20: Total Fixed Costs | B20: =SUM(B14:B19) -> 0 | C20: =SUM(C14:C19) -> 0.0562 | D20: =SUM(D14:D19) -> 0.19975369 | E20: =SUM(E14:E19) -> 0.29116435 | F20: =SUM(F14:F19) -> 0 | G20: =SUM(G14:G19) -> 0 | H20: =SUM(H14:H19) -> 0.29116435 | I20: =SUM(I14:I19) -> 0 | J20: =SUM(J14:J19) -> 0
A22: TOTAL COSTS PER POUND | B22: =B12+B20 -> 0 | C22: =C12+C20 -> 0.1666 | D22: =D12+D20 -> 0.30458288 | E22: =E12+E20 -> 0.37483624 | F22: =F12+F20 -> 0 | G22: =G12+G20 -> 0 | H22: =H12+H20 -> 0.37483624 | I22: =I12+I20 -> 0 | J22: =J12+J20 -> 0
A24: PRODUCTION ( in 000 lbs ) | B24: =+B54 -> 0 | C24: 0 | D24: 80000 | E24: =+B55 -> 0 | F24: 0 | G24: 0 | H24: =+B56 -> 0 | I24: 0 | J24: 0
B26: XXX | E26: HA PELLETS
B27: =$B$4 -> 25 Standard | C27: =+C4 -> 23 Actual | D27: =+D4 -> 20 Standard | E27: 24 Standard | F27: 23 Actual | G27: 22 Standard | H27: =+B27 -> 25 Standard | I27: =+C27 -> 23 Actual | J27: =+D27 -> 20 Standard
C28: (Jan-Sept) | F28: (Jan-Aug)
A29: Materials | B29: =D82 -> 0.065965818 | C29: 0 | D29: 0 | E29: =IF(E47<>0,$L$96,0) -> 0.070852832 | F29: 0.078 | G29: 0.06025968 | H29: 0 | I29: 0 | J29: 0
A30: Electricity | B30: =D169 -> 0 | C30: 0 | D30: 0 | E30: =IF(E47<>0,$G$169,0) -> 0.043918811 | F30: 0.0432 | G30: 0.026879418 | H30: 0 | I30: 0 | J30: 0
A31: Gas | B31: =D170 -> 0 | C31: 0 | D31: 0 | E31: =IF(E47<>0,$G$170,0) -> 0.026 | F31: 0.019 | G31: 0.028567 | H31: =J170 -> 0 | I31: 0 | J31: 0
A32: R&M Supplies and Service | B32: =IF($B$47<>0,$H$177,0) -> 0 | C32: 0 | D32: 0 | E32: =IF(E47<>0,$H$177,0) -> 0.03 | F32: 0.0298 | G32: 0.027777778 | H32: 0 | I32: 0 | J32: 0
A33: Manufacturing Supplies | B33: =IF($B$47<>0,$H$181,0) -> 0 | C33: 0 | D33: 0 | E33: =IF(E47<>0,$H$181,0) -> 0.0055102041 | F33: 0.0012 | G33: 0.0069444444 | H33: 0 | I33: 0 | J33: 0
A34: Other variable | B34: =IF($B$47<>0,$H$184,0) -> 0 | C34: 0 | D34: 0 | E34: =IF(E47<>0,$H$184,0) -> 0.01122449 | F34: 0.0139 | G34: 0.0125 | H34: 0 | I34: 0 | J34: 0
A35: Total Variable Costs | B35: =SUM(B29:B34) -> 0.065965818 | C35: =SUM(C29:C34) -> 0 | D35: =SUM(D29:D34) -> 0 | E35: =SUM(E29:E34) -> 0.18750634 | F35: =SUM(F29:F34) -> 0.1851 | G35: =SUM(G29:G34) -> 0.16292832 | H35: =SUM(H29:H34) -> 0 | I35: =SUM(I29:I34) -> 0 | J35: =SUM(J29:J34) -> 0
A37: Production Labor | B37: =$D$124*$E$108/$B$49/1000 -> 0.00093026761 | C37: 0 | D37: 0 | E37: =IF($E$47<>0,$F$127/$E$47/1000,0) -> 0.040001507 | F37: 0.0353 | G37: 0.02156921 | H37: 0 | I37: 0 | J37: 0
A38: Repairs & Maintenance Labor | B38: =$H$124*$E$108/$B$49/1000 -> 0 | C38: 0 | D38: 0 | E38: =IF($E$47<>0,$F$128/$E$47/1000,0) -> 0.0048061173 | F38: 0.0067 | G38: 0.0051700857 | H38: 0 | I38: 0 | J38: 0
A39: Indirect Payroll Costs (Benefits) | B39: =$D$131*$E$108/$B$49/1000 -> 0 | C39: 0 | D39: 0 | E39: =IF($E$47<>0,$F$130/$E$47/1000,0) -> 0.012994211 | F39: 0.0112 | G39: 0.0080162316 | H39: 0 | I39: 0 | J39: 0
A40: Supervision | B40: =IF($B$49<>0,$F$194,0) -> 0 | C40: 0 | D40: 0 | E40: =IF($E$47<>0,$F$129/$E$47/1000,0) -> 0 | F40: 0 | G40: 0.00047638889 | H40: 0 | I40: 0 | J40: 0
A41: Depreciation | B41: =IF($B$49<>0,$F$196,0) -> 0.055866735 | C41: 0 | D41: 0 | E41: =IF($E$47<>0,$B$196/$B$49/1000/4,0) -> 0.0011638903 | F41: 0.0085 | G41: 0.0056777778 | H41: 0 | I41: 0 | J41: 0
A42: Insurance & Taxes | B42: =IF($B$49<>0,$F$195,0) -> 0.23436735 | C42: 0 | D42: 0 | E42: =IF($E$47<>0,$B$195/$B$49/1000/4,0) -> 0.0048826531 | F42: 0.0362 | G42: 0.025861111 | H42: 0 | I42: 0 | J42: 0
A43: Total Fixed Costs | B43: =SUM(B37:B42) -> 0.29116435 | C43: =SUM(C37:C42) -> 0 | D43: =SUM(D37:D42) -> 0 | E43: =SUM(E37:E42) -> 0.063848379 | F43: =SUM(F37:F42) -> 0.0979 | G43: =SUM(G37:G42) -> 0.066770805 | H43: =SUM(H37:H42) -> 0 | I43: =SUM(I37:I42) -> 0 | J43: =SUM(J37:J42) -> 0
A44: Excess Costs | F44: -0.0455
A45: TOTAL COSTS PER POUND | B45: =B35+B43 -> 0.35713017 | C45: =C35+C43 -> 0 | D45: 0.19962946 | E45: =E35+E43+E44 -> 0.25135472 | F45: =F35+F43+F44 -> 0.2375 | G45: =+G35+G43 -> 0.22969913 | H45: =H35+H43 -> 0 | I45: =I35+I43 -> 0 | J45: =J35+J43 -> 0 | L45: =E45-0.245 -> 0.0063547165 | M45: =E47*1000*L45 -> 31138.111
M46: =M45/12 -> 2594.8426
...

Sheet Jun
A1: TOOMSBORO STANDARD 2025
B3: CERAMICS | E3: CG 280 | H3: CG 300
B4: 25 Standard | C4: 23 Actual | D4: 20 Standard | E4: =$B$4 -> 25 Standard | F4: =+C4 -> 23 Actual | G4: =+D4 -> 20 Standard | H4: =+B4 -> 25 Standard | I4: =+C4 -> 23 Actual | J4: =+D4 -> 20 Standard
C5: (Jan-Sept) | F5: (Jan-Sept) | I5: (Jan-Sept)
A6: Materials | B6: =IF(B24<>0,$D$82,0) -> 0 | C6: 0.0585 | D6: 0.04156581 | E6: =+H82 -> 0 | F6: 0 | G6: 0 | H6: =+D96 -> 0 | I6: 0 | J6: 0
A7: Electricity | B7: =IF(B24<>0,$D$163,0) -> 0 | C7: 0.0105 | D7: 0.020277329 | E7: =G163 -> 0.0198372 | F7: 0 | G7: 0 | H7: =J163 -> 0.0198372 | I7: 0 | J7: 0
A8: Gas | B8: =IF(B24<>0,$D$164,0) -> 0 | C8: 0.0156 | D8: 0.014965 | E8: =G164 -> 0.0171 | F8: 0 | G8: 0 | H8: =J164 -> 0.0171 | I8: 0 | J8: 0
A9: R&M Supplies and Service | B9: =IF(B24<>0,$J$177,0) -> 0 | C9: 0.0192 | D9: 0.015915789 | E9: =$H$177 -> 0.03 | F9: 0 | G9: 0 | H9: =$H$177 -> 0.03 | I9: 0 | J9: 0
A10: Manufacturing Supplies | B10: =IF(B24<>0,$J$181,0) -> 0 | C10: 0.0008 | D10: 0.0026315789 | E10: =$H$181 -> 0.0055102041 | F10: 0 | G10: 0 | H10: =$H$181 -> 0.0055102041 | I10: 0 | J10: 0
A11: Other variable | B11: =IF(B24<>0,$J$184,0) -> 0 | C11: 0.0058 | D11: 0.0094736842 | E11: =$H$184 -> 0.01122449 | F11: 0 | G11: 0 | H11: =$H$184 -> 0.01122449 | I11: 0 | J11: 0
A12: Total Variable Costs | B12: =SUM(B6:B11) -> 0 | C12: =SUM(C6:C11) -> 0.1104 | D12: =SUM(D6:D11) -> 0.10482919 | E12: =SUM(E6:E11) -> 0.083671894 | F12: =SUM(F6:F11) -> 0 | G12: =SUM(G6:G11) -> 0 | H12: =SUM(H6:H11) -> 0.083671894 | I12: =SUM(I6:I11) -> 0 | J12: =SUM(J6:J11) -> 0
A14: Production Labor | B14: =IF($B$24<>0,$F$152/B24/1000,0) -> 0 | C14: 0.0246 | D14: 0.0073599375 | E14: =$D$124*$E$108/$B$49/1000 -> 0.00093026761 | F14: 0 | G14: 0 | H14: =$D$124*$E$108/$B$49/1000 -> 0.00093026761 | I14: 0 | J14: 0
A15: Repairs & Maintenance Labor | B15: =IF($B$24<>0,$F$153/$B$24/1000,0) -> 0 | C15: 0.009 | D15: 0.0042419375 | E15: =$H$124*$E$108/$B$49/1000 -> 0 | F15: 0 | G15: 0 | H15: =$H$124*$E$108/$B$49/1000 -> 0 | I15: 0 | J15: 0
A16: Indirect Payroll Costs (Benefits) | B16: =IF($B$24<>0,$F$155/$B$24/1000,0) -> 0 | C16: 0.0079 | D16: 0.0053897125 | E16: =$D$131*$E$108/$B$49/1000 -> 0 | F16: 0 | G16: 0 | H16: =$D$131*$E$108/$B$49/1000 -> 0 | I16: 0 | J16: 0
A17: Supervision | B17: =IF($B$24<>0,$F$154/$B$24/1000,0) -> 0 | C17: 0 | D17: 0.0026778947 | E17: =$F$194 -> 0 | F17: 0 | G17: 0 | H17: =$F$194 -> 0 | I17: 0 | J17: 0
A18: Depreciation | B18: =IF($B$24<>0,$B$196/$B$49/1000,0) -> 0 | C18: 0.0027 | D18: 0.1672 | E18: =$F$196 -> 0.055866735 | F18: 0 | G18: 0 | H18: =$F$196 -> 0.055866735 | I18: 0 | J18: 0
A19: Insurance & Taxes | B19: =IF($B$24<>0,$B$195/$B$49/1000,0) -> 0 | C19: 0.012 | D19: 0.012884211 | E19: =$F$195 -> 0.23436735 | F19: 0 | G19: 0 | H19: =$F$195 -> 0.23436735 | I19: 0 | J19: 0
A20: Total Fixed Costs | B20: =SUM(B14:B19) -> 0 | C20: =SUM(C14:C19) -> 0.0562 | D20: =SUM(D14:D19) -> 0.19975369 | E20: =SUM(E14:E19) -> 0.29116435 | F20: =SUM(F14:F19) -> 0 | G20: =SUM(G14:G19) -> 0 | H20: =SUM(H14:H19) -> 0.29116435 | I20: =SUM(I14:I19) -> 0 | J20: =SUM(J14:J19) -> 0
A22: TOTAL COSTS PER POUND | B22: =B12+B20 -> 0 | C22: =C12+C20 -> 0.1666 | D22: =D12+D20 -> 0.30458288 | E22: =E12+E20 -> 0.37483624 | F22: =F12+F20 -> 0 | G22: =G12+G20 -> 0 | H22: =H12+H20 -> 0.37483624 | I22: =I12+I20 -> 0 | J22: =J12+J20 -> 0
A24: PRODUCTION ( in 000 lbs ) | B24: =+B54 -> 0 | C24: 0 | D24: 80000 | E24: =+B55 -> 0 | F24: 0 | G24: 0 | H24: =+B56 -> 0 | I24: 0 | J24: 0
B26: XXX | E26: HA PELLETS
B27: =$B$4 -> 25 Standard | C27: =+C4 -> 23 Actual | D27: =+D4 -> 20 Standard | E27: 24 Standard | F27: 23 Actual | G27: 22 Standard | H27: =+B27 -> 25 Standard | I27: =+C27 -> 23 Actual | J27: =+D27 -> 20 Standard
C28: (Jan-Sept) | F28: (Jan-Aug)
A29: Materials | B29: =D82 -> 0.065965818 | C29: 0 | D29: 0 | E29: =IF(E47<>0,$L$96,0) -> 0.070852832 | F29: 0.078 | G29: 0.06025968 | H29: 0 | I29: 0 | J29: 0
A30: Electricity | B30: =D169 -> 0 | C30: 0 | D30: 0 | E30: =IF(E47<>0,$G$169,0) -> 0.043918811 | F30: 0.0432 | G30: 0.026879418 | H30: 0 | I30: 0 | J30: 0
A31: Gas | B31: =D170 -> 0 | C31: 0 | D31: 0 | E31: =IF(E47<>0,$G$170,0) -> 0.026 | F31: 0.019 | G31: 0.028567 | H31: =J170 -> 0 | I31: 0 | J31: 0
A32: R&M Supplies and Service | B32: =IF($B$47<>0,$H$177,0) -> 0 | C32: 0 | D32: 0 | E32: =IF(E47<>0,$H$177,0) -> 0.03 | F32: 0.0298 | G32: 0.027777778 | H32: 0 | I32: 0 | J32: 0
A33: Manufacturing Supplies | B33: =IF($B$47<>0,$H$181,0) -> 0 | C33: 0 | D33: 0 | E33: =IF(E47<>0,$H$181,0) -> 0.0055102041 | F33: 0.0012 | G33: 0.0069444444 | H33: 0 | I33: 0 | J33: 0
A34: Other variable | B34: =IF($B$47<>0,$H$184,0) -> 0 | C34: 0 | D34: 0 | E34: =IF(E47<>0,$H$184,0) -> 0.01122449 | F34: 0.0139 | G34: 0.0125 | H34: 0 | I34: 0 | J34: 0
A35: Total Variable Costs | B35: =SUM(B29:B34) -> 0.065965818 | C35: =SUM(C29:C34) -> 0 | D35: =SUM(D29:D34) -> 0 | E35: =SUM(E29:E34) -> 0.18750634 | F35: =SUM(F29:F34) -> 0.1851 | G35: =SUM(G29:G34) -> 0.16292832 | H35: =SUM(H29:H34) -> 0 | I35: =SUM(I29:I34) -> 0 | J35: =SUM(J29:J34) -> 0
A37: Production Labor | B37: =$D$124*$E$108/$B$49/1000 -> 0.00093026761 | C37: 0 | D37: 0 | E37: =IF($E$47<>0,$F$127/$E$47/1000,0) -> 0.040001507 | F37: 0.0353 | G37: 0.02156921 | H37: 0 | I37: 0 | J37: 0
A38: Repairs & Maintenance Labor | B38: =$H$124*$E$108/$B$49/1000 -> 0 | C38: 0 | D38: 0 | E38: =IF($E$47<>0,$F$128/$E$47/1000,0) -> 0.0048061173 | F38: 0.0067 | G38: 0.0051700857 | H38: 0 | I38: 0 | J38: 0
A39: Indirect Payroll Costs (Benefits) | B39: =$D$131*$E$108/$B$49/1000 -> 0 | C39: 0 | D39: 0 | E39: =IF($E$47<>0,$F$130/$E$47/1000,0) -> 0.012994211 | F39: 0.0112 | G39: 0.0080162316 | H39: 0 | I39: 0 | J39: 0
A40: Supervision | B40: =IF($B$49<>0,$F$194,0) -> 0 | C40: 0 | D40: 0 | E40: =IF($E$47<>0,$F$129/$E$47/1000,0) -> 0 | F40: 0 | G40: 0.00047638889 | H40: 0 | I40: 0 | J40: 0
A41: Depreciation | B41: =IF($B$49<>0,$F$196,0) -> 0.055866735 | C41: 0 | D41: 0 | E41: =IF($E$47<>0,$B$196/$B$49/1000/4,0) -> 0.0011638903 | F41: 0.0085 | G41: 0.0056777778 | H41: 0 | I41: 0 | J41: 0
A42: Insurance & Taxes | B42: =IF($B$49<>0,$F$195,0) -> 0.23436735 | C42: 0 | D42: 0 | E42: =IF($E$47<>0,$B$195/$B$49/1000/4,0) -> 0.0048826531 | F42: 0.0362 | G42: 0.025861111 | H42: 0 | I42: 0 | J42: 0
A43: Total Fixed Costs | B43: =SUM(B37:B42) -> 0.29116435 | C43: =SUM(C37:C42) -> 0 | D43: =SUM(D37:D42) -> 0 | E43: =SUM(E37:E42) -> 0.063848379 | F43: =SUM(F37:F42) -> 0.0979 | G43: =SUM(G37:G42) -> 0.066770805 | H43: =SUM(H37:H42) -> 0 | I43: =SUM(I37:I42) -> 0 | J43: =SUM(J37:J42) -> 0
A44: Excess Costs | F44: -0.0455
A45: TOTAL COSTS PER POUND | B45: =B35+B43 -> 0.35713017 | C45: =C35+C43 -> 0 | D45: 0.19962946 | E45: =E35+E43+E44 -> 0.25135472 | F45: =F35+F43+F44 -> 0.2375 | G45: =+G35+G43 -> 0.22969913 | H45: =H35+H43 -> 0 | I45: =I35+I43 -> 0 | J45: =J35+J43 -> 0 | L45: =E45-0.245 -> 0.0063547165 | M45: =E47*1000*L45 -> 31138.111
M46: =M45/12 -> 2594.8426
...

Sheet Jul
A1: TOOMSBORO STANDARD 2025
B3: CERAMICS | E3: CG 280 | H3: CG 300
B4: 25 Standard | C4: 23 Actual | D4: 20 Standard | E4: =$B$4 -> 25 Standard | F4: =+C4 -> 23 Actual | G4: =+D4 -> 20 Standard | H4: =+B4 -> 25 Standard | I4: =+C4 -> 23 Actual | J4: =+D4 -> 20 Standard
C5: (Jan-Sept) | F5: (Jan-Sept) | I5: (Jan-Sept)
A6: Materials | B6: =IF(B24<>0,$D$82,0) -> 0 | C6: 0.0585 | D6: 0.04156581 | E6: =+H82 -> 0 | F6: 0 | G6: 0 | H6: =+D96 -> 0 | I6: 0 | J6: 0
A7: Electricity | B7: =IF(B24<>0,$D$163,0) -> 0 | C7: 0.0105 | D7: 0.020277329 | E7: =G163 -> 0.0198372 | F7: 0 | G7: 0 | H7: =J163 -> 0.0198372 | I7: 0 | J7: 0
A8: Gas | B8: =IF(B24<>0,$D$164,0) -> 0 | C8: 0.0156 | D8: 0.014965 | E8: =G164 -> 0.0171 | F8: 0 | G8: 0 | H8: =J164 -> 0.0171 | I8: 0 | J8: 0
A9: R&M Supplies and Service | B9: =IF(B24<>0,$J$177,0) -> 0 | C9: 0.0192 | D9: 0.015915789 | E9: =$H$177 -> 0.03 | F9: 0 | G9: 0 | H9: =$H$177 -> 0.03 | I9: 0 | J9: 0
A10: Manufacturing Supplies | B10: =IF(B24<>0,$J$181,0) -> 0 | C10: 0.0008 | D10: 0.0026315789 | E10: =$H$181 -> 0.0055102041 | F10: 0 | G10: 0 | H10: =$H$181 -> 0.0055102041 | I10: 0 | J10: 0
A11: Other variable | B11: =IF(B24<>0,$J$184,0) -> 0 | C11: 0.0058 | D11: 0.0094736842 | E11: =$H$184 -> 0.01122449 | F11: 0 | G11: 0 | H11: =$H$184 -> 0.01122449 | I11: 0 | J11: 0
A12: Total Variable Costs | B12: =SUM(B6:B11) -> 0 | C12: =SUM(C6:C11) -> 0.1104 | D12: =SUM(D6:D11) -> 0.10482919 | E12: =SUM(E6:E11) -> 0.083671894 | F12: =SUM(F6:F11) -> 0 | G12: =SUM(G6:G11) -> 0 | H12: =SUM(H6:H11) -> 0.083671894 | I12: =SUM(I6:I11) -> 0 | J12: =SUM(J6:J11) -> 0
A14: Production Labor | B14: =IF($B$24<>0,$F$152/B24/1000,0) -> 0 | C14: 0.0246 | D14: 0.0073599375 | E14: =$D$124*$E$108/$B$49/1000 -> 0.00093026761 | F14: 0 | G14: 0 | H14: =$D$124*$E$108/$B$49/1000 -> 0.00093026761 | I14: 0 | J14: 0
A15: Repairs & Maintenance Labor | B15: =IF($B$24<>0,$F$153/$B$24/1000,0) -> 0 | C15: 0.009 | D15: 0.0042419375 | E15: =$H$124*$E$108/$B$49/1000 -> 0 | F15: 0 | G15: 0 | H15: =$H$124*$E$108/$B$49/1000 -> 0 | I15: 0 | J15: 0
A16: Indirect Payroll Costs (Benefits) | B16: =IF($B$24<>0,$F$155/$B$24/1000,0) -> 0 | C16: 0.0079 | D16: 0.0053897125 | E16: =$D$131*$E$108/$B$49/1000 -> 0 | F16: 0 | G16: 0 | H16: =$D$131*$E$108/$B$49/1000 -> 0 | I16: 0 | J16: 0
A17: Supervision | B17: =IF($B$24<>0,$F$154/$B$24/1000,0) -> 0 | C17: 0 | D17: 0.0026778947 | E17: =$F$194 -> 0 | F17: 0 | G17: 0 | H17: =$F$194 -> 0 | I17: 0 | J17: 0
A18: Depreciation | B18: =IF($B$24<>0,$B$196/$B$49/1000,0) -> 0 | C18: 0.0027 | D18: 0.1672 | E18: =$F$196 -> 0.055866735 | F18: 0 | G18: 0 | H18: =$F$196 -> 0.055866735 | I18: 0 | J18: 0
A19: Insurance & Taxes | B19: =IF($B$24<>0,$B$195/$B$49/1000,0) -> 0 | C19: 0.012 | D19: 0.012884211 | E19: =$F$195 -> 0.23436735 | F19: 0 | G19: 0 | H19: =$F$195 -> 0.23436735 | I19: 0 | J19: 0
A20: Total Fixed Costs | B20: =SUM(B14:B19) -> 0 | C20: =SUM(C14:C19) -> 0.0562 | D20: =SUM(D14:D19) -> 0.19975369 | E20: =SUM(E14:E19) -> 0.29116435 | F20: =SUM(F14:F19) -> 0 | G20: =SUM(G14:G19) -> 0 | H20: =SUM(H14:H19) -> 0.29116435 | I20: =SUM(I14:I19) -> 0 | J20: =SUM(J14:J19) -> 0
A22: TOTAL COSTS PER POUND | B22: =B12+B20 -> 0 | C22: =C12+C20 -> 0.1666 | D22: =D12+D20 -> 0.30458288 | E22: =E12+E20 -> 0.37483624 | F22: =F12+F20 -> 0 | G22: =G12+G20 -> 0 | H22: =H12+H20 -> 0.37483624 | I22: =I12+I20 -> 0 | J22: =J12+J20 -> 0
A24: PRODUCTION ( in 000 lbs ) | B24: =+B54 -> 0 | C24: 0 | D24: 80000 | E24: =+B55 -> 0 | F24: 0 | G24: 0 | H24: =+B56 -> 0 | I24: 0 | J24: 0
B26: XXX | E26: HA PELLETS
B27: =$B$4 -> 25 Standard | C27: =+C4 -> 23 Actual | D27: =+D4 -> 20 Standard | E27: 24 Standard | F27: 23 Actual | G27: 22 Standard | H27: =+B27 -> 25 Standard | I27: =+C27 -> 23 Actual | J27: =+D27 -> 20 Standard
C28: (Jan-Sept) | F28: (Jan-Aug)
A29: Materials | B29: =D82 -> 0.065965818 | C29: 0 | D29: 0 | E29: =IF(E47<>0,$L$96,0) -> 0.070852832 | F29: 0.078 | G29: 0.06025968 | H29: 0 | I29: 0 | J29: 0
A30: Electricity | B30: =D169 -> 0 | C30: 0 | D30: 0 | E30: =IF(E47<>0,$G$169,0) -> 0.043918811 | F30: 0.0432 | G30: 0.026879418 | H30: 0 | I30: 0 | J30: 0
A31: Gas | B31: =D170 -> 0 | C31: 0 | D31: 0 | E31: =IF(E47<>0,$G$170,0) -> 0.026 | F31: 0.019 | G31: 0.028567 | H31: =J170 -> 0 | I31: 0 | J31: 0
A32: R&M Supplies and Service | B32: =IF($B$47<>0,$H$177,0) -> 0 | C32: 0 | D32: 0 | E32: =IF(E47<>0,$H$177,0) -> 0.03 | F32: 0.0298 | G32: 0.027777778 | H32: 0 | I32: 0 | J32: 0
A33: Manufacturing Supplies | B33: =IF($B$47<>0,$H$181,0) -> 0 | C33: 0 | D33: 0 | E33: =IF(E47<>0,$H$181,0) -> 0.0055102041 | F33: 0.0012 | G33: 0.0069444444 | H33: 0 | I33: 0 | J33: 0
A34: Other variable | B34: =IF($B$47<>0,$H$184,0) -> 0 | C34: 0 | D34: 0 | E34: =IF(E47<>0,$H$184,0) -> 0.01122449 | F34: 0.0139 | G34: 0.0125 | H34: 0 | I34: 0 | J34: 0
A35: Total Variable Costs | B35: =SUM(B29:B34) -> 0.065965818 | C35: =SUM(C29:C34) -> 0 | D35: =SUM(D29:D34) -> 0 | E35: =SUM(E29:E34) -> 0.18750634 | F35: =SUM(F29:F34) -> 0.1851 | G35: =SUM(G29:G34) -> 0.16292832 | H35: =SUM(H29:H34) -> 0 | I35: =SUM(I29:I34) -> 0 | J35: =SUM(J29:J34) -> 0
A37: Production Labor | B37: =$D$124*$E$108/$B$49/1000 -> 0.00093026761 | C37: 0 | D37: 0 | E37: =IF($E$47<>0,$F$127/$E$47/1000,0) -> 0.040001507 | F37: 0.0353 | G37: 0.02156921 | H37: 0 | I37: 0 | J37: 0
A38: Repairs & Maintenance Labor | B38: =$H$124*$E$108/$B$49/1000 -> 0 | C38: 0 | D38: 0 | E38: =IF($E$47<>0,$F$128/$E$47/1000,0) -> 0.0048061173 | F38: 0.0067 | G38: 0.0051700857 | H38: 0 | I38: 0 | J38: 0
A39: Indirect Payroll Costs (Benefits) | B39: =$D$131*$E$108/$B$49/1000 -> 0 | C39: 0 | D39: 0 | E39: =IF($E$47<>0,$F$130/$E$47/1000,0) -> 0.012994211 | F39: 0.0112 | G39: 0.0080162316 | H39: 0 | I39: 0 | J39: 0
A40: Supervision | B40: =IF($B$49<>0,$F$194,0) -> 0 | C40: 0 | D40: 0 | E40: =IF($E$47<>0,$F$129/$E$47/1000,0) -> 0 | F40: 0 | G40: 0.00047638889 | H40: 0 | I40: 0 | J40: 0
A41: Depreciation | B41: =IF($B$49<>0,$F$196,0) -> 0.055866735 | C41: 0 | D41: 0 | E41: =IF($E$47<>0,$B$196/$B$49/1000/4,0) -> 0.0011638903 | F41: 0.0085 | G41: 0.0056777778 | H41: 0 | I41: 0 | J41: 0
A42: Insurance & Taxes | B42: =IF($B$49<>0,$F$195,0) -> 0.23436735 | C42: 0 | D42: 0 | E42: =IF($E$47<>0,$B$195/$B$49/1000/4,0) -> 0.0048826531 | F42: 0.0362 | G42: 0.025861111 | H42: 0 | I42: 0 | J42: 0
A43: Total Fixed Costs | B43: =SUM(B37:B42) -> 0.29116435 | C43: =SUM(C37:C42) -> 0 | D43: =SUM(D37:D42) -> 0 | E43: =SUM(E37:E42) -> 0.063848379 | F43: =SUM(F37:F42) -> 0.0979 | G43: =SUM(G37:G42) -> 0.066770805 | H43: =SUM(H37:H42) -> 0 | I43: =SUM(I37:I42) -> 0 | J43: =SUM(J37:J42) -> 0
A44: Excess Costs | F44: -0.0455
A45: TOTAL COSTS PER POUND | B45: =B35+B43 -> 0.35713017 | C45: =C35+C43 -> 0 | D45: 0.19962946 | E45: =E35+E43+E44 -> 0.25135472 | F45: =F35+F43+F44 -> 0.2375 | G45: =+G35+G43 -> 0.22969913 | H45: =H35+H43 -> 0 | I45: =I35+I43 -> 0 | J45: =J35+J43 -> 0 | L45: =E45-0.245 -> 0.0063547165 | M45: =E47*1000*L45 -> 31138.111
M46: =M45/12 -> 2594.8426
...

Sheet Aug
A1: TOOMSBORO STANDARD 2025
B3: CERAMICS | E3: CG 280 | H3: CG 300
B4: 25 Standard | C4: 23 Actual | D4: 20 Standard | E4: =$B$4 -> 25 Standard | F4: =+C4 -> 23 Actual | G4: =+D4 -> 20 Standard | H4: =+B4 -> 25 Standard | I4: =+C4 -> 23 Actual | J4: =+D4 -> 20 Standard
C5: (Jan-Sept) | F5: (Jan-Sept) | I5: (Jan-Sept)
A6: Materials | B6: =IF(B24<>0,$D$82,0) -> 0 | C6: 0.0585 | D6: 0.04156581 | E6: =+H82 -> 0 | F6: 0 | G6: 0 | H6: =+D96 -> 0 | I6: 0 | J6: 0
A7: Electricity | B7: =IF(B24<>0,$D$163,0) -> 0 | C7: 0.0105 | D7: 0.020277329 | E7: =G163 -> 0.0198372 | F7: 0 | G7: 0 | H7: =J163 -> 0.0198372 | I7: 0 | J7: 0
A8: Gas | B8: =IF(B24<>0,$D$164,0) -> 0 | C8: 0.0156 | D8: 0.014965 | E8: =G164 -> 0.0171 | F8: 0 | G8: 0 | H8: =J164 -> 0.0171 | I8: 0 | J8: 0
A9: R&M Supplies and Service | B9: =IF(B24<>0,$J$177,0) -> 0 | C9: 0.0192 | D9: 0.015915789 | E9: =$H$177 -> 0.03 | F9: 0 | G9: 0 | H9: =$H$177 -> 0.03 | I9: 0 | J9: 0
A10: Manufacturing Supplies | B10: =IF(B24<>0,$J$181,0) -> 0 | C10: 0.0008 | D10: 0.0026315789 | E10: =$H$181 -> 0.0055102041 | F10: 0 | G10: 0 | H10: =$H$181 -> 0.0055102041 | I10: 0 | J10: 0
A11: Other variable | B11: =IF(B24<>0,$J$184,0) -> 0 | C11: 0.0058 | D11: 0.0094736842 | E11: =$H$184 -> 0.01122449 | F11: 0 | G11: 0 | H11: =$H$184 -> 0.01122449 | I11: 0 | J11: 0
A12: Total Variable Costs | B12: =SUM(B6:B11) -> 0 | C12: =SUM(C6:C11) -> 0.1104 | D12: =SUM(D6:D11) -> 0.10482919 | E12: =SUM(E6:E11) -> 0.083671894 | F12: =SUM(F6:F11) -> 0 | G12: =SUM(G6:G11) -> 0 | H12: =SUM(H6:H11) -> 0.083671894 | I12: =SUM(I6:I11) -> 0 | J12: =SUM(J6:J11) -> 0
A14: Production Labor | B14: =IF($B$24<>0,$F$152/B24/1000,0) -> 0 | C14: 0.0246 | D14: 0.0073599375 | E14: =$D$124*$E$108/$B$49/1000 -> 0.00093026761 | F14: 0 | G14: 0 | H14: =$D$124*$E$108/$B$49/1000 -> 0.00093026761 | I14: 0 | J14: 0
A15: Repairs & Maintenance Labor | B15: =IF($B$24<>0,$F$153/$B$24/1000,0) -> 0 | C15: 0.009 | D15: 0.0042419375 | E15: =$H$124*$E$108/$B$49/1000 -> 0 | F15: 0 | G15: 0 | H15: =$H$124*$E$108/$B$49/1000 -> 0 | I15: 0 | J15: 0
A16: Indirect Payroll Costs (Benefits) | B16: =IF($B$24<>0,$F$155/$B$24/1000,0) -> 0 | C16: 0.0079 | D16: 0.0053897125 | E16: =$D$131*$E$108/$B$49/1000 -> 0 | F16: 0 | G16: 0 | H16: =$D$131*$E$108/$B$49/1000 -> 0 | I16: 0 | J16: 0
A17: Supervision | B17: =IF($B$24<>0,$F$154/$B$24/1000,0) -> 0 | C17: 0 | D17: 0.0026778947 | E17: =$F$194 -> 0 | F17: 0 | G17: 0 | H17: =$F$194 -> 0 | I17: 0 | J17: 0
A18: Depreciation | B18: =IF($B$24<>0,$B$196/$B$49/1000,0) -> 0 | C18: 0.0027 | D18: 0.1672 | E18: =$F$196 -> 0.055866735 | F18: 0 | G18: 0 | H18: =$F$196 -> 0.055866735 | I18: 0 | J18: 0
A19: Insurance & Taxes | B19: =IF($B$24<>0,$B$195/$B$49/1000,0) -> 0 | C19: 0.012 | D19: 0.012884211 | E19: =$F$195 -> 0.23436735 | F19: 0 | G19: 0 | H19: =$F$195 -> 0.23436735 | I19: 0 | J19: 0
A20: Total Fixed Costs | B20: =SUM(B14:B19) -> 0 | C20: =SUM(C14:C19) -> 0.0562 | D20: =SUM(D14:D19) -> 0.19975369 | E20: =SUM(E14:E19) -> 0.29116435 | F20: =SUM(F14:F19) -> 0 | G20: =SUM(G14:G19) -> 0 | H20: =SUM(H14:H19) -> 0.29116435 | I20: =SUM(I14:I19) -> 0 | J20: =SUM(J14:J19) -> 0
A22: TOTAL COSTS PER POUND | B22: =B12+B20 -> 0 | C22: =C12+C20 -> 0.1666 | D22: =D12+D20 -> 0.30458288 | E22: =E12+E20 -> 0.37483624 | F22: =F12+F20 -> 0 | G22: =G12+G20 -> 0 | H22: =H12+H20 -> 0.37483624 | I22: =I12+I20 -> 0 | J22: =J12+J20 -> 0
A24: PRODUCTION ( in 000 lbs ) | B24: =+B54 -> 0 | C24: 0 | D24: 80000 | E24: =+B55 -> 0 | F24: 0 | G24: 0 | H24: =+B56 -> 0 | I24: 0 | J24: 0
B26: XXX | E26: HA PELLETS
B27: =$B$4 -> 25 Standard | C27: =+C4 -> 23 Actual | D27: =+D4 -> 20 Standard | E27: 24 Standard | F27: 23 Actual | G27: 22 Standard | H27: =+B27 -> 25 Standard | I27: =+C27 -> 23 Actual | J27: =+D27 -> 20 Standard
C28: (Jan-Sept) | F28: (Jan-Aug)
A29: Materials | B29: =D82 -> 0.065965818 | C29: 0 | D29: 0 | E29: =IF(E47<>0,$L$96,0) -> 0.070852832 | F29: 0.078 | G29: 0.06025968 | H29: 0 | I29: 0 | J29: 0
A30: Electricity | B30: =D169 -> 0 | C30: 0 | D30: 0 | E30: =IF(E47<>0,$G$169,0) -> 0.043918811 | F30: 0.0432 | G30: 0.026879418 | H30: 0 | I30: 0 | J30: 0
A31: Gas | B31: =D170 -> 0 | C31: 0 | D31: 0 | E31: =IF(E47<>0,$G$170,0) -> 0.026 | F31: 0.019 | G31: 0.028567 | H31: =J170 -> 0 | I31: 0 | J31: 0
A32: R&M Supplies and Service | B32: =IF($B$47<>0,$H$177,0) -> 0 | C32: 0 | D32: 0 | E32: =IF(E47<>0,$H$177,0) -> 0.03 | F32: 0.0298 | G32: 0.027777778 | H32: 0 | I32: 0 | J32: 0
A33: Manufacturing Supplies | B33: =IF($B$47<>0,$H$181,0) -> 0 | C33: 0 | D33: 0 | E33: =IF(E47<>0,$H$181,0) -> 0.0055102041 | F33: 0.0012 | G33: 0.0069444444 | H33: 0 | I33: 0 | J33: 0
A34: Other variable | B34: =IF($B$47<>0,$H$184,0) -> 0 | C34: 0 | D34: 0 | E34: =IF(E47<>0,$H$184,0) -> 0.01122449 | F34: 0.0139 | G34: 0.0125 | H34: 0 | I34: 0 | J34: 0
A35: Total Variable Costs | B35: =SUM(B29:B34) -> 0.065965818 | C35: =SUM(C29:C34) -> 0 | D35: =SUM(D29:D34) -> 0 | E35: =SUM(E29:E34) -> 0.18750634 | F35: =SUM(F29:F34) -> 0.1851 | G35: =SUM(G29:G34) -> 0.16292832 | H35: =SUM(H29:H34) -> 0 | I35: =SUM(I29:I34) -> 0 | J35: =SUM(J29:J34) -> 0
A37: Production Labor | B37: =$D$124*$E$108/$B$49/1000 -> 0.00093026761 | C37: 0 | D37: 0 | E37: =IF($E$47<>0,$F$127/$E$47/1000,0) -> 0.040001507 | F37: 0.0353 | G37: 0.02156921 | H37: 0 | I37: 0 | J37: 0
A38: Repairs & Maintenance Labor | B38: =$H$124*$E$108/$B$49/1000 -> 0 | C38: 0 | D38: 0 | E38: =IF($E$47<>0,$F$128/$E$47/1000,0) -> 0.0048061173 | F38: 0.0067 | G38: 0.0051700857 | H38: 0 | I38: 0 | J38: 0
A39: Indirect Payroll Costs (Benefits) | B39: =$D$131*$E$108/$B$49/1000 -> 0 | C39: 0 | D39: 0 | E39: =IF($E$47<>0,$F$130/$E$47/1000,0) -> 0.012994211 | F39: 0.0112 | G39: 0.0080162316 | H39: 0 | I39: 0 | J39: 0
A40: Supervision | B40: =IF($B$49<>0,$F$194,0) -> 0 | C40: 0 | D40: 0 | E40: =IF($E$47<>0,$F$129/$E$47/1000,0) -> 0 | F40: 0 | G40: 0.00047638889 | H40: 0 | I40: 0 | J40: 0
A41: Depreciation | B41: =IF($B$49<>0,$F$196,0) -> 0.055866735 | C41: 0 | D41: 0 | E41: =IF($E$47<>0,$B$196/$B$49/1000/4,0) -> 0.0011638903 | F41: 0.0085 | G41: 0.0056777778 | H41: 0 | I41: 0 | J41: 0
A42: Insurance & Taxes | B42: =IF($B$49<>0,$F$195,0) -> 0.23436735 | C42: 0 | D42: 0 | E42: =IF($E$47<>0,$B$195/$B$49/1000/4,0) -> 0.0048826531 | F42: 0.0362 | G42: 0.025861111 | H42: 0 | I42: 0 | J42: 0
A43: Total Fixed Costs | B43: =SUM(B37:B42) -> 0.29116435 | C43: =SUM(C37:C42) -> 0 | D43: =SUM(D37:D42) -> 0 | E43: =SUM(E37:E42) -> 0.063848379 | F43: =SUM(F37:F42) -> 0.0979 | G43: =SUM(G37:G42) -> 0.066770805 | H43: =SUM(H37:H42) -> 0 | I43: =SUM(I37:I42) -> 0 | J43: =SUM(J37:J42) -> 0
A44: Excess Costs | F44: -0.0455
A45: TOTAL COSTS PER POUND | B45: =B35+B43 -> 0.35713017 | C45: =C35+C43 -> 0 | D45: 0.19962946 | E45: =E35+E43+E44 -> 0.25135472 | F45: =F35+F43+F44 -> 0.2375 | G45: =+G35+G43 -> 0.22969913 | H45: =H35+H43 -> 0 | I45: =I35+I43 -> 0 | J45: =J35+J43 -> 0 | L45: =E45-0.245 -> 0.0063547165 | M45: =E47*1000*L45 -> 31138.111
M46: =M45/12 -> 2594.8426
...

Sheet Sep
A1: TOOMSBORO STANDARD 2025
B3: CERAMICS | E3: CG 280 | H3: CG 300
B4: 25 Standard | C4: 23 Actual | D4: 20 Standard | E4: =$B$4 -> 25 Standard | F4: =+C4 -> 23 Actual | G4: =+D4 -> 20 Standard | H4: =+B4 -> 25 Standard | I4: =+C4 -> 23 Actual | J4: =+D4 -> 20 Standard
C5: (Jan-Sept) | F5: (Jan-Sept) | I5: (Jan-Sept)
A6: Materials | B6: =IF(B24<>0,$D$82,0) -> 0 | C6: 0.0585 | D6: 0.04156581 | E6: =+H82 -> 0 | F6: 0 | G6: 0 | H6: =+D96 -> 0 | I6: 0 | J6: 0
A7: Electricity | B7: =IF(B24<>0,$D$163,0) -> 0 | C7: 0.0105 | D7: 0.020277329 | E7: =G163 -> 0.0198372 | F7: 0 | G7: 0 | H7: =J163 -> 0.0198372 | I7: 0 | J7: 0
A8: Gas | B8: =IF(B24<>0,$D$164,0) -> 0 | C8: 0.0156 | D8: 0.014965 | E8: =G164 -> 0.0171 | F8: 0 | G8: 0 | H8: =J164 -> 0.0171 | I8: 0 | J8: 0
A9: R&M Supplies and Service | B9: =IF(B24<>0,$J$177,0) -> 0 | C9: 0.0192 | D9: 0.015915789 | E9: =$H$177 -> 0.03 | F9: 0 | G9: 0 | H9: =$H$177 -> 0.03 | I9: 0 | J9: 0
A10: Manufacturing Supplies | B10: =IF(B24<>0,$J$181,0) -> 0 | C10: 0.0008 | D10: 0.0026315789 | E10: =$H$181 -> 0.0055102041 | F10: 0 | G10: 0 | H10: =$H$181 -> 0.0055102041 | I10: 0 | J10: 0
A11: Other variable | B11: =IF(B24<>0,$J$184,0) -> 0 | C11: 0.0058 | D11: 0.0094736842 | E11: =$H$184 -> 0.01122449 | F11: 0 | G11: 0 | H11: =$H$184 -> 0.01122449 | I11: 0 | J11: 0
A12: Total Variable Costs | B12: =SUM(B6:B11) -> 0 | C12: =SUM(C6:C11) -> 0.1104 | D12: =SUM(D6:D11) -> 0.10482919 | E12: =SUM(E6:E11) -> 0.083671894 | F12: =SUM(F6:F11) -> 0 | G12: =SUM(G6:G11) -> 0 | H12: =SUM(H6:H11) -> 0.083671894 | I12: =SUM(I6:I11) -> 0 | J12: =SUM(J6:J11) -> 0
A14: Production Labor | B14: =IF($B$24<>0,$F$152/B24/1000,0) -> 0 | C14: 0.0246 | D14: 0.0073599375 | E14: =$D$124*$E$108/$B$49/1000 -> 0.00093026761 | F14: 0 | G14: 0 | H14: =$D$124*$E$108/$B$49/1000 -> 0.00093026761 | I14: 0 | J14: 0
A15: Repairs & Maintenance Labor | B15: =IF($B$24<>0,$F$153/$B$24/1000,0) -> 0 | C15: 0.009 | D15: 0.0042419375 | E15: =$H$124*$E$108/$B$49/1000 -> 0 | F15: 0 | G15: 0 | H15: =$H$124*$E$108/$B$49/1000 -> 0 | I15: 0 | J15: 0
A16: Indirect Payroll Costs (Benefits) | B16: =IF($B$24<>0,$F$155/$B$24/1000,0) -> 0 | C16: 0.0079 | D16: 0.0053897125 | E16: =$D$131*$E$108/$B$49/1000 -> 0 | F16: 0 | G16: 0 | H16: =$D$131*$E$108/$B$49/1000 -> 0 | I16: 0 | J16: 0
A17: Supervision | B17: =IF($B$24<>0,$F$154/$B$24/1000,0) -> 0 | C17: 0 | D17: 0.0026778947 | E17: =$F$194 -> 0 | F17: 0 | G17: 0 | H17: =$F$194 -> 0 | I17: 0 | J17: 0
