Workbook

Sheet 18 Std v1 (Recap)
B1: 2018 Standards | G1: Reference
B2: 100.1M LB Scenario | E2: 140.1M LB Scenario | G2: Jan-Oct 2017 Actual | J2: 2017 Standard
B3: LBS in 000s | C3: $/LB | E3: LBS in 000s | F3: $/LB | G3: LBS in 000s | H3: $/LB | J3: LBS in 000s | K3: $/LB
A4: NIRO:
A5: CEP/CL/HP/CARBOBEAD | B5: ='18 Std (v1)'!$B$24 -> 50100 | C5: ='18 Std (v1)'!$B$22 -> 0.20646543 | E5: ='18 Std v1 (140.1M)'!$B$24 -> 90100 | F5: ='18 Std v1 (140.1M)'!$B$22 -> 0.1661563 | G5: ='18 Std (v1)'!C24 -> 121112.43 | H5: ='18 Std (v1)'!C22 -> 0.16329172 | J5: ='18 Std (v1)'!D24 -> 190000 | K5: ='18 Std (v1)'!D22 -> 0.11902659
A6: NRT/FUSION | B6: ='18 Std (v1)'!$K$24 -> 0 | C6: ='18 Std (v1)'!$K$22 -> 0.43673061 | E6: ='18 Std v1 (140.1M)'!$K$24 -> 0 | F6: ='18 Std v1 (140.1M)'!$K$22 -> 0.39642148 | G6: ='18 Std (v1)'!L24 -> 630.366 | H6: ='18 Std (v1)'!L22 -> 0.39939454 | J6: ='18 Std (v1)'!M24 -> 0 | K6: ='18 Std (v1)'!M22 -> 0
A7: CARBOGRIND | B7: ='18 Std (v1)'!$N$24 -> 0 | C7: ='18 Std (v1)'!$N$22 -> 0.30703664 | E7: ='18 Std v1 (140.1M)'!$N$24 -> 0 | F7: ='18 Std v1 (140.1M)'!$N$22 -> 0.30469592 | G7: ='18 Std (v1)'!O24 -> 1071.4 | H7: ='18 Std (v1)'!O22 -> 0.31298551 | J7: ='18 Std (v1)'!P24 -> 0 | K7: ='18 Std (v1)'!P22 -> 0
A8: NIRO TOTAL | B8: =SUM(B5:B7) -> 50100 | E8: =SUM(E5:E7) -> 90100 | G8: =SUM(G5:G7) -> 122814.2 | J8: =SUM(J5:J7) -> 190000
A10: KS:
A11: KSLD/KRYPTOCAST | B11: ='18 Std (v1)'!$E$24 -> 35000 | C11: ='18 Std (v1)'!$E$22 -> 0.40829992 | E11: ='18 Std v1 (140.1M)'!$E$24 -> 35000 | F11: ='18 Std v1 (140.1M)'!$E$22 -> 0.37065519 | G11: ='18 Std (v1)'!F24 -> 8379.436 | H11: ='18 Std (v1)'!F22 -> 0.36206859 | J11: ='18 Std (v1)'!G24 -> 40000 | K11: ='18 Std (v1)'!G22 -> 0.25987429
A12: KSHD | B12: ='18 Std (v1)'!$H$24 -> 15000 | C12: ='18 Std (v1)'!$H$22 -> 0.8438075 | E12: ='18 Std v1 (140.1M)'!$H$24 -> 15000 | F12: ='18 Std v1 (140.1M)'!$H$22 -> 0.80616277 | G12: ='18 Std (v1)'!I24 -> 15451 | H12: ='18 Std (v1)'!I22 -> 0.77540423 | J12: ='18 Std (v1)'!J24 -> 6000 | K12: ='18 Std (v1)'!J22 -> 0.79889817
A13: KS TOTAL | B13: =SUM(B11:B12) -> 50000 | E13: =SUM(E11:E12) -> 50000 | G13: =SUM(G11:G12) -> 23830.436 | J13: =SUM(J11:J12) -> 46000
A15: GRAND TOTAL | B15: =B8+B13 -> 100100 | E15: =E8+E13 -> 140100 | G15: =G8+G13 -> 146644.64 | J15: =J8+J13 -> 236000

Sheet 18 Std v1 (140.1M)
A1: EUFAULA PLANT STANDARDS | W1: Cost Center 10001002 Total | AF1: Cost Center 10001002 Bulk Production | AO1: CEP/CL | AP1: KSLD | AQ1: KSHD | AR1: Total | AS1: CEP/CL | AT1: KSLD | AU1: KSHD
W2: Production | X2: Bagging | Y2: Total Cost | Z2: Unit Qty | AA2: Unit Price | AB2: UOM | AC2: Activity/Matl | AD2: Account | AE2: Acct % | AF2: CEP/CL | AG2: KSLD | AH2: KSHD | AI2: Total Cost | AJ2: CEP/CL Qty | AK2: KSLD Qty | AL2: KSHD Qty | AM2: Total Qty | AN2: Unit Price | AO2: Qty/1000 lbs | AP2: Qty/1000 lbs | AQ2: Qty/1000 lbs | AR2: Under-Abs | AS2: Under-Abs | AT2: Under-Abs | AU2: Under-Abs
B3: CEP/CL/HP/CARBOBEAD (NIRO) | E3: KSLD | H3: KSHD | K3: NRT/FUSION (NIRO) | N3: CARBOGRIND (NIRO) | R3: COMPOSITE
B4: 18 Std | C4: 17 Act | D4: 17 Std | E4: 18 Std | F4: 17 Act | G4: 17 Std | H4: 18 Std | I4: 17 Act | J4: 17 Std | K4: 18 Std | L4: 17 Act | M4: 17 Std | N4: 18 Std | O4: 17 Act | P4: 17 Std | R4: 18 Std | S4: Absorb Limit | T4: 18 Absorb | U4: 18 Underabs
C5: (Jan-Oct) | F5: (Jan-Oct) | I5: (Jan-Oct) | L5: (Jan-Oct) | O5: (Jan-Oct)
A6: Materials | B6: =IF($B$24<>0,$D$56,0) -> 0.046284643 | C6: 0.04891789 | D6: 0.037383237 | E6: =$F$56 -> 0.14603303 | F6: 0.14828624 | G6: 0.10706625 | H6: =IF($H$24<>0,$H$56,0) -> 0.58154061 | I6: 0.58125835 | J6: 0.50666479 | K6: =J56 -> 0.27654982 | L6: 0.28027625 | M6: 0 | N6: =L56 -> 0.18482427 | O6: 0.18504975 | P6: 0 | R6: =(B6*B$24+E6*E$24+H6*H$24+K6*K$24+N6*N$24)/R$24 -> 0.12851186 | S6: =R6 -> 0.12851186 | T6: =R6 -> 0.12851186 | U6: =R6-T6 -> 0 | V6: =R6*$R$24 -> 18004.511
A7: Electricity | B7: =IF($B$24<>0,$D$104,0) -> 0.0061759711 | C7: 0.0067184367 | D7: 0.0056445202 | E7: =$H$104 -> 0.0538927 | F7: 0.053032975 | G7: 0.046359529 | H7: =IF($H$24<>0,$H$104,0) -> 0.0538927 | I7: 0.0550883 | J7: 0.051146 | K7: =B7 -> 0.0061759711 | L7: 0.0045711698 | M7: 0 | N7: =B7 -> 0.0061759711 | O7: 0.0047608363 | P7: 0 | R7: =(B7*B$24+E7*E$24+H7*H$24+K7*K$24+N7*N$24)/R$24 -> 0.023205496 | S7: 0.0065396807 | T7: =IF($R$22<$S$22,R7,IF($R$12<$S$12,R7,IF(AND($R$12>$S$12,$R$20<$S$20),(($S$7+$S$8+$S$9+$S$10+$S$11)+($S$20-$R$20))/($R$7+$R$8+$R$9+$R$10+$R$11)*R7,R7/($R$7+$R$8+$R$9+$R$10+$R$11)*($S$7+$S$8+$S$9+$S$10+$S$11)))) -> 0.016526343 | U7: =R7-T7 -> 0.0066791526 | V7: =R7*$R$24 -> 3251.09 | W7: =ROUND($G$98*$H$98,0) -> 3251090 | X7: 0 | Y7: =SUM(W7:X7) -> 3251090 | Z7: =G98 -> 44218400 | AA7: =Y7/Z7 -> 0.073523465 | AB7: kwh | AC7: ELE01 | AD7: 630010 | AE7: 1 | AF7: =ROUND($B$104*$C$104*$B$24*1000,0) -> 556455 | AG7: =ROUND($F$104*$G$104*$E$24*1000,0) -> 1886245 | AH7: =ROUND($F$104*$G$104*$H$24*1000,0) -> 808391 | AI7: =SUM(AF7:AH7) -> 3251091 | AJ7: =$B$104*$B$24*1000 -> 7568400 | AK7: =$F$104*$E$24*1000 -> 25655000 | AL7: =$F$104*$H$24*1000 -> 10995000 | AM7: =SUM(AJ7:AL7) -> 44218400 | AN7: =AI7/AM7 -> 0.073523488 | AO7: =ROUND(AJ7/$B$24,3) -> 84 | AP7: =ROUND(AK7/$E$24,3) -> 733 | AQ7: =IF($H$24<>0,ROUND(AL7/$H$24,3),0) -> 733 | AR7: =U7*$R$24 -> 935.74928 | AS7: =$AR7/$AM7*AJ7 -> 160.1624 | AT7: =$AR7/$AM7*AK7 -> 542.91082 | AU7: =$AR7/$AM7*AL7 -> 232.67607
A8: Gas | B8: =IF($B$24<>0,$D$109,0) -> 0.01909316 | C8: 0.023250696 | D8: 0.017573111 | E8: =$H$109 -> 0.010739902 | F8: 0.014393442 | G8: 0.010073294 | H8: =IF($H$24<>0,$H$109,0) -> 0.010739902 | I8: 0.012985865 | J8: 0.0124745 | K8: =B8 -> 0.01909316 | L8: 0.031930815 | M8: 0 | N8: =B8 -> 0.01909316 | O8: 0.020645268 | P8: 0 | R8: =(B8*B$24+E8*E$24+H8*H$24+K8*K$24+N8*N$24)/R$24 -> 0.016111983 | S8: 0.029646433 | T8: =IF($R$22<$S$22,R8,IF($R$12<$S$12,R8,IF(AND($R$12>$S$12,$R$20<$S$20),(($S$7+$S$8+$S$9+$S$10+$S$11)+($S$20-$R$20))/($R$7+$R$8+$R$9+$R$10+$R$11)*R8,R8/($R$7+$R$8+$R$9+$R$10+$R$11)*($S$7+$S$8+$S$9+$S$10+$S$11)))) -> 0.01147453 | U8: =R8-T8 -> 0.0046374528 | V8: =R8*$R$24 -> 2257.2888 | W8: =ROUND($D$98*$C$98,0) -> 2257289 | X8: 0 | Y8: =SUM(W8:X8) -> 2257289 | Z8: =C98*1000 -> 5.6748e+08 | AA8: =Y8/Z8 -> 0.0039777419 | AB8: mbtu | AC8: GAS01 | AD8: 630015 | AE8: 1 | AF8: =ROUND($B$109*$C$109*$B$24*1000,0) -> 1720294 | AG8: =ROUND($F$109*$G$109*$E$24*1000,0) -> 375897 | AH8: =ROUND($F$109*$G$109*$H$24*1000,0) -> 161099 | AI8: =SUM(AF8:AH8) -> 2257290 | AJ8: =$B$109*$B$24*1000*1000 -> 4.3248e+08 | AK8: =$F$109*$E$24*1000*1000 -> 94500000 | AL8: =$F$109*$H$24*1000*1000 -> 40500000 | AM8: =SUM(AJ8:AL8) -> 5.6748e+08 | AN8: =AI8/AM8 -> 0.0039777437 | AO8: =ROUND(AJ8/$B$24,3) -> 4800 | AP8: =ROUND(AK8/$E$24,3) -> 2700 | AQ8: =IF($H$24<>0,ROUND(AL8/$H$24,3),0) -> 2700 | AR8: =U8*$R$24 -> 649.70714 | AS8: =$AR8/$AM8*AJ8 -> 495.14581 | AT8: =$AR8/$AM8*AK8 -> 108.19293 | AU8: =$AR8/$AM8*AL8 -> 46.368399
A9: R&M Supplies and Service | B9: =IF($B$24<>0,$H$119,0) -> 0.025695933 | C9: 0.020888729 | D9: 0.0091201588 | E9: =$H$119 -> 0.025695933 | F9: 0.021258138 | G9: 0.0093875756 | H9: =IF($H$24<>0,$H$119,0) -> 0.025695933 | I9: 0.015830358 | J9: 0.031944443 | K9: =B9 -> 0.025695933 | L9: 0.01877303 | M9: 0 | N9: =B9 -> 0.025695933 | O9: 0.024556496 | P9: 0 | R9: =(B9*B$24+E9*E$24+H9*H$24+K9*K$24+N9*N$24)/R$24 -> 0.025695933 | S9: 0.014439611 | T9: =IF($R$22<$S$22,R9,IF($R$12<$S$12,R9,IF(AND($R$12>$S$12,$R$20<$S$20),(($S$7+$S$8+$S$9+$S$10+$S$11)+($S$20-$R$20))/($R$7+$R$8+$R$9+$R$10+$R$11)*R9,R9/($R$7+$R$8+$R$9+$R$10+$R$11)*($S$7+$S$8+$S$9+$S$10+$S$11)))) -> 0.018299967 | U9: =R9-T9 -> 0.0073959658 | V9: =R9*$R$24 -> 3600.0001 | W9: =ROUND($G$119,0) -> 3600000 | X9: 0 | Y9: =SUM(W9:X9) -> 3600000 | Z9: =$B$25*1000 -> 140100000 | AA9: =Y9/Z9 -> 0.025695931 | AB9: lb | AC9: RMS01 | AD9: 630000 | AE9: 1 | AF9: =$H$119*$B$24*1000 -> 2315203.5 | AG9: =$H$119*$E$24*1000 -> 899357.64 | AH9: =$H$119*$H$24*1000 -> 385438.99 | AI9: =SUM(AF9:AH9) -> 3600000.1 | AJ9: =$B$24*1000 -> 90100000 | AK9: =$E$24*1000 -> 35000000 | AL9: =$H$24*1000 -> 15000000 | AM9: =SUM(AJ9:AL9) -> 140100000 | AN9: =AI9/AM9 -> 0.025695933 | AO9: =ROUND(AJ9/$B$24,3) -> 1000 | AP9: =ROUND(AK9/$E$24,3) -> 1000 | AQ9: =IF($H$24<>0,ROUND(AL9/$H$24,3),0) -> 1000 | AR9: =U9*$R$24 -> 1036.1748 | AS9: =$AR9/$AM9*AJ9 -> 666.37652 | AT9: =$AR9/$AM9*AK9 -> 258.8588 | AU9: =$AR9/$AM9*AL9 -> 110.93949
A10: Manufacturing Supplies | B10: =IF($B$24<>0,$H$123,0) -> 0.0034261242 | C10: 0.0025984533 | D10: 0.00079305734 | E10: =$H$123 -> 0.0034261242 | F10: 0.0020231732 | G10: 0.00081631098 | H10: =IF($H$24<>0,$H$123,0) -> 0.0034261242 | I10: 0.0035917746 | J10: 0.0027777778 | K10: =B10 -> 0.0034261242 | L10: 0.0021372028 | M10: 0 | N10: =B10 -> 0.0034261242 | O10: 0.0016521561 | P10: 0 | R10: =(B10*B$24+E10*E$24+H10*H$24+K10*K$24+N10*N$24)/R$24 -> 0.0034261242 | S10: 0.0011089115 | T10: =IF($R$22<$S$22,R10,IF($R$12<$S$12,R10,IF(AND($R$12>$S$12,$R$20<$S$20),(($S$7+$S$8+$S$9+$S$10+$S$11)+($S$20-$R$20))/($R$7+$R$8+$R$9+$R$10+$R$11)*R10,R10/($R$7+$R$8+$R$9+$R$10+$R$11)*($S$7+$S$8+$S$9+$S$10+$S$11)))) -> 0.0024399955 | U10: =R10-T10 -> 0.00098612873 | V10: =R10*$R$24 -> 480 | W10: =ROUND($G$123,0) -> 480000 | X10: 0 | Y10: =SUM(W10:X10) -> 480000 | Z10: =$B$25*1000 -> 140100000 | AA10: =Y10/Z10 -> 0.0034261242 | AB10: lb | AC10: MFG01 | AD10: 631050 | AE10: 1 | AF10: =$H$123*$B$24*1000 -> 308693.79 | AG10: =$H$123*$E$24*1000 -> 119914.35 | AH10: =$H$123*$H$24*1000 -> 51391.863 | AI10: =SUM(AF10:AH10) -> 480000 | AJ10: =$B$24*1000 -> 90100000 | AK10: =$E$24*1000 -> 35000000 | AL10: =$H$24*1000 -> 15000000 | AM10: =SUM(AJ10:AL10) -> 140100000 | AN10: =AI10/AM10 -> 0.0034261242 | AO10: =ROUND(AJ10/$B$24,3) -> 1000 | AP10: =ROUND(AK10/$E$24,3) -> 1000 | AQ10: =IF($H$24<>0,ROUND(AL10/$H$24,3),0) -> 1000 | AR10: =U10*$R$24 -> 138.15664 | AS10: =$AR10/$AM10*AJ10 -> 88.850199 | AT10: =$AR10/$AM10*AK10 -> 34.514506 | AU10: =$AR10/$AM10*AL10 -> 14.791931
A11: Other variable | B11: =IF($B$24<>0,$H$126,0) -> 0.0085653105 | C11: 0.0071261242 | D11: 0.002973965 | E11: =$H$126 -> 0.0085653105 | F11: 0.008722241 | G11: 0.0030611662 | H11: =IF($H$24<>0,$H$126,0) -> 0.0085653105 | I11: 0.0068701845 | J11: 0.010416667 | K11: =B11 -> 0.0085653105 | L11: 0.0078377165 | M11: 0 | N11: =B11 -> 0.0085653105 | O11: 0.011616427 | P11: 0 | R11: =(B11*B$24+E11*E$24+H11*H$24+K11*K$24+N11*N$24)/R$24 -> 0.0085653105 | S11: 0.0031061887 | T11: =IF($R$22<$S$22,R11,IF($R$12<$S$12,R11,IF(AND($R$12>$S$12,$R$20<$S$20),(($S$7+$S$8+$S$9+$S$10+$S$11)+($S$20-$R$20))/($R$7+$R$8+$R$9+$R$10+$R$11)*R11,R11/($R$7+$R$8+$R$9+$R$10+$R$11)*($S$7+$S$8+$S$9+$S$10+$S$11)))) -> 0.0060999887 | U11: =R11-T11 -> 0.0024653218 | V11: =R11*$R$24 -> 1200 | W11: =ROUND($G$126,0) -> 1200000 | X11: 0 | Y11: =SUM(W11:X11) -> 1200000 | Z11: =$B$25*1000 -> 140100000 | AA11: =Y11/Z11 -> 0.0085653105 | AB11: lb | AC11: VAR01 | AD11: see below | AE11: see below | AF11: =$H$126*$B$24*1000 -> 771734.48 | AG11: =$H$126*$E$24*1000 -> 299785.87 | AH11: =$H$126*$H$24*1000 -> 128479.66 | AI11: =SUM(AF11:AH11) -> 1200000 | AJ11: =$B$24*1000 -> 90100000 | AK11: =$E$24*1000 -> 35000000 | AL11: =$H$24*1000 -> 15000000 | AM11: =SUM(AJ11:AL11) -> 140100000 | AN11: =AI11/AM11 -> 0.0085653105 | AO11: =ROUND(AJ11/$B$24,3) -> 1000 | AP11: =ROUND(AK11/$E$24,3) -> 1000 | AQ11: =IF($H$24<>0,ROUND(AL11/$H$24,3),0) -> 1000 | AR11: =U11*$R$24 -> 345.39159 | AS11: =$AR11/$AM11*AJ11 -> 222.1255 | AT11: =$AR11/$AM11*AK11 -> 86.286264 | AU11: =$AR11/$AM11*AL11 -> 36.979827
A12: Total Variable Costs | B12: =SUM(B6:B11) -> 0.10924114 | C12: =SUM(C6:C11) -> 0.10950033 | D12: =SUM(D6:D11) -> 0.073488049 | E12: =SUM(E6:E11) -> 0.248353 | F12: =SUM(F6:F11) -> 0.24771621 | G12: =SUM(G6:G11) -> 0.17676413 | H12: =SUM(H6:H11) -> 0.68386058 | I12: =SUM(I6:I11) -> 0.67562483 | ... P12: =SUM(P6:P11) -> 0 | R12: =SUM(R6:R11) -> 0.2055167 | S12: =SUM(S6:S11) -> 0.18335268 | T12: =SUM(T6:T11) -> 0.18335268 | U12: =SUM(U6:U11) -> 0.022164022 | V12: =SUM(V7:V11) -> 10788.379 | W12: =SUM(W7:W11) -> 10788379 | X12: =SUM(X7:X11) -> 0 | Y12: =SUM(Y7:Y11) -> 10788379 | AF12: =SUM(AF7:AF11) -> 5672380.8 | AG12: =SUM(AG7:AG11) -> 3581199.9 | AH12: =SUM(AH7:AH11) -> 1534800.5 | AI12: =SUM(AI7:AI11) -> 10788381 | AR12: =SUM(AR7:AR11) -> 3105.1794 | AS12: =SUM(AS7:AS11) -> 1632.6604 | AT12: =SUM(AT7:AT11) -> 1030.7633 | AU12: =SUM(AU7:AU11) -> 441.75571
A14: Production Labor | B14: =IF($B$24<>0,$F$89/$B$24/1000,0) -> 0.021671575 | C14: 0.0130835 | D14: 0.015388494 | E14: =$H$89/($E$24+$H$24)/1000 -> 0.021671575 | F14: 0.015315616 | G14: 0.015854474 | H14: =IF($H$24<>0,$H$89/($E$24+$H$24)/1000,0) -> 0.021671575 | I14: 0.035737987 | J14: 0.055160288 | K14: =B14 -> 0.021671575 | L14: 0.014090322 | M14: 0 | N14: =B14 -> 0.021671575 | O14: 0.013746771 | P14: 0 | R14: =(B14*B$24+E14*E$24+H14*H$24+K14*K$24+N14*N$24)/R$24 -> 0.021671575 | S14: 0.011308447 | T14: =R14 -> 0.021671575 | U14: =R14-T14 -> 0 | V14: =R14*$R$24 -> 3036.1876 | W14: =ROUND($D$78,0) -> 3036188 | X14: =ROUND($D$77,0) -> 68408 | Y14: =SUM(W14:X14) -> 3104596 | Z14: =$B$76 -> 99348 | AA14: =Y14/Z14 -> 31.249708 | AB14: hr | AC14: DLAB01 | AD14: see below | AE14: see below | AF14: =$F89 -> 1952608.9 | AG14: =$H89/($E$24+$H$24)*E24 -> 758505.12 | AH14: =$H89/($E$24+$H$24)*H24 -> 325073.62 | AI14: =SUM(AF14:AH14) -> 3036187.6 | AJ14: =$E89 -> 62484.085 | AK14: =$G89/($E$24+$H$24)*E24 -> 24272.397 | AL14: =$G89/($E$24+$H$24)*H24 -> 10402.456 | AM14: =SUM(AJ14:AL14) -> 97158.938 | AN14: =AI14/AM14 -> 31.2497 | AO14: =ROUND(AJ14/$B$24,3) -> 0.693 | AP14: =ROUND(AK14/$E$24,3) -> 0.693 | AQ14: =IF($H$24<>0,ROUND(AL14/$H$24,3),0) -> 0.693 | AR14: =U14*$R$24 -> 0 | AS14: =$AR14/$AM14*AJ14 -> 0 | AT14: =$AR14/$AM14*AK14 -> 0 | AU14: =$AR14/$AM14*AL14 -> 0
A15: Repairs & Maintenance Labor | B15: =IF($B$24<>0,$F$90/$B$24/1000,0) -> 0.0086067633 | C15: 0.0055430533 | D15: 0.0054755569 | E15: =$H$90/($E$24+$H$24)/1000 -> 0.0086067633 | F15: 0.0064201194 | G15: 0.0056361085 | H15: =IF($H$24<>0,$H$90/($E$24+$H$24)/1000,0) -> 0.0086067633 | I15: 0.014775811 | J15: 0.01917879 | K15: =B15 -> 0.0086067633 | L15: 0.0061446049 | M15: 0 | N15: =B15 -> 0.0086067633 | O15: 0.0062273101 | P15: 0 | R15: =(B15*B$24+E15*E$24+H15*H$24+K15*K$24+N15*N$24)/R$24 -> 0.0086067633 | S15: 0.0052712801 | T15: =S22-T12-T14 -> 0.01699873 | U15: =R15-T15 -> -0.0083919666 | V15: =R15*$R$24 -> 1205.8075 | W15: =ROUND($H$76,0) -> 1205808 | X15: 0 | Y15: =SUM(W15:X15) -> 1205808 | Z15: =$F$76 -> 36691.2 | AA15: =Y15/Z15 -> 32.863684 | AB15: hr | AC15: MLAB01 | AD15: see below | AE15: see below | AF15: =$F90 -> 775469.38 | AG15: =$H90/($E$24+$H$24)*E24 -> 301236.72 | AH15: =$H90/($E$24+$H$24)*H24 -> 129101.45 | AI15: =SUM(AF15:AH15) -> 1205807.5 | AJ15: =$E90 -> 23596.553 | AK15: =$G90/($E$24+$H$24)*E24 -> 9166.2527 | AL15: =$G90/($E$24+$H$24)*H24 -> 3928.394 | AM15: =SUM(AJ15:AL15) -> 36691.2 | AN15: =AI15/AM15 -> 32.863671 | AO15: =ROUND(AJ15/$B$24,3) -> 0.262 | AP15: =ROUND(AK15/$E$24,3) -> 0.262 | AQ15: =IF($H$24<>0,ROUND(AL15/$H$24,3),0) -> 0.262 | AR15: =U15*$R$24 -> -1175.7145 | AS15: =$AR15/$AM15*AJ15 -> -756.11619 | AT15: =$AR15/$AM15*AK15 -> -293.71883 | AU15: =$AR15/$AM15*AL15 -> -125.8795
A16: Indirect Payroll Costs (Benefits) | B16: =IF($B$24<>0,$F$91/$B$24/1000,0) -> 0.012035476 | C16: 0.0071493219 | D16: 0.0093107449 | E16: =$H$91/($E$24+$H$24)/1000 -> 0.012035476 | F16: 0.0082509873 | G16: 0.0095926839 | H16: =IF($H$24<>0,$H$91/($E$24+$H$24)/1000,0) -> 0.012035476 | I16: 0.019322727 | J16: 0.033374504 | K16: =B16 -> 0.012035476 | L16: 0.0080163112 | M16: 0 | N16: =B16 -> 0.012035476 | O16: 0.0074639164 | P16: 0 | R16: =(B16*B$24+E16*E$24+H16*H$24+K16*K$24+N16*N$24)/R$24 -> 0.012035476 | S16: 0.0080958839 | T16: =S22-T12-T14-T15 -> 0 | U16: =R16-T16 -> 0.012035476 | V16: =R16*$R$24 -> 1686.1702 | W16: =ROUND($D$86,0) -> 1686170 | X16: =ROUND($D$85,0) -> 37991 | Y16: =SUM(W16:X16) -> 1724161 | Z16: =$B$84 -> 99348 | AA16: =Y16/Z16 -> 17.354763 | AB16: hr | AC16: IPC01 | AD16: see below | AE16: see below | AF16: =$F91 -> 1084396.4 | AG16: =$H91/($E$24+$H$24)*E24 -> 421241.67 | AH16: =$H91/($E$24+$H$24)*H24 -> 180532.14 | AI16: =SUM(AF16:AH16) -> 1686170.2 | AJ16: =$E91 -> 62484.085 | AK16: =$G91/($E$24+$H$24)*E24 -> 24272.397 | AL16: =$G91/($E$24+$H$24)*H24 -> 10402.456 | AM16: =SUM(AJ16:AL16) -> 97158.937 | AN16: =AI16/AM16 -> 17.354762 | AO16: =ROUND(AJ16/$B$24,3) -> 0.693 | AP16: =ROUND(AK16/$E$24,3) -> 0.693 | AQ16: =IF($H$24<>0,ROUND(AL16/$H$24,3),0) -> 0.693 | AR16: =U16*$R$24 -> 1686.1702 | AS16: =$AR16/$AM16*AJ16 -> 1084.3964 | AT16: =$AR16/$AM16*AK16 -> 421.24167 | AU16: =$AR16/$AM16*AL16 -> 180.53214
A17: Supervision | B17: =IF($B$24<>0,$D$136,0) -> 0.0027052106 | C17: 0.0020941539 | D17: 0.0014661648 | E17: =$E$136 -> 0.0027052106 | F17: 0.002255474 | G17: 0.0015091549 | H17: =IF($H$24<>0,$E$136,0) -> 0.0027052106 | I17: 0.0019750709 | J17: 0.0051354167 | K17: =B17 -> 0.0027052106 | L17: 0.0024827481 | M17: 0 | N17: =B17 -> 0.0027052106 | O17: 0.0025772821 | P17: 0 | R17: =(B17*B$24+E17*E$24+H17*H$24+K17*K$24+N17*N$24)/R$24 -> 0.0027052106 | S17: 0.0020913266 | T17: =S22-T12-T14-T15-T16 -> 0 | U17: =R17-T17 -> 0.0027052106 | V17: =R17*$R$24 -> 379 | W17: =ROUND($C$136,0) -> 379000 | X17: 0 | Y17: =SUM(W17:X17) -> 379000 | Z17: =$B$25*1000 -> 140100000 | AA17: =Y17/Z17 -> 0.0027052106 | AB17: lb | AC17: SUP01 | AD17: 611000 | AE17: 1 | AF17: =$D$136*$B$24*1000 -> 243739.47 | AG17: =$E$136*$E$24*1000 -> 94682.37 | AH17: =$E$136*$H$24*1000 -> 40578.158 | AI17: =SUM(AF17:AH17) -> 379000 | AJ17: =ROUND(AF17/$AA17,0) -> 90100000 | AK17: =ROUND(AG17/$AA17,0) -> 35000000 | AL17: =ROUND(AH17/$AA17,0) -> 15000000 | AM17: =SUM(AJ17:AL17) -> 140100000 | AN17: =AI17/AM17 -> 0.0027052106 | AO17: =ROUND(AJ17/$B$24,3) -> 1000 | AP17: =ROUND(AK17/$E$24,3) -> 1000 | AQ17: =IF($H$24<>0,ROUND(AL17/$H$24,3),0) -> 1000 | AR17: =U17*$R$24 -> 379 | AS17: =$AR17/$AM17*AJ17 -> 243.73947 | AT17: =$AR17/$AM17*AK17 -> 94.68237 | AU17: =$AR17/$AM17*AL17 -> 40.578158
A18: Insurance & Taxes | B18: =IF($B$24<>0,$D$137,0) -> 0.0028551035 | C18: 0.0022245575 | D18: 0.0011301067 | E18: =$E$137 -> 0.0028551035 | F18: 0.0025373784 | G18: 0.0011632431 | H18: =IF($H$24<>0,$E$137,0) -> 0.0028551035 | I18: 0.0017392298 | J18: 0.0039583333 | K18: =B18 -> 0.0028551035 | L18: 0.0021055704 | M18: 0 | N18: =B18 -> 0.0028551035 | O18: 0.0042373717 | P18: 0 | R18: =(B18*B$24+E18*E$24+H18*H$24+K18*K$24+N18*N$24)/R$24 -> 0.0028551035 | S18: 0.0031981538 | T18: =S22-T12-T14-T15-T16-T17 -> 0 | U18: =R18-T18 -> 0.0028551035 | V18: =R18*$R$24 -> 400 | W18: =ROUND($C$137,0) -> 400000 | X18: 0 | Y18: =SUM(W18:X18) -> 400000 | Z18: =$B$25*1000 -> 140100000 | AA18: =Y18/Z18 -> 0.0028551035 | AB18: lb | AC18: INS01 | AD18: see below | AE18: see below | AF18: =$D$137*$B$24*1000 -> 257244.83 | AG18: =$E$137*$E$24*1000 -> 99928.622 | AH18: =$E$137*$H$24*1000 -> 42826.552 | AI18: =SUM(AF18:AH18) -> 400000 | AJ18: =ROUND(AF18/$AA18,0) -> 90100000 | AK18: =ROUND(AG18/$AA18,0) -> 35000000 | AL18: =ROUND(AH18/$AA18,0) -> 15000000 | AM18: =SUM(AJ18:AL18) -> 140100000 | AN18: =AI18/AM18 -> 0.0028551035 | AO18: =ROUND(AJ18/$B$24,3) -> 1000 | AP18: =ROUND(AK18/$E$24,3) -> 1000 | AQ18: =IF($H$24<>0,ROUND(AL18/$H$24,3),0) -> 1000 | AR18: =U18*$R$24 -> 400 | AS18: =$AR18/$AM18*AJ18 -> 257.24483 | AT18: =$AR18/$AM18*AK18 -> 99.928622 | AU18: =$AR18/$AM18*AL18 -> 42.826552
A19: Depreciation | B19: =IF($B$24<>0,$D$138,0) -> 0.009041029 | C19: 0.023696807 | D19: 0.012767474 | E19: =$E$138 -> 0.074428066 | F19: 0.079572807 | G19: 0.049354497 | H19: =IF($H$24<>0,$E$138,0) -> 0.074428066 | I19: 0.026228572 | J19: 0.066666667 | K19: =B19 -> 0.009041029 | L19: 0.021028799 | M19: 0 | N19: =B19 -> 0.009041029 | O19: 0.030451932 | P19: 0 | R19: =(B19*B$24+E19*E$24+H19*H$24+K19*K$24+N19*N$24)/R$24 -> 0.032376874 | S19: 0.0087052134 | T19: =S22-T12-T14-T15-T16-T17-T18 -> 0 | U19: =R19-T19 -> 0.032376874 | V19: =R19*$R$24 -> 4536 | W19: =ROUND($C$138,0) -> 4536000 | X19: 0 | Y19: =SUM(W19:X19) -> 4536000 | Z19: =$B$25*1000 -> 140100000 | AA19: =Y19/Z19 -> 0.032376874 | AB19: lb | AC19: DEP01 | AD19: see below | AE19: see below | AF19: =$D$138*$B$24*1000 -> 814596.72 | AG19: =$E$138*$E$24*1000 -> 2604982.3 | AH19: =$E$138*$H$24*1000 -> 1116421 | AI19: =SUM(AF19:AH19) -> 4536000 | AJ19: =AF19/$AA19 -> 25159832 | AK19: =AG19/$AA19 -> 80458117 | AL19: =AH19/$AA19 -> 34482050 | AM19: =SUM(AJ19:AL19) -> 140100000 | AN19: =AI19/AM19 -> 0.032376874 | AO19: =ROUND(AJ19/$B$24,3) -> 279.243 | AP19: =ROUND(AK19/$E$24,3) -> 2298.803 | AQ19: =IF($H$24<>0,ROUND(AL19/$H$24,3),0) -> 2298.803 | AR19: =U19*$R$24 -> 4536 | AS19: =$AR19/$AM19*AJ19 -> 814.59672 | AT19: =$AR19/$AM19*AK19 -> 2604.9823 | AU19: =$AR19/$AM19*AL19 -> 1116.421
A20: Total Fixed Costs | B20: =SUM(B14:B19) -> 0.056915158 | C20: =SUM(C14:C19) -> 0.053791393 | D20: =SUM(D14:D19) -> 0.045538542 | E20: =SUM(E14:E19) -> 0.12230219 | F20: =SUM(F14:F19) -> 0.11435238 | G20: =SUM(G14:G19) -> 0.083110161 | H20: =SUM(H14:H19) -> 0.12230219 | I20: =SUM(I14:I19) -> 0.099779397 | ... P20: =SUM(P14:P19) -> 0 | R20: =SUM(R14:R19) -> 0.080251002 | S20: =SUM(S14:S19) -> 0.038670305 | T20: =SUM(T14:T19) -> 0.038670305 | U20: =SUM(U14:U19) -> 0.041580697 | V20: =SUM(V14:V19) -> 11243.165 | W20: =SUM(W14:W19) -> 11243166 | X20: =SUM(X14:X19) -> 106399 | Y20: =SUM(Y14:Y19) -> 11349565 | AF20: =SUM(AF14:AF19) -> 5128055.7 | AG20: =SUM(AG14:AG19) -> 4280576.8 | AH20: =SUM(AH14:AH19) -> 1834532.9 | AI20: =SUM(AI14:AI19) -> 11243165 | AR20: =SUM(AR14:AR19) -> 5825.4557 | AS20: =SUM(AS14:AS19) -> 1643.8612 | AT20: =SUM(AT14:AT19) -> 2927.1161 | AU20: =SUM(AU14:AU19) -> 1254.4783
V21: =V12+V20 -> 22031.544 | W21: =W12+W20 -> 22031545 | X21: =X12+X20 -> 106399 | Y21: =Y12+Y20 -> 22137944 | AF21: =AF12+AF20 -> 10800436 | AG21: =AG12+AG20 -> 7861776.6 | AH21: =AH12+AH20 -> 3369333.4 | AI21: =AI12+AI20 -> 22031547 | AR21: =AR12+AR20 -> 8930.6352 | AS21: =AS12+AS20 -> 3276.5216 | AT21: =AT12+AT20 -> 3957.8795 | AU21: =AU12+AU20 -> 1696.2341
A22: TOTAL COST PER POUND | B22: =B12+B20 -> 0.1661563 | C22: =C12+C20 -> 0.16329172 | D22: =D12+D20 -> 0.11902659 | E22: =E12+E20 -> 0.37065519 | F22: =F12+F20 -> 0.36206859 | G22: =G12+G20 -> 0.25987429 | H22: =H12+H20 -> 0.80616277 | I22: =I12+I20 -> 0.77540423 | ... P22: =P12+P20 -> 0 | R22: =R12+R20 -> 0.28576771 | S22: =S12+S20 -> 0.22202299 | T22: =T12+T20 -> 0.22202299 | U22: =U12+U20 -> 0.063744719 | V22: =V6+V21 -> 40036.056 | AD22: Excl. Raw Matl | AF22: =ROUND(AF21/AF24,5) -> 0.11987 | AG22: =ROUND(AG21/AG24,5) -> 0.22462 | AH22: =IF(AH24<>0,ROUND(AH21/AH24,5),0) -> 0.22462 | AI22: =ROUND(AI21/AI24,5) -> 0.15726
AD23: Incl. Raw Matl | AF23: =ROUND(AF22+B6,5) -> 0.16615 | AG23: =ROUND(AG22+E6,5) -> 0.37065 | AH23: =IF(AH24<>0,ROUND(AH22+H6,5),0) -> 0.80616 | AI23: =ROUND(AI22+(B6*B24+E6*E24+H6*H24)/B25,5) -> 0.28577
A24: TOTAL PRODUCTION (000 lbs) | B24: =$B$30+$B$31 -> 90100 | C24: 121112.43 | D24: 190000 | E24: =$B$32 -> 35000 | F24: 8379.436 | G24: 40000 | H24: =$B$33 -> 15000 | I24: 15451 | J24: 6000 | K24: 0 | L24: 630.366 | M24: 0 | N24: 0 | O24: 1071.4 | P24: 0 | R24: =B25 -> 140100 | AD24: Bulk Prodn lbs | AF24: =ROUND(B24*1000,0) -> 90100000 | AG24: =ROUND(E24*1000,0) -> 35000000 | AH24: =ROUND(H24*1000,0) -> 15000000 | AI24: =SUM(AF24:AH24) -> 140100000
A25: TOTAL PLANT PRODUCTION (000 lbs) | B25: =B24+E24+H24+K24+N24 -> 140100 | C25: =C24+F24+I24+L24+O24 -> 146644.64 | D25: =D24+G24+J24+M24+P24 -> 236000
A27: Variable Costs - Material | B27: Purchase Price/lb * Yield Factor * Scrap Factor * Mix = Std. Cost Contribution | S27: Total | T27: Variable | U27: Fixed
R28: 18 Annual: | S28: ($ in 000s)
A29: Production Plan: | B29: Pounds (000) | C29: Product Split | R29: Abs by Prodn | S29: =SUM(T29:U29) -> 31105.421 | T29: =T12*$R$24 -> 25687.711 | U29: =T20*$R$24 -> 5417.7097
A30: CARBO EconoProp | B30: =36000+40000 -> 76000 | C30: =+B30/$B$34 -> 0.54246966 | R30: Under-abs Exp | S30: =SUM(T30:U30) -> 8930.6352 | T30: =U12*R24 -> 3105.1794 | U30: =U20*R24 -> 5825.4557
A31: CARBO Lite | B31: =17500+4600-8000 -> 14100 | C31: =+B31/$B$34 -> 0.1006424 | R31: Gas Net Settled | S31: =SUM(T31:U31) -> 0 | T31: =IF(C97<>0,0,(((((D96/1.06564)-0.33)*0.974)-D97)*(240000-C96))/1000) -> 0 | U31: 0
A32: Kryptosphere LD | B32: =35000 -> 35000 | C32: =+B32/$B$34 -> 0.24982156 | R32: Total Cost | S32: =SUM(S29:S31) -> 40036.056 | T32: =SUM(T29:T31) -> 28792.89 | U32: =SUM(U29:U31) -> 11243.165
A33: Kryptosphere HD | B33: =15000 -> 15000 | C33: =+B33/$B$34 -> 0.10706638 | R33: Less: Non-cash | S33: =SUM(T33:U33) -> -4536 | T33: 0 | U33: =-R19*R24 -> -4536
A34: Total | B34: =SUM(B30:B33) -> 140100 | C34: =SUM(C30:C33) -> 1 | R34: Cash | S34: =SUM(S32:S33) -> 35500.056 | T34: =SUM(T32:T33) -> 28792.89 | U34: =SUM(U32:U33) -> 6707.1654
C36: CEP/CL/HP | E36: KSLD | G36: KSHD | I36: NRT/FUSION | K36: CARBOGRIND | R36: 18 Monthly:
A37: Raw Material: | B37: Price ($/NT) | C37: Ratio/Mix | E37: Ratio/Mix | G37: Ratio/Mix | I37: Ratio/Mix | K37: Ratio/Mix | R37: Abs by Prodn | S37: =SUM(T37:U37) -> 2592.1184 | T37: =T29/12 -> 2140.6426 | U37: =U29/12 -> 451.47581
A38: Arcilla | B38: =13.3*2 -> 26.6 | C38: 0.5 | E38: 0.5 | G38: 0 | I38: 0.5 | K38: 0.5 | R38: Under-abs Exp | S38: =SUM(T38:U38) -> 744.2196 | T38: =T30/12 -> 258.76495 | U38: =U30/12 -> 485.45464
A39: CARBO | B39: =12.41*2 -> 24.82 | C39: 0.5 | E39: 0.5 | G39: 0 | I39: 0.5 | K39: 0.5 | R39: Gas Net Settled | S39: =SUM(T39:U39) -> 0 | T39: =T31/12 -> 0 | U39: =U31/12 -> 0
A40: Weighted Average (LW) | B40: =+B38*C38+B39*C39 -> 25.71 | C40: =SUM(C38:C39) -> 1 | E40: =SUM(E38:E39) -> 1 | G40: =SUM(G38:G39) -> 0 | I40: =SUM(I38:I39) -> 1 | K40: =SUM(K38:K39) -> 1 | R40: Total Cost | S40: =SUM(S37:S39) -> 3336.338 | T40: =SUM(T37:T39) -> 2399.4075 | U40: =SUM(U37:U39) -> 936.93045
R41: Less: Non-cash | S41: =SUM(T41:U41) -> -378 | T41: =T33/12 -> 0 | U41: =U33/12 -> -378
A42: Materials: | B42: Price ($/lb) | C42: Usage Factor | D42: Std $ Contrib | E42: Usage Factor | F42: Std $ Contrib | G42: Usage Factor | H42: Std $ Contrib | I42: Usage Factor | J42: Std $ Contrib | K42: Usage Factor | L42: Std $ Contrib | R42: Cash | S42: =SUM(S40:S41) -> 2958.338 | T42: =SUM(T40:T41) -> 2399.4075 | U42: =SUM(U40:U41) -> 558.93045 | AR42: lbs required | AS42: 10/31/16 Inv | AT42: % of requ | AU42: cost per lb
A43: Clay/Kaolin (30015) | B43: =$B$40/2000 -> 0.012855 | C43: 2.1972328 | D43: =B43*C43 -> 0.028245428 | E43: 2.4102522 | F43: =B43*E43 -> 0.030983792 | G43: 0 | H43: =$B43*G43 -> 0 | I43: 2.6302429 | J43: =$B43*I43 -> 0.033811772 | K43: 1.4950065 | L43: =$B43*K43 -> 0.019218309 | AA43: =B43*1000 -> 12.855 | AB43: lb | AC43: 30015/U102 | AO43: =IF(B43<>0,D43/B43*1000,0) -> 2197.2328 | AP43: =IF(B43<>0,F43/B43*1000,0) -> 2410.2522 | AQ43: =IF(B43<>0,H43/B43*1000,0) -> 0 | AR43: =AO43*$B$24+AP43*$E$24+AQ43*$H$24 -> 2.823295e+08 | AS43: 202343432 | AT43: =AS43/AR43 -> 0.71669248 | AU43: =343597.02/24291676.299 -> 0.01414464
...

Sheet Comparative
B1: EP/CL | E1: KSLD | H1: KSHD | K1: NRT/FUSION | N1: NRT+ | Q1: NRT KSLD | T1: CG280 | W1: CG300
B2: 19 Std (2) | C2: 19 Std | D2: Diff | E2: 19 Std (2) | F2: 19 Std | G2: Diff | H2: 19 Std (2) | I2: 19 Std | J2: Diff | K2: 19 Std (2) | L2: 19 Std | M2: Diff | N2: 19 Std (2) | O2: 19 Std | P2: Diff | Q2: 19 Std (2) | R2: 19 Std | S2: Diff | T2: 19 Std (2) | U2: 19 Std | V2: Diff | W2: 19 Std (2) | X2: 19 Std | Y2: Diff
A4: Materials | B4: 0.052442084 | C4: 0.052442084 | D4: =B4-C4 -> 0 | E4: 0.11900853 | F4: 0.11900853 | G4: =E4-F4 -> 0 | H4: 0.42313082 | I4: 0.42313082 | J4: =H4-I4 -> 0 | K4: 0.12711514 | L4: 0.12711514 | M4: =K4-L4 -> 0 | N4: 1.9292536 | O4: 1.9292536 | P4: =N4-O4 -> 0 | Q4: 0.21033033 | R4: 0.21033033 | S4: =Q4-R4 -> 0 | T4: 0.11317584 | U4: 0.11317584 | V4: =T4-U4 -> 0 | W4: 0.28172044 | X4: 0.28172044 | Y4: =W4-X4 -> 0
A5: Electricity | B5: 0.0098763951 | C5: 0.0098763951 | D5: =B5-C5 -> 0 | E5: 0.055687674 | F5: 0.055687674 | G5: =E5-F5 -> 0 | H5: 0.055687674 | I5: 0.055687674 | J5: =H5-I5 -> 0 | K5: 0.0098763951 | L5: 0.0098763951 | M5: =K5-L5 -> 0 | N5: 0.0098763951 | O5: 0.0098763951 | P5: =N5-O5 -> 0 | Q5: 0.055687674 | R5: 0.055687674 | S5: =Q5-R5 -> 0 | T5: 0.0098763951 | U5: 0.0098763951 | V5: =T5-U5 -> 0 | W5: 0.0098763951 | X5: 0.0098763951 | Y5: =W5-X5 -> 0
A6: Gas | B6: 0.0168 | C6: 0.0168 | D6: =B6-C6 -> 0 | E6: 0.0098 | F6: 0.0098 | G6: =E6-F6 -> 0 | H6: 0.0098 | I6: 0.0098 | J6: =H6-I6 -> 0 | K6: 0.0168 | L6: 0.0168 | M6: =K6-L6 -> 0 | N6: 0.0168 | O6: 0.0168 | P6: =N6-O6 -> 0 | Q6: 0.0098 | R6: 0.0098 | S6: =Q6-R6 -> 0 | T6: 0.0168 | U6: 0.0168 | V6: =T6-U6 -> 0 | W6: 0.0168 | X6: 0.0168 | Y6: =W6-X6 -> 0
A7: R&M Supplies and Service | B7: 0.02718869 | C7: 0.02718869 | D7: =B7-C7 -> 0 | E7: 0.02718869 | F7: 0.02718869 | G7: =E7-F7 -> 0 | H7: 0.02718869 | I7: 0.02718869 | J7: =H7-I7 -> 0 | K7: 0.02718869 | L7: 0.02718869 | M7: =K7-L7 -> 0 | N7: 0.02718869 | O7: 0.02718869 | P7: =N7-O7 -> 0 | Q7: 0.02718869 | R7: 0.02718869 | S7: =Q7-R7 -> 0 | T7: 0.02718869 | U7: 0.02718869 | V7: =T7-U7 -> 0 | W7: 0.02718869 | X7: 0.02718869 | Y7: =W7-X7 -> 0
A8: Manufacturing Supplies | B8: 0.0043501903 | C8: 0.0043501903 | D8: =B8-C8 -> 0 | E8: 0.0043501903 | F8: 0.0043501903 | G8: =E8-F8 -> 0 | H8: 0.0043501903 | I8: 0.0043501903 | J8: =H8-I8 -> 0 | K8: 0.0043501903 | L8: 0.0043501903 | M8: =K8-L8 -> 0 | N8: 0.0043501903 | O8: 0.0043501903 | P8: =N8-O8 -> 0 | Q8: 0.0043501903 | R8: 0.0043501903 | S8: =Q8-R8 -> 0 | T8: 0.0043501903 | U8: 0.0043501903 | V8: =T8-U8 -> 0 | W8: 0.0043501903 | X8: 0.0043501903 | Y8: =W8-X8 -> 0
A9: Other variable | B9: 0.010875476 | C9: 0.010875476 | D9: =B9-C9 -> 0 | E9: 0.010875476 | F9: 0.010875476 | G9: =E9-F9 -> 0 | H9: 0.010875476 | I9: 0.010875476 | J9: =H9-I9 -> 0 | K9: 0.010875476 | L9: 0.010875476 | M9: =K9-L9 -> 0 | N9: 0.010875476 | O9: 0.010875476 | P9: =N9-O9 -> 0 | Q9: 0.010875476 | R9: 0.010875476 | S9: =Q9-R9 -> 0 | T9: 0.010875476 | U9: 0.010875476 | V9: =T9-U9 -> 0 | W9: 0.010875476 | X9: 0.010875476 | Y9: =W9-X9 -> 0
A10: Total Variable Costs | B10: =SUM(B4:B9) -> 0.12153283 | C10: =SUM(C4:C9) -> 0.12153283 | D10: =SUM(D4:D9) -> 0 | E10: =SUM(E4:E9) -> 0.22691056 | F10: =SUM(F4:F9) -> 0.22691056 | G10: =SUM(G4:G9) -> 0 | H10: =SUM(H4:H9) -> 0.53103284 | I10: =SUM(I4:I9) -> 0.53103284 | ... Y10: =SUM(Y4:Y9) -> 0
A12: Production Labor | B12: 0.038989507 | C12: 0.049677855 | D12: =B12-C12 -> -0.010688348 | E12: 0.038989507 | F12: 0.049677855 | G12: =E12-F12 -> -0.010688348 | H12: 0.038989507 | I12: 0.049677855 | J12: =H12-I12 -> -0.010688348 | K12: 0.038989507 | L12: 0.049677855 | M12: =K12-L12 -> -0.010688348 | N12: 0.038989507 | O12: 0.049677855 | P12: =N12-O12 -> -0.010688348 | Q12: 0.038989507 | R12: 0.049677855 | S12: =Q12-R12 -> -0.010688348 | T12: 0.038989507 | U12: 0.049677855 | V12: =T12-U12 -> -0.010688348 | W12: 0.038989507 | X12: 0.049677855 | Y12: =W12-X12 -> -0.010688348
A13: Repairs & Maintenance Labor | B13: 0.020329845 | C13: 0.025902946 | D13: =B13-C13 -> -0.0055731008 | E13: 0.020329845 | F13: 0.025902946 | G13: =E13-F13 -> -0.0055731008 | H13: 0.020329845 | I13: 0.025902946 | J13: =H13-I13 -> -0.0055731008 | K13: 0.020329845 | L13: 0.025902946 | M13: =K13-L13 -> -0.0055731008 | N13: 0.020329845 | O13: 0.025902946 | P13: =N13-O13 -> -0.0055731008 | Q13: 0.020329845 | R13: 0.025902946 | S13: =Q13-R13 -> -0.0055731008 | T13: 0.020329845 | U13: 0.025902946 | V13: =T13-U13 -> -0.0055731008 | W13: 0.020329845 | X13: 0.025902946 | Y13: =W13-X13 -> -0.0055731008
A14: Indirect Payroll Costs (Benefits) | B14: 0.026450178 | C14: 0.03370107 | D14: =B14-C14 -> -0.0072508918 | E14: 0.026450178 | F14: 0.03370107 | G14: =E14-F14 -> -0.0072508918 | H14: 0.026450178 | I14: 0.03370107 | J14: =H14-I14 -> -0.0072508918 | K14: 0.026450178 | L14: 0.03370107 | M14: =K14-L14 -> -0.0072508918 | N14: 0.026450178 | O14: 0.03370107 | P14: =N14-O14 -> -0.0072508918 | Q14: 0.026450178 | R14: 0.03370107 | S14: =Q14-R14 -> -0.0072508918 | T14: 0.026450178 | U14: 0.03370107 | V14: =T14-U14 -> -0.0072508918 | W14: 0.026450178 | X14: 0.03370107 | Y14: =W14-X14 -> -0.0072508918
A15: Supervision | B15: 0.0068776509 | C15: 0.0087630485 | D15: =B15-C15 -> -0.0018853976 | E15: 0.0068776509 | F15: 0.0087630485 | G15: =E15-F15 -> -0.0018853976 | H15: 0.0068776509 | I15: 0.0087630485 | J15: =H15-I15 -> -0.0018853976 | K15: 0.0068776509 | L15: 0.0087630485 | M15: =K15-L15 -> -0.0018853976 | N15: 0.0068776509 | O15: 0.0087630485 | P15: =N15-O15 -> -0.0018853976 | Q15: 0.0068776509 | R15: 0.0087630485 | S15: =Q15-R15 -> -0.0018853976 | T15: 0.0068776509 | U15: 0.0087630485 | V15: =T15-U15 -> -0.0018853976 | W15: 0.0068776509 | X15: 0.0087630485 | Y15: =W15-X15 -> -0.0018853976
A16: Depreciation | B16: 0.021572981 | C16: 0.0289071 | D16: =B16-C16 -> -0.0073341183 | E16: 0.11680294 | F16: 0.12232835 | G16: =E16-F16 -> -0.0055254115 | H16: 0.11680294 | I16: 0.12232835 | J16: =H16-I16 -> -0.0055254115 | K16: 0.021572981 | L16: 0.0289071 | M16: =K16-L16 -> -0.0073341183 | N16: 0.021572981 | O16: 0.0289071 | P16: =N16-O16 -> -0.0073341183 | Q16: 0.11680294 | R16: 0.12232835 | S16: =Q16-R16 -> -0.0055254115 | T16: 0.021572981 | U16: 0.0289071 | V16: =T16-U16 -> -0.0073341183 | W16: 0.021572981 | X16: 0.0289071 | Y16: =W16-X16 -> -0.0073341183
A17: Insurance & Taxes | B17: 0.012688055 | C17: 0.016166282 | D17: =B17-C17 -> -0.0034782267 | E17: 0.012688055 | F17: 0.016166282 | G17: =E17-F17 -> -0.0034782267 | H17: 0.012688055 | I17: 0.016166282 | J17: =H17-I17 -> -0.0034782267 | K17: 0.012688055 | L17: 0.016166282 | M17: =K17-L17 -> -0.0034782267 | N17: 0.012688055 | O17: 0.016166282 | P17: =N17-O17 -> -0.0034782267 | Q17: 0.012688055 | R17: 0.016166282 | S17: =Q17-R17 -> -0.0034782267 | T17: 0.012688055 | U17: 0.016166282 | V17: =T17-U17 -> -0.0034782267 | W17: 0.012688055 | X17: 0.016166282 | Y17: =W17-X17 -> -0.0034782267
A18: Total Fixed Costs | B18: =SUM(B12:B17) -> 0.12690822 | C18: =SUM(C12:C17) -> 0.1631183 | D18: =SUM(D12:D17) -> -0.036210083 | E18: =SUM(E12:E17) -> 0.22213818 | F18: =SUM(F12:F17) -> 0.25653955 | G18: =SUM(G12:G17) -> -0.034401376 | H18: =SUM(H12:H17) -> 0.22213818 | I18: =SUM(I12:I17) -> 0.25653955 | ... Y18: =SUM(Y12:Y17) -> -0.036210083
A20: TOTAL COST PER POUND | B20: =B10+B18 -> 0.24844105 | C20: =C10+C18 -> 0.28465114 | D20: =D10+D18 -> -0.036210083 | E20: =E10+E18 -> 0.44904874 | F20: =F10+F18 -> 0.48345012 | G20: =G10+G18 -> -0.034401376 | H20: =H10+H18 -> 0.75317102 | I20: =I10+I18 -> 0.7875724 | ... Y20: =Y10+Y18 -> -0.036210083
A21: LESS: EXCESS FIXED COSTS | B21: -0.11199897 | C21: -0.14820909 | D21: =B21-C21 -> 0.036210124 | E21: -0.19604021 | F21: -0.23044158 | G21: =E21-F21 -> 0.034401376 | H21: -0.13204021 | I21: -0.16644158 | J21: =H21-I21 -> 0.034401376 | K21: -0.11199897 | L21: -0.14820905 | M21: =K21-L21 -> 0.036210083 | N21: -0.11199897 | O21: -0.14820905 | P21: =N21-O21 -> 0.036210083 | Q21: -0.19604021 | R21: -0.23044158 | S21: =Q21-R21 -> 0.034401376 | T21: -0.11199897 | U21: -0.14820905 | V21: =T21-U21 -> 0.036210083 | W21: -0.11199897 | X21: -0.14820905 | Y21: =W21-X21 -> 0.036210083
A22: ABSORBED COST PER POUND | B22: =SUM(B20:B21) -> 0.13644208 | C22: =SUM(C20:C21) -> 0.13644204 | D22: =SUM(D20:D21) -> 4.0784653e-08 | E22: =SUM(E20:E21) -> 0.25300853 | F22: =SUM(F20:F21) -> 0.25300853 | G22: =SUM(G20:G21) -> 0 | H22: =SUM(H20:H21) -> 0.62113082 | I22: =SUM(I20:I21) -> 0.62113082 | ... Y22: =SUM(Y20:Y21) -> 0

Sheet 19 Std (2)
A1: EUFAULA PLANT STANDARDS | AF1: Cost Center 10001002 Total | AO1: Cost Center 10001002 Bulk Production | BH1: CEP/CL | BI1: KSLD | BJ1: KSHD | BK1: NRT/Fusion | BL1: NRT+ | BM1: NRT KSLD | BN1: CG280 | BO1: CG300 | BP1: Total | BQ1: CEP/CL | BR1: KSLD | BS1: KSHD | BT1: NRT/Fusion | BU1: NRT+ | BV1: NRT KSLD | BW1: CG280 | BX1: CG300
AF2: Production | AG2: Bagging | AH2: Total Cost | AI2: Unit Qty | AJ2: Unit Price | AK2: UOM | AL2: Activity/Matl | AM2: Account | AN2: Acct % | AO2: EP/CL | AP2: KSLD | AQ2: KSHD | AR2: NRT/Fusion | AS2: NRT+ | AT2: NRT KSLD | AU2: CG280 | AV2: CG300 | AW2: Total Cost | AX2: EP/CL Qty | AY2: KSLD Qty | AZ2: KSHD Qty | BA2: NRT/Fusion Qty | BB2: NRT+ Qty | BC2: NRT KSLD Qty | BD2: CG280 Qty | BE2: CG300 Qty | BF2: Total Qty | BG2: Unit Price | BH2: Qty/1000 lbs | BI2: Qty/1000 lbs | BJ2: Qty/1000 lbs | BK2: Qty/1000 lbs | BL2: Qty/1000 lbs | BM2: Qty/1000 lbs | BN2: Qty/1000 lbs | BO2: Qty/1000 lbs | BP2: Under-Abs | BQ2: Under-Abs | BR2: Under-Abs | BS2: Under-Abs | BT2: Under-Abs | BU2: Under-Abs | BV2: Under-Abs | BW2: Under-Abs | BX2: Under-Abs
B3: CEP/CL/HP | E3: KSLD | H3: KSHD | K3: NRT/FUSION | N3: NRT+ | Q3: NRT KSLD | T3: CG280 | W3: CG300 | AA3: COMPOSITE | AO3: B | AP3: E | AQ3: H | AR3: K | AS3: N | AT3: Q | AU3: T | AV3: W | AX3: B | AY3: E | AZ3: H | BA3: K | BB3: N | BC3: Q | BD3: T | BE3: W | BQ3: B | BR3: E | BS3: H | BT3: K | BU3: N | BV3: Q | BW3: T | BX3: W
B4: 19 Std | C4: 18 Act | D4: 18 Std | E4: 19 Std | F4: 18 Act | G4: 18 Std | H4: 19 Std | I4: 18 Act | J4: 18 Std | K4: 19 Std | L4: 18 Act | M4: 18 Std | N4: 19 Std | O4: 18 Act | P4: 18 Std | Q4: 19 Std | R4: 18 Act | S4: 18 Std | T4: 19 Std | U4: 18 Act | V4: 18 Std | W4: 19 Std | X4: 18 Act | Y4: 18 Std | AA4: 19 Std | AB4: 19 Absorb | AC4: 19 Underabs
C5: (Jan-Oct) | F5: (Jan-Oct) | I5: (Jan-Oct) | L5: (Jan-Oct) | O5: (Jan-Oct) | R5: (Jan-Oct) | U5: (Jan-Oct) | X5: (Jan-Oct)
A6: Materials | B6: =$D$66 -> 0.052442084 | C6: 0.052476066 | D6: 0.046284643 | E6: =$F$66 -> 0.11900853 | F6: 0.11639619 | G6: 0.14603303 | H6: =$H$66 -> 0.42313082 | I6: 0.41696458 | J6: 0.58154061 | K6: =$J$66 -> 0.12711514 | L6: 0.12044521 | M6: 0.27654982 | N6: =$L$66 -> 1.9292536 | O6: 1.8366354 | P6: 0 | Q6: =$N$66 -> 0.21033033 | R6: 0.19631709 | S6: 0.2134758 | T6: =$P$66 -> 0.11317584 | U6: 0.26903053 | V6: 0.14685585 | W6: =$R$66 -> 0.28172044 | X6: 0.41772519 | Y6: 0.14685585 | AA6: =(B6*B$26+E6*E$26+H6*H$26+K6*K$26+N6*N$26+Q6*Q$26+T6*T$26+W6*W$26)/AA$26 -> 0.17383503 | AB6: =AA6 -> 0.17383503 | AC6: =AA6-AB6 -> 0 | AE6: =AA6*$AA$26 -> 9590.4786
A7: Electricity | B7: =$D$114 -> 0.0098763951 | C7: 0.013296851 | D7: 0.0058460609 | E7: =$H$114 -> 0.055687674 | F7: 0.0503476 | G7: 0.051013841 | H7: =$H$114 -> 0.055687674 | I7: 0.063041198 | J7: 0.051013841 | K7: =$D$114 -> 0.0098763951 | L7: 0.0043388439 | M7: 0.0058460609 | N7: =$D$114 -> 0.0098763951 | O7: 0.0051273333 | P7: 0 | Q7: =$H$114 -> 0.055687674 | R7: 0.074619382 | S7: 0.051013841 | T7: =$D$114 -> 0.0098763951 | U7: 0.0084103379 | V7: 0.0058460609 | W7: =$D$114 -> 0.0098763951 | X7: 0.0054841618 | Y7: 0.0058460609 | AA7: =(B7*B$26+E7*E$26+H7*H$26+K7*K$26+N7*N$26+Q7*Q$26+T7*T$26+W7*W$26)/AA$26 -> 0.038108831 | AB7: =AA7 -> 0.038108831 | AC7: =AA7-AB7 -> 0 | AE7: =AA7*$AA$26 -> 2102.4642 | AF7: =ROUND($G$108*$H$108,0) -> 2102464 | AG7: 0 | AH7: =SUM(AF7:AG7) -> 2102464 | AI7: =G108 -> 27674100 | AJ7: =AH7/AI7 -> 0.075972263 | AK7: kwh | AL7: ELE01 | AM7: 630010 | AN7: 1 | AO7: =ROUND($B$114*$C$114*$B$26*1000,0) -> 91850 | AP7: =ROUND($F$114*$G$114*$E$26*1000,0) -> 1336504 | AQ7: =ROUND($F$114*$G$114*$H$26*1000,0) -> 556877 | AR7: =ROUND($B$114*$C$114*$K$26*1000,0) -> 46123 | AS7: =ROUND($B$114*$C$114*$N$26*1000,0) -> 0 | AT7: =ROUND($F$114*$G$114*$Q$26*1000,0) -> 0 | AU7: =ROUND($B$114*$C$114*$T$26*1000,0) -> 35555 | AV7: =ROUND($B$114*$C$114*$W$26*1000,0) -> 35555 | AW7: =SUM(AO7:AV7) -> 2102464 | AX7: =$B$114*$B$26*1000 -> 1209000 | AY7: =$F$114*$E$26*1000 -> 17592000 | AZ7: =$F$114*$H$26*1000 -> 7330000 | BA7: =$B$114*$K$26*1000 -> 607100 | BB7: =$B$114*$N$26*1000 -> 0 | BC7: =$F$114*$Q$26*1000 -> 0 | BD7: =$B$114*$T$26*1000 -> 468000 | BE7: =$B$114*$W$26*1000 -> 468000 | BF7: =SUM(AX7:BE7) -> 27674100 | BG7: =AW7/BF7 -> 0.075972263 | BH7: =IF(AO$26<>0,ROUND(AX7/AO$26*1000,3),0) -> 130 | BI7: =IF(AP$26<>0,ROUND(AY7/AP$26*1000,3),0) -> 733 | BJ7: =IF(AQ$26<>0,ROUND(AZ7/AQ$26*1000,3),0) -> 733 | BK7: =IF(AR$26<>0,ROUND(BA7/AR$26*1000,3),0) -> 130 | BL7: =IF(AS$26<>0,ROUND(BB7/AS$26*1000,3),BH7) -> 130 | BM7: =IF(AT$26<>0,ROUND(BC7/AT$26*1000,3),BI7) -> 733 | BN7: =IF(AU$26<>0,ROUND(BD7/AU$26*1000,3),0) -> 130 | BO7: =IF(AV$26<>0,ROUND(BE7/AV$26*1000,3),0) -> 130 | BP7: =AC7*$AA$26 -> 0 | BQ7: =$AC7*AO$26/1000 -> 0 | BR7: =$AC7*AP$26/1000 -> 0 | BS7: =$AC7*AQ$26/1000 -> 0 | BT7: =$AC7*AR$26/1000 -> 0 | BU7: =$AC7*AS$26/1000 -> 0 | BV7: =$AC7*AT$26/1000 -> 0 | BW7: =$AC7*AU$26/1000 -> 0 | BX7: =$AC7*AV$26/1000 -> 0
A8: Gas | B8: =$D$119 -> 0.0168 | C8: 0.023514844 | D8: 0.025057338 | E8: =$H$119 -> 0.0098 | F8: 0.020991938 | G8: 0.014094753 | H8: =$H$119 -> 0.0098 | I8: 0.015002511 | J8: 0.014094753 | K8: =$D$119 -> 0.0168 | L8: 0.025939135 | M8: 0.025057338 | N8: =$D$119 -> 0.0168 | O8: 0.02896025 | P8: 0 | Q8: =$H$119 -> 0.0098 | R8: 0.015185188 | S8: 0.014094753 | T8: =$D$119 -> 0.0168 | U8: 0.011419925 | V8: 0.025057338 | W8: =$D$119 -> 0.0168 | X8: 0.01214861 | Y8: 0.025057338 | AA8: =(B8*B$26+E8*E$26+H8*H$26+K8*K$26+N8*N$26+Q8*Q$26+T8*T$26+W8*W$26)/AA$26 -> 0.012486061 | AB8: =AA8 -> 0.012486061 | AC8: =AA8-AB8 -> 0 | AE8: =AA8*$AA$26 -> 688.856 | AF8: =ROUND($D$108*$C$108,0) -> 688856 | AG8: 0 | AH8: =SUM(AF8:AG8) -> 688856 | AI8: =C108*1000 -> 1.96816e+08 | AJ8: =AH8/AI8 -> 0.0035 | AK8: mbtu | AL8: GAS01 | AM8: 630015 | AN8: 1 | AO8: =ROUND($B$119*$C$119*$B$26*1000,0) -> 156240 | AP8: =ROUND($F$119*$G$119*$E$26*1000,0) -> 235200 | AQ8: =ROUND($F$119*$G$119*$H$26*1000,0) -> 98000 | AR8: =ROUND($B$119*$C$119*$K$26*1000,0) -> 78456 | AS8: =ROUND($B$119*$C$119*$N$26*1000,0) -> 0 | AT8: =ROUND($F$119*$G$119*$Q$26*1000,0) -> 0 | AU8: =ROUND($B$119*$C$119*$T$26*1000,0) -> 60480 | AV8: =ROUND($B$119*$C$119*$W$26*1000,0) -> 60480 | AW8: =SUM(AO8:AV8) -> 688856 | AX8: =$B$119*$B$26*1000*1000 -> 44640000 | AY8: =$F$119*$E$26*1000*1000 -> 67200000 | AZ8: =$F$119*$H$26*1000*1000 -> 28000000 | BA8: =$B$119*$K$26*1000*1000 -> 22416000 | BB8: =$B$119*$N$26*1000*1000 -> 0 | BC8: =$F$119*$Q$26*1000*1000 -> 0 | BD8: =$B$119*$T$26*1000*1000 -> 17280000 | BE8: =$B$119*$W$26*1000*1000 -> 17280000 | BF8: =SUM(AX8:BE8) -> 1.96816e+08 | BG8: =AW8/BF8 -> 0.0035 | BH8: =IF(AO$26<>0,ROUND(AX8/AO$26*1000,3),0) -> 4800 | BI8: =IF(AP$26<>0,ROUND(AY8/AP$26*1000,3),0) -> 2800 | BJ8: =IF(AQ$26<>0,ROUND(AZ8/AQ$26*1000,3),0) -> 2800 | BK8: =IF(AR$26<>0,ROUND(BA8/AR$26*1000,3),0) -> 4800 | BL8: =IF(AS$26<>0,ROUND(BB8/AS$26*1000,3),BH8) -> 4800 | BM8: =IF(AT$26<>0,ROUND(BC8/AT$26*1000,3),BI8) -> 2800 | BN8: =IF(AU$26<>0,ROUND(BD8/AU$26*1000,3),0) -> 4800 | BO8: =IF(AV$26<>0,ROUND(BE8/AV$26*1000,3),0) -> 4800 | BP8: =AC8*$AA$26 -> 0 | BQ8: =$AC8*AO$26/1000 -> 0 | BR8: =$AC8*AP$26/1000 -> 0 | BS8: =$AC8*AQ$26/1000 -> 0 | BT8: =$AC8*AR$26/1000 -> 0 | BU8: =$AC8*AS$26/1000 -> 0 | BV8: =$AC8*AT$26/1000 -> 0 | BW8: =$AC8*AU$26/1000 -> 0 | BX8: =$AC8*AV$26/1000 -> 0
A9: R&M Supplies and Service | B9: =$H$129 -> 0.02718869 | C9: 0.022502448 | D9: 0.049930654 | E9: =$H$129 -> 0.02718869 | F9: 0.034492916 | G9: 0.049930654 | H9: =$H$129 -> 0.02718869 | I9: 0.033203792 | J9: 0.049930654 | K9: =$H$129 -> 0.02718869 | L9: 0.025464135 | M9: 0.049930654 | N9: =$H$129 -> 0.02718869 | O9: 0.03200775 | P9: 0 | Q9: =$H$129 -> 0.02718869 | R9: 0.012887626 | S9: 0.049930654 | T9: =$H$129 -> 0.02718869 | U9: 0.027627116 | V9: 0.049930654 | W9: =$H$129 -> 0.02718869 | X9: 0.034060431 | Y9: 0.049930654 | AA9: =(B9*B$26+E9*E$26+H9*H$26+K9*K$26+N9*N$26+Q9*Q$26+T9*T$26+W9*W$26)/AA$26 -> 0.02718869 | AB9: =AA9 -> 0.02718869 | AC9: =AA9-AB9 -> 0 | AE9: =AA9*$AA$26 -> 1500 | AF9: =ROUND($G$129,0) -> 1500000 | AG9: 0 | AH9: =SUM(AF9:AG9) -> 1500000 | AI9: =$B$28*1000 -> 55170000 | AJ9: =AH9/AI9 -> 0.02718869 | AK9: lb | AL9: RMS01 | AM9: 630000 | AN9: 1 | AO9: =$H$129*$B$26*1000 -> 252854.81 | AP9: =$H$129*$E$26*1000 -> 652528.55 | AQ9: =$H$129*$H$26*1000 -> 271886.9 | AR9: =$H$129*$K$26*1000 -> 126971.18 | AS9: =$H$129*$N$26*1000 -> 0 | AT9: =$H$129*$Q$26*1000 -> 0 | AU9: =$H$129*$T$26*1000 -> 97879.282 | AV9: =$H$129*$W$26*1000 -> 97879.282 | AW9: =SUM(AO9:AV9) -> 1500000 | AX9: =$B$26*1000 -> 9300000 | AY9: =$E$26*1000 -> 24000000 | AZ9: =$H$26*1000 -> 10000000 | BA9: =$K$26*1000 -> 4670000 | BB9: =$N$26*1000 -> 0 | BC9: =$Q$26*1000 -> 0 | BD9: =$T$26*1000 -> 3600000 | BE9: =$W$26*1000 -> 3600000 | BF9: =SUM(AX9:BE9) -> 55170000 | BG9: =AW9/BF9 -> 0.02718869 | BH9: =IF(AO$26<>0,ROUND(AX9/AO$26*1000,3),0) -> 1000 | BI9: =IF(AP$26<>0,ROUND(AY9/AP$26*1000,3),0) -> 1000 | BJ9: =IF(AQ$26<>0,ROUND(AZ9/AQ$26*1000,3),0) -> 1000 | BK9: =IF(AR$26<>0,ROUND(BA9/AR$26*1000,3),0) -> 1000 | BL9: =IF(AS$26<>0,ROUND(BB9/AS$26*1000,3),BH9) -> 1000 | BM9: =IF(AT$26<>0,ROUND(BC9/AT$26*1000,3),BI9) -> 1000 | BN9: =IF(AU$26<>0,ROUND(BD9/AU$26*1000,3),0) -> 1000 | BO9: =IF(AV$26<>0,ROUND(BE9/AV$26*1000,3),0) -> 1000 | BP9: =AC9*$AA$26 -> 0 | BQ9: =$AC9*AO$26/1000 -> 0 | BR9: =$AC9*AP$26/1000 -> 0 | BS9: =$AC9*AQ$26/1000 -> 0 | BT9: =$AC9*AR$26/1000 -> 0 | BU9: =$AC9*AS$26/1000 -> 0 | BV9: =$AC9*AT$26/1000 -> 0 | BW9: =$AC9*AU$26/1000 -> 0 | BX9: =$AC9*AV$26/1000 -> 0
A10: Manufacturing Supplies | B10: =$H$133 -> 0.0043501903 | C10: 0.0023760034 | D10: 0.0066574202 | E10: =$H$133 -> 0.0043501903 | F10: 0.010081949 | G10: 0.0066574202 | H10: =$H$133 -> 0.0043501903 | I10: 0.0057492015 | J10: 0.0066574202 | K10: =$H$133 -> 0.0043501903 | L10: 0.0074659488 | M10: 0.0066574202 | N10: =$H$133 -> 0.0043501903 | O10: 2.4083333e-05 | P10: 0 | Q10: =$H$133 -> 0.0043501903 | R10: 0.0062434068 | S10: 0.0066574202 | T10: =$H$133 -> 0.0043501903 | U10: 0.0028120484 | V10: 0.0066574202 | W10: =$H$133 -> 0.0043501903 | X10: 0.0040891998 | Y10: 0.0066574202 | AA10: =(B10*B$26+E10*E$26+H10*H$26+K10*K$26+N10*N$26+Q10*Q$26+T10*T$26+W10*W$26)/AA$26 -> 0.0043501903 | AB10: =AA10 -> 0.0043501903 | AC10: =AA10-AB10 -> 0 | AE10: =AA10*$AA$26 -> 240 | AF10: =ROUND($G$133,0) -> 240000 | AG10: 0 | AH10: =SUM(AF10:AG10) -> 240000 | AI10: =$B$28*1000 -> 55170000 | AJ10: =AH10/AI10 -> 0.0043501903 | AK10: lb | AL10: MFG01 | AM10: 631050 | AN10: 1 | AO10: =$H$133*$B$26*1000 -> 40456.77 | AP10: =$H$133*$E$26*1000 -> 104404.57 | AQ10: =$H$133*$H$26*1000 -> 43501.903 | AR10: =$H$133*$K$26*1000 -> 20315.389 | AS10: =$H$133*$N$26*1000 -> 0 | AT10: =$H$133*$Q$26*1000 -> 0 | AU10: =$H$133*$T$26*1000 -> 15660.685 | AV10: =$H$133*$W$26*1000 -> 15660.685 | AW10: =SUM(AO10:AV10) -> 240000 | AX10: =$B$26*1000 -> 9300000 | AY10: =$E$26*1000 -> 24000000 | AZ10: =$H$26*1000 -> 10000000 | BA10: =$K$26*1000 -> 4670000 | BB10: =$N$26*1000 -> 0 | BC10: =$Q$26*1000 -> 0 | BD10: =$T$26*1000 -> 3600000 | BE10: =$W$26*1000 -> 3600000 | BF10: =SUM(AX10:BE10) -> 55170000 | BG10: =AW10/BF10 -> 0.0043501903 | BH10: =IF(AO$26<>0,ROUND(AX10/AO$26*1000,3),0) -> 1000 | BI10: =IF(AP$26<>0,ROUND(AY10/AP$26*1000,3),0) -> 1000 | BJ10: =IF(AQ$26<>0,ROUND(AZ10/AQ$26*1000,3),0) -> 1000 | BK10: =IF(AR$26<>0,ROUND(BA10/AR$26*1000,3),0) -> 1000 | BL10: =IF(AS$26<>0,ROUND(BB10/AS$26*1000,3),BH10) -> 1000 | BM10: =IF(AT$26<>0,ROUND(BC10/AT$26*1000,3),BI10) -> 1000 | BN10: =IF(AU$26<>0,ROUND(BD10/AU$26*1000,3),0) -> 1000 | BO10: =IF(AV$26<>0,ROUND(BE10/AV$26*1000,3),0) -> 1000 | BP10: =AC10*$AA$26 -> 0 | BQ10: =$AC10*AO$26/1000 -> 0 | BR10: =$AC10*AP$26/1000 -> 0 | BS10: =$AC10*AQ$26/1000 -> 0 | BT10: =$AC10*AR$26/1000 -> 0 | BU10: =$AC10*AS$26/1000 -> 0 | BV10: =$AC10*AT$26/1000 -> 0 | BW10: =$AC10*AU$26/1000 -> 0 | BX10: =$AC10*AV$26/1000 -> 0
A11: Other variable | B11: =$H$136 -> 0.010875476 | C11: 0.0084782467 | D11: 0.016643551 | E11: =$H$136 -> 0.010875476 | F11: 0.013888916 | G11: 0.016643551 | H11: =$H$136 -> 0.010875476 | I11: 0.017367487 | J11: 0.016643551 | K11: =$H$136 -> 0.010875476 | L11: 0.003624579 | M11: 0.016643551 | N11: =$H$136 -> 0.010875476 | O11: 0.013958 | P11: 0 | Q11: =$H$136 -> 0.010875476 | R11: 0.013900072 | S11: 0.016643551 | T11: =$H$136 -> 0.010875476 | U11: 0.013435556 | V11: 0.016643551 | W11: =$H$136 -> 0.010875476 | X11: 0.018878704 | Y11: 0.016643551 | AA11: =(B11*B$26+E11*E$26+H11*H$26+K11*K$26+N11*N$26+Q11*Q$26+T11*T$26+W11*W$26)/AA$26 -> 0.010875476 | AB11: =AA11 -> 0.010875476 | AC11: =AA11-AB11 -> 0 | AE11: =AA11*$AA$26 -> 600 | AF11: =ROUND($G$136,0) -> 600000 | AG11: 0 | AH11: =SUM(AF11:AG11) -> 600000 | AI11: =$B$28*1000 -> 55170000 | AJ11: =AH11/AI11 -> 0.010875476 | AK11: lb | AL11: VAR01 | AM11: see below | AN11: see below | AO11: =$H$136*$B$26*1000 -> 101141.92 | AP11: =$H$136*$E$26*1000 -> 261011.42 | AQ11: =$H$136*$H$26*1000 -> 108754.76 | AR11: =$H$136*$K$26*1000 -> 50788.472 | AS11: =$H$136*$N$26*1000 -> 0 | AT11: =$H$136*$Q$26*1000 -> 0 | AU11: =$H$136*$T$26*1000 -> 39151.713 | AV11: =$H$136*$W$26*1000 -> 39151.713 | AW11: =SUM(AO11:AV11) -> 600000 | AX11: =$B$26*1000 -> 9300000 | AY11: =$E$26*1000 -> 24000000 | AZ11: =$H$26*1000 -> 10000000 | BA11: =$K$26*1000 -> 4670000 | BB11: =$N$26*1000 -> 0 | BC11: =$Q$26*1000 -> 0 | BD11: =$T$26*1000 -> 3600000 | BE11: =$W$26*1000 -> 3600000 | BF11: =SUM(AX11:BE11) -> 55170000 | BG11: =AW11/BF11 -> 0.010875476 | BH11: =IF(AO$26<>0,ROUND(AX11/AO$26*1000,3),0) -> 1000 | BI11: =IF(AP$26<>0,ROUND(AY11/AP$26*1000,3),0) -> 1000 | BJ11: =IF(AQ$26<>0,ROUND(AZ11/AQ$26*1000,3),0) -> 1000 | BK11: =IF(AR$26<>0,ROUND(BA11/AR$26*1000,3),0) -> 1000 | BL11: =IF(AS$26<>0,ROUND(BB11/AS$26*1000,3),BH11) -> 1000 | BM11: =IF(AT$26<>0,ROUND(BC11/AT$26*1000,3),BI11) -> 1000 | BN11: =IF(AU$26<>0,ROUND(BD11/AU$26*1000,3),0) -> 1000 | BO11: =IF(AV$26<>0,ROUND(BE11/AV$26*1000,3),0) -> 1000 | BP11: =AC11*$AA$26 -> 0 | BQ11: =$AC11*AO$26/1000 -> 0 | BR11: =$AC11*AP$26/1000 -> 0 | BS11: =$AC11*AQ$26/1000 -> 0 | BT11: =$AC11*AR$26/1000 -> 0 | BU11: =$AC11*AS$26/1000 -> 0 | BV11: =$AC11*AT$26/1000 -> 0 | BW11: =$AC11*AU$26/1000 -> 0 | BX11: =$AC11*AV$26/1000 -> 0
A12: Total Variable Costs | B12: =SUM(B6:B11) -> 0.12153283 | C12: =SUM(C6:C11) -> 0.12264446 | D12: =SUM(D6:D11) -> 0.15041967 | E12: =SUM(E6:E11) -> 0.22691056 | F12: =SUM(F6:F11) -> 0.24619951 | G12: =SUM(G6:G11) -> 0.28437325 | H12: =SUM(H6:H11) -> 0.53103284 | I12: =SUM(I6:I11) -> 0.55132877 | ... Y12: =SUM(Y6:Y11) -> 0.25099088 | AA12: =SUM(AA6:AA11) -> 0.26684428 | AB12: =SUM(AB6:AB11) -> 0.26684428 | AC12: =SUM(AC6:AC11) -> 0 | AE12: =SUM(AE7:AE11) -> 5131.3202 | AF12: =SUM(AF7:AF11) -> 5131320 | AG12: =SUM(AG7:AG11) -> 0 | AH12: =SUM(AH7:AH11) -> 5131320 | AO12: =SUM(AO7:AO11) -> 642543.51 | AP12: =SUM(AP7:AP11) -> 2589648.5 | AQ12: =SUM(AQ7:AQ11) -> 1079020.6 | AW12: =SUM(AW7:AW11) -> 5131320 | BP12: =SUM(BP7:BP11) -> 0 | BQ12: =SUM(BQ7:BQ11) -> 0 | BR12: =SUM(BR7:BR11) -> 0 | BS12: =SUM(BS7:BS11) -> 0 | BT12: =SUM(BT7:BT11) -> 0 | BU12: =SUM(BU7:BU11) -> 0 | BV12: =SUM(BV7:BV11) -> 0 | BW12: =SUM(BW7:BW11) -> 0 | BX12: =SUM(BX7:BX11) -> 0
A14: Production Labor | B14: =IF($B$142<>0,$F99/$B$142/1000,0) -> 0.038989507 | C14: 0.018989996 | D14: 0.042571296 | E14: =IF($C$142<>0,$H99/$C$142/1000,0) -> 0.038989507 | F14: 0.028644278 | G14: 0.042571296 | H14: =IF($C$142<>0,$H99/$C$142/1000,0) -> 0.038989507 | I14: 0.055686215 | J14: 0.042571296 | K14: =IF($B$142<>0,$F99/$B$142/1000,0) -> 0.038989507 | L14: 0.014388196 | M14: 0.042571296 | N14: =IF($B$142<>0,$F99/$B$142/1000,0) -> 0.038989507 | O14: 0.029732 | P14: 0 | Q14: =IF($C$142<>0,$H99/$C$142/1000,0) -> 0.038989507 | R14: 0.020196803 | S14: 0.042571296 | T14: =IF($B$142<>0,$F99/$B$142/1000,0) -> 0.038989507 | U14: 0.0016157561 | V14: 0.042571296 | W14: =IF($B$142<>0,$F99/$B$142/1000,0) -> 0.038989507 | X14: 0.0014495359 | Y14: 0.042571296 | AA14: =(B14*B$26+E14*E$26+H14*H$26+K14*K$26+N14*N$26+Q14*Q$26+T14*T$26+W14*W$26)/AA$26 -> 0.038989507 | AB14: =AB22-AB12 -> 0.033405108 | AC14: =AA14-AB14 -> 0.0055843995 | AE14: =AA14*$AA$26 -> 2151.0511 | AF14: =ROUND($D$88,0) -> 2151051 | AG14: =ROUND($D$87,0) -> 29082 | AH14: =SUM(AF14:AG14) -> 2180133 | AI14: =$B$86 -> 64622.4 | AJ14: =AH14/AI14 -> 33.736491 | AK14: hr | AL14: DLAB01 | AM14: see below | AN14: see below | AO14: =$F99/$B$142*B$26 -> 362602.42 | AP14: =$H99/$C$142*E$26 -> 935748.18 | AQ14: =$H99/$C$142*H$26 -> 389895.07 | AR14: =$F99/$B$142*K$26 -> 182081 | AS14: =$F99/$B$142*N$26 -> 0 | AT14: =$H99/$C$142*Q$26 -> 0 | AU14: =$F99/$B$142*T$26 -> 140362.23 | AV14: =$F99/$B$142*W$26 -> 140362.23 | AW14: =SUM(AO14:AV14) -> 2151051.1 | AX14: =$E99/$B$142*B$26 -> 10748.077 | AY14: =$G99/$C$142*E$26 -> 27736.974 | AZ14: =$G99/$C$142*H$26 -> 11557.072 | BA14: =$E99/$B$142*K$26 -> 5397.1528 | BB14: =$E99/$B$142*N$26 -> 0 | BC14: =$G99/$C$142*Q$26 -> 0 | BD14: =$E99/$B$142*T$26 -> 4160.5461 | BE14: =$E99/$B$142*W$26 -> 4160.5461 | BF14: =SUM(AX14:BE14) -> 63760.369 | BG14: =AW14/BF14 -> 33.736491 | BH14: =IF(AO$26<>0,ROUND(AX14/AO$26*1000,3),0) -> 1.156 | BI14: =IF(AP$26<>0,ROUND(AY14/AP$26*1000,3),0) -> 1.156 | BJ14: =IF(AQ$26<>0,ROUND(AZ14/AQ$26*1000,3),0) -> 1.156 | BK14: =IF(AR$26<>0,ROUND(BA14/AR$26*1000,3),0) -> 1.156 | BL14: =IF(AS$26<>0,ROUND(BB14/AS$26*1000,3),BH14) -> 1.156 | BM14: =IF(AT$26<>0,ROUND(BC14/AT$26*1000,3),BI14) -> 1.156 | BN14: =IF(AU$26<>0,ROUND(BD14/AU$26*1000,3),0) -> 1.156 | BO14: =IF(AV$26<>0,ROUND(BE14/AV$26*1000,3),0) -> 1.156 | BP14: =AC14*$AA$26 -> 308.09132 | BQ14: =$AC14*AO$26/1000 -> 51.934916 | BR14: =$AC14*AP$26/1000 -> 134.02559 | BS14: =$AC14*AQ$26/1000 -> 55.843995 | BT14: =$AC14*AR$26/1000 -> 26.079146 | BU14: =$AC14*AS$26/1000 -> 0 | BV14: =$AC14*AT$26/1000 -> 0 | BW14: =$AC14*AU$26/1000 -> 20.103838 | BX14: =$AC14*AV$26/1000 -> 20.103838
A15: Repairs & Maintenance Labor | B15: =IF($B$142<>0,$F100/$B$142/1000,0) -> 0.020329845 | C15: 0.010091097 | D15: 0.016724099 | E15: =IF($C$142<>0,$H100/$C$142/1000,0) -> 0.020329845 | F15: 0.015211939 | G15: 0.016724099 | H15: =IF($C$142<>0,$H100/$C$142/1000,0) -> 0.020329845 | I15: 0.021872855 | J15: 0.016724099 | K15: =IF($B$142<>0,$F100/$B$142/1000,0) -> 0.020329845 | L15: 0.0051394268 | M15: 0.016724099 | N15: =IF($B$142<>0,$F100/$B$142/1000,0) -> 0.020329845 | O15: 0.01789125 | P15: 0 | Q15: =IF($C$142<>0,$H100/$C$142/1000,0) -> 0.020329845 | R15: 0.0086290824 | S15: 0.016724099 | T15: =IF($B$142<>0,$F100/$B$142/1000,0) -> 0.020329845 | U15: 0.00092575296 | V15: 0.016724099 | W15: =IF($B$142<>0,$F100/$B$142/1000,0) -> 0.020329845 | X15: 0.00073897059 | Y15: 0.016724099 | AA15: =(B15*B$26+E15*E$26+H15*H$26+K15*K$26+N15*N$26+Q15*Q$26+T15*T$26+W15*W$26)/AA$26 -> 0.020329845 | AB15: =AB22-AB12-AB14 -> 0 | AC15: =AA15-AB15 -> 0.020329845 | AE15: =AA15*$AA$26 -> 1121.5976 | AF15: =ROUND($H$86,0) -> 1121598 | AG15: 0 | AH15: =SUM(AF15:AG15) -> 1121598 | AI15: =$F$86 -> 31449.6 | AJ15: =AH15/AI15 -> 35.663347 | AK15: hr | AL15: MLAB01 | AM15: see below | AN15: see below | AO15: =$F100/$B$142*B$26 -> 189067.56 | AP15: =$H100/$C$142*E$26 -> 487916.29 | AQ15: =$H100/$C$142*H$26 -> 203298.45 | AR15: =$F100/$B$142*K$26 -> 94940.378 | AS15: =$F100/$B$142*N$26 -> 0 | AT15: =$H100/$C$142*Q$26 -> 0 | AU15: =$F100/$B$142*T$26 -> 73187.443 | AV15: =$F100/$B$142*W$26 -> 73187.443 | AW15: =SUM(AO15:AV15) -> 1121597.6 | AX15: =$E100/$B$142*B$26 -> 5301.4551 | AY15: =$G100/$C$142*E$26 -> 13681.175 | AZ15: =$G100/$C$142*H$26 -> 5700.4894 | BA15: =$E100/$B$142*K$26 -> 2662.1285 | BB15: =$E100/$B$142*N$26 -> 0 | BC15: =$G100/$C$142*Q$26 -> 0 | BD15: =$E100/$B$142*T$26 -> 2052.1762 | BE15: =$E100/$B$142*W$26 -> 2052.1762 | BF15: =SUM(AX15:BE15) -> 31449.6 | BG15: =AW15/BF15 -> 35.663333 | BH15: =IF(AO$26<>0,ROUND(AX15/AO$26*1000,3),0) -> 0.57 | BI15: =IF(AP$26<>0,ROUND(AY15/AP$26*1000,3),0) -> 0.57 | BJ15: =IF(AQ$26<>0,ROUND(AZ15/AQ$26*1000,3),0) -> 0.57 | BK15: =IF(AR$26<>0,ROUND(BA15/AR$26*1000,3),0) -> 0.57 | BL15: =IF(AS$26<>0,ROUND(BB15/AS$26*1000,3),BH15) -> 0.57 | BM15: =IF(AT$26<>0,ROUND(BC15/AT$26*1000,3),BI15) -> 0.57 | BN15: =IF(AU$26<>0,ROUND(BD15/AU$26*1000,3),0) -> 0.57 | BO15: =IF(AV$26<>0,ROUND(BE15/AV$26*1000,3),0) -> 0.57 | BP15: =AC15*$AA$26 -> 1121.5976 | BQ15: =$AC15*AO$26/1000 -> 189.06756 | BR15: =$AC15*AP$26/1000 -> 487.91629 | BS15: =$AC15*AQ$26/1000 -> 203.29845 | BT15: =$AC15*AR$26/1000 -> 94.940378 | BU15: =$AC15*AS$26/1000 -> 0 | BV15: =$AC15*AT$26/1000 -> 0 | BW15: =$AC15*AU$26/1000 -> 73.187443 | BX15: =$AC15*AV$26/1000 -> 73.187443
A16: Indirect Payroll Costs (Benefits) | B16: =IF($B$142<>0,$F101/$B$142/1000,0) -> 0.026450178 | C16: 0.014602185 | D16: 0.023642298 | E16: =IF($C$142<>0,$H101/$C$142/1000,0) -> 0.026450178 | F16: 0.019376157 | G16: 0.023642298 | H16: =IF($C$142<>0,$H101/$C$142/1000,0) -> 0.026450178 | I16: 0.033118009 | J16: 0.023642298 | K16: =IF($B$142<>0,$F101/$B$142/1000,0) -> 0.026450178 | L16: 0.0067939767 | M16: 0.023642298 | N16: =IF($B$142<>0,$F101/$B$142/1000,0) -> 0.026450178 | O16: 0.0179385 | P16: 0 | Q16: =IF($C$142<>0,$H101/$C$142/1000,0) -> 0.026450178 | R16: 0.011299855 | S16: 0.023642298 | T16: =IF($B$142<>0,$F101/$B$142/1000,0) -> 0.026450178 | U16: 0.0012972166 | V16: 0.023642298 | W16: =IF($B$142<>0,$F101/$B$142/1000,0) -> 0.026450178 | X16: 0.0009368989 | Y16: 0.023642298 | AA16: =(B16*B$26+E16*E$26+H16*H$26+K16*K$26+N16*N$26+Q16*Q$26+T16*T$26+W16*W$26)/AA$26 -> 0.026450178 | AB16: =AB22-AB12-AB14-AB15 -> 0 | AC16: =AA16-AB16 -> 0.026450178 | AE16: =AA16*$AA$26 -> 1459.2563 | AF16: =ROUND($D$96,0) -> 1459256 | AG16: =ROUND($D$95,0) -> 13212 | AH16: =SUM(AF16:AG16) -> 1472468 | AI16: =$B$94 -> 96072 | AJ16: =AH16/AI16 -> 15.326713 | AK16: hr | AL16: IPC01 | AM16: see below | AN16: see below | AO16: =$F101/$B$142*B$26 -> 245986.66 | AP16: =$H101/$C$142*E$26 -> 634804.28 | AQ16: =$H101/$C$142*H$26 -> 264501.78 | AR16: =$F101/$B$142*K$26 -> 123522.33 | AS16: =$F101/$B$142*N$26 -> 0 | AT16: =$H101/$C$142*Q$26 -> 0 | AU16: =$F101/$B$142*T$26 -> 95220.641 | AV16: =$F101/$B$142*W$26 -> 95220.641 | AW16: =SUM(AO16:AV16) -> 1459256.3 | AX16: =$E101/$B$142*B$26 -> 16049.533 | AY16: =$G101/$C$142*E$26 -> 41418.148 | AZ16: =$G101/$C$142*H$26 -> 17257.562 | BA16: =$E101/$B$142*K$26 -> 8059.2814 | BB16: =$E101/$B$142*N$26 -> 0 | BC16: =$G101/$C$142*Q$26 -> 0 | BD16: =$E101/$B$142*T$26 -> 6212.7223 | BE16: =$E101/$B$142*W$26 -> 6212.7223 | BF16: =SUM(AX16:BE16) -> 95209.969 | BG16: =AW16/BF16 -> 15.326718 | BH16: =IF(AO$26<>0,ROUND(AX16/AO$26*1000,3),0) -> 1.726 | BI16: =IF(AP$26<>0,ROUND(AY16/AP$26*1000,3),0) -> 1.726 | BJ16: =IF(AQ$26<>0,ROUND(AZ16/AQ$26*1000,3),0) -> 1.726 | BK16: =IF(AR$26<>0,ROUND(BA16/AR$26*1000,3),0) -> 1.726 | BL16: =IF(AS$26<>0,ROUND(BB16/AS$26*1000,3),BH16) -> 1.726 | BM16: =IF(AT$26<>0,ROUND(BC16/AT$26*1000,3),BI16) -> 1.726 | BN16: =IF(AU$26<>0,ROUND(BD16/AU$26*1000,3),0) -> 1.726 | BO16: =IF(AV$26<>0,ROUND(BE16/AV$26*1000,3),0) -> 1.726 | BP16: =AC16*$AA$26 -> 1459.2563 | BQ16: =$AC16*AO$26/1000 -> 245.98666 | BR16: =$AC16*AP$26/1000 -> 634.80428 | BS16: =$AC16*AQ$26/1000 -> 264.50178 | BT16: =$AC16*AR$26/1000 -> 123.52233 | BU16: =$AC16*AS$26/1000 -> 0 | BV16: =$AC16*AT$26/1000 -> 0 | BW16: =$AC16*AU$26/1000 -> 95.220641 | BX16: =$AC16*AV$26/1000 -> 95.220641
